File: G 1- Incubated Samples test to failure-20210303/Specimen_RawData_1.csv
Specimen properties : Specimen label,"Sample-1"
Specimen properties : Length,"18.50000",mm
Specimen properties : Diameter,"0.35400",mm
Test : Rate 1,"5.00000",mm/min

Extension,Load,Tensile stress,Time,PIP count,Tenacity,Tensile extension,Tensile strain (Extension)
(mm),(N),(MPa),(s),,(N/tex),(mm),(mm/mm)
"0.00000","-0.00125","-0.01268","0.00000","0.00000","-0.00125","0.00000","0.00000"
"0.00000","-0.00259","-0.02630","0.03000","0.00000","-0.00259","0.00000","0.00000"
"0.00021","0.00606","0.06153","0.06000","0.00000","0.00606","0.00021","0.00001"
"0.00062","0.00547","0.05554","0.09000","0.00000","0.00547","0.00062","0.00003"
"0.00125","0.00919","0.09339","0.12000","0.00000","0.00919","0.00125","0.00007"
"0.00229","0.02549","0.25897","0.15000","0.00000","0.02549","0.00229","0.00012"
"0.00396","0.04077","0.41426","0.18000","0.00000","0.04077","0.00396","0.00021"
"0.00604","0.05640","0.57301","0.21000","0.00000","0.05640","0.00604","0.00033"
"0.00875","0.08230","0.83616","0.24000","0.00000","0.08230","0.00875","0.00047"
"0.01208","0.13050","1.32586","0.27000","0.00000","0.13050","0.01208","0.00065"
"0.01604","0.17091","1.73652","0.30000","0.00000","0.17091","0.01604","0.00087"
"0.02000","0.21688","2.20359","0.33000","0.00000","0.21688","0.02000","0.00108"
"0.02375","0.26111","2.65291","0.36000","0.00000","0.26111","0.02375","0.00128"
"0.02729","0.30287","3.07724","0.39000","0.00000","0.30287","0.02729","0.00148"
"0.03062","0.34614","3.51690","0.42000","0.00000","0.34614","0.03062","0.00166"
"0.03375","0.37674","3.82776","0.45000","0.00000","0.37674","0.03375","0.00182"
"0.03687","0.41585","4.22512","0.48000","0.00000","0.41585","0.03687","0.00199"
"0.03979","0.44212","4.49205","0.51000","0.00000","0.44212","0.03979","0.00215"
"0.04271","0.47317","4.80748","0.54000","0.00000","0.47317","0.04271","0.00231"
"0.04542","0.49564","5.03581","0.57000","0.00000","0.49564","0.04542","0.00245"
"0.04812","0.52605","5.34479","0.60000","0.00000","0.52605","0.04812","0.00260"
"0.05083","0.54840","5.57190","0.63000","0.00000","0.54840","0.05083","0.00275"
"0.05375","0.56922","5.78342","0.66000","0.00000","0.56922","0.05375","0.00291"
"0.05646","0.59140","6.00880","0.69000","0.00000","0.59140","0.05646","0.00305"
"0.05937","0.62164","6.31603","0.72000","0.00000","0.62164","0.05937","0.00321"
"0.06208","0.64227","6.52560","0.75000","0.00000","0.64227","0.06208","0.00336"
"0.06479","0.66529","6.75946","0.78000","0.00000","0.66529","0.06479","0.00350"
"0.06771","0.69310","7.04201","0.81000","0.00000","0.69310","0.06771","0.00366"
"0.07021","0.71259","7.24004","0.84000","0.00000","0.71259","0.07021","0.00380"
"0.07292","0.73477","7.46539","0.87000","0.00000","0.73477","0.07292","0.00394"
"0.07542","0.75097","7.63000","0.90000","0.00000","0.75097","0.07542","0.00408"
"0.07792","0.77541","7.87833","0.93000","0.00000","0.77541","0.07792","0.00421"
"0.08021","0.78929","8.01942","0.96000","0.00000","0.78929","0.08021","0.00434"
"0.08250","0.80029","8.13116","0.99000","0.00000","0.80029","0.08250","0.00446"
"0.08500","0.82661","8.39851","1.02000","0.00000","0.82661","0.08500","0.00459"
"0.08729","0.84319","8.56699","1.05000","0.00000","0.84319","0.08729","0.00472"
"0.08979","0.86061","8.74401","1.08000","0.00000","0.86061","0.08979","0.00485"
"0.09250","0.88200","8.96134","1.11000","0.00000","0.88200","0.09250","0.00500"
"0.09500","0.90905","9.23612","1.14000","0.00000","0.90905","0.09500","0.00514"
"0.09750","0.92459","9.39401","1.17000","0.00000","0.92459","0.09750","0.00527"
"0.10000","0.94282","9.57930","1.20000","0.00000","0.94282","0.10000","0.00541"
"0.10250","0.96290","9.78326","1.23000","0.00000","0.96290","0.10250","0.00554"
"0.10521","0.96606","9.81535","1.26000","0.00000","0.96606","0.10521","0.00569"
"0.10771","0.98561","10.01405","1.29000","0.00000","0.98561","0.10771","0.00582"
"0.11042","1.01892","10.35251","1.32000","0.00000","1.01892","0.11042","0.00597"
"0.11292","1.03625","10.52856","1.35000","0.00000","1.03625","0.11292","0.00610"
"0.11542","1.04051","10.57184","1.38000","0.00000","1.04051","0.11542","0.00624"
"0.11792","1.05978","10.76762","1.41000","0.00000","1.05978","0.11792","0.00637"
"0.12042","1.08945","11.06904","1.44000","0.00000","1.08945","0.12042","0.00651"
"0.12271","1.09504","11.12590","1.47000","0.00000","1.09504","0.12271","0.00663"
"0.12521","1.10751","11.25258","1.50000","0.00000","1.10751","0.12521","0.00677"
"0.12750","1.13640","11.54611","1.53000","0.00000","1.13640","0.12750","0.00689"
"0.13021","1.14827","11.66671","1.56000","0.00000","1.14827","0.13021","0.00704"
"0.13250","1.16233","11.80950","1.59000","0.00000","1.16233","0.13250","0.00716"
"0.13500","1.18420","12.03175","1.62000","0.00000","1.18420","0.13500","0.00730"
"0.13750","1.19556","12.14716","1.65000","0.00000","1.19556","0.13750","0.00743"
"0.14000","1.20961","12.28989","1.68000","0.00000","1.20961","0.14000","0.00757"
"0.14250","1.22552","12.45158","1.71000","0.00000","1.22552","0.14250","0.00770"
"0.14521","1.24663","12.66603","1.74000","0.00000","1.24663","0.14521","0.00785"
"0.14771","1.26272","12.82955","1.77000","0.00000","1.26272","0.14771","0.00798"
"0.15042","1.27924","12.99738","1.80000","0.00000","1.27924","0.15042","0.00813"
"0.15292","1.29355","13.14272","1.83000","0.00000","1.29355","0.15292","0.00827"
"0.15562","1.30195","13.22808","1.86000","0.00000","1.30195","0.15562","0.00841"
"0.15812","1.32450","13.45723","1.89000","0.00000","1.32450","0.15812","0.00855"
"0.16042","1.34113","13.62620","1.92000","0.00000","1.34113","0.16042","0.00867"
"0.16271","1.34764","13.69234","1.95000","0.00000","1.34764","0.16271","0.00880"
"0.16521","1.36229","13.84119","1.98000","0.00000","1.36229","0.16521","0.00893"
"0.16750","1.38376","14.05934","2.01000","0.00000","1.38376","0.16750","0.00905"
"0.17000","1.39282","14.15139","2.04000","0.00000","1.39282","0.17000","0.00919"
"0.17250","1.40267","14.25149","2.07000","0.00000","1.40267","0.17250","0.00932"
"0.17521","1.42100","14.43770","2.10000","0.00000","1.42100","0.17521","0.00947"
"0.17771","1.43770","14.60739","2.13000","0.00000","1.43770","0.17771","0.00961"
"0.18021","1.44998","14.73212","2.16000","0.00000","1.44998","0.18021","0.00974"
"0.18271","1.47079","14.94353","2.19000","0.00000","1.47079","0.18271","0.00988"
"0.18542","1.48530","15.09104","2.22000","0.00000","1.48530","0.18542","0.01002"
"0.18792","1.49421","15.18154","2.25000","0.00000","1.49421","0.18792","0.01016"
"0.19062","1.51706","15.41371","2.28000","0.00000","1.51706","0.19062","0.01030"
"0.19312","1.52591","15.50363","2.31000","0.00000","1.52591","0.19312","0.01044"
"0.19583","1.53793","15.62575","2.34000","0.00000","1.53793","0.19583","0.01059"
"0.19833","1.55672","15.81665","2.37000","0.00000","1.55672","0.19833","0.01072"
"0.20062","1.56922","15.94362","2.40000","0.00000","1.56922","0.20062","0.01084"
"0.20312","1.57643","16.01686","2.43000","0.00000","1.57643","0.20312","0.01098"
"0.20542","1.59825","16.23858","2.46000","0.00000","1.59825","0.20542","0.01110"
"0.20792","1.61528","16.41165","2.49000","0.00000","1.61528","0.20792","0.01124"
"0.21042","1.62082","16.46794","2.52000","0.00000","1.62082","0.21042","0.01137"
"0.21292","1.63109","16.57230","2.55000","0.00000","1.63109","0.21292","0.01151"
"0.21542","1.65108","16.77535","2.58000","0.00000","1.65108","0.21542","0.01164"
"0.21792","1.66697","16.93677","2.61000","0.00000","1.66697","0.21792","0.01178"
"0.22042","1.67689","17.03762","2.64000","0.00000","1.67689","0.22042","0.01191"
"0.22292","1.68935","17.16418","2.67000","0.00000","1.68935","0.22292","0.01205"
"0.22542","1.69861","17.25826","2.70000","0.00000","1.69861","0.22542","0.01218"
"0.22812","1.71522","17.42705","2.73000","0.00000","1.71522","0.22812","0.01233"
"0.23062","1.72764","17.55324","2.76000","0.00000","1.72764","0.23062","0.01247"
"0.23312","1.74807","17.76083","2.79000","0.00000","1.74807","0.23312","0.01260"
"0.23562","1.75871","17.86888","2.82000","0.00000","1.75871","0.23562","0.01274"
"0.23812","1.77295","18.01355","2.85000","0.00000","1.77295","0.23812","0.01287"
"0.24062","1.78134","18.09878","2.88000","0.00000","1.78134","0.24062","0.01301"
"0.24292","1.79414","18.22886","2.91000","0.00000","1.79414","0.24292","0.01313"
"0.24542","1.81277","18.41813","2.94000","0.00000","1.81277","0.24542","0.01327"
"0.24792","1.82258","18.51785","2.97000","0.00000","1.82258","0.24792","0.01340"
"0.25021","1.83494","18.64346","3.00000","0.00000","1.83494","0.25021","0.01352"
"0.25271","1.84976","18.79397","3.03000","0.00000","1.84976","0.25271","0.01366"
"0.25542","1.86028","18.90088","3.06000","0.00000","1.86028","0.25542","0.01381"
"0.25771","1.86822","18.98152","3.09000","0.00000","1.86822","0.25771","0.01393"
"0.26021","1.88477","19.14974","3.12000","0.00000","1.88477","0.26021","0.01407"
"0.26292","1.90367","19.34172","3.15000","0.00000","1.90367","0.26292","0.01421"
"0.26542","1.90453","19.35050","3.18000","0.00000","1.90453","0.26542","0.01435"
"0.26792","1.91136","19.41987","3.21000","0.00000","1.91136","0.26792","0.01448"
"0.27042","1.92113","19.51913","3.24000","0.00000","1.92113","0.27042","0.01462"
"0.27312","1.94135","19.72458","3.27000","0.00000","1.94135","0.27312","0.01476"
"0.27562","1.95526","19.86590","3.30000","0.00000","1.95526","0.27562","0.01490"
"0.27833","1.96777","19.99296","3.33000","0.00000","1.96777","0.27833","0.01505"
"0.28062","1.97955","20.11268","3.36000","0.00000","1.97955","0.28062","0.01517"
"0.28312","1.98671","20.18545","3.39000","0.00000","1.98671","0.28312","0.01530"
"0.28562","2.00087","20.32928","3.42000","0.00000","2.00087","0.28562","0.01544"
"0.28792","2.01474","20.47022","3.45000","0.00000","2.01474","0.28792","0.01556"
"0.29042","2.02496","20.57404","3.48000","0.00000","2.02496","0.29042","0.01570"
"0.29292","2.04193","20.74652","3.51000","0.00000","2.04193","0.29292","0.01583"
"0.29542","2.05693","20.89890","3.54000","0.00000","2.05693","0.29542","0.01597"
"0.29771","2.06445","20.97527","3.57000","0.00000","2.06445","0.29771","0.01609"
"0.30042","2.08206","21.15426","3.60000","0.00000","2.08206","0.30042","0.01624"
"0.30292","2.09479","21.28354","3.63000","0.00000","2.09479","0.30292","0.01637"
"0.30542","2.11073","21.44553","3.66000","0.00000","2.11073","0.30542","0.01651"
"0.30792","2.11936","21.53321","3.69000","0.00000","2.11936","0.30792","0.01664"
"0.31021","2.12515","21.59203","3.72000","0.00000","2.12515","0.31021","0.01677"
"0.31271","2.13279","21.66969","3.75000","0.00000","2.13279","0.31271","0.01690"
"0.31521","2.14976","21.84202","3.78000","0.00000","2.14976","0.31521","0.01704"
"0.31792","2.16420","21.98882","3.81000","0.00000","2.16420","0.31792","0.01718"
"0.32042","2.17749","22.12379","3.84000","0.00000","2.17749","0.32042","0.01732"
"0.32271","2.19044","22.25541","3.87000","0.00000","2.19044","0.32271","0.01744"
"0.32542","2.20489","22.40223","3.90000","0.00000","2.20489","0.32542","0.01759"
"0.32792","2.21346","22.48929","3.93000","0.00000","2.21346","0.32792","0.01773"
"0.33021","2.22859","22.64296","3.96000","0.00000","2.22859","0.33021","0.01785"
"0.33271","2.23369","22.69481","3.99000","0.00000","2.23369","0.33271","0.01798"
"0.33521","2.24515","22.81124","4.02000","0.00000","2.24515","0.33521","0.01812"
"0.33771","2.25949","22.95695","4.05000","0.00000","2.25949","0.33771","0.01825"
"0.34000","2.27122","23.07614","4.08000","0.00000","2.27122","0.34000","0.01838"
"0.34271","2.28030","23.16840","4.11000","0.00000","2.28030","0.34271","0.01852"
"0.34542","2.29828","23.35110","4.14000","0.00000","2.29828","0.34542","0.01867"
"0.34771","2.31304","23.50099","4.17000","0.00000","2.31304","0.34771","0.01880"
"0.35021","2.32311","23.60338","4.20000","0.00000","2.32311","0.35021","0.01893"
"0.35250","2.33643","23.73866","4.23000","0.00000","2.33643","0.35250","0.01905"
"0.35521","2.35075","23.88417","4.26000","0.00000","2.35075","0.35521","0.01920"
"0.35771","2.36230","24.00153","4.29000","0.00000","2.36230","0.35771","0.01934"
"0.36021","2.36847","24.06416","4.32000","0.00000","2.36847","0.36021","0.01947"
"0.36271","2.37988","24.18012","4.35000","0.00000","2.37988","0.36271","0.01961"
"0.36521","2.40115","24.39623","4.38000","0.00000","2.40115","0.36521","0.01974"
"0.36792","2.41083","24.49462","4.41000","0.00000","2.41083","0.36792","0.01989"
"0.37021","2.42141","24.60213","4.44000","0.00000","2.42141","0.37021","0.02001"
"0.37271","2.43213","24.71101","4.47000","0.00000","2.43213","0.37271","0.02015"
"0.37521","2.44915","24.88394","4.50000","0.00000","2.44915","0.37521","0.02028"
"0.37771","2.45868","24.98081","4.53000","0.00000","2.45868","0.37771","0.02042"
"0.38021","2.47053","25.10111","4.56000","0.00000","2.47053","0.38021","0.02055"
"0.38271","2.48587","25.25697","4.59000","0.00000","2.48587","0.38271","0.02069"
"0.38542","2.50038","25.40442","4.62000","0.00000","2.50038","0.38542","0.02083"
"0.38771","2.50664","25.46809","4.65000","0.00000","2.50664","0.38771","0.02096"
"0.39042","2.52646","25.66945","4.68000","0.00000","2.52646","0.39042","0.02110"
"0.39292","2.53307","25.73658","4.71000","0.00000","2.53307","0.39292","0.02124"
"0.39542","2.54815","25.88983","4.74000","0.00000","2.54815","0.39542","0.02137"
"0.39792","2.54976","25.90616","4.77000","0.00000","2.54976","0.39792","0.02151"
"0.40062","2.56308","26.04152","4.80000","0.00000","2.56308","0.40062","0.02166"
"0.40312","2.58146","26.22823","4.83000","0.00000","2.58146","0.40312","0.02179"
"0.40583","2.59544","26.37026","4.86000","0.00000","2.59544","0.40583","0.02194"
"0.40833","2.60948","26.51292","4.89000","0.00000","2.60948","0.40833","0.02207"
"0.41083","2.61948","26.61450","4.92000","0.00000","2.61948","0.41083","0.02221"
"0.41333","2.63287","26.75052","4.95000","0.00000","2.63287","0.41333","0.02234"
"0.41583","2.64491","26.87287","4.98000","0.00000","2.64491","0.41583","0.02248"
"0.41833","2.65616","26.98721","5.01000","0.00000","2.65616","0.41833","0.02261"
"0.42083","2.66006","27.02680","5.04000","0.00000","2.66006","0.42083","0.02275"
"0.42312","2.67673","27.19617","5.07000","0.00000","2.67673","0.42312","0.02287"
"0.42562","2.68832","27.31395","5.10000","0.00000","2.68832","0.42562","0.02301"
"0.42792","2.69743","27.40651","5.13000","0.00000","2.69743","0.42792","0.02313"
"0.43042","2.70805","27.51440","5.16000","0.00000","2.70805","0.43042","0.02327"
"0.43292","2.72201","27.65627","5.19000","0.00000","2.72201","0.43292","0.02340"
"0.43542","2.72957","27.73310","5.22000","0.00000","2.72957","0.43542","0.02354"
"0.43771","2.73743","27.81297","5.25000","0.00000","2.73743","0.43771","0.02366"
"0.44021","2.74744","27.91461","5.28000","0.00000","2.74744","0.44021","0.02380"
"0.44271","2.75957","28.03791","5.31000","0.00000","2.75957","0.44271","0.02393"
"0.44542","2.77010","28.14486","5.34000","0.00000","2.77010","0.44542","0.02408"
"0.44792","2.77547","28.19938","5.37000","0.00000","2.77547","0.44792","0.02421"
"0.45042","2.79351","28.38269","5.40000","0.00000","2.79351","0.45042","0.02435"
"0.45292","2.80235","28.47248","5.43000","0.00000","2.80235","0.45292","0.02448"
"0.45542","2.81700","28.62136","5.46000","0.00000","2.81700","0.45542","0.02462"
"0.45792","2.83209","28.77469","5.49000","0.00000","2.83209","0.45792","0.02475"
"0.46042","2.84038","28.85892","5.52000","0.00000","2.84038","0.46042","0.02489"
"0.46292","2.85196","28.97661","5.55000","0.00000","2.85196","0.46292","0.02502"
"0.46542","2.86481","29.10710","5.58000","0.00000","2.86481","0.46542","0.02516"
"0.46792","2.87785","29.23964","5.61000","0.00000","2.87785","0.46792","0.02529"
"0.47042","2.87907","29.25206","5.64000","0.00000","2.87907","0.47042","0.02543"
"0.47292","2.89210","29.38444","5.67000","0.00000","2.89210","0.47292","0.02556"
"0.47542","2.90338","29.49903","5.70000","0.00000","2.90338","0.47542","0.02570"
"0.47792","2.91744","29.64187","5.73000","0.00000","2.91744","0.47792","0.02583"
"0.48021","2.92449","29.71348","5.76000","0.00000","2.92449","0.48021","0.02596"
"0.48271","2.93217","29.79148","5.79000","0.00000","2.93217","0.48271","0.02609"
"0.48542","2.94352","29.90686","5.82000","0.00000","2.94352","0.48542","0.02624"
"0.48792","2.95811","30.05504","5.85000","0.00000","2.95811","0.48792","0.02637"
"0.49062","2.96833","30.15897","5.88000","0.00000","2.96833","0.49062","0.02652"
"0.49312","2.97721","30.24914","5.91000","0.00000","2.97721","0.49312","0.02666"
"0.49562","2.99253","30.40478","5.94000","0.00000","2.99253","0.49562","0.02679"
"0.49812","3.00332","30.51439","5.97000","0.00000","3.00332","0.49812","0.02693"
"0.50062","3.00920","30.57412","6.00000","0.00000","3.00920","0.50062","0.02706"
"0.50312","3.02056","30.68955","6.03000","0.00000","3.02056","0.50312","0.02720"
"0.50562","3.03260","30.81190","6.06000","0.00000","3.03260","0.50562","0.02733"
"0.50792","3.04287","30.91629","6.09000","0.00000","3.04287","0.50792","0.02745"
"0.51042","3.05465","31.03596","6.12000","0.00000","3.05465","0.51042","0.02759"
"0.51292","3.06180","31.10859","6.15000","0.00000","3.06180","0.51292","0.02773"
"0.51521","3.07567","31.24947","6.18000","0.00000","3.07567","0.51521","0.02785"
"0.51750","3.07347","31.22718","6.21000","0.00000","3.07347","0.51750","0.02797"
"0.52000","3.08834","31.37825","6.24000","0.00000","3.08834","0.52000","0.02811"
"0.52250","3.09289","31.42448","6.27000","0.00000","3.09289","0.52250","0.02824"
"0.52500","3.10201","31.51714","6.30000","0.00000","3.10201","0.52500","0.02838"
"0.52771","3.12019","31.70184","6.33000","0.00000","3.12019","0.52771","0.02852"
"0.53021","3.13045","31.80613","6.36000","0.00000","3.13045","0.53021","0.02866"
"0.53292","3.14489","31.95280","6.39000","0.00000","3.14489","0.53292","0.02881"
"0.53542","3.15345","32.03979","6.42000","0.00000","3.15345","0.53542","0.02894"
"0.53792","3.16203","32.12700","6.45000","0.00000","3.16203","0.53792","0.02908"
"0.54042","3.17208","32.22908","6.48000","0.00000","3.17208","0.54042","0.02921"
"0.54312","3.17830","32.29223","6.51000","0.00000","3.17830","0.54312","0.02936"
"0.54542","3.19186","32.43001","6.54000","0.00000","3.19186","0.54542","0.02948"
"0.54792","3.19996","32.51232","6.57000","0.00000","3.19996","0.54792","0.02962"
"0.55042","3.20611","32.57486","6.60000","0.00000","3.20611","0.55042","0.02975"
"0.55271","3.21783","32.69391","6.63000","0.00000","3.21783","0.55271","0.02988"
"0.55500","3.22733","32.79039","6.66000","0.00000","3.22733","0.55500","0.03000"
"0.55750","3.23435","32.86177","6.69000","0.00000","3.23435","0.55750","0.03014"
"0.56000","3.24241","32.94368","6.72000","0.00000","3.24241","0.56000","0.03027"
"0.56250","3.25440","33.06547","6.75000","0.00000","3.25440","0.56250","0.03041"
"0.56500","3.25749","33.09690","6.78000","0.00000","3.25749","0.56500","0.03054"
"0.56771","3.26858","33.20951","6.81000","0.00000","3.26858","0.56771","0.03069"
"0.57021","3.28001","33.32571","6.84000","0.00000","3.28001","0.57021","0.03082"
"0.57292","3.29015","33.42864","6.87000","0.00000","3.29015","0.57292","0.03097"
"0.57562","3.30356","33.56490","6.90000","0.00000","3.30356","0.57562","0.03111"
"0.57812","3.31631","33.69446","6.93000","0.00000","3.31631","0.57812","0.03125"
"0.58062","3.32010","33.73296","6.96000","0.00000","3.32010","0.58062","0.03139"
"0.58292","3.32514","33.78424","6.99000","0.00000","3.32514","0.58292","0.03151"
"0.58542","3.33491","33.88346","7.02000","0.00000","3.33491","0.58542","0.03164"
"0.58792","3.34452","33.98112","7.05000","0.00000","3.34452","0.58792","0.03178"
"0.59021","3.34947","34.03141","7.08000","0.00000","3.34947","0.59021","0.03190"
"0.59271","3.35801","34.11814","7.11000","0.00000","3.35801","0.59271","0.03204"
"0.59521","3.37089","34.24898","7.14000","0.00000","3.37089","0.59521","0.03217"
"0.59750","3.38593","34.40188","7.17000","0.00000","3.38593","0.59750","0.03230"
"0.60000","3.38667","34.40940","7.20000","0.00000","3.38667","0.60000","0.03243"
"0.60271","3.39834","34.52790","7.23000","0.00000","3.39834","0.60271","0.03258"
"0.60542","3.40299","34.57520","7.26000","0.00000","3.40299","0.60542","0.03273"
"0.60792","3.41668","34.71421","7.29000","0.00000","3.41668","0.60792","0.03286"
"0.61062","3.41929","34.74074","7.32000","0.00000","3.41929","0.61062","0.03301"
"0.61312","3.42877","34.83709","7.35000","0.00000","3.42877","0.61312","0.03314"
"0.61583","3.44342","34.98597","7.38000","0.00000","3.44342","0.61583","0.03329"
"0.61833","3.46100","35.16456","7.41000","0.00000","3.46100","0.61833","0.03342"
"0.62083","3.46833","35.23909","7.44000","0.00000","3.46833","0.62083","0.03356"
"0.62333","3.46833","35.23900","7.47000","0.00000","3.46833","0.62333","0.03369"
"0.62583","3.48083","35.36603","7.50000","0.00000","3.48083","0.62583","0.03383"
"0.62812","3.48897","35.44879","7.53000","0.00000","3.48897","0.62813","0.03395"
"0.63062","3.49694","35.52968","7.56000","0.00000","3.49694","0.63062","0.03409"
"0.63292","3.50616","35.62335","7.59000","0.00000","3.50616","0.63292","0.03421"
"0.63521","3.50192","35.58033","7.62000","0.00000","3.50192","0.63521","0.03434"
"0.63771","3.51403","35.70333","7.65000","0.00000","3.51403","0.63771","0.03447"
"0.64000","3.52224","35.78676","7.68000","0.00000","3.52224","0.64000","0.03459"
"0.64250","3.53496","35.91599","7.71000","0.00000","3.53496","0.64250","0.03473"
"0.64521","3.54398","36.00767","7.74000","0.00000","3.54398","0.64521","0.03488"
"0.64771","3.55004","36.06919","7.77000","0.00000","3.55004","0.64771","0.03501"
"0.65042","3.56092","36.17973","7.80000","0.00000","3.56092","0.65042","0.03516"
"0.65292","3.56936","36.26551","7.83000","0.00000","3.56936","0.65292","0.03529"
"0.65542","3.57644","36.33741","7.86000","0.00000","3.57644","0.65542","0.03543"
"0.65812","3.58161","36.38995","7.89000","0.00000","3.58161","0.65812","0.03557"
"0.66062","3.58873","36.46236","7.92000","0.00000","3.58873","0.66062","0.03571"
"0.66312","3.59781","36.55458","7.95000","0.00000","3.59781","0.66312","0.03584"
"0.66562","3.60706","36.64858","7.98000","0.00000","3.60706","0.66562","0.03598"
"0.66792","3.61661","36.74556","8.01000","0.00000","3.61661","0.66792","0.03610"
"0.67042","3.61689","36.74842","8.04000","0.00000","3.61689","0.67042","0.03624"
"0.67292","3.62586","36.83959","8.07000","0.00000","3.62586","0.67292","0.03637"
"0.67500","3.63256","36.90760","8.10000","0.00000","3.63256","0.67500","0.03649"
"0.67750","3.63926","36.97569","8.13000","0.00000","3.63926","0.67750","0.03662"
"0.68000","3.65651","37.15101","8.16000","0.00000","3.65651","0.68000","0.03676"
"0.68250","3.65702","37.15612","8.19000","0.00000","3.65702","0.68250","0.03689"
"0.68521","3.67139","37.30222","8.22000","0.00000","3.67139","0.68521","0.03704"
"0.68771","3.67650","37.35409","8.25000","0.00000","3.67650","0.68771","0.03717"
"0.69021","3.67465","37.33527","8.28000","0.00000","3.67465","0.69021","0.03731"
"0.69292","3.68087","37.39851","8.31000","0.00000","3.68087","0.69292","0.03745"
"0.69542","3.68831","37.47405","8.34000","0.00000","3.68831","0.69542","0.03759"
"0.69792","3.69881","37.58075","8.37000","0.00000","3.69881","0.69792","0.03773"
"0.70042","3.70620","37.65585","8.40000","0.00000","3.70620","0.70042","0.03786"
"0.70312","3.71644","37.75986","8.43000","0.00000","3.71644","0.70312","0.03801"
"0.70562","3.72069","37.80311","8.46000","0.00000","3.72069","0.70562","0.03814"
"0.70792","3.71983","37.79437","8.49000","0.00000","3.71983","0.70792","0.03827"
"0.71042","3.73144","37.91229","8.52000","0.00000","3.73144","0.71042","0.03840"
"0.71271","3.74322","38.03201","8.55000","0.00000","3.74322","0.71271","0.03852"
"0.71521","3.74470","38.04706","8.58000","0.00000","3.74470","0.71521","0.03866"
"0.71750","3.75241","38.12534","8.61000","0.00000","3.75241","0.71750","0.03878"
"0.72000","3.75870","38.18924","8.64000","0.00000","3.75870","0.72000","0.03892"
"0.72250","3.77369","38.34155","8.67000","0.00000","3.77369","0.72250","0.03905"
"0.72500","3.76935","38.29745","8.70000","0.00000","3.76935","0.72500","0.03919"
"0.72750","3.77541","38.35902","8.73000","0.00000","3.77541","0.72750","0.03932"
"0.73000","3.78644","38.47108","8.76000","0.00000","3.78644","0.73000","0.03946"
"0.73271","3.79879","38.59662","8.79000","0.00000","3.79879","0.73271","0.03961"
"0.73521","3.80377","38.64718","8.82000","0.00000","3.80377","0.73521","0.03974"
"0.73792","3.80876","38.69783","8.85000","0.00000","3.80876","0.73792","0.03989"
"0.74042","3.81341","38.74516","8.88000","0.00000","3.81341","0.74042","0.04002"
"0.74312","3.82044","38.81659","8.91000","0.00000","3.82044","0.74312","0.04017"
"0.74562","3.83021","38.91583","8.94000","0.00000","3.83021","0.74562","0.04030"
"0.74812","3.83610","38.97567","8.97000","0.00000","3.83610","0.74812","0.04044"
"0.75042","3.84063","39.02169","9.00000","0.00000","3.84063","0.75042","0.04056"
"0.75292","3.84449","39.06093","9.03000","0.00000","3.84449","0.75292","0.04070"
"0.75521","3.85631","39.18105","9.06000","0.00000","3.85631","0.75521","0.04082"
"0.75750","3.85806","39.19874","9.09000","0.00000","3.85806","0.75750","0.04095"
"0.76000","3.86223","39.24116","9.12000","0.00000","3.86223","0.76000","0.04108"
"0.76250","3.86525","39.27180","9.15000","0.00000","3.86525","0.76250","0.04122"
"0.76500","3.86984","39.31849","9.18000","0.00000","3.86984","0.76500","0.04135"
"0.76750","3.87556","39.37657","9.21000","0.00000","3.87556","0.76750","0.04149"
"0.77000","3.87477","39.36861","9.24000","0.00000","3.87477","0.77000","0.04162"
"0.77271","3.89046","39.52800","9.27000","0.00000","3.89046","0.77271","0.04177"
"0.77521","3.90288","39.65420","9.30000","0.00000","3.90288","0.77521","0.04190"
"0.77771","3.90226","39.64782","9.33000","0.00000","3.90226","0.77771","0.04204"
"0.78042","3.90866","39.71290","9.36000","0.00000","3.90866","0.78042","0.04218"
"0.78292","3.91466","39.77388","9.39000","0.00000","3.91466","0.78292","0.04232"
"0.78562","3.92634","39.89251","9.42000","0.00000","3.92634","0.78562","0.04247"
"0.78792","3.92558","39.88477","9.45000","0.00000","3.92558","0.78792","0.04259"
"0.79042","3.93080","39.93788","9.48000","0.00000","3.93080","0.79042","0.04273"
"0.79271","3.93559","39.98647","9.51000","0.00000","3.93559","0.79271","0.04285"
"0.79521","3.94072","40.03866","9.54000","0.00000","3.94072","0.79521","0.04298"
"0.79750","3.94359","40.06775","9.57000","0.00000","3.94359","0.79750","0.04311"
"0.80021","3.94939","40.12677","9.60000","0.00000","3.94939","0.80021","0.04325"
"0.80250","3.95392","40.17274","9.63000","0.00000","3.95392","0.80250","0.04338"
"0.80521","3.96507","40.28601","9.66000","0.00000","3.96507","0.80521","0.04352"
"0.80771","3.96956","40.33160","9.69000","0.00000","3.96956","0.80771","0.04366"
"0.81021","3.96833","40.31915","9.72000","0.00000","3.96833","0.81021","0.04380"
"0.81292","3.97664","40.40361","9.75000","0.00000","3.97664","0.81292","0.04394"
"0.81562","3.98182","40.45619","9.78000","0.00000","3.98182","0.81562","0.04409"
"0.81812","3.98435","40.48192","9.81000","0.00000","3.98435","0.81812","0.04422"
"0.82083","3.98847","40.52376","9.84000","0.00000","3.98847","0.82083","0.04437"
"0.82333","4.00253","40.66666","9.87000","0.00000","4.00253","0.82333","0.04450"
"0.82583","4.01392","40.78235","9.90000","0.00000","4.01392","0.82583","0.04464"
"0.82833","4.01634","40.80693","9.93000","0.00000","4.01634","0.82833","0.04477"
"0.83083","4.00846","40.72689","9.96000","0.00000","4.00846","0.83083","0.04491"
"0.83312","4.00812","40.72343","9.99000","0.00000","4.00812","0.83312","0.04503"
"0.83542","4.01009","40.74345","10.02000","0.00000","4.01009","0.83542","0.04516"
"0.83771","4.01811","40.82497","10.05000","0.00000","4.01811","0.83771","0.04528"
"0.84021","4.02723","40.91762","10.08000","0.00000","4.02723","0.84021","0.04542"
"0.84250","4.02826","40.92802","10.11000","0.00000","4.02826","0.84250","0.04554"
"0.84500","4.02518","40.89681","10.14000","0.00000","4.02518","0.84500","0.04568"
"0.84750","4.03842","41.03130","10.17000","0.00000","4.03842","0.84750","0.04581"
"0.85021","4.04481","41.09622","10.20000","0.00000","4.04481","0.85021","0.04596"
"0.85271","4.04595","41.10777","10.23000","0.00000","4.04595","0.85271","0.04609"
"0.85521","4.04303","41.07811","10.26000","0.00000","4.04303","0.85521","0.04623"
"0.85792","4.04681","41.11655","10.29000","0.00000","4.04681","0.85792","0.04637"
"0.86062","4.05414","41.19099","10.32000","0.00000","4.05414","0.86062","0.04652"
"0.86312","4.05625","41.21244","10.35000","0.00000","4.05625","0.86312","0.04666"
"0.86562","4.05879","41.23828","10.38000","0.00000","4.05879","0.86562","0.04679"
"0.86812","4.05824","41.23266","10.41000","0.00000","4.05824","0.86812","0.04693"
"0.87062","4.06400","41.29116","10.44000","0.00000","4.06400","0.87062","0.04706"
"0.87312","4.07191","41.37158","10.47000","0.00000","4.07191","0.87312","0.04720"
"0.87542","4.07047","41.35696","10.50000","0.00000","4.07047","0.87542","0.04732"
"0.87771","4.07048","41.35701","10.53000","0.00000","4.07048","0.87771","0.04744"
"0.88021","4.07434","41.39623","10.56000","0.00000","4.07434","0.88021","0.04758"
"0.88250","4.08006","41.45439","10.59000","0.00000","4.08006","0.88250","0.04770"
"0.88500","4.08739","41.52879","10.62000","0.00000","4.08739","0.88500","0.04784"
"0.88750","4.08857","41.54077","10.65000","0.00000","4.08857","0.88750","0.04797"
"0.89000","4.08435","41.49796","10.68000","0.00000","4.08435","0.89000","0.04811"
"0.89271","4.08244","41.47852","10.71000","0.00000","4.08244","0.89271","0.04825"
"0.89521","4.09532","41.60944","10.74000","0.00000","4.09532","0.89521","0.04839"
"0.89792","4.09854","41.64212","10.77000","0.00000","4.09854","0.89792","0.04854"
"0.90042","4.09372","41.59313","10.80000","0.00000","4.09372","0.90042","0.04867"
"0.90312","4.09147","41.57032","10.83000","0.00000","4.09147","0.90312","0.04882"
"0.90562","4.10263","41.68369","10.86000","0.00000","4.10263","0.90562","0.04895"
"0.90812","4.09448","41.60084","10.89000","0.00000","4.09448","0.90812","0.04909"
"0.91062","4.09429","41.59895","10.92000","0.00000","4.09429","0.91062","0.04922"
"0.91292","4.09824","41.63904","10.95000","0.00000","4.09824","0.91292","0.04935"
"0.91521","4.10291","41.68657","10.98000","0.00000","4.10291","0.91521","0.04947"
"0.91771","4.10219","41.67921","11.01000","0.00000","4.10219","0.91771","0.04961"
"0.92000","4.10520","41.70974","11.04000","0.00000","4.10520","0.92000","0.04973"
"0.92250","4.09538","41.61003","11.07000","0.00000","4.09538","0.92250","0.04986"
"0.92500","4.09262","41.58194","11.10000","0.00000","4.09262","0.92500","0.05000"
"0.92750","4.09847","41.64139","11.13000","0.00000","4.09847","0.92750","0.05014"
"0.93000","4.10445","41.70217","11.16000","0.00000","4.10445","0.93000","0.05027"
"0.93250","4.10395","41.69713","11.19000","0.00000","4.10395","0.93250","0.05041"
"0.93521","4.10841","41.74238","11.22000","0.00000","4.10841","0.93521","0.05055"
"0.93771","4.11108","41.76951","11.25000","0.00000","4.11108","0.93771","0.05069"
"0.94021","4.11253","41.78424","11.28000","0.00000","4.11253","0.94021","0.05082"
"0.94292","4.11243","41.78327","11.31000","0.00000","4.11243","0.94292","0.05097"
"0.94542","4.11577","41.81717","11.34000","0.00000","4.11577","0.94542","0.05110"
"0.94812","4.11610","41.82057","11.37000","0.00000","4.11610","0.94812","0.05125"
"0.95062","4.11616","41.82116","11.40000","0.00000","4.11616","0.95062","0.05139"
"0.95292","4.10818","41.74008","11.43000","0.00000","4.10818","0.95292","0.05151"
"0.95542","4.11260","41.78500","11.46000","0.00000","4.11260","0.95542","0.05164"
"0.95771","4.11314","41.79042","11.49000","0.00000","4.11314","0.95771","0.05177"
"0.96021","4.11530","41.81236","11.52000","0.00000","4.11530","0.96021","0.05190"
"0.96271","4.11701","41.82978","11.55000","0.00000","4.11701","0.96271","0.05204"
"0.96521","4.11687","41.82839","11.58000","0.00000","4.11687","0.96521","0.05217"
"0.96750","4.11029","41.76147","11.61000","0.00000","4.11029","0.96750","0.05230"
"0.97000","4.11473","41.80658","11.64000","0.00000","4.11473","0.97000","0.05243"
"0.97250","4.11756","41.83538","11.67000","0.00000","4.11756","0.97250","0.05257"
"0.97500","4.11924","41.85240","11.70000","0.00000","4.11924","0.97500","0.05270"
"0.97750","4.11634","41.82293","11.73000","0.00000","4.11634","0.97750","0.05284"
"0.98021","4.11609","41.82044","11.76000","0.00000","4.11609","0.98021","0.05298"
"0.98271","4.11235","41.78242","11.79000","0.00000","4.11235","0.98271","0.05312"
"0.98521","4.11724","41.83212","11.82000","0.00000","4.11724","0.98521","0.05325"
"0.98792","4.11560","41.81544","11.85000","0.00000","4.11560","0.98792","0.05340"
"0.99042","4.11012","41.75978","11.88000","0.00000","4.11012","0.99042","0.05354"
"0.99292","4.11132","41.77192","11.91000","0.00000","4.11132","0.99292","0.05367"
"0.99521","4.11313","41.79032","11.94000","0.00000","4.11313","0.99521","0.05380"
"0.99771","4.11466","41.80589","11.97000","0.00000","4.11466","0.99771","0.05393"
"1.00021","4.10797","41.73792","12.00000","0.00000","4.10797","1.00021","0.05407"
"1.00271","4.11519","41.81131","12.03000","0.00000","4.11519","1.00271","0.05420"
"1.00500","4.10217","41.67902","12.06000","0.00000","4.10217","1.00500","0.05432"
"1.00771","4.10223","41.67957","12.09000","0.00000","4.10223","1.00771","0.05447"
"1.01021","4.09844","41.64111","12.12000","0.00000","4.09844","1.01021","0.05461"
"1.01250","4.09327","41.58859","12.15000","0.00000","4.09327","1.01250","0.05473"
"1.01500","4.09505","41.60666","12.18000","0.00000","4.09505","1.01500","0.05486"
"1.01771","4.09291","41.58493","12.21000","0.00000","4.09291","1.01771","0.05501"
"1.02042","4.09408","41.59681","12.24000","0.00000","4.09408","1.02042","0.05516"
"1.02292","4.09076","41.56309","12.27000","0.00000","4.09076","1.02292","0.05529"
"1.02562","4.08804","41.53547","12.30000","0.00000","4.08804","1.02562","0.05544"
"1.02833","4.08341","41.48838","12.33000","0.00000","4.08341","1.02833","0.05559"
"1.03083","4.07510","41.40401","12.36000","0.00000","4.07510","1.03083","0.05572"
"1.03333","4.07424","41.39523","12.39000","0.00000","4.07424","1.03333","0.05586"
"1.03562","4.07321","41.38471","12.42000","0.00000","4.07321","1.03562","0.05598"
"1.03812","4.05437","41.19334","12.45000","0.00000","4.05437","1.03812","0.05611"
"1.04042","4.05421","41.19167","12.48000","0.00000","4.05421","1.04042","0.05624"
"1.04312","4.04725","41.12096","12.51000","0.00000","4.04725","1.04312","0.05639"
"1.04542","4.03751","41.02205","12.54000","0.00000","4.03751","1.04542","0.05651"
"1.04792","4.03219","40.96797","12.57000","0.00000","4.03219","1.04792","0.05664"
"1.05042","4.02763","40.92163","12.60000","0.00000","4.02763","1.05042","0.05678"
"1.05292","4.02035","40.84764","12.63000","0.00000","4.02035","1.05292","0.05691"
"1.05542","4.01781","40.82192","12.66000","0.00000","4.01781","1.05542","0.05705"
"1.05792","4.00904","40.73280","12.69000","0.00000","4.00904","1.05792","0.05718"
"1.06042","4.00884","40.73075","12.72000","0.00000","4.00884","1.06042","0.05732"
"1.06292","4.00452","40.68689","12.75000","0.00000","4.00452","1.06292","0.05745"
"1.06562","3.99095","40.54896","12.78000","0.00000","3.99095","1.06562","0.05760"
"1.06812","3.98246","40.46272","12.81000","0.00000","3.98246","1.06812","0.05774"
"1.07062","3.97898","40.42738","12.84000","0.00000","3.97898","1.07062","0.05787"
"1.07312","3.97960","40.43363","12.87000","0.00000","3.97960","1.07312","0.05801"
"1.07562","3.96342","40.26925","12.90000","0.00000","3.96342","1.07562","0.05814"
"1.07812","3.96269","40.26186","12.93000","0.00000","3.96269","1.07812","0.05828"
"1.08042","3.95376","40.17111","12.96000","0.00000","3.95376","1.08042","0.05840"
"1.08292","3.94359","40.06781","12.99000","0.00000","3.94359","1.08292","0.05854"
"1.08542","3.92478","39.87670","13.02000","0.00000","3.92478","1.08542","0.05867"
"1.08792","3.92100","39.83824","13.05000","0.00000","3.92100","1.08792","0.05881"
"1.09021","3.90939","39.72030","13.08000","0.00000","3.90939","1.09021","0.05893"
"1.09271","3.90301","39.65553","13.11000","0.00000","3.90301","1.09271","0.05907"
"1.09521","3.89327","39.55650","13.14000","0.00000","3.89327","1.09521","0.05920"
"1.09792","3.88159","39.43781","13.17000","0.00000","3.88159","1.09792","0.05935"
"1.10042","3.86584","39.27782","13.20000","0.00000","3.86584","1.10042","0.05948"
"1.10292","3.85263","39.14362","13.23000","0.00000","3.85263","1.10292","0.05962"
"1.10542","3.83688","38.98361","13.26000","0.00000","3.83688","1.10542","0.05975"
"1.10812","3.82681","38.88128","13.29000","0.00000","3.82681","1.10812","0.05990"
"1.11062","3.81933","38.80532","13.32000","0.00000","3.81933","1.11062","0.06003"
"1.11312","3.80251","38.63435","13.35000","0.00000","3.80251","1.11312","0.06017"
"1.11562","3.78503","38.45683","13.38000","0.00000","3.78503","1.11562","0.06030"
"1.11792","3.76863","38.29020","13.41000","0.00000","3.76863","1.11792","0.06043"
"1.12042","3.75126","38.11367","13.44000","0.00000","3.75126","1.12042","0.06056"
"1.12292","3.74209","38.02045","13.47000","0.00000","3.74209","1.12292","0.06070"
"1.12542","3.71740","37.76967","13.50000","0.00000","3.71740","1.12542","0.06083"
"1.12792","3.70787","37.67286","13.53000","0.00000","3.70787","1.12792","0.06097"
"1.13021","3.69936","37.58631","13.56000","0.00000","3.69936","1.13021","0.06109"
"1.13271","3.67816","37.37095","13.59000","0.00000","3.67816","1.13271","0.06123"
"1.13542","3.65333","37.11873","13.62000","0.00000","3.65333","1.13542","0.06137"
"1.13792","3.62846","36.86598","13.65000","0.00000","3.62846","1.13792","0.06151"
"1.14042","3.60660","36.64385","13.68000","0.00000","3.60660","1.14042","0.06164"
"1.14292","3.58661","36.44076","13.71000","0.00000","3.58661","1.14292","0.06178"
"1.14542","3.57047","36.27684","13.74000","0.00000","3.57047","1.14542","0.06191"
"1.14792","3.54501","36.01813","13.77000","0.00000","3.54501","1.14792","0.06205"
"1.15042","3.52641","35.82909","13.80000","0.00000","3.52641","1.15042","0.06218"
"1.15292","3.49167","35.47620","13.83000","0.00000","3.49167","1.15292","0.06232"
"1.15542","3.46899","35.24574","13.86000","0.00000","3.46899","1.15542","0.06245"
"1.15792","3.45301","35.08339","13.89000","0.00000","3.45301","1.15792","0.06259"
"1.16021","3.43240","34.87399","13.92000","0.00000","3.43240","1.16021","0.06271"
"1.16271","3.40014","34.54625","13.95000","0.00000","3.40014","1.16271","0.06285"
"1.16521","3.38167","34.35857","13.98000","0.00000","3.38167","1.16521","0.06298"
"1.16771","3.36119","34.15051","14.01000","0.00000","3.36119","1.16771","0.06312"
"1.17000","3.33552","33.88966","14.04000","0.00000","3.33552","1.17000","0.06324"
"1.17271","3.32255","33.75786","14.07000","0.00000","3.32255","1.17271","0.06339"
"1.17521","3.29355","33.46327","14.10000","0.00000","3.29355","1.17521","0.06352"
"1.17771","3.27134","33.23761","14.13000","0.00000","3.27134","1.17771","0.06366"
"1.18021","3.24751","32.99543","14.16000","0.00000","3.24751","1.18021","0.06380"
"1.18271","3.22838","32.80111","14.19000","0.00000","3.22838","1.18271","0.06393"
"1.18500","3.20409","32.55425","14.22000","0.00000","3.20409","1.18500","0.06405"
"1.18771","3.17974","32.30694","14.25000","0.00000","3.17974","1.18771","0.06420"
"1.19021","3.15070","32.01187","14.28000","0.00000","3.15070","1.19021","0.06434"
"1.19250","3.11239","31.62259","14.31000","0.00000","3.11239","1.19250","0.06446"
"1.19521","3.07835","31.27671","14.34000","0.00000","3.07835","1.19521","0.06461"
"1.19771","3.03889","30.87585","14.37000","0.00000","3.03889","1.19771","0.06474"
"1.20021","2.97528","30.22950","14.40000","0.00000","2.97528","1.20021","0.06488"
"1.20271","2.90982","29.56448","14.43000","0.00000","2.90982","1.20271","0.06501"
"1.20521","2.83574","28.81182","14.46000","0.00000","2.83574","1.20521","0.06515"
"1.20771","2.76226","28.06523","14.49000","0.00000","2.76226","1.20771","0.06528"
"1.21021","2.67808","27.20987","14.52000","0.00000","2.67808","1.21021","0.06542"
"1.21271","2.58469","26.26106","14.55000","0.00000","2.58469","1.21271","0.06555"
"1.21542","2.46150","25.00944","14.58000","0.00000","2.46150","1.21542","0.06570"
"1.21792","2.29973","23.36580","14.61000","0.00000","2.29973","1.21792","0.06583"
"1.22042","2.11147","21.45302","14.64000","0.00000","2.11147","1.22042","0.06597"
"1.22292","1.75719","17.85342","14.67000","0.00000","1.75719","1.22292","0.06610"
"1.22542","1.15132","11.69765","14.70000","0.00000","1.15132","1.22542","0.06624"
"1.22792","0.62808","6.38141","14.73000","0.00000","0.62808","1.22792","0.06637"
"1.23042","0.32832","3.33581","14.76000","0.00000","0.32832","1.23042","0.06651"
"1.23292","-0.25717","-2.61288","14.79000","0.00000","-0.25717","1.23292","0.06664"
"1.23562","-0.82889","-8.42176","14.82000","0.00000","-0.82889","1.23562","0.06679"
"1.23812","-0.98369","-9.99450","14.85000","0.00000","-0.98369","1.23812","0.06693"
"1.24083","-1.01709","-10.33382","14.88000","0.00000","-1.01709","1.24083","0.06707"
"1.24312","-1.03990","-10.56565","14.91000","0.00000","-1.03990","1.24312","0.06720"
"1.24562","-1.07260","-10.89784","14.94000","0.00000","-1.07260","1.24562","0.06733"
"1.24812","-1.09298","-11.10493","14.97000","0.00000","-1.09298","1.24812","0.06747"
"1.25062","-1.10385","-11.21537","15.00000","0.00000","-1.10385","1.25062","0.06760"
"1.25312","-1.11839","-11.36310","15.03000","0.00000","-1.11839","1.25312","0.06774"
"1.25562","-1.12932","-11.47418","15.06000","0.00000","-1.12932","1.25562","0.06787"
"1.25812","-1.14152","-11.59811","15.09000","0.00000","-1.14152","1.25812","0.06801"
"1.26062","-1.15128","-11.69731","15.12000","0.00000","-1.15128","1.26062","0.06814"
"1.26292","-1.15771","-11.76255","15.15000","0.00000","-1.15771","1.26292","0.06827"
"1.26542","-1.16136","-11.79964","15.18000","0.00000","-1.16136","1.26542","0.06840"
"1.26812","-1.17017","-11.88923","15.21000","0.00000","-1.17017","1.26812","0.06855"
"1.27042","-1.18164","-12.00573","15.24000","0.00000","-1.18164","1.27042","0.06867"
"1.27292","-1.18407","-12.03038","15.27000","0.00000","-1.18407","1.27292","0.06881"
"1.27542","-1.18292","-12.01876","15.30000","0.00000","-1.18292","1.27542","0.06894"
"1.27812","-1.19253","-12.11637","15.33000","0.00000","-1.19253","1.27812","0.06909"
"1.28062","-1.19221","-12.11315","15.36000","0.00000","-1.19221","1.28062","0.06922"
"1.28312","-1.19621","-12.15381","15.39000","0.00000","-1.19621","1.28312","0.06936"
"1.28562","-1.20039","-12.19626","15.42000","0.00000","-1.20039","1.28562","0.06949"
"1.28812","-1.20124","-12.20491","15.45000","0.00000","-1.20124","1.28812","0.06963"
"1.29062","-1.20896","-12.28327","15.48000","0.00000","-1.20896","1.29062","0.06976"
"1.29292","-1.21119","-12.30601","15.51000","0.00000","-1.21119","1.29292","0.06989"
"1.29562","-1.21671","-12.36204","15.54000","0.00000","-1.21671","1.29562","0.07003"
"1.29812","-1.21467","-12.34136","15.57000","0.00000","-1.21467","1.29812","0.07017"
"1.30062","-1.22087","-12.40436","15.60000","0.00000","-1.22087","1.30062","0.07030"
"1.30292","-1.22829","-12.47974","15.63000","0.00000","-1.22829","1.30292","0.07043"
"1.30562","-1.22216","-12.41740","15.66000","0.00000","-1.22216","1.30562","0.07057"
"1.30812","-1.23160","-12.51330","15.69000","0.00000","-1.23160","1.30812","0.07071"
"1.31042","-1.23398","-12.53748","15.72000","0.00000","-1.23398","1.31042","0.07083"
"1.31292","-1.23328","-12.53043","15.75000","0.00000","-1.23328","1.31292","0.07097"
"1.31521","-1.23708","-12.56898","15.78000","0.00000","-1.23708","1.31521","0.07109"
"1.31792","-1.23888","-12.58727","15.81000","0.00000","-1.23888","1.31792","0.07124"
"1.32042","-1.24470","-12.64649","15.84000","0.00000","-1.24470","1.32042","0.07137"
"1.32312","-1.24476","-12.64706","15.87000","0.00000","-1.24476","1.32312","0.07152"
"1.32542","-1.24504","-12.64986","15.90000","0.00000","-1.24504","1.32542","0.07164"
"1.32792","-1.25074","-12.70777","15.93000","0.00000","-1.25074","1.32792","0.07178"
"1.33042","-1.24974","-12.69761","15.96000","0.00000","-1.24974","1.33042","0.07191"
"1.33292","-1.25474","-12.74843","15.99000","0.00000","-1.25474","1.33292","0.07205"
"1.33542","-1.25087","-12.70917","16.02000","0.00000","-1.25087","1.33542","0.07218"
"1.33792","-1.25442","-12.74517","16.05000","0.00000","-1.25442","1.33792","0.07232"
"1.34042","-1.25498","-12.75094","16.08000","0.00000","-1.25498","1.34042","0.07245"
"1.34292","-1.25880","-12.78973","16.11000","0.00000","-1.25880","1.34292","0.07259"
"1.34542","-1.25783","-12.77984","16.14000","0.00000","-1.25783","1.34542","0.07273"
"1.34771","-1.26222","-12.82440","16.17000","0.00000","-1.26222","1.34771","0.07285"
"1.35021","-1.26042","-12.80616","16.20000","0.00000","-1.26042","1.35021","0.07298"
"1.35250","-1.26181","-12.82027","16.23000","0.00000","-1.26181","1.35250","0.07311"
"1.35500","-1.27109","-12.91457","16.26000","0.00000","-1.27109","1.35500","0.07324"
"1.35750","-1.26044","-12.80641","16.29000","0.00000","-1.26044","1.35750","0.07338"
"1.36021","-1.27113","-12.91497","16.32000","0.00000","-1.27113","1.36021","0.07352"
"1.36292","-1.27213","-12.92517","16.35000","0.00000","-1.27213","1.36292","0.07367"
"1.36542","-1.27166","-12.92033","16.38000","0.00000","-1.27166","1.36542","0.07381"
"1.36792","-1.27038","-12.90740","16.41000","0.00000","-1.27038","1.36792","0.07394"
"1.37042","-1.27795","-12.98425","16.44000","0.00000","-1.27795","1.37042","0.07408"
"1.37292","-1.28121","-13.01744","16.47000","0.00000","-1.28121","1.37292","0.07421"
"1.37542","-1.27999","-13.00497","16.50000","0.00000","-1.27999","1.37542","0.07435"
"1.37792","-1.28562","-13.06223","16.53000","0.00000","-1.28562","1.37792","0.07448"
"1.38042","-1.28645","-13.07065","16.56000","0.00000","-1.28645","1.38042","0.07462"
"1.38271","-1.28078","-13.01298","16.59000","0.00000","-1.28078","1.38271","0.07474"
"1.38521","-1.28230","-13.02847","16.62000","0.00000","-1.28230","1.38521","0.07488"
"1.38750","-1.31092","-13.31921","16.65000","0.00000","-1.31092","1.38750","0.07500"
"1.39000","-1.29145","-13.12142","16.68000","0.00000","-1.29145","1.39000","0.07514"
"1.39250","-1.26299","-12.83228","16.71000","0.00000","-1.26299","1.39250","0.07527"
"1.39479","-1.29368","-13.14413","16.74000","0.00000","-1.29368","1.39479","0.07539"
"1.39750","-1.29318","-13.13900","16.77000","0.00000","-1.29318","1.39750","0.07554"
"1.40021","-1.28579","-13.06392","16.80000","0.00000","-1.28579","1.40021","0.07569"
"1.40271","-1.30851","-13.29475","16.83000","0.00000","-1.30851","1.40271","0.07582"
"1.40542","-1.29215","-13.12855","16.86000","0.00000","-1.29215","1.40542","0.07597"
"1.40812","-1.27754","-12.98012","16.89000","0.00000","-1.27754","1.40812","0.07611"
"1.41042","-1.30160","-13.22458","16.92000","0.00000","-1.30160","1.41042","0.07624"
"1.41312","-1.30462","-13.25527","16.95000","0.00000","-1.30462","1.41312","0.07639"
"1.41542","-1.28364","-13.04213","16.98000","0.00000","-1.28364","1.41542","0.07651"
"1.41792","-1.29599","-13.16758","17.01000","0.00000","-1.29599","1.41792","0.07664"
"1.42042","-1.30382","-13.24715","17.04000","0.00000","-1.30382","1.42042","0.07678"
"1.42292","-1.28713","-13.07750","17.07000","0.00000","-1.28713","1.42292","0.07691"
"1.42542","-1.29360","-13.14325","17.10000","0.00000","-1.29360","1.42542","0.07705"
"1.42771","-1.31056","-13.31556","17.13000","0.00000","-1.31056","1.42771","0.07717"
"1.43021","-1.29482","-13.15565","17.16000","0.00000","-1.29482","1.43021","0.07731"
"1.43250","-1.29828","-13.19078","17.19000","0.00000","-1.29828","1.43250","0.07743"
"1.43521","-1.31124","-13.32247","17.22000","0.00000","-1.31124","1.43521","0.07758"
"1.43771","-1.30606","-13.26990","17.25000","0.00000","-1.30606","1.43771","0.07771"
"1.44042","-1.29970","-13.20526","17.28000","0.00000","-1.29970","1.44042","0.07786"
"1.44312","-1.30999","-13.30978","17.31000","0.00000","-1.30999","1.44312","0.07801"
"1.44562","-1.31006","-13.31051","17.34000","0.00000","-1.31006","1.44562","0.07814"
"1.44833","-1.30735","-13.28294","17.37000","0.00000","-1.30735","1.44833","0.07829"
"1.45083","-1.31576","-13.36838","17.40000","0.00000","-1.31576","1.45083","0.07842"
"1.45333","-1.31224","-13.33270","17.43000","0.00000","-1.31224","1.45333","0.07856"
"1.45583","-1.30354","-13.24426","17.46000","0.00000","-1.30354","1.45583","0.07869"
"1.45833","-1.30834","-13.29304","17.49000","0.00000","-1.30834","1.45833","0.07883"
"1.46062","-1.32581","-13.47054","17.52000","0.00000","-1.32581","1.46062","0.07895"
"1.46312","-1.30626","-13.27193","17.55000","0.00000","-1.30626","1.46312","0.07909"
"1.46542","-1.30758","-13.28527","17.58000","0.00000","-1.30758","1.46542","0.07921"
"1.46792","-1.32380","-13.45009","17.61000","0.00000","-1.32380","1.46792","0.07935"
"1.47021","-1.31666","-13.37759","17.64000","0.00000","-1.31666","1.47021","0.07947"
"1.47271","-1.30734","-13.28288","17.67000","0.00000","-1.30734","1.47271","0.07961"
"1.47521","-1.32206","-13.43239","17.70000","0.00000","-1.32206","1.47521","0.07974"
"1.47771","-1.31695","-13.38051","17.73000","0.00000","-1.31695","1.47771","0.07988"
"1.48042","-1.31549","-13.36564","17.76000","0.00000","-1.31549","1.48042","0.08002"
"1.48292","-1.32659","-13.47848","17.79000","0.00000","-1.32659","1.48292","0.08016"
"1.48562","-1.32904","-13.50340","17.82000","0.00000","-1.32904","1.48562","0.08030"
"1.48812","-1.31154","-13.32553","17.85000","0.00000","-1.31154","1.48812","0.08044"
"1.49062","-1.31536","-13.36434","17.88000","0.00000","-1.31536","1.49062","0.08057"
"1.49125","-1.31752","-13.38630","17.88600","0.00000","-1.31752","1.49125","0.08061"