File: G 1- Incubated Samples test to failure-20210303/Specimen_RawData_3.csv
Specimen properties : Specimen label,"sample 3"
Specimen properties : Length,"15.70000",mm
Specimen properties : Diameter,"0.19500",mm
Test : Rate 1,"5.00000",mm/min

Extension,Load,Tensile stress,Time,PIP count,Tenacity,Tensile extension,Tensile strain (Extension)
(mm),(N),(MPa),(s),,(N/tex),(mm),(mm/mm)
"0.00000","0.01108","0.37086","0.00000","0.00000","0.01108","0.00000","0.00000"
"0.00083","0.00161","0.05382","0.06000","0.00000","0.00161","0.00083","0.00005"
"0.00458","0.02582","0.86450","0.12000","0.00000","0.02582","0.00458","0.00029"
"0.01062","0.06800","2.27679","0.18000","0.00000","0.06800","0.01062","0.00068"
"0.01687","0.11589","3.88035","0.24000","0.00000","0.11589","0.01687","0.00107"
"0.02250","0.16070","5.38106","0.30000","0.00000","0.16070","0.02250","0.00143"
"0.02833","0.20094","6.72840","0.36000","0.00000","0.20094","0.02833","0.00180"
"0.03375","0.23166","7.75713","0.42000","0.00000","0.23166","0.03375","0.00215"
"0.03937","0.26949","9.02366","0.48000","0.00000","0.26949","0.03937","0.00251"
"0.04500","0.29895","10.00998","0.54000","0.00000","0.29895","0.04500","0.00287"
"0.05021","0.33544","11.23203","0.60000","0.00000","0.33544","0.05021","0.00320"
"0.05521","0.36552","12.23901","0.66000","0.00000","0.36552","0.05521","0.00352"
"0.06000","0.39857","13.34572","0.72000","0.00000","0.39857","0.06000","0.00382"
"0.06458","0.41155","13.78055","0.78000","0.00000","0.41155","0.06458","0.00411"
"0.06958","0.44860","15.02113","0.84000","0.00000","0.44860","0.06958","0.00443"
"0.07479","0.47564","15.92650","0.90000","0.00000","0.47564","0.07479","0.00476"
"0.08000","0.50647","16.95880","0.96000","0.00000","0.50647","0.08000","0.00510"
"0.08521","0.52927","17.72229","1.02000","0.00000","0.52927","0.08521","0.00543"
"0.09042","0.55402","18.55100","1.08000","0.00000","0.55402","0.09042","0.00576"
"0.09521","0.57224","19.16090","1.14000","0.00000","0.57224","0.09521","0.00606"
"0.10000","0.59576","19.94851","1.20000","0.00000","0.59576","0.10000","0.00637"
"0.10479","0.61800","20.69312","1.26000","0.00000","0.61800","0.10479","0.00667"
"0.10979","0.64026","21.43852","1.32000","0.00000","0.64026","0.10979","0.00699"
"0.11479","0.66168","22.15600","1.38000","0.00000","0.66168","0.11479","0.00731"
"0.11979","0.68209","22.83913","1.44000","0.00000","0.68209","0.11979","0.00763"
"0.12521","0.70857","23.72612","1.50000","0.00000","0.70857","0.12521","0.00798"
"0.13042","0.72503","24.27715","1.56000","0.00000","0.72503","0.13042","0.00831"
"0.13521","0.74583","24.97372","1.62000","0.00000","0.74583","0.13521","0.00861"
"0.13979","0.76388","25.57786","1.68000","0.00000","0.76388","0.13979","0.00890"
"0.14479","0.77991","26.11469","1.74000","0.00000","0.77991","0.14479","0.00922"
"0.14979","0.79581","26.64704","1.80000","0.00000","0.79581","0.14979","0.00954"
"0.15479","0.82183","27.51855","1.86000","0.00000","0.82183","0.15479","0.00986"
"0.15979","0.83800","28.05967","1.92000","0.00000","0.83800","0.15979","0.01018"
"0.16500","0.85829","28.73923","1.98000","0.00000","0.85829","0.16500","0.01051"
"0.17021","0.87279","29.22485","2.04000","0.00000","0.87279","0.17021","0.01084"
"0.17521","0.90086","30.16474","2.10000","0.00000","0.90086","0.17521","0.01116"
"0.18000","0.90562","30.32413","2.16000","0.00000","0.90562","0.18000","0.01146"
"0.18479","0.92224","30.88046","2.22000","0.00000","0.92224","0.18479","0.01177"
"0.18958","0.94298","31.57508","2.28000","0.00000","0.94298","0.18958","0.01208"
"0.19458","0.95646","32.02653","2.34000","0.00000","0.95646","0.19458","0.01239"
"0.19958","0.97188","32.54285","2.40000","0.00000","0.97188","0.19958","0.01271"
"0.20479","0.98792","33.07988","2.46000","0.00000","0.98792","0.20479","0.01304"
"0.21000","1.00882","33.77946","2.52000","0.00000","1.00882","0.21000","0.01338"
"0.21521","1.02682","34.38222","2.58000","0.00000","1.02682","0.21521","0.01371"
"0.22000","1.03639","34.70273","2.64000","0.00000","1.03639","0.22000","0.01401"
"0.22500","1.05173","35.21646","2.70000","0.00000","1.05173","0.22500","0.01433"
"0.22979","1.07092","35.85889","2.76000","0.00000","1.07092","0.22979","0.01464"
"0.23479","1.07973","36.15390","2.82000","0.00000","1.07973","0.23479","0.01495"
"0.23979","1.09742","36.74633","2.88000","0.00000","1.09742","0.23979","0.01527"
"0.24500","1.11307","37.27043","2.94000","0.00000","1.11307","0.24500","0.01561"
"0.25021","1.13314","37.94223","3.00000","0.00000","1.13314","0.25021","0.01594"
"0.25542","1.14503","38.34042","3.06000","0.00000","1.14503","0.25542","0.01627"
"0.26021","1.16571","39.03297","3.12000","0.00000","1.16571","0.26021","0.01657"
"0.26500","1.17821","39.45135","3.18000","0.00000","1.17821","0.26500","0.01688"
"0.27000","1.19871","40.13808","3.24000","0.00000","1.19871","0.27000","0.01720"
"0.27500","1.20826","40.45771","3.30000","0.00000","1.20826","0.27500","0.01752"
"0.28000","1.22349","40.96761","3.36000","0.00000","1.22349","0.28000","0.01783"
"0.28521","1.23456","41.33847","3.42000","0.00000","1.23456","0.28521","0.01817"
"0.29021","1.25313","41.96016","3.48000","0.00000","1.25313","0.29021","0.01848"
"0.29542","1.25797","42.12229","3.54000","0.00000","1.25797","0.29542","0.01882"
"0.30000","1.27972","42.85034","3.60000","0.00000","1.27972","0.30000","0.01911"
"0.30500","1.29452","43.34611","3.66000","0.00000","1.29452","0.30500","0.01943"
"0.31000","1.29793","43.46020","3.72000","0.00000","1.29793","0.31000","0.01975"
"0.31479","1.32259","44.28590","3.78000","0.00000","1.32259","0.31479","0.02005"
"0.32000","1.33135","44.57945","3.84000","0.00000","1.33135","0.32000","0.02038"
"0.32521","1.34664","45.09111","3.90000","0.00000","1.34664","0.32521","0.02071"
"0.33021","1.36261","45.62595","3.96000","0.00000","1.36261","0.33021","0.02103"
"0.33542","1.36884","45.83445","4.02000","0.00000","1.36884","0.33542","0.02136"
"0.34021","1.39534","46.72202","4.08000","0.00000","1.39534","0.34021","0.02167"
"0.34521","1.41208","47.28248","4.14000","0.00000","1.41208","0.34521","0.02199"
"0.35000","1.41847","47.49632","4.20000","0.00000","1.41847","0.35000","0.02229"
"0.35500","1.42620","47.75531","4.26000","0.00000","1.42620","0.35500","0.02261"
"0.36000","1.44665","48.44007","4.32000","0.00000","1.44665","0.36000","0.02293"
"0.36500","1.45890","48.85007","4.38000","0.00000","1.45890","0.36500","0.02325"
"0.37000","1.46712","49.12539","4.44000","0.00000","1.46712","0.37000","0.02357"
"0.37500","1.47682","49.45022","4.50000","0.00000","1.47682","0.37500","0.02389"
"0.38000","1.49095","49.92334","4.56000","0.00000","1.49095","0.38000","0.02420"
"0.38500","1.50079","50.25281","4.62000","0.00000","1.50079","0.38500","0.02452"
"0.39000","1.52218","50.96912","4.68000","0.00000","1.52218","0.39000","0.02484"
"0.39479","1.53364","51.35282","4.74000","0.00000","1.53364","0.39479","0.02515"
"0.40000","1.54243","51.64714","4.80000","0.00000","1.54243","0.40000","0.02548"
"0.40500","1.56222","52.30976","4.86000","0.00000","1.56222","0.40500","0.02580"
"0.40979","1.56973","52.56119","4.92000","0.00000","1.56973","0.40979","0.02610"
"0.41479","1.58428","53.04852","4.98000","0.00000","1.58428","0.41479","0.02642"
"0.41979","1.59450","53.39055","5.04000","0.00000","1.59450","0.41979","0.02674"
"0.42500","1.60773","53.83366","5.10000","0.00000","1.60773","0.42500","0.02707"
"0.42979","1.61993","54.24233","5.16000","0.00000","1.61993","0.42979","0.02738"
"0.43479","1.63482","54.74064","5.22000","0.00000","1.63482","0.43479","0.02769"
"0.44000","1.65059","55.26871","5.28000","0.00000","1.65059","0.44000","0.02803"
"0.44500","1.66331","55.69484","5.34000","0.00000","1.66331","0.44500","0.02834"
"0.45000","1.67762","56.17391","5.40000","0.00000","1.67762","0.45000","0.02866"
"0.45521","1.68673","56.47908","5.46000","0.00000","1.68673","0.45521","0.02899"
"0.46021","1.69789","56.85266","5.52000","0.00000","1.69789","0.46021","0.02931"
"0.46542","1.71574","57.45038","5.58000","0.00000","1.71574","0.46542","0.02964"
"0.47021","1.72465","57.74851","5.64000","0.00000","1.72465","0.47021","0.02995"
"0.47521","1.74370","58.38652","5.70000","0.00000","1.74370","0.47521","0.03027"
"0.48042","1.75061","58.61799","5.76000","0.00000","1.75061","0.48042","0.03060"
"0.48521","1.76245","59.01438","5.82000","0.00000","1.76245","0.48521","0.03090"
"0.49021","1.77847","59.55082","5.88000","0.00000","1.77847","0.49021","0.03122"
"0.49500","1.78068","59.62477","5.94000","0.00000","1.78068","0.49500","0.03153"
"0.50000","1.79406","60.07289","6.00000","0.00000","1.79406","0.50000","0.03185"
"0.50500","1.80871","60.56332","6.06000","0.00000","1.80871","0.50500","0.03217"
"0.51021","1.81973","60.93232","6.12000","0.00000","1.81973","0.51021","0.03250"
"0.51500","1.83369","61.39978","6.18000","0.00000","1.83369","0.51500","0.03280"
"0.52021","1.84900","61.91243","6.24000","0.00000","1.84900","0.52021","0.03313"
"0.52521","1.85467","62.10221","6.30000","0.00000","1.85467","0.52521","0.03345"
"0.53021","1.86890","62.57861","6.36000","0.00000","1.86890","0.53021","0.03377"
"0.53500","1.88069","62.97346","6.42000","0.00000","1.88069","0.53500","0.03408"
"0.54000","1.89611","63.48971","6.48000","0.00000","1.89611","0.54000","0.03439"
"0.54521","1.90681","63.84811","6.54000","0.00000","1.90681","0.54521","0.03473"
"0.55021","1.92055","64.30811","6.60000","0.00000","1.92055","0.55021","0.03505"
"0.55521","1.93432","64.76938","6.66000","0.00000","1.93432","0.55521","0.03536"
"0.56021","1.94623","65.16796","6.72000","0.00000","1.94623","0.56021","0.03568"
"0.56500","1.95711","65.53236","6.78000","0.00000","1.95711","0.56500","0.03599"
"0.57000","1.97065","65.98571","6.84000","0.00000","1.97065","0.57000","0.03631"
"0.57479","1.97956","66.28403","6.90000","0.00000","1.97956","0.57479","0.03661"
"0.57979","1.99052","66.65100","6.96000","0.00000","1.99052","0.57979","0.03693"
"0.58500","2.00216","67.04085","7.02000","0.00000","2.00216","0.58500","0.03726"
"0.59021","2.01745","67.55274","7.08000","0.00000","2.01745","0.59021","0.03759"
"0.59521","2.02518","67.81154","7.14000","0.00000","2.02518","0.59521","0.03791"
"0.60021","2.04675","68.53384","7.20000","0.00000","2.04675","0.60021","0.03823"
"0.60500","2.06000","68.97770","7.26000","0.00000","2.06000","0.60500","0.03854"
"0.61000","2.06621","69.18545","7.32000","0.00000","2.06621","0.61000","0.03885"
"0.61458","2.07978","69.64009","7.38000","0.00000","2.07978","0.61458","0.03915"
"0.61958","2.08666","69.87016","7.44000","0.00000","2.08666","0.61958","0.03946"
"0.62479","2.11332","70.76292","7.50000","0.00000","2.11332","0.62479","0.03980"
"0.63000","2.11678","70.87886","7.56000","0.00000","2.11678","0.63000","0.04013"
"0.63521","2.12173","71.04469","7.62000","0.00000","2.12173","0.63521","0.04046"
"0.64021","2.14343","71.77135","7.68000","0.00000","2.14343","0.64021","0.04078"
"0.64500","2.16032","72.33661","7.74000","0.00000","2.16032","0.64500","0.04108"
"0.65000","2.16614","72.53159","7.80000","0.00000","2.16614","0.65000","0.04140"
"0.65479","2.17822","72.93620","7.86000","0.00000","2.17822","0.65479","0.04171"
"0.65979","2.19077","73.35632","7.92000","0.00000","2.19077","0.65979","0.04202"
"0.66500","2.20475","73.82458","7.98000","0.00000","2.20475","0.66500","0.04236"
"0.67021","2.21492","74.16512","8.04000","0.00000","2.21492","0.67021","0.04269"
"0.67542","2.22746","74.58481","8.10000","0.00000","2.22746","0.67542","0.04302"
"0.68042","2.24083","75.03263","8.16000","0.00000","2.24083","0.68042","0.04334"
"0.68542","2.25378","75.46610","8.22000","0.00000","2.25378","0.68542","0.04366"
"0.69021","2.26615","75.88026","8.28000","0.00000","2.26615","0.69021","0.04396"
"0.69479","2.27427","76.15218","8.34000","0.00000","2.27427","0.69479","0.04425"
"0.69979","2.28956","76.66433","8.40000","0.00000","2.28956","0.69979","0.04457"
"0.70500","2.29170","76.73605","8.46000","0.00000","2.29170","0.70500","0.04490"
"0.71021","2.31110","77.38555","8.52000","0.00000","2.31110","0.71021","0.04524"
"0.71521","2.32632","77.89525","8.58000","0.00000","2.32632","0.71521","0.04555"
"0.72042","2.33929","78.32930","8.64000","0.00000","2.33929","0.72042","0.04589"
"0.72521","2.35257","78.77425","8.70000","0.00000","2.35257","0.72521","0.04619"
"0.73000","2.36540","79.20373","8.76000","0.00000","2.36540","0.73000","0.04650"
"0.73479","2.37326","79.46703","8.82000","0.00000","2.37326","0.73479","0.04680"
"0.73979","2.38413","79.83102","8.88000","0.00000","2.38413","0.73979","0.04712"
"0.74500","2.39821","80.30248","8.94000","0.00000","2.39821","0.74500","0.04745"
"0.75021","2.41888","80.99438","9.00000","0.00000","2.41888","0.75021","0.04778"
"0.75521","2.42293","81.13014","9.06000","0.00000","2.42293","0.75521","0.04810"
"0.76042","2.43911","81.67184","9.12000","0.00000","2.43911","0.76042","0.04843"
"0.76521","2.45646","82.25291","9.18000","0.00000","2.45646","0.76521","0.04874"
"0.77000","2.45633","82.24856","9.24000","0.00000","2.45633","0.77000","0.04904"
"0.77479","2.47231","82.78342","9.30000","0.00000","2.47231","0.77479","0.04935"
"0.77958","2.47703","82.94144","9.36000","0.00000","2.47703","0.77958","0.04965"
"0.78479","2.48872","83.33286","9.42000","0.00000","2.48872","0.78479","0.04999"
"0.78979","2.50797","83.97760","9.48000","0.00000","2.50797","0.78979","0.05031"
"0.79500","2.52119","84.42039","9.54000","0.00000","2.52119","0.79500","0.05064"
"0.80021","2.53138","84.76155","9.60000","0.00000","2.53138","0.80021","0.05097"
"0.80521","2.55128","85.42783","9.66000","0.00000","2.55128","0.80521","0.05129"
"0.81000","2.55940","85.69965","9.72000","0.00000","2.55940","0.81000","0.05159"
"0.81479","2.57159","86.10781","9.78000","0.00000","2.57159","0.81479","0.05190"
"0.81958","2.57360","86.17525","9.84000","0.00000","2.57360","0.81958","0.05220"
"0.82479","2.59442","86.87218","9.90000","0.00000","2.59442","0.82479","0.05253"
"0.82979","2.60788","87.32292","9.96000","0.00000","2.60788","0.82979","0.05285"
"0.83500","2.61739","87.64148","10.02000","0.00000","2.61739","0.83500","0.05318"
"0.84021","2.63705","88.29956","10.08000","0.00000","2.63705","0.84021","0.05352"
"0.84521","2.65222","88.80763","10.14000","0.00000","2.65222","0.84521","0.05383"
"0.85000","2.66031","89.07867","10.20000","0.00000","2.66031","0.85000","0.05414"
"0.85479","2.68452","89.88931","10.26000","0.00000","2.68452","0.85479","0.05445"
"0.85979","2.68381","89.86533","10.32000","0.00000","2.68381","0.85979","0.05476"
"0.86479","2.70066","90.42971","10.38000","0.00000","2.70066","0.86479","0.05508"
"0.87000","2.72038","91.08981","10.44000","0.00000","2.72038","0.87000","0.05541"
"0.87521","2.73016","91.41757","10.50000","0.00000","2.73016","0.87521","0.05575"
"0.88042","2.74244","91.82869","10.56000","0.00000","2.74244","0.88042","0.05608"
"0.88562","2.76272","92.50753","10.62000","0.00000","2.76272","0.88562","0.05641"
"0.89042","2.76130","92.46018","10.68000","0.00000","2.76130","0.89042","0.05671"
"0.89500","2.78694","93.31857","10.74000","0.00000","2.78694","0.89500","0.05701"
"0.90000","2.79692","93.65298","10.80000","0.00000","2.79692","0.90000","0.05732"
"0.90479","2.80412","93.89401","10.86000","0.00000","2.80412","0.90479","0.05763"
"0.91000","2.82124","94.46716","10.92000","0.00000","2.82124","0.91000","0.05796"
"0.91500","2.83401","94.89473","10.98000","0.00000","2.83401","0.91500","0.05828"
"0.92042","2.85243","95.51154","11.04000","0.00000","2.85243","0.92042","0.05863"
"0.92542","2.86461","95.91948","11.10000","0.00000","2.86461","0.92542","0.05894"
"0.93021","2.87862","96.38864","11.16000","0.00000","2.87862","0.93021","0.05925"
"0.93479","2.88507","96.60464","11.22000","0.00000","2.88507","0.93479","0.05954"
"0.93979","2.90064","97.12589","11.28000","0.00000","2.90064","0.93979","0.05986"
"0.94479","2.91850","97.72372","11.34000","0.00000","2.91850","0.94479","0.06018"
"0.94979","2.93265","98.19772","11.40000","0.00000","2.93265","0.94979","0.06050"
"0.95500","2.94513","98.61544","11.46000","0.00000","2.94513","0.95500","0.06083"
"0.96042","2.96616","99.31971","11.52000","0.00000","2.96616","0.96042","0.06117"
"0.96542","2.97582","99.64306","11.58000","0.00000","2.97582","0.96542","0.06149"
"0.97021","2.99192","100.18214","11.64000","0.00000","2.99192","0.97021","0.06180"
"0.97479","2.99652","100.33621","11.70000","0.00000","2.99652","0.97479","0.06209"
"0.97958","3.00179","100.51276","11.76000","0.00000","3.00179","0.97958","0.06239"
"0.98458","3.02688","101.35290","11.82000","0.00000","3.02688","0.98458","0.06271"
"0.98958","3.03590","101.65475","11.88000","0.00000","3.03590","0.98958","0.06303"
"0.99479","3.04714","102.03144","11.94000","0.00000","3.04714","0.99479","0.06336"
"1.00021","3.06293","102.56016","12.00000","0.00000","3.06293","1.00021","0.06371"
"1.00521","3.07598","102.99696","12.06000","0.00000","3.07598","1.00521","0.06403"
"1.01021","3.09786","103.72959","12.12000","0.00000","3.09786","1.01021","0.06434"
"1.01500","3.11194","104.20101","12.18000","0.00000","3.11194","1.01500","0.06465"
"1.01979","3.11682","104.36440","12.24000","0.00000","3.11682","1.01979","0.06495"
"1.02479","3.13436","104.95193","12.30000","0.00000","3.13436","1.02479","0.06527"
"1.02979","3.14728","105.38436","12.36000","0.00000","3.14728","1.02979","0.06559"
"1.03479","3.15599","105.67597","12.42000","0.00000","3.15599","1.03479","0.06591"
"1.04000","3.16537","105.99004","12.48000","0.00000","3.16537","1.04000","0.06624"
"1.04521","3.18432","106.62470","12.54000","0.00000","3.18432","1.04521","0.06657"
"1.05021","3.20124","107.19105","12.60000","0.00000","3.20124","1.05021","0.06689"
"1.05479","3.21299","107.58466","12.66000","0.00000","3.21299","1.05479","0.06718"
"1.05979","3.21883","107.78036","12.72000","0.00000","3.21883","1.05979","0.06750"
"1.06479","3.23089","108.18417","12.78000","0.00000","3.23089","1.06479","0.06782"
"1.06979","3.24468","108.64565","12.84000","0.00000","3.24468","1.06979","0.06814"
"1.07479","3.26263","109.24678","12.90000","0.00000","3.26263","1.07479","0.06846"
"1.08021","3.27463","109.64857","12.96000","0.00000","3.27463","1.08021","0.06880"
"1.08542","3.28951","110.14685","13.02000","0.00000","3.28951","1.08542","0.06913"
"1.09042","3.29892","110.46193","13.08000","0.00000","3.29892","1.09042","0.06945"
"1.09521","3.32351","111.28520","13.14000","0.00000","3.32351","1.09521","0.06976"
"1.10021","3.33077","111.52833","13.20000","0.00000","3.33077","1.10021","0.07008"
"1.10500","3.34171","111.89465","13.26000","0.00000","3.34171","1.10500","0.07038"
"1.11000","3.35862","112.46102","13.32000","0.00000","3.35862","1.11000","0.07070"
"1.11500","3.36334","112.61909","13.38000","0.00000","3.36334","1.11500","0.07102"
"1.12021","3.38215","113.24899","13.44000","0.00000","3.38215","1.12021","0.07135"
"1.12521","3.39592","113.70977","13.50000","0.00000","3.39592","1.12521","0.07167"
"1.13021","3.41227","114.25746","13.56000","0.00000","3.41227","1.13021","0.07199"
"1.13500","3.42382","114.64427","13.62000","0.00000","3.42382","1.13500","0.07229"
"1.14000","3.43266","114.94020","13.68000","0.00000","3.43266","1.14000","0.07261"
"1.14500","3.44532","115.36388","13.74000","0.00000","3.44532","1.14500","0.07293"
"1.14979","3.46200","115.92241","13.80000","0.00000","3.46200","1.14979","0.07324"
"1.15500","3.47881","116.48542","13.86000","0.00000","3.47881","1.15500","0.07357"
"1.16021","3.48813","116.79742","13.92000","0.00000","3.48813","1.16021","0.07390"
"1.16521","3.50446","117.34431","13.98000","0.00000","3.50446","1.16521","0.07422"
"1.17042","3.51632","117.74141","14.04000","0.00000","3.51632","1.17042","0.07455"
"1.17521","3.52743","118.11336","14.10000","0.00000","3.52743","1.17521","0.07485"
"1.18000","3.54100","118.56766","14.16000","0.00000","3.54100","1.18000","0.07516"
"1.18500","3.54984","118.86395","14.22000","0.00000","3.54984","1.18500","0.07548"
"1.18979","3.56958","119.52486","14.28000","0.00000","3.56958","1.18979","0.07578"
"1.19500","3.58628","120.08414","14.34000","0.00000","3.58628","1.19500","0.07611"
"1.20000","3.59419","120.34882","14.40000","0.00000","3.59419","1.20000","0.07643"
"1.20479","3.61262","120.96591","14.46000","0.00000","3.61262","1.20479","0.07674"
"1.21000","3.62906","121.51632","14.52000","0.00000","3.62906","1.21000","0.07707"
"1.21500","3.63899","121.84887","14.58000","0.00000","3.63899","1.21500","0.07739"
"1.22000","3.65868","122.50816","14.64000","0.00000","3.65868","1.22000","0.07771"
"1.22500","3.67198","122.95343","14.70000","0.00000","3.67198","1.22500","0.07803"
"1.22979","3.68815","123.49520","14.76000","0.00000","3.68815","1.22979","0.07833"
"1.23500","3.69676","123.78318","14.82000","0.00000","3.69676","1.23500","0.07866"
"1.23979","3.70896","124.19167","14.88000","0.00000","3.70896","1.23979","0.07897"
"1.24458","3.72298","124.66123","14.94000","0.00000","3.72298","1.24458","0.07927"
"1.24958","3.73905","125.19953","15.00000","0.00000","3.73905","1.24958","0.07959"
"1.25479","3.75863","125.85514","15.06000","0.00000","3.75863","1.25479","0.07992"
"1.25979","3.76688","126.13119","15.12000","0.00000","3.76688","1.25979","0.08024"
"1.26479","3.78572","126.76225","15.18000","0.00000","3.78572","1.26479","0.08056"
"1.26979","3.79772","127.16384","15.24000","0.00000","3.79772","1.26979","0.08088"
"1.27500","3.81516","127.74796","15.30000","0.00000","3.81516","1.27500","0.08121"
"1.28000","3.83632","128.45634","15.36000","0.00000","3.83632","1.28000","0.08153"
"1.28521","3.84810","128.85071","15.42000","0.00000","3.84810","1.28521","0.08186"
"1.29021","3.86462","129.40405","15.48000","0.00000","3.86462","1.29021","0.08218"
"1.29542","3.87386","129.71324","15.54000","0.00000","3.87386","1.29542","0.08251"
"1.30042","3.89072","130.27795","15.60000","0.00000","3.89072","1.30042","0.08283"
"1.30521","3.90864","130.87787","15.66000","0.00000","3.90864","1.30521","0.08313"
"1.31021","3.91429","131.06703","15.72000","0.00000","3.91429","1.31021","0.08345"
"1.31521","3.92866","131.54834","15.78000","0.00000","3.92866","1.31521","0.08377"
"1.32021","3.94707","132.16487","15.84000","0.00000","3.94707","1.32021","0.08409"
"1.32521","3.95947","132.58008","15.90000","0.00000","3.95947","1.32521","0.08441"
"1.33000","3.98161","133.32149","15.96000","0.00000","3.98161","1.33000","0.08471"
"1.33500","3.99078","133.62842","16.02000","0.00000","3.99078","1.33500","0.08503"
"1.34021","4.01304","134.37370","16.08000","0.00000","4.01304","1.34021","0.08536"
"1.34521","4.02341","134.72086","16.14000","0.00000","4.02341","1.34521","0.08568"
"1.35021","4.03619","135.14882","16.20000","0.00000","4.03619","1.35021","0.08600"
"1.35521","4.05141","135.65843","16.26000","0.00000","4.05141","1.35521","0.08632"
"1.36021","4.06644","136.16194","16.32000","0.00000","4.06644","1.36021","0.08664"
"1.36521","4.07615","136.48698","16.38000","0.00000","4.07615","1.36521","0.08696"
"1.37000","4.08997","136.94969","16.44000","0.00000","4.08997","1.37000","0.08726"
"1.37500","4.10514","137.45757","16.50000","0.00000","4.10514","1.37500","0.08758"
"1.38021","4.12161","138.00908","16.56000","0.00000","4.12161","1.38021","0.08791"
"1.38521","4.13032","138.30064","16.62000","0.00000","4.13032","1.38521","0.08823"
"1.39000","4.14724","138.86749","16.68000","0.00000","4.14724","1.39000","0.08854"
"1.39521","4.15495","139.12560","16.74000","0.00000","4.15495","1.39521","0.08887"
"1.40000","4.16749","139.54555","16.80000","0.00000","4.16749","1.40000","0.08917"
"1.40500","4.18242","140.04532","16.86000","0.00000","4.18242","1.40500","0.08949"
"1.40979","4.19281","140.39337","16.92000","0.00000","4.19281","1.40979","0.08980"
"1.41479","4.20059","140.65366","16.98000","0.00000","4.20059","1.41479","0.09011"
"1.42000","4.22126","141.34583","17.04000","0.00000","4.22126","1.42000","0.09045"
"1.42521","4.23657","141.85843","17.10000","0.00000","4.23657","1.42521","0.09078"
"1.43021","4.24234","142.05159","17.16000","0.00000","4.24234","1.43021","0.09110"
"1.43521","4.26293","142.74104","17.22000","0.00000","4.26293","1.43521","0.09141"
"1.44000","4.28180","143.37282","17.28000","0.00000","4.28180","1.44000","0.09172"
"1.44500","4.27785","143.24071","17.34000","0.00000","4.27785","1.44500","0.09204"
"1.44979","4.29906","143.95102","17.40000","0.00000","4.29906","1.44979","0.09234"
"1.45479","4.30134","144.02710","17.46000","0.00000","4.30134","1.45479","0.09266"
"1.46000","4.30923","144.29140","17.52000","0.00000","4.30923","1.46000","0.09299"
"1.46521","4.32375","144.77754","17.58000","0.00000","4.32375","1.46521","0.09333"
"1.47021","4.33179","145.04683","17.64000","0.00000","4.33179","1.47021","0.09364"
"1.47521","4.34629","145.53239","17.70000","0.00000","4.34629","1.47521","0.09396"
"1.48000","4.35748","145.90698","17.76000","0.00000","4.35748","1.48000","0.09427"
"1.48479","4.36382","146.11935","17.82000","0.00000","4.36382","1.48479","0.09457"
"1.48958","4.36583","146.18661","17.88000","0.00000","4.36583","1.48958","0.09488"
"1.49479","4.37681","146.55435","17.94000","0.00000","4.37681","1.49479","0.09521"
"1.50021","4.38830","146.93900","18.00000","0.00000","4.38830","1.50021","0.09555"
"1.50542","4.39536","147.17543","18.06000","0.00000","4.39536","1.50542","0.09589"
"1.51042","4.40416","147.47018","18.12000","0.00000","4.40416","1.51042","0.09620"
"1.51542","4.40782","147.59254","18.18000","0.00000","4.40782","1.51542","0.09652"
"1.52021","4.41889","147.96329","18.24000","0.00000","4.41889","1.52021","0.09683"
"1.52500","4.42451","148.15138","18.30000","0.00000","4.42451","1.52500","0.09713"
"1.52979","4.42807","148.27074","18.36000","0.00000","4.42807","1.52979","0.09744"
"1.53479","4.44182","148.73105","18.42000","0.00000","4.44182","1.53479","0.09776"
"1.54000","4.44107","148.70604","18.48000","0.00000","4.44107","1.54000","0.09809"
"1.54521","4.45980","149.33310","18.54000","0.00000","4.45980","1.54521","0.09842"
"1.55042","4.46839","149.62080","18.60000","0.00000","4.46839","1.55042","0.09875"
"1.55542","4.46914","149.64586","18.66000","0.00000","4.46914","1.55542","0.09907"
"1.56021","4.47894","149.97403","18.72000","0.00000","4.47894","1.56021","0.09938"
"1.56500","4.48256","150.09544","18.78000","0.00000","4.48256","1.56500","0.09968"
"1.56979","4.48587","150.20612","18.84000","0.00000","4.48587","1.56979","0.09999"
"1.57479","4.49493","150.50934","18.90000","0.00000","4.49493","1.57479","0.10031"
"1.57979","4.49565","150.53362","18.96000","0.00000","4.49565","1.57979","0.10062"
"1.58521","4.50057","150.69821","19.02000","0.00000","4.50057","1.58521","0.10097"
"1.59021","4.51155","151.06599","19.08000","0.00000","4.51155","1.59021","0.10129"
"1.59542","4.51105","151.04932","19.14000","0.00000","4.51105","1.59542","0.10162"
"1.60021","4.50559","150.86641","19.20000","0.00000","4.50559","1.60021","0.10192"
"1.60500","4.51422","151.15555","19.26000","0.00000","4.51422","1.60500","0.10223"
"1.60979","4.50449","150.82942","19.32000","0.00000","4.50449","1.60979","0.10253"
"1.61458","4.50603","150.88120","19.38000","0.00000","4.50603","1.61458","0.10284"
"1.61979","4.51354","151.13249","19.44000","0.00000","4.51354","1.61979","0.10317"
"1.62479","4.51938","151.32817","19.50000","0.00000","4.51938","1.62479","0.10349"
"1.63000","4.52415","151.48785","19.56000","0.00000","4.52415","1.63000","0.10382"
"1.63521","4.53469","151.84073","19.62000","0.00000","4.53469","1.63521","0.10415"
"1.64021","4.53377","151.81009","19.68000","0.00000","4.53377","1.64021","0.10447"
"1.64500","4.54397","152.15163","19.74000","0.00000","4.54397","1.64500","0.10478"
"1.64958","4.53983","152.01289","19.80000","0.00000","4.53983","1.64958","0.10507"
"1.65458","4.54403","152.15355","19.86000","0.00000","4.54403","1.65458","0.10539"
"1.65958","4.56022","152.69554","19.92000","0.00000","4.56022","1.65958","0.10571"
"1.66479","4.55847","152.63712","19.98000","0.00000","4.55847","1.66479","0.10604"
"1.67000","4.56487","152.85141","20.04000","0.00000","4.56487","1.67000","0.10637"
"1.67521","4.57504","153.19193","20.10000","0.00000","4.57504","1.67521","0.10670"
"1.68021","4.57924","153.33263","20.16000","0.00000","4.57924","1.68021","0.10702"
"1.68500","4.58720","153.59904","20.22000","0.00000","4.58720","1.68500","0.10732"
"1.68979","4.58361","153.47896","20.28000","0.00000","4.58361","1.68979","0.10763"
"1.69458","4.60474","154.18634","20.34000","0.00000","4.60474","1.69458","0.10794"
"1.69958","4.60081","154.05492","20.40000","0.00000","4.60081","1.69958","0.10825"
"1.70500","4.59832","153.97136","20.46000","0.00000","4.59832","1.70500","0.10860"
"1.71042","4.61436","154.50862","20.52000","0.00000","4.61436","1.71042","0.10894"
"1.71562","4.62665","154.92003","20.58000","0.00000","4.62665","1.71562","0.10928"
"1.72042","4.63056","155.05078","20.64000","0.00000","4.63056","1.72042","0.10958"
"1.72521","4.63712","155.27054","20.70000","0.00000","4.63712","1.72521","0.10989"
"1.73000","4.63899","155.33330","20.76000","0.00000","4.63899","1.73000","0.11019"
"1.73479","4.64622","155.57530","20.82000","0.00000","4.64622","1.73479","0.11050"
"1.73979","4.65413","155.84029","20.88000","0.00000","4.65413","1.73979","0.11081"
"1.74479","4.65043","155.71632","20.94000","0.00000","4.65043","1.74479","0.11113"
"1.75021","4.65743","155.95061","21.00000","0.00000","4.65743","1.75021","0.11148"
"1.75542","4.66708","156.27364","21.06000","0.00000","4.66708","1.75542","0.11181"
"1.76021","4.66939","156.35120","21.12000","0.00000","4.66939","1.76021","0.11212"
"1.76500","4.67406","156.50754","21.18000","0.00000","4.67406","1.76500","0.11242"
"1.76979","4.67170","156.42834","21.24000","0.00000","4.67170","1.76979","0.11273"
"1.77479","4.67354","156.48999","21.30000","0.00000","4.67354","1.77479","0.11304"
"1.77979","4.68556","156.89255","21.36000","0.00000","4.68556","1.77979","0.11336"
"1.78479","4.68655","156.92578","21.42000","0.00000","4.68655","1.78479","0.11368"
"1.79021","4.68676","156.93274","21.48000","0.00000","4.68676","1.79021","0.11403"
"1.79542","4.68475","156.86551","21.54000","0.00000","4.68475","1.79542","0.11436"
"1.80042","4.69225","157.11655","21.60000","0.00000","4.69225","1.80042","0.11468"
"1.80521","4.69958","157.36209","21.66000","0.00000","4.69958","1.80521","0.11498"
"1.80979","4.69627","157.25117","21.72000","0.00000","4.69627","1.80979","0.11527"
"1.81479","4.69634","157.25340","21.78000","0.00000","4.69634","1.81479","0.11559"
"1.81979","4.69270","157.13179","21.84000","0.00000","4.69270","1.81979","0.11591"
"1.82479","4.69473","157.19966","21.90000","0.00000","4.69473","1.82479","0.11623"
"1.82979","4.69852","157.32669","21.96000","0.00000","4.69852","1.82979","0.11655"
"1.83521","4.70670","157.60057","22.02000","0.00000","4.70670","1.83521","0.11689"
"1.84042","4.70327","157.48570","22.08000","0.00000","4.70327","1.84042","0.11722"
"1.84521","4.70715","157.61548","22.14000","0.00000","4.70715","1.84521","0.11753"
"1.85000","4.71195","157.77609","22.20000","0.00000","4.71195","1.85000","0.11783"
"1.85479","4.71699","157.94499","22.26000","0.00000","4.71699","1.85479","0.11814"
"1.85979","4.70675","157.60202","22.32000","0.00000","4.70675","1.85979","0.11846"
"1.86479","4.71723","157.95297","22.38000","0.00000","4.71723","1.86479","0.11878"
"1.87000","4.70979","157.70386","22.44000","0.00000","4.70979","1.87000","0.11911"
"1.87500","4.71714","157.95016","22.50000","0.00000","4.71714","1.87500","0.11943"
"1.88021","4.70681","157.60411","22.56000","0.00000","4.70681","1.88021","0.11976"
"1.88500","4.70631","157.58749","22.62000","0.00000","4.70631","1.88500","0.12006"
"1.88979","4.71807","157.98126","22.68000","0.00000","4.71807","1.88979","0.12037"
"1.89458","4.71836","157.99086","22.74000","0.00000","4.71836","1.89458","0.12067"
"1.89979","4.71193","157.77570","22.80000","0.00000","4.71193","1.89979","0.12101"
"1.90458","4.71851","157.99597","22.86000","0.00000","4.71851","1.90458","0.12131"
"1.91000","4.72531","158.22346","22.92000","0.00000","4.72531","1.91000","0.12166"
"1.91521","4.72447","158.19539","22.98000","0.00000","4.72447","1.91521","0.12199"
"1.92042","4.73433","158.52550","23.04000","0.00000","4.73433","1.92042","0.12232"
"1.92542","4.72908","158.34976","23.10000","0.00000","4.72908","1.92542","0.12264"
"1.93021","4.74063","158.73640","23.16000","0.00000","4.74063","1.93021","0.12294"
"1.93521","4.74503","158.88385","23.22000","0.00000","4.74503","1.93521","0.12326"
"1.94000","4.74629","158.92610","23.28000","0.00000","4.74629","1.94000","0.12357"
"1.94500","4.75058","159.06976","23.34000","0.00000","4.75058","1.94500","0.12389"
"1.95000","4.75375","159.17572","23.40000","0.00000","4.75375","1.95000","0.12420"
"1.95521","4.75425","159.19275","23.46000","0.00000","4.75425","1.95521","0.12454"
"1.96021","4.76157","159.43761","23.52000","0.00000","4.76157","1.96021","0.12485"
"1.96521","4.77398","159.85326","23.58000","0.00000","4.77398","1.96521","0.12517"
"1.97000","4.77820","159.99460","23.64000","0.00000","4.77820","1.97000","0.12548"
"1.97500","4.79202","160.45731","23.70000","0.00000","4.79202","1.97500","0.12580"
"1.98000","4.79221","160.46370","23.76000","0.00000","4.79221","1.98000","0.12611"
"1.98500","4.79900","160.69118","23.82000","0.00000","4.79900","1.98500","0.12643"
"1.99021","4.80555","160.91022","23.88000","0.00000","4.80555","1.99021","0.12676"
"1.99521","4.81503","161.22783","23.94000","0.00000","4.81503","1.99521","0.12708"
"2.00042","4.82408","161.53069","24.00000","0.00000","4.82408","2.00042","0.12742"
"2.00542","4.83444","161.87769","24.06000","0.00000","4.83444","2.00542","0.12773"
"2.01021","4.84032","162.07460","24.12000","0.00000","4.84032","2.01021","0.12804"
"2.01500","4.84756","162.31688","24.18000","0.00000","4.84756","2.01500","0.12834"
"2.02000","4.85936","162.71202","24.24000","0.00000","4.85936","2.02000","0.12866"
"2.02479","4.86447","162.88313","24.30000","0.00000","4.86447","2.02479","0.12897"
"2.03000","4.86359","162.85394","24.36000","0.00000","4.86359","2.03000","0.12930"
"2.03479","4.87588","163.26546","24.42000","0.00000","4.87588","2.03479","0.12960"
"2.03979","4.86961","163.05553","24.48000","0.00000","4.86961","2.03979","0.12992"
"2.04479","4.87635","163.28090","24.54000","0.00000","4.87635","2.04479","0.13024"
"2.04979","4.87406","163.20422","24.60000","0.00000","4.87406","2.04979","0.13056"
"2.05479","4.87407","163.20473","24.66000","0.00000","4.87407","2.05479","0.13088"
"2.05979","4.88295","163.50217","24.72000","0.00000","4.88295","2.05979","0.13120"
"2.06479","4.88389","163.53339","24.78000","0.00000","4.88389","2.06479","0.13152"
"2.07000","4.89046","163.75368","24.84000","0.00000","4.89046","2.07000","0.13185"
"2.07479","4.89954","164.05739","24.90000","0.00000","4.89954","2.07479","0.13215"
"2.07979","4.89479","163.89842","24.96000","0.00000","4.89479","2.07979","0.13247"
"2.08479","4.90352","164.19075","25.02000","0.00000","4.90352","2.08479","0.13279"
"2.09000","4.90086","164.10164","25.08000","0.00000","4.90086","2.09000","0.13312"
"2.09500","4.90668","164.29672","25.14000","0.00000","4.90668","2.09500","0.13344"
"2.10000","4.90085","164.10150","25.20000","0.00000","4.90085","2.10000","0.13376"
"2.10500","4.90915","164.37918","25.26000","0.00000","4.90915","2.10500","0.13408"
"2.11000","4.91519","164.58165","25.32000","0.00000","4.91519","2.11000","0.13439"
"2.11500","4.91256","164.49364","25.38000","0.00000","4.91256","2.11500","0.13471"
"2.12000","4.92378","164.86914","25.44000","0.00000","4.92378","2.12000","0.13503"
"2.12521","4.92605","164.94519","25.50000","0.00000","4.92605","2.12521","0.13536"
"2.13042","4.92740","164.99055","25.56000","0.00000","4.92740","2.13042","0.13570"
"2.13542","4.94047","165.42816","25.62000","0.00000","4.94047","2.13542","0.13601"
"2.14021","4.94931","165.72397","25.68000","0.00000","4.94931","2.14021","0.13632"
"2.14521","4.94223","165.48714","25.74000","0.00000","4.94223","2.14521","0.13664"
"2.15021","4.94897","165.71277","25.80000","0.00000","4.94897","2.15021","0.13696"
"2.15521","4.95353","165.86539","25.86000","0.00000","4.95353","2.15521","0.13727"
"2.16021","4.96260","166.16917","25.92000","0.00000","4.96260","2.16021","0.13759"
"2.16500","4.96904","166.38461","25.98000","0.00000","4.96904","2.16500","0.13790"
"2.17021","4.97644","166.63239","26.04000","0.00000","4.97644","2.17021","0.13823"
"2.17521","4.98458","166.90503","26.10000","0.00000","4.98458","2.17521","0.13855"
"2.18021","4.99295","167.18542","26.16000","0.00000","4.99295","2.18021","0.13887"
"2.18521","4.99572","167.27803","26.22000","0.00000","4.99572","2.18521","0.13919"
"2.19021","5.01104","167.79112","26.28000","0.00000","5.01104","2.19021","0.13950"
"2.19521","5.01093","167.78734","26.34000","0.00000","5.01093","2.19521","0.13982"
"2.20000","5.02225","168.16644","26.40000","0.00000","5.02225","2.20000","0.14013"
"2.20500","5.03152","168.47696","26.46000","0.00000","5.03152","2.20500","0.14045"
"2.21021","5.04014","168.76538","26.52000","0.00000","5.04014","2.21021","0.14078"
"2.21521","5.04842","169.04265","26.58000","0.00000","5.04842","2.21521","0.14110"
"2.22021","5.05827","169.37262","26.64000","0.00000","5.05827","2.22021","0.14141"
"2.22500","5.06331","169.54132","26.70000","0.00000","5.06331","2.22500","0.14172"
"2.23021","5.07882","170.06062","26.76000","0.00000","5.07882","2.23021","0.14205"
"2.23521","5.09081","170.46205","26.82000","0.00000","5.09081","2.23521","0.14237"
"2.24000","5.10073","170.79411","26.88000","0.00000","5.10073","2.24000","0.14268"
"2.24479","5.10870","171.06111","26.94000","0.00000","5.10870","2.24479","0.14298"
"2.24979","5.12105","171.47478","27.00000","0.00000","5.12105","2.24979","0.14330"
"2.25521","5.12662","171.66104","27.06000","0.00000","5.12662","2.25521","0.14364"
"2.26021","5.14227","172.18524","27.12000","0.00000","5.14227","2.26021","0.14396"
"2.26521","5.15513","172.61565","27.18000","0.00000","5.15513","2.26521","0.14428"
"2.27021","5.16001","172.77927","27.24000","0.00000","5.16001","2.27021","0.14460"
"2.27500","5.17489","173.27728","27.30000","0.00000","5.17489","2.27500","0.14490"
"2.27979","5.17261","173.20097","27.36000","0.00000","5.17261","2.27979","0.14521"
"2.28458","5.17802","173.38232","27.42000","0.00000","5.17802","2.28458","0.14551"
"2.28958","5.19165","173.83865","27.48000","0.00000","5.19165","2.28958","0.14583"
"2.29479","5.20232","174.19598","27.54000","0.00000","5.20232","2.29479","0.14617"
"2.30000","5.21394","174.58496","27.60000","0.00000","5.21394","2.30000","0.14650"
"2.30521","5.22922","175.09674","27.66000","0.00000","5.22922","2.30521","0.14683"
"2.31021","5.22652","175.00610","27.72000","0.00000","5.22652","2.31021","0.14715"
"2.31521","5.23960","175.44423","27.78000","0.00000","5.23960","2.31521","0.14747"
"2.32000","5.24848","175.74167","27.84000","0.00000","5.24848","2.32000","0.14777"
"2.32479","5.25342","175.90694","27.90000","0.00000","5.25342","2.32479","0.14808"
"2.33000","5.26822","176.40253","27.96000","0.00000","5.26822","2.33000","0.14841"
"2.33521","5.28152","176.84775","28.02000","0.00000","5.28152","2.33521","0.14874"
"2.34042","5.29443","177.28024","28.08000","0.00000","5.29443","2.34042","0.14907"
"2.34542","5.30864","177.75583","28.14000","0.00000","5.30864","2.34542","0.14939"
"2.35042","5.31898","178.10222","28.20000","0.00000","5.31898","2.35042","0.14971"
"2.35521","5.33202","178.53893","28.26000","0.00000","5.33202","2.35521","0.15001"
"2.36000","5.34006","178.80809","28.32000","0.00000","5.34006","2.36000","0.15032"
"2.36479","5.34135","178.85139","28.38000","0.00000","5.34135","2.36479","0.15062"
"2.37000","5.36135","179.52083","28.44000","0.00000","5.36135","2.37000","0.15096"
"2.37500","5.37809","180.08148","28.50000","0.00000","5.37809","2.37500","0.15127"
"2.38021","5.38885","180.44180","28.56000","0.00000","5.38885","2.38021","0.15161"
"2.38542","5.40799","181.08249","28.62000","0.00000","5.40799","2.38542","0.15194"
"2.39042","5.41506","181.31946","28.68000","0.00000","5.41506","2.39042","0.15226"
"2.39521","5.43263","181.90755","28.74000","0.00000","5.43263","2.39521","0.15256"
"2.40000","5.43869","182.11067","28.80000","0.00000","5.43869","2.40000","0.15287"
"2.40479","5.45005","182.49097","28.86000","0.00000","5.45005","2.40479","0.15317"
"2.40979","5.46665","183.04691","28.92000","0.00000","5.46665","2.40979","0.15349"
"2.41500","5.48015","183.49899","28.98000","0.00000","5.48015","2.41500","0.15382"
"2.42000","5.49817","184.10210","29.04000","0.00000","5.49817","2.42000","0.15414"
"2.42542","5.51209","184.56827","29.10000","0.00000","5.51209","2.42542","0.15449"
"2.43021","5.52280","184.92688","29.16000","0.00000","5.52280","2.43021","0.15479"
"2.43521","5.52749","185.08415","29.22000","0.00000","5.52749","2.43521","0.15511"
"2.43979","5.54577","185.69617","29.28000","0.00000","5.54577","2.43979","0.15540"
"2.44458","5.55976","186.16447","29.34000","0.00000","5.55976","2.44458","0.15571"
"2.44958","5.55621","186.04576","29.40000","0.00000","5.55621","2.44958","0.15602"
"2.45479","5.56732","186.41769","29.46000","0.00000","5.56732","2.45479","0.15636"
"2.46000","5.58356","186.96138","29.52000","0.00000","5.58356","2.46000","0.15669"
"2.46521","5.59610","187.38139","29.58000","0.00000","5.59610","2.46521","0.15702"
"2.47042","5.60862","187.80049","29.64000","0.00000","5.60862","2.47042","0.15735"
"2.47521","5.61757","188.10010","29.70000","0.00000","5.61757","2.47521","0.15766"
"2.47979","5.63034","188.52802","29.76000","0.00000","5.63034","2.47979","0.15795"
"2.48479","5.64614","189.05688","29.82000","0.00000","5.64614","2.48479","0.15827"
"2.48958","5.64626","189.06107","29.88000","0.00000","5.64626","2.48958","0.15857"
"2.49458","5.66168","189.57741","29.94000","0.00000","5.66168","2.49458","0.15889"
"2.49979","5.67514","190.02792","30.00000","0.00000","5.67514","2.49979","0.15922"
"2.50500","5.67943","190.17157","30.06000","0.00000","5.67943","2.50500","0.15955"
"2.51021","5.69779","190.78647","30.12000","0.00000","5.69779","2.51021","0.15989"
"2.51500","5.70616","191.06676","30.18000","0.00000","5.70616","2.51500","0.16019"
"2.51979","5.71983","191.52446","30.24000","0.00000","5.71983","2.51979","0.16050"
"2.52479","5.72857","191.81694","30.30000","0.00000","5.72857","2.52479","0.16081"
"2.52979","5.74145","192.24840","30.36000","0.00000","5.74145","2.52979","0.16113"
"2.53479","5.75337","192.64742","30.42000","0.00000","5.75337","2.53479","0.16145"
"2.54021","5.77061","193.22476","30.48000","0.00000","5.77061","2.54021","0.16180"
"2.54542","5.77300","193.30461","30.54000","0.00000","5.77300","2.54542","0.16213"
"2.55062","5.78708","193.77618","30.60000","0.00000","5.78708","2.55062","0.16246"
"2.55542","5.79674","194.09973","30.66000","0.00000","5.79674","2.55542","0.16277"
"2.56021","5.79666","194.09691","30.72000","0.00000","5.79666","2.56021","0.16307"
"2.56500","5.81615","194.74971","30.78000","0.00000","5.81615","2.56500","0.16338"
"2.56979","5.82488","195.04204","30.84000","0.00000","5.82488","2.56979","0.16368"
"2.57500","5.83707","195.45001","30.90000","0.00000","5.83707","2.57500","0.16401"
"2.58000","5.85355","196.00197","30.96000","0.00000","5.85355","2.58000","0.16433"
"2.58542","5.85558","196.06982","31.02000","0.00000","5.85558","2.58542","0.16468"
"2.59042","5.86896","196.51773","31.08000","0.00000","5.86896","2.59042","0.16499"
"2.59542","5.87954","196.87222","31.14000","0.00000","5.87954","2.59542","0.16531"
"2.60000","5.89056","197.24100","31.20000","0.00000","5.89056","2.60000","0.16561"
"2.60479","5.89086","197.25114","31.26000","0.00000","5.89086","2.60479","0.16591"
"2.60958","5.89954","197.54196","31.32000","0.00000","5.89954","2.60958","0.16622"
"2.61479","5.90665","197.77979","31.38000","0.00000","5.90665","2.61479","0.16655"
"2.61979","5.91900","198.19353","31.44000","0.00000","5.91900","2.61979","0.16687"
"2.62521","5.92796","198.49352","31.50000","0.00000","5.92796","2.62521","0.16721"
"2.63042","5.93072","198.58586","31.56000","0.00000","5.93072","2.63042","0.16754"
"2.63521","5.93933","198.87433","31.62000","0.00000","5.93933","2.63521","0.16785"
"2.63979","5.93650","198.77957","31.68000","0.00000","5.93650","2.63979","0.16814"
"2.64479","5.94616","199.10292","31.74000","0.00000","5.94616","2.64479","0.16846"
"2.64958","5.94818","199.17038","31.80000","0.00000","5.94818","2.64958","0.16876"
"2.65479","5.96084","199.59425","31.86000","0.00000","5.96084","2.65479","0.16909"
"2.65979","5.96367","199.68922","31.92000","0.00000","5.96367","2.65979","0.16941"
"2.66500","5.97074","199.92581","31.98000","0.00000","5.97074","2.66500","0.16975"
"2.67021","5.98329","200.34628","32.04000","0.00000","5.98329","2.67021","0.17008"
"2.67542","5.98404","200.37108","32.10000","0.00000","5.98404","2.67542","0.17041"
"2.68000","5.99046","200.58612","32.16000","0.00000","5.99046","2.68000","0.17070"
"2.68479","5.99859","200.85857","32.22000","0.00000","5.99859","2.68479","0.17101"
"2.68979","5.99416","200.71001","32.28000","0.00000","5.99416","2.68979","0.17132"
"2.69479","6.01210","201.31071","32.34000","0.00000","6.01210","2.69479","0.17164"
"2.69958","6.01218","201.31358","32.40000","0.00000","6.01218","2.69958","0.17195"
"2.70479","6.01754","201.49297","32.46000","0.00000","6.01754","2.70479","0.17228"
"2.71000","6.02312","201.67987","32.52000","0.00000","6.02312","2.71000","0.17261"
"2.71500","6.01808","201.51117","32.58000","0.00000","6.01808","2.71500","0.17293"
"2.72000","6.02759","201.82942","32.64000","0.00000","6.02759","2.72000","0.17325"
"2.72479","6.02183","201.63649","32.70000","0.00000","6.02183","2.72479","0.17355"
"2.72979","6.02104","201.61024","32.76000","0.00000","6.02104","2.72979","0.17387"
"2.73479","6.01464","201.39600","32.82000","0.00000","6.01464","2.73479","0.17419"
"2.73979","6.00424","201.04776","32.88000","0.00000","6.00424","2.73979","0.17451"
"2.74521","5.99208","200.64030","32.94000","0.00000","5.99208","2.74521","0.17485"
"2.75042","5.97391","200.03201","33.00000","0.00000","5.97391","2.75042","0.17519"
"2.75562","5.95199","199.29819","33.06000","0.00000","5.95199","2.75562","0.17552"
"2.76021","5.93326","198.67087","33.12000","0.00000","5.93326","2.76021","0.17581"
"2.76521","5.88229","196.96425","33.18000","0.00000","5.88229","2.76521","0.17613"
"2.77000","5.81328","194.65350","33.24000","0.00000","5.81328","2.77000","0.17643"
"2.77500","4.51210","151.08452","33.30000","0.00000","4.51210","2.77500","0.17675"
"2.78000","0.68589","22.96655","33.36000","0.00000","0.68589","2.78000","0.17707"
"2.78521","0.80088","26.81700","33.42000","0.00000","0.80088","2.78521","0.17740"
"2.79021","0.65832","22.04344","33.48000","0.00000","0.65832","2.79021","0.17772"
"2.79542","0.63787","21.35861","33.54000","0.00000","0.63787","2.79542","0.17805"
"2.80021","0.64669","21.65379","33.60000","0.00000","0.64669","2.80021","0.17836"
"2.80500","0.63085","21.12370","33.66000","0.00000","0.63085","2.80500","0.17866"
"2.81000","0.59156","19.80790","33.72000","0.00000","0.59156","2.81000","0.17898"
"2.81479","0.55350","18.53343","33.78000","0.00000","0.55350","2.81479","0.17929"
"2.82000","0.52330","17.52246","33.84000","0.00000","0.52330","2.82000","0.17962"
"2.82521","0.49943","16.72301","33.90000","0.00000","0.49943","2.82521","0.17995"
"2.83000","0.47835","16.01724","33.96000","0.00000","0.47835","2.83000","0.18025"
"2.83521","0.44097","14.76560","34.02000","0.00000","0.44097","2.83521","0.18059"
"2.84021","0.38369","12.84760","34.08000","0.00000","0.38369","2.84021","0.18090"
"2.84500","0.35643","11.93486","34.14000","0.00000","0.35643","2.84500","0.18121"
"2.85000","0.33395","11.18223","34.20000","0.00000","0.33395","2.85000","0.18153"
"2.85479","0.33519","11.22349","34.26000","0.00000","0.33519","2.85479","0.18183"
"2.86000","0.32081","10.74216","34.32000","0.00000","0.32081","2.86000","0.18217"
"2.86500","0.31129","10.42329","34.38000","0.00000","0.31129","2.86500","0.18248"
"2.87000","0.30041","10.05887","34.44000","0.00000","0.30041","2.87000","0.18280"
"2.87500","0.29424","9.85230","34.50000","0.00000","0.29424","2.87500","0.18312"
"2.88000","0.28066","9.39753","34.56000","0.00000","0.28066","2.88000","0.18344"
"2.88500","0.27836","9.32077","34.62000","0.00000","0.27836","2.88500","0.18376"
"2.89000","0.28445","9.52452","34.68000","0.00000","0.28445","2.89000","0.18408"
"2.89500","0.29511","9.88162","34.74000","0.00000","0.29511","2.89500","0.18439"
"2.90000","0.29740","9.95809","34.80000","0.00000","0.29740","2.90000","0.18471"
"2.90500","0.29826","9.98698","34.86000","0.00000","0.29826","2.90500","0.18503"
"2.90979","0.29710","9.94807","34.92000","0.00000","0.29710","2.90979","0.18534"
"2.91479","0.28976","9.70233","34.98000","0.00000","0.28976","2.91479","0.18566"
"2.91979","0.28565","9.56490","35.04000","0.00000","0.28565","2.91979","0.18597"
"2.92500","0.26957","9.02644","35.10000","0.00000","0.26957","2.92500","0.18631"
"2.92979","0.27864","9.33013","35.16000","0.00000","0.27864","2.92979","0.18661"
"2.93479","0.27273","9.13229","35.22000","0.00000","0.27273","2.93479","0.18693"
"2.94000","0.26508","8.87608","35.28000","0.00000","0.26508","2.94000","0.18726"
"2.94500","0.26586","8.90213","35.34000","0.00000","0.26586","2.94500","0.18758"
"2.95000","0.27920","9.34878","35.40000","0.00000","0.27920","2.95000","0.18790"
"2.95500","0.26924","9.01541","35.46000","0.00000","0.26924","2.95500","0.18822"
"2.96021","0.26026","8.71467","35.52000","0.00000","0.26026","2.96021","0.18855"
"2.96542","0.24015","8.04109","35.58000","0.00000","0.24015","2.96542","0.18888"
"2.97021","0.22806","7.63639","35.64000","0.00000","0.22806","2.97021","0.18919"
"2.97521","0.21520","7.20594","35.70000","0.00000","0.21520","2.97521","0.18950"
"2.98021","0.20903","6.99934","35.76000","0.00000","0.20903","2.98021","0.18982"
"2.98521","0.20084","6.72487","35.82000","0.00000","0.20084","2.98521","0.19014"
"2.98792","0.20343","6.81168","35.85200","0.00000","0.20343","2.98792","0.19031"