File: G 1- Incubated Samples test to failure-20210303/Specimen_RawData_2.csv
Specimen properties : Specimen label,"Sample-2"
Specimen properties : Length,"11.10000",mm
Specimen properties : Diameter,"0.34100",mm
Test : Rate 1,"5.00000",mm/min

Extension,Load,Tensile stress,Time,PIP count,Tenacity,Tensile extension,Tensile strain (Extension)
(mm),(N),(MPa),(s),,(N/tex),(mm),(mm/mm)
"0.00000","0.00336","0.03680","0.00000","0.00000","0.00336","0.00000","0.00000"
"0.00104","0.00698","0.07643","0.08000","0.00000","0.00698","0.00104","0.00009"
"0.00458","0.02224","0.24352","0.16000","0.00000","0.02224","0.00458","0.00041"
"0.01125","0.05922","0.64847","0.24000","0.00000","0.05922","0.01125","0.00101"
"0.02062","0.11890","1.30194","0.32000","0.00000","0.11890","0.02062","0.00186"
"0.02917","0.18519","2.02773","0.40000","0.00000","0.18519","0.02917","0.00263"
"0.03687","0.23974","2.62505","0.48000","0.00000","0.23974","0.03687","0.00332"
"0.04458","0.28256","3.09392","0.56000","0.00000","0.28256","0.04458","0.00402"
"0.05208","0.31881","3.49085","0.64000","0.00000","0.31881","0.05208","0.00469"
"0.05937","0.34997","3.83208","0.72000","0.00000","0.34997","0.05937","0.00535"
"0.06667","0.36770","4.02616","0.80000","0.00000","0.36770","0.06667","0.00601"
"0.07312","0.42198","4.62059","0.88000","0.00000","0.42198","0.07312","0.00659"
"0.07958","0.45338","4.96433","0.96000","0.00000","0.45338","0.07958","0.00717"
"0.08625","0.49102","5.37646","1.04000","0.00000","0.49102","0.08625","0.00777"
"0.09333","0.48766","5.33971","1.12000","0.00000","0.48766","0.09333","0.00841"
"0.10021","0.54167","5.93107","1.20000","0.00000","0.54167","0.10021","0.00903"
"0.10729","0.57601","6.30717","1.28000","0.00000","0.57601","0.10729","0.00967"
"0.11354","0.27910","3.05602","1.36000","0.00000","0.27910","0.11354","0.01023"
"0.12000","0.34775","3.80773","1.44000","0.00000","0.34775","0.12000","0.01081"
"0.12667","0.40103","4.39120","1.52000","0.00000","0.40103","0.12667","0.01141"
"0.13333","0.45163","4.94524","1.60000","0.00000","0.45163","0.13333","0.01201"
"0.14021","0.48859","5.34986","1.68000","0.00000","0.48859","0.14021","0.01263"
"0.14708","0.52819","5.78347","1.76000","0.00000","0.52819","0.14708","0.01325"
"0.15354","0.56102","6.14297","1.84000","0.00000","0.56102","0.15354","0.01383"
"0.15979","0.60251","6.59730","1.92000","0.00000","0.60251","0.15979","0.01440"
"0.16646","0.64337","7.04469","2.00000","0.00000","0.64337","0.16646","0.01500"
"0.17333","0.66591","7.29155","2.08000","0.00000","0.66591","0.17333","0.01562"
"0.18021","0.72323","7.91919","2.16000","0.00000","0.72323","0.18021","0.01623"
"0.18708","0.75746","8.29396","2.24000","0.00000","0.75746","0.18708","0.01685"
"0.19354","0.79998","8.75947","2.32000","0.00000","0.79998","0.19354","0.01744"
"0.20000","0.84839","9.28961","2.40000","0.00000","0.84839","0.20000","0.01802"
"0.20646","0.87618","9.59391","2.48000","0.00000","0.87618","0.20646","0.01860"
"0.21312","0.87848","9.61912","2.56000","0.00000","0.87848","0.21312","0.01920"
"0.22000","0.90735","9.93515","2.64000","0.00000","0.90735","0.22000","0.01982"
"0.22687","0.94628","10.36146","2.72000","0.00000","0.94628","0.22687","0.02044"
"0.23354","0.97479","10.67362","2.80000","0.00000","0.97479","0.23354","0.02104"
"0.24000","0.99957","10.94502","2.88000","0.00000","0.99957","0.24000","0.02162"
"0.24646","1.03981","11.38560","2.96000","0.00000","1.03981","0.24646","0.02220"
"0.25312","1.06618","11.67438","3.04000","0.00000","1.06618","0.25312","0.02280"
"0.25979","1.09796","12.02230","3.12000","0.00000","1.09796","0.25979","0.02340"
"0.26687","1.13024","12.37574","3.20000","0.00000","1.13024","0.26687","0.02404"
"0.27375","1.16225","12.72630","3.28000","0.00000","1.16225","0.27375","0.02466"
"0.28000","1.18136","12.93555","3.36000","0.00000","1.18136","0.28000","0.02523"
"0.28667","1.19931","13.13205","3.44000","0.00000","1.19931","0.28667","0.02583"
"0.29312","1.21721","13.32806","3.52000","0.00000","1.21721","0.29312","0.02641"
"0.30000","1.23643","13.53848","3.60000","0.00000","1.23643","0.30000","0.02703"
"0.30708","1.24559","13.63878","3.68000","0.00000","1.24559","0.30708","0.02767"
"0.31396","1.25646","13.75789","3.76000","0.00000","1.25646","0.31396","0.02828"
"0.32021","1.22044","13.36343","3.84000","0.00000","1.22044","0.32021","0.02885"
"0.32687","1.25122","13.70048","3.92000","0.00000","1.25122","0.32687","0.02945"
"0.33333","1.27662","13.97859","4.00000","0.00000","1.27662","0.33333","0.03003"
"0.34021","1.30541","14.29382","4.08000","0.00000","1.30541","0.34021","0.03065"
"0.34708","1.33981","14.67047","4.16000","0.00000","1.33981","0.34708","0.03127"
"0.35375","1.36303","14.92472","4.24000","0.00000","1.36303","0.35375","0.03187"
"0.36021","1.38688","15.18593","4.32000","0.00000","1.38688","0.36021","0.03245"
"0.36687","1.41240","15.46532","4.40000","0.00000","1.41240","0.36687","0.03305"
"0.37333","1.43087","15.66758","4.48000","0.00000","1.43087","0.37333","0.03363"
"0.38000","1.46293","16.01862","4.56000","0.00000","1.46293","0.38000","0.03423"
"0.38687","1.48575","16.26848","4.64000","0.00000","1.48575","0.38687","0.03485"
"0.39375","1.50815","16.51378","4.72000","0.00000","1.50815","0.39375","0.03547"
"0.40021","1.53571","16.81557","4.80000","0.00000","1.53571","0.40021","0.03605"
"0.40687","1.56496","17.13576","4.88000","0.00000","1.56496","0.40687","0.03666"
"0.41333","1.59030","17.41326","4.96000","0.00000","1.59030","0.41333","0.03724"
"0.42021","1.60863","17.61393","5.04000","0.00000","1.60863","0.42021","0.03786"
"0.42667","1.62033","17.74213","5.12000","0.00000","1.62033","0.42667","0.03844"
"0.43354","1.65183","18.08697","5.20000","0.00000","1.65183","0.43354","0.03906"
"0.44021","1.66515","18.23287","5.28000","0.00000","1.66515","0.44021","0.03966"
"0.44687","1.69324","18.54041","5.36000","0.00000","1.69324","0.44687","0.04026"
"0.45333","1.70791","18.70106","5.44000","0.00000","1.70791","0.45333","0.04084"
"0.46000","1.72992","18.94203","5.52000","0.00000","1.72992","0.46000","0.04144"
"0.46646","1.74967","19.15827","5.60000","0.00000","1.74967","0.46646","0.04202"
"0.47312","1.77177","19.40035","5.68000","0.00000","1.77177","0.47312","0.04262"
"0.48000","1.77807","19.46935","5.76000","0.00000","1.77807","0.48000","0.04324"
"0.48687","1.81034","19.82260","5.84000","0.00000","1.81034","0.48687","0.04386"
"0.49354","1.83296","20.07036","5.92000","0.00000","1.83296","0.49354","0.04446"
"0.50021","1.85317","20.29157","6.00000","0.00000","1.85317","0.50021","0.04506"
"0.50687","1.86112","20.37866","6.08000","0.00000","1.86112","0.50687","0.04566"
"0.51375","1.88565","20.64729","6.16000","0.00000","1.88565","0.51375","0.04628"
"0.52042","1.90075","20.81264","6.24000","0.00000","1.90075","0.52042","0.04688"
"0.52708","1.92560","21.08465","6.32000","0.00000","1.92560","0.52708","0.04748"
"0.53375","1.93393","21.17588","6.40000","0.00000","1.93393","0.53375","0.04809"
"0.54042","1.95467","21.40306","6.48000","0.00000","1.95467","0.54042","0.04869"
"0.54687","1.98133","21.69490","6.56000","0.00000","1.98133","0.54687","0.04927"
"0.55333","1.99690","21.86544","6.64000","0.00000","1.99690","0.55333","0.04985"
"0.56000","2.00590","21.96397","6.72000","0.00000","2.00590","0.56000","0.05045"
"0.56667","2.03167","22.24608","6.80000","0.00000","2.03167","0.56667","0.05105"
"0.57333","2.05480","22.49943","6.88000","0.00000","2.05480","0.57333","0.05165"
"0.58021","2.05469","22.49823","6.96000","0.00000","2.05469","0.58021","0.05227"
"0.58687","2.09187","22.90531","7.04000","0.00000","2.09187","0.58687","0.05287"
"0.59354","2.10432","23.04160","7.12000","0.00000","2.10432","0.59354","0.05347"
"0.60021","2.11844","23.19622","7.20000","0.00000","2.11844","0.60021","0.05407"
"0.60708","2.13439","23.37084","7.28000","0.00000","2.13439","0.60708","0.05469"
"0.61354","2.14710","23.51009","7.36000","0.00000","2.14710","0.61354","0.05527"
"0.62021","2.16911","23.75110","7.44000","0.00000","2.16911","0.62021","0.05587"
"0.62667","2.18865","23.96507","7.52000","0.00000","2.18865","0.62667","0.05646"
"0.63312","2.19835","24.07122","7.60000","0.00000","2.19835","0.63312","0.05704"
"0.63979","2.21311","24.23284","7.68000","0.00000","2.21311","0.63979","0.05764"
"0.64687","2.22943","24.41152","7.76000","0.00000","2.22943","0.64687","0.05828"
"0.65354","2.24454","24.57702","7.84000","0.00000","2.24454","0.65354","0.05888"
"0.66021","2.25598","24.70224","7.92000","0.00000","2.25598","0.66021","0.05948"
"0.66667","2.27127","24.86966","8.00000","0.00000","2.27127","0.66667","0.06006"
"0.67292","2.29528","25.13257","8.08000","0.00000","2.29528","0.67292","0.06062"
"0.67979","2.30361","25.22375","8.16000","0.00000","2.30361","0.67979","0.06124"
"0.68687","2.32432","25.45056","8.24000","0.00000","2.32432","0.68687","0.06188"
"0.69354","2.34394","25.66541","8.32000","0.00000","2.34394","0.69354","0.06248"
"0.70021","2.36477","25.89352","8.40000","0.00000","2.36477","0.70021","0.06308"
"0.70667","2.38082","26.06918","8.48000","0.00000","2.38082","0.70667","0.06366"
"0.71312","2.40166","26.29746","8.56000","0.00000","2.40166","0.71312","0.06425"
"0.72000","2.41515","26.44508","8.64000","0.00000","2.41515","0.72000","0.06486"
"0.72708","2.43636","26.67736","8.72000","0.00000","2.43636","0.72708","0.06550"
"0.73396","2.45604","26.89284","8.80000","0.00000","2.45604","0.73396","0.06612"
"0.74062","2.46424","26.98266","8.88000","0.00000","2.46424","0.74062","0.06672"
"0.74708","2.30795","25.27133","8.96000","0.00000","2.30795","0.74708","0.06730"
"0.75333","2.30918","25.28476","9.04000","0.00000","2.30918","0.75333","0.06787"
"0.75979","2.33855","25.60640","9.12000","0.00000","2.33855","0.75979","0.06845"
"0.76667","2.35993","25.84049","9.20000","0.00000","2.35993","0.76667","0.06907"
"0.77333","2.38469","26.11159","9.28000","0.00000","2.38469","0.77333","0.06967"
"0.78021","2.40481","26.33194","9.36000","0.00000","2.40481","0.78021","0.07029"
"0.78687","2.41224","26.41321","9.44000","0.00000","2.41224","0.78687","0.07089"
"0.79312","2.40405","26.32352","9.52000","0.00000","2.40405","0.79312","0.07145"
"0.80000","2.40175","26.29839","9.60000","0.00000","2.40175","0.80000","0.07207"
"0.80687","2.42096","26.50868","9.68000","0.00000","2.42096","0.80687","0.07269"
"0.81396","2.45122","26.84003","9.76000","0.00000","2.45122","0.81396","0.07333"
"0.82042","2.47138","27.06085","9.84000","0.00000","2.47138","0.82042","0.07391"
"0.82687","2.48579","27.21864","9.92000","0.00000","2.48579","0.82687","0.07449"
"0.83333","2.49943","27.36800","10.00000","0.00000","2.49943","0.83333","0.07508"
"0.83979","2.51263","27.51246","10.08000","0.00000","2.51263","0.83979","0.07566"
"0.84667","2.53150","27.71908","10.16000","0.00000","2.53150","0.84667","0.07628"
"0.85354","2.51794","27.57064","10.24000","0.00000","2.51794","0.85354","0.07690"
"0.86021","2.44930","26.81903","10.32000","0.00000","2.44930","0.86021","0.07750"
"0.86667","2.41528","26.44654","10.40000","0.00000","2.41528","0.86667","0.07808"
"0.87312","2.27981","24.96317","10.48000","0.00000","2.27981","0.87312","0.07866"
"0.87979","2.21659","24.27092","10.56000","0.00000","2.21659","0.87979","0.07926"
"0.88646","2.23831","24.50874","10.64000","0.00000","2.23831","0.88646","0.07986"
"0.89333","2.25260","24.66525","10.72000","0.00000","2.25260","0.89333","0.08048"
"0.90042","2.27536","24.91450","10.80000","0.00000","2.27536","0.90042","0.08112"
"0.90687","2.29796","25.16194","10.88000","0.00000","2.29796","0.90687","0.08170"
"0.91312","2.32191","25.42416","10.96000","0.00000","2.32191","0.91312","0.08226"
"0.91979","2.33940","25.61567","11.04000","0.00000","2.33940","0.91979","0.08286"
"0.92667","2.35507","25.78727","11.12000","0.00000","2.35507","0.92667","0.08348"
"0.93375","2.38973","26.16674","11.20000","0.00000","2.38973","0.93375","0.08412"
"0.94083","2.40965","26.38487","11.28000","0.00000","2.40965","0.94083","0.08476"
"0.94708","2.42446","26.54709","11.36000","0.00000","2.42446","0.94708","0.08532"
"0.95333","2.43735","26.68818","11.44000","0.00000","2.43735","0.95333","0.08589"
"0.95979","2.45417","26.87239","11.52000","0.00000","2.45417","0.95979","0.08647"
"0.96667","2.48031","27.15860","11.60000","0.00000","2.48031","0.96667","0.08709"
"0.97354","2.49928","27.36631","11.68000","0.00000","2.49928","0.97354","0.08771"
"0.98042","2.52234","27.61886","11.76000","0.00000","2.52234","0.98042","0.08833"
"0.98708","2.50702","27.45107","11.84000","0.00000","2.50702","0.98708","0.08893"
"0.99333","2.52102","27.60440","11.92000","0.00000","2.52102","0.99333","0.08949"
"0.99979","2.53323","27.73810","12.00000","0.00000","2.53323","0.99979","0.09007"
"1.00646","2.56383","28.07308","12.08000","0.00000","2.56383","1.00646","0.09067"
"1.01354","2.58703","28.32716","12.16000","0.00000","2.58703","1.01354","0.09131"
"1.02062","2.61097","28.58932","12.24000","0.00000","2.61097","1.02062","0.09195"
"1.02708","2.62693","28.76404","12.32000","0.00000","2.62693","1.02708","0.09253"
"1.03333","2.64972","29.01358","12.40000","0.00000","2.64972","1.03333","0.09309"
"1.03979","2.65927","29.11819","12.48000","0.00000","2.65927","1.03979","0.09367"
"1.04646","2.68852","29.43843","12.56000","0.00000","2.68852","1.04646","0.09428"
"1.05333","2.70864","29.65869","12.64000","0.00000","2.70864","1.05333","0.09489"
"1.06042","2.72561","29.84456","12.72000","0.00000","2.72561","1.06042","0.09553"
"1.06687","2.73825","29.98299","12.80000","0.00000","2.73825","1.06687","0.09611"
"1.07312","2.75099","30.12243","12.88000","0.00000","2.75099","1.07312","0.09668"
"1.07958","2.78135","30.45494","12.96000","0.00000","2.78135","1.07958","0.09726"
"1.08625","2.79259","30.57799","13.04000","0.00000","2.79259","1.08625","0.09786"
"1.09312","2.81022","30.77102","13.12000","0.00000","2.81022","1.09312","0.09848"
"1.10000","2.83369","31.02802","13.20000","0.00000","2.83369","1.10000","0.09910"
"1.10687","2.84818","31.18661","13.28000","0.00000","2.84818","1.10687","0.09972"
"1.11312","2.86909","31.41563","13.36000","0.00000","2.86909","1.11312","0.10028"
"1.11979","2.88777","31.62019","13.44000","0.00000","2.88777","1.11979","0.10088"
"1.12646","2.91207","31.88625","13.52000","0.00000","2.91207","1.12646","0.10148"
"1.13354","2.92281","32.00378","13.60000","0.00000","2.92281","1.13354","0.10212"
"1.14042","2.94269","32.22155","13.68000","0.00000","2.94269","1.14042","0.10274"
"1.14729","2.96907","32.51036","13.76000","0.00000","2.96907","1.14729","0.10336"
"1.15375","2.98594","32.69511","13.84000","0.00000","2.98594","1.15375","0.10394"
"1.16021","2.99525","32.79701","13.92000","0.00000","2.99525","1.16021","0.10452"
"1.16667","3.00356","32.88802","14.00000","0.00000","3.00356","1.16667","0.10511"
"1.17354","3.01873","33.05409","14.08000","0.00000","3.01873","1.17354","0.10572"
"1.18021","3.04356","33.32605","14.16000","0.00000","3.04356","1.18021","0.10633"
"1.18708","3.05702","33.47342","14.24000","0.00000","3.05702","1.18708","0.10694"
"1.19354","3.07117","33.62830","14.32000","0.00000","3.07117","1.19354","0.10753"
"1.20021","3.09295","33.86682","14.40000","0.00000","3.09295","1.20021","0.10813"
"1.20667","3.10247","33.97108","14.48000","0.00000","3.10247","1.20667","0.10871"
"1.21354","3.11298","34.08618","14.56000","0.00000","3.11298","1.21354","0.10933"
"1.22021","3.14614","34.44924","14.64000","0.00000","3.14614","1.22021","0.10993"
"1.22708","3.15324","34.52696","14.72000","0.00000","3.15324","1.22708","0.11055"
"1.23354","3.16790","34.68751","14.80000","0.00000","3.16790","1.23354","0.11113"
"1.24021","3.17656","34.78236","14.88000","0.00000","3.17656","1.24021","0.11173"
"1.24667","3.19247","34.95650","14.96000","0.00000","3.19247","1.24667","0.11231"
"1.25354","3.19423","34.97584","15.04000","0.00000","3.19423","1.25354","0.11293"
"1.26000","3.20585","35.10307","15.12000","0.00000","3.20585","1.26000","0.11351"
"1.26667","3.22201","35.28002","15.20000","0.00000","3.22201","1.26667","0.11411"
"1.27333","3.22705","35.33518","15.28000","0.00000","3.22705","1.27333","0.11471"
"1.28000","3.24225","35.50164","15.36000","0.00000","3.24225","1.28000","0.11532"
"1.28646","3.26419","35.74185","15.44000","0.00000","3.26419","1.28646","0.11590"
"1.29333","3.28296","35.94731","15.52000","0.00000","3.28296","1.29333","0.11652"
"1.29979","3.29582","36.08818","15.60000","0.00000","3.29582","1.29979","0.11710"
"1.30646","3.30594","36.19901","15.68000","0.00000","3.30594","1.30646","0.11770"
"1.31333","3.32071","36.36076","15.76000","0.00000","3.32071","1.31333","0.11832"
"1.32000","3.34591","36.63659","15.84000","0.00000","3.34591","1.32000","0.11892"
"1.32667","3.36981","36.89830","15.92000","0.00000","3.36981","1.32667","0.11952"
"1.33333","3.38584","37.07381","16.00000","0.00000","3.38584","1.33333","0.12012"
"1.34000","3.39769","37.20360","16.08000","0.00000","3.39769","1.34000","0.12072"
"1.34687","3.42325","37.48344","16.16000","0.00000","3.42325","1.34687","0.12134"
"1.35375","3.44669","37.74015","16.24000","0.00000","3.44669","1.35375","0.12196"
"1.36042","3.45610","37.84315","16.32000","0.00000","3.45610","1.36042","0.12256"
"1.36708","3.47208","38.01812","16.40000","0.00000","3.47208","1.36708","0.12316"
"1.37375","3.49154","38.23127","16.48000","0.00000","3.49154","1.37375","0.12376"
"1.38021","3.50983","38.43154","16.56000","0.00000","3.50983","1.38021","0.12434"
"1.38667","3.53590","38.71695","16.64000","0.00000","3.53590","1.38667","0.12492"
"1.39354","3.54924","38.86306","16.72000","0.00000","3.54924","1.39354","0.12554"
"1.40021","3.56746","39.06255","16.80000","0.00000","3.56746","1.40021","0.12614"
"1.40687","3.59307","39.34298","16.88000","0.00000","3.59307","1.40687","0.12675"
"1.41375","3.61202","39.55045","16.96000","0.00000","3.61202","1.41375","0.12736"
"1.42021","3.63031","39.75077","17.04000","0.00000","3.63031","1.42021","0.12795"
"1.42687","3.64094","39.86710","17.12000","0.00000","3.64094","1.42687","0.12855"
"1.43354","3.66442","40.12418","17.20000","0.00000","3.66442","1.43354","0.12915"
"1.44042","3.67077","40.19374","17.28000","0.00000","3.67077","1.44042","0.12977"
"1.44687","3.68913","40.39481","17.36000","0.00000","3.68913","1.44687","0.13035"
"1.45375","3.69802","40.49212","17.44000","0.00000","3.69802","1.45375","0.13097"
"1.46021","3.71099","40.63419","17.52000","0.00000","3.71099","1.46021","0.13155"
"1.46646","3.71463","40.67402","17.60000","0.00000","3.71463","1.46646","0.13211"
"1.47333","3.71608","40.68983","17.68000","0.00000","3.71608","1.47333","0.13273"
"1.48021","3.72009","40.73375","17.76000","0.00000","3.72009","1.48021","0.13335"
"1.48687","3.71278","40.65376","17.84000","0.00000","3.71278","1.48687","0.13395"
"1.49354","3.69635","40.47379","17.92000","0.00000","3.69635","1.49354","0.13455"
"1.50021","3.42585","37.51193","18.00000","0.00000","3.42585","1.50021","0.13515"
"1.50646","3.43113","37.56982","18.08000","0.00000","3.43113","1.50646","0.13572"
"1.51312","3.46728","37.96559","18.16000","0.00000","3.46728","1.51312","0.13632"
"1.52000","3.50611","38.39079","18.24000","0.00000","3.50611","1.52000","0.13694"
"1.52687","3.54702","38.83873","18.32000","0.00000","3.54702","1.52687","0.13756"
"1.53354","3.57853","39.18376","18.40000","0.00000","3.57853","1.53354","0.13816"
"1.54021","3.60932","39.52090","18.48000","0.00000","3.60932","1.54021","0.13876"
"1.54646","3.64245","39.88361","18.56000","0.00000","3.64245","1.54646","0.13932"
"1.55333","3.66941","40.17883","18.64000","0.00000","3.66941","1.55333","0.13994"
"1.56021","3.70607","40.58023","18.72000","0.00000","3.70607","1.56021","0.14056"
"1.56729","3.73694","40.91826","18.80000","0.00000","3.73694","1.56729","0.14120"
"1.57417","3.76617","41.23840","18.88000","0.00000","3.76617","1.57417","0.14182"
"1.58042","3.80044","41.61359","18.96000","0.00000","3.80044","1.58042","0.14238"
"1.58667","3.82584","41.89167","19.04000","0.00000","3.82584","1.58667","0.14294"
"1.59354","3.85294","42.18842","19.12000","0.00000","3.85294","1.59354","0.14356"
"1.60042","3.88763","42.56835","19.20000","0.00000","3.88763","1.60042","0.14418"
"1.60708","3.90464","42.75460","19.28000","0.00000","3.90464","1.60708","0.14478"
"1.61354","3.93534","43.09072","19.36000","0.00000","3.93534","1.61354","0.14536"
"1.62000","3.96768","43.44485","19.44000","0.00000","3.96768","1.62000","0.14595"
"1.62646","3.98454","43.62946","19.52000","0.00000","3.98454","1.62646","0.14653"
"1.63312","4.01090","43.91809","19.60000","0.00000","4.01090","1.63312","0.14713"
"1.64000","4.04114","44.24923","19.68000","0.00000","4.04114","1.64000","0.14775"
"1.64708","4.06907","44.55502","19.76000","0.00000","4.06907","1.64708","0.14839"
"1.65396","4.09523","44.84149","19.84000","0.00000","4.09523","1.65396","0.14901"
"1.66021","4.11374","45.04416","19.92000","0.00000","4.11374","1.66021","0.14957"
"1.66646","4.12994","45.22156","20.00000","0.00000","4.12994","1.66646","0.15013"
"1.67312","4.14953","45.43607","20.08000","0.00000","4.14953","1.67312","0.15073"
"1.68000","4.17579","45.72352","20.16000","0.00000","4.17579","1.68000","0.15135"
"1.68667","4.19960","45.98424","20.24000","0.00000","4.19960","1.68667","0.15195"
"1.69375","4.22124","46.22124","20.32000","0.00000","4.22124","1.69375","0.15259"
"1.70000","4.23371","46.35778","20.40000","0.00000","4.23371","1.70000","0.15315"
"1.70646","4.25978","46.64322","20.48000","0.00000","4.25978","1.70646","0.15373"
"1.71312","4.26717","46.72409","20.56000","0.00000","4.26717","1.71312","0.15434"
"1.72000","4.28776","46.94964","20.64000","0.00000","4.28776","1.72000","0.15495"
"1.72667","4.30795","47.17063","20.72000","0.00000","4.30795","1.72667","0.15556"
"1.73375","4.33280","47.44274","20.80000","0.00000","4.33280","1.73375","0.15619"
"1.74021","4.34735","47.60214","20.88000","0.00000","4.34735","1.74021","0.15678"
"1.74646","4.36579","47.80402","20.96000","0.00000","4.36579","1.74646","0.15734"
"1.75312","4.39306","48.10257","21.04000","0.00000","4.39306","1.75312","0.15794"
"1.76000","4.40691","48.25422","21.12000","0.00000","4.40691","1.76000","0.15856"
"1.76708","4.42277","48.42795","21.20000","0.00000","4.42277","1.76708","0.15920"
"1.77396","4.43476","48.55916","21.28000","0.00000","4.43476","1.77396","0.15982"
"1.78042","4.44369","48.65693","21.36000","0.00000","4.44369","1.78042","0.16040"
"1.78667","4.45240","48.75237","21.44000","0.00000","4.45240","1.78667","0.16096"
"1.79333","4.47836","49.03658","21.52000","0.00000","4.47836","1.79333","0.16156"
"1.80000","4.49804","49.25212","21.60000","0.00000","4.49804","1.80000","0.16216"
"1.80687","4.51557","49.44401","21.68000","0.00000","4.51557","1.80687","0.16278"
"1.81375","4.53282","49.63297","21.76000","0.00000","4.53282","1.81375","0.16340"
"1.82042","4.55928","49.92270","21.84000","0.00000","4.55928","1.82042","0.16400"
"1.82667","4.57576","50.10315","21.92000","0.00000","4.57576","1.82667","0.16456"
"1.83312","4.59615","50.32638","22.00000","0.00000","4.59615","1.83312","0.16515"
"1.84000","4.61400","50.52176","22.08000","0.00000","4.61400","1.84000","0.16577"
"1.84708","4.63397","50.74045","22.16000","0.00000","4.63397","1.84708","0.16640"
"1.85396","4.66215","51.04905","22.24000","0.00000","4.66215","1.85396","0.16702"
"1.86042","4.67648","51.20599","22.32000","0.00000","4.67648","1.86042","0.16761"
"1.86646","4.69409","51.39882","22.40000","0.00000","4.69409","1.86646","0.16815"
"1.87312","4.71562","51.63451","22.48000","0.00000","4.71562","1.87312","0.16875"
"1.87979","4.73477","51.84420","22.56000","0.00000","4.73477","1.87979","0.16935"
"1.88646","4.75466","52.06202","22.64000","0.00000","4.75466","1.88646","0.16995"
"1.89354","4.77516","52.28651","22.72000","0.00000","4.77516","1.89354","0.17059"
"1.90021","4.79751","52.53122","22.80000","0.00000","4.79751","1.90021","0.17119"
"1.90646","4.81049","52.67337","22.88000","0.00000","4.81049","1.90646","0.17175"
"1.91312","4.83433","52.93436","22.96000","0.00000","4.83433","1.91312","0.17235"
"1.91979","4.84246","53.02343","23.04000","0.00000","4.84246","1.91979","0.17295"
"1.92667","4.86230","53.24060","23.12000","0.00000","4.86230","1.92667","0.17357"
"1.93354","4.87481","53.37764","23.20000","0.00000","4.87481","1.93354","0.17419"
"1.94021","4.88940","53.53737","23.28000","0.00000","4.88940","1.94021","0.17479"
"1.94667","4.90166","53.67159","23.36000","0.00000","4.90166","1.94667","0.17538"
"1.95312","4.91144","53.77863","23.44000","0.00000","4.91144","1.95312","0.17596"
"1.95979","4.92418","53.91814","23.52000","0.00000","4.92418","1.95979","0.17656"
"1.96667","4.94794","54.17840","23.60000","0.00000","4.94794","1.96667","0.17718"
"1.97375","4.95904","54.29987","23.68000","0.00000","4.95904","1.97375","0.17782"
"1.98042","4.98257","54.55749","23.76000","0.00000","4.98257","1.98042","0.17842"
"1.98687","5.01130","54.87212","23.84000","0.00000","5.01130","1.98687","0.17900"
"1.99354","5.02050","54.97285","23.92000","0.00000","5.02050","1.99354","0.17960"
"2.00000","5.03800","55.16443","24.00000","0.00000","5.03800","2.00000","0.18018"
"2.00687","5.05648","55.36688","24.08000","0.00000","5.05648","2.00687","0.18080"
"2.01375","5.07866","55.60971","24.16000","0.00000","5.07866","2.01375","0.18142"
"2.02042","5.10263","55.87219","24.24000","0.00000","5.10263","2.02042","0.18202"
"2.02687","5.12120","56.07553","24.32000","0.00000","5.12120","2.02687","0.18260"
"2.03333","5.13811","56.26061","24.40000","0.00000","5.13811","2.03333","0.18318"
"2.03979","5.16640","56.57044","24.48000","0.00000","5.16640","2.03979","0.18376"
"2.04667","5.18277","56.74966","24.56000","0.00000","5.18277","2.04667","0.18438"
"2.05354","5.20434","56.98583","24.64000","0.00000","5.20434","2.05354","0.18500"
"2.06042","5.21968","57.15380","24.72000","0.00000","5.21968","2.06042","0.18562"
"2.06708","5.24460","57.42670","24.80000","0.00000","5.24460","2.06708","0.18622"
"2.07354","5.25975","57.59262","24.88000","0.00000","5.25975","2.07354","0.18681"
"2.08000","5.27112","57.71702","24.96000","0.00000","5.27112","2.08000","0.18739"
"2.08687","5.30651","58.10460","25.04000","0.00000","5.30651","2.08687","0.18801"
"2.09333","5.31624","58.21107","25.12000","0.00000","5.31624","2.09333","0.18859"
"2.10000","5.34114","58.48380","25.20000","0.00000","5.34114","2.10000","0.18919"
"2.10667","5.36439","58.73838","25.28000","0.00000","5.36439","2.10667","0.18979"
"2.11333","5.37424","58.84616","25.36000","0.00000","5.37424","2.11333","0.19039"
"2.11979","5.39848","59.11161","25.44000","0.00000","5.39848","2.11979","0.19097"
"2.12667","5.42442","59.39566","25.52000","0.00000","5.42442","2.12667","0.19159"
"2.13333","5.44620","59.63411","25.60000","0.00000","5.44620","2.13333","0.19219"
"2.13979","5.45535","59.73432","25.68000","0.00000","5.45535","2.13979","0.19277"
"2.14667","5.47573","59.95753","25.76000","0.00000","5.47573","2.14667","0.19339"
"2.15333","5.49671","60.18722","25.84000","0.00000","5.49671","2.15333","0.19399"
"2.16000","5.50957","60.32806","25.92000","0.00000","5.50957","2.16000","0.19459"
"2.16687","5.52933","60.54436","26.00000","0.00000","5.52933","2.16687","0.19521"
"2.17354","5.54425","60.70779","26.08000","0.00000","5.54425","2.17354","0.19581"
"2.18021","5.56706","60.95749","26.16000","0.00000","5.56706","2.18021","0.19642"
"2.18708","5.57549","61.04981","26.24000","0.00000","5.57549","2.18708","0.19703"
"2.19375","5.59612","61.27576","26.32000","0.00000","5.59612","2.19375","0.19764"
"2.20042","5.62182","61.55715","26.40000","0.00000","5.62182","2.20042","0.19824"
"2.20708","5.62772","61.62168","26.48000","0.00000","5.62772","2.20708","0.19884"
"2.21354","5.65348","61.90382","26.56000","0.00000","5.65348","2.21354","0.19942"
"2.22000","5.67567","62.14671","26.64000","0.00000","5.67567","2.22000","0.20000"
"2.22687","5.70839","62.50505","26.72000","0.00000","5.70839","2.22687","0.20062"
"2.23354","5.73042","62.74630","26.80000","0.00000","5.73042","2.23354","0.20122"
"2.24021","5.74824","62.94137","26.88000","0.00000","5.74824","2.24021","0.20182"
"2.24687","5.77236","63.20547","26.96000","0.00000","5.77236","2.24687","0.20242"
"2.25354","5.79891","63.49617","27.04000","0.00000","5.79891","2.25354","0.20302"
"2.26021","5.82468","63.77832","27.12000","0.00000","5.82468","2.26021","0.20362"
"2.26687","5.84616","64.01362","27.20000","0.00000","5.84616","2.26687","0.20422"
"2.27375","5.86559","64.22627","27.28000","0.00000","5.86559","2.27375","0.20484"
"2.28021","5.89387","64.53603","27.36000","0.00000","5.89387","2.28021","0.20542"
"2.28687","5.91743","64.79395","27.44000","0.00000","5.91743","2.28687","0.20602"
"2.29333","5.93286","64.96288","27.52000","0.00000","5.93286","2.29333","0.20661"
"2.29979","5.96704","65.33717","27.60000","0.00000","5.96704","2.29979","0.20719"
"2.30646","5.98003","65.47945","27.68000","0.00000","5.98003","2.30646","0.20779"
"2.31333","6.00732","65.77818","27.76000","0.00000","6.00732","2.31333","0.20841"
"2.32021","6.02747","65.99886","27.84000","0.00000","6.02747","2.32021","0.20903"
"2.32687","6.05294","66.27777","27.92000","0.00000","6.05294","2.32687","0.20963"
"2.33333","6.06612","66.42201","28.00000","0.00000","6.06612","2.33333","0.21021"
"2.33979","6.08928","66.67569","28.08000","0.00000","6.08928","2.33979","0.21079"
"2.34646","6.12018","67.01397","28.16000","0.00000","6.12018","2.34646","0.21139"
"2.35333","6.13851","67.21467","28.24000","0.00000","6.13851","2.35333","0.21201"
"2.36042","6.15643","67.41091","28.32000","0.00000","6.15643","2.36042","0.21265"
"2.36687","6.18351","67.70744","28.40000","0.00000","6.18351","2.36687","0.21323"
"2.37333","6.20519","67.94485","28.48000","0.00000","6.20519","2.37333","0.21381"
"2.37979","6.21656","68.06929","28.56000","0.00000","6.21656","2.37979","0.21440"
"2.38687","6.24902","68.42477","28.64000","0.00000","6.24902","2.38687","0.21503"
"2.39375","6.26906","68.64418","28.72000","0.00000","6.26906","2.39375","0.21565"
"2.40042","6.29510","68.92931","28.80000","0.00000","6.29510","2.40042","0.21625"
"2.40708","6.31181","69.11225","28.88000","0.00000","6.31181","2.40708","0.21685"
"2.41354","6.33597","69.37678","28.96000","0.00000","6.33597","2.41354","0.21744"
"2.41979","6.34207","69.44362","29.04000","0.00000","6.34207","2.41979","0.21800"
"2.42667","6.37029","69.75258","29.12000","0.00000","6.37029","2.42667","0.21862"
"2.43333","6.39397","70.01191","29.20000","0.00000","6.39397","2.43333","0.21922"
"2.44021","6.40927","70.17939","29.28000","0.00000","6.40927","2.44021","0.21984"
"2.44708","6.42692","70.37268","29.36000","0.00000","6.42692","2.44708","0.22046"
"2.45354","6.43648","70.47741","29.44000","0.00000","6.43648","2.45354","0.22104"
"2.45979","6.45341","70.66280","29.52000","0.00000","6.45341","2.45979","0.22160"
"2.46646","6.47192","70.86546","29.60000","0.00000","6.47192","2.46646","0.22220"
"2.47333","6.49131","71.07779","29.68000","0.00000","6.49131","2.47333","0.22282"
"2.48042","6.50944","71.27628","29.76000","0.00000","6.50944","2.48042","0.22346"
"2.48708","6.52819","71.48157","29.84000","0.00000","6.52819","2.48708","0.22406"
"2.49354","6.53899","71.59978","29.92000","0.00000","6.53899","2.49354","0.22464"
"2.49979","6.56133","71.84442","30.00000","0.00000","6.56133","2.49979","0.22521"
"2.50646","6.58389","72.09153","30.08000","0.00000","6.58389","2.50646","0.22581"
"2.51312","6.58226","72.07366","30.16000","0.00000","6.58226","2.51312","0.22641"
"2.52000","6.60623","72.33610","30.24000","0.00000","6.60623","2.52000","0.22703"
"2.52708","6.61904","72.47636","30.32000","0.00000","6.61904","2.52708","0.22767"
"2.53354","6.63664","72.66911","30.40000","0.00000","6.63664","2.53354","0.22825"
"2.53979","6.64524","72.76321","30.48000","0.00000","6.64524","2.53979","0.22881"
"2.54646","6.66146","72.94083","30.56000","0.00000","6.66146","2.54646","0.22941"
"2.55333","6.68073","73.15179","30.64000","0.00000","6.68073","2.55333","0.23003"
"2.56000","6.69231","73.27864","30.72000","0.00000","6.69231","2.56000","0.23063"
"2.56687","6.71515","73.52877","30.80000","0.00000","6.71515","2.56687","0.23125"
"2.57354","6.72877","73.67786","30.88000","0.00000","6.72877","2.57354","0.23185"
"2.58000","6.74150","73.81727","30.96000","0.00000","6.74150","2.58000","0.23243"
"2.58646","6.75902","74.00908","31.04000","0.00000","6.75902","2.58646","0.23301"
"2.59333","6.77752","74.21163","31.12000","0.00000","6.77752","2.59333","0.23363"
"2.60042","6.79636","74.41800","31.20000","0.00000","6.79636","2.60042","0.23427"
"2.60729","6.82111","74.68891","31.28000","0.00000","6.82111","2.60729","0.23489"
"2.61375","6.83900","74.88481","31.36000","0.00000","6.83900","2.61375","0.23547"
"2.62021","6.85707","75.08275","31.44000","0.00000","6.85707","2.62021","0.23605"
"2.62667","6.87043","75.22897","31.52000","0.00000","6.87043","2.62667","0.23664"
"2.63333","6.89232","75.46873","31.60000","0.00000","6.89232","2.63333","0.23724"
"2.64021","6.91489","75.71584","31.68000","0.00000","6.91489","2.64021","0.23786"
"2.64708","6.93907","75.98058","31.76000","0.00000","6.93907","2.64708","0.23848"
"2.65375","6.95537","76.15911","31.84000","0.00000","6.95537","2.65375","0.23908"
"2.65979","6.97215","76.34277","31.92000","0.00000","6.97215","2.65979","0.23962"
"2.66646","6.99705","76.61546","32.00000","0.00000","6.99705","2.66646","0.24022"
"2.67312","7.01404","76.80147","32.08000","0.00000","7.01404","2.67312","0.24082"
"2.68021","7.03713","77.05429","32.16000","0.00000","7.03713","2.68021","0.24146"
"2.68708","7.06083","77.31380","32.24000","0.00000","7.06083","2.68708","0.24208"
"2.69375","7.08308","77.55740","32.32000","0.00000","7.08308","2.69375","0.24268"
"2.69979","7.09638","77.70305","32.40000","0.00000","7.09638","2.69979","0.24322"
"2.70646","7.11215","77.87571","32.48000","0.00000","7.11215","2.70646","0.24383"
"2.71312","7.13053","78.07698","32.56000","0.00000","7.13053","2.71312","0.24443"
"2.72000","7.15741","78.37135","32.64000","0.00000","7.15741","2.72000","0.24505"
"2.72687","7.17263","78.53795","32.72000","0.00000","7.17263","2.72687","0.24566"
"2.73354","7.19542","78.78754","32.80000","0.00000","7.19542","2.73354","0.24626"
"2.74000","7.21889","79.04456","32.88000","0.00000","7.21889","2.74000","0.24685"
"2.74646","7.23520","79.22314","32.96000","0.00000","7.23520","2.74646","0.24743"
"2.75312","7.25006","79.38582","33.04000","0.00000","7.25006","2.75312","0.24803"
"2.75979","7.27042","79.60873","33.12000","0.00000","7.27042","2.75979","0.24863"
"2.76667","7.29308","79.85688","33.20000","0.00000","7.29308","2.76667","0.24925"
"2.77354","7.31114","80.05465","33.28000","0.00000","7.31114","2.77354","0.24987"
"2.78000","7.33524","80.31849","33.36000","0.00000","7.33524","2.78000","0.25045"
"2.78646","7.35448","80.52923","33.44000","0.00000","7.35448","2.78646","0.25103"
"2.79312","7.36892","80.68736","33.52000","0.00000","7.36892","2.79312","0.25163"
"2.80000","7.39030","80.92146","33.60000","0.00000","7.39030","2.80000","0.25225"
"2.80708","7.41786","81.22314","33.68000","0.00000","7.41786","2.80708","0.25289"
"2.81375","7.43905","81.45525","33.76000","0.00000","7.43905","2.81375","0.25349"
"2.82021","7.45651","81.64638","33.84000","0.00000","7.45651","2.82021","0.25407"
"2.82687","7.47430","81.84120","33.92000","0.00000","7.47430","2.82687","0.25467"
"2.83333","7.49528","82.07095","34.00000","0.00000","7.49528","2.83333","0.25526"
"2.84021","7.51196","82.25353","34.08000","0.00000","7.51196","2.84021","0.25587"
"2.84687","7.53544","82.51068","34.16000","0.00000","7.53544","2.84687","0.25648"
"2.85375","7.56071","82.78731","34.24000","0.00000","7.56071","2.85375","0.25709"
"2.86042","7.57147","82.90517","34.32000","0.00000","7.57147","2.86042","0.25770"
"2.86687","7.58950","83.10262","34.40000","0.00000","7.58950","2.86687","0.25828"
"2.87333","7.61512","83.38313","34.48000","0.00000","7.61512","2.87333","0.25886"
"2.88021","7.64041","83.65998","34.56000","0.00000","7.64041","2.88021","0.25948"
"2.88687","7.65838","83.85684","34.64000","0.00000","7.65838","2.88687","0.26008"
"2.89375","7.67278","84.01447","34.72000","0.00000","7.67278","2.89375","0.26070"
"2.90021","7.69431","84.25023","34.80000","0.00000","7.69431","2.90021","0.26128"
"2.90687","7.70832","84.40366","34.88000","0.00000","7.70832","2.90687","0.26188"
"2.91333","7.73490","84.69469","34.96000","0.00000","7.73490","2.91333","0.26246"
"2.92021","7.75048","84.86532","35.04000","0.00000","7.75048","2.92021","0.26308"
"2.92667","7.77547","85.13886","35.12000","0.00000","7.77547","2.92667","0.26366"
"2.93333","7.78999","85.29793","35.20000","0.00000","7.78999","2.93333","0.26426"
"2.94000","7.81048","85.52221","35.28000","0.00000","7.81048","2.94000","0.26486"
"2.94667","7.83324","85.77141","35.36000","0.00000","7.83324","2.94667","0.26547"
"2.95312","7.85504","86.01016","35.44000","0.00000","7.85504","2.95312","0.26605"
"2.96000","7.87146","86.18990","35.52000","0.00000","7.87146","2.96000","0.26667"
"2.96667","7.88579","86.34686","35.60000","0.00000","7.88579","2.96667","0.26727"
"2.97312","7.90511","86.55838","35.68000","0.00000","7.90511","2.97312","0.26785"
"2.98000","7.92707","86.79892","35.76000","0.00000","7.92707","2.98000","0.26847"
"2.98667","7.94048","86.94571","35.84000","0.00000","7.94048","2.98667","0.26907"
"2.99333","7.96121","87.17270","35.92000","0.00000","7.96121","2.99333","0.26967"
"3.00000","7.98598","87.44395","36.00000","0.00000","7.98598","3.00000","0.27027"
"3.00667","8.00366","87.63754","36.08000","0.00000","8.00366","3.00667","0.27087"
"3.01354","8.02094","87.82668","36.16000","0.00000","8.02094","3.01354","0.27149"
"3.02042","8.03892","88.02361","36.24000","0.00000","8.03892","3.02042","0.27211"
"3.02708","8.05515","88.20133","36.32000","0.00000","8.05515","3.02708","0.27271"
"3.03375","8.07831","88.45486","36.40000","0.00000","8.07831","3.03375","0.27331"
"3.04042","8.09895","88.68092","36.48000","0.00000","8.09895","3.04042","0.27391"
"3.04687","8.11373","88.84278","36.56000","0.00000","8.11373","3.04687","0.27449"
"3.05354","8.14137","89.14540","36.64000","0.00000","8.14137","3.05354","0.27509"
"3.06021","8.15253","89.26760","36.72000","0.00000","8.15253","3.06021","0.27569"
"3.06687","8.16994","89.45818","36.80000","0.00000","8.16994","3.06687","0.27629"
"3.07354","8.18973","89.67496","36.88000","0.00000","8.18973","3.07354","0.27690"
"3.08042","8.21595","89.96196","36.96000","0.00000","8.21595","3.08042","0.27751"
"3.08687","8.23796","90.20306","37.04000","0.00000","8.23796","3.08687","0.27810"
"3.09354","8.23907","90.21516","37.12000","0.00000","8.23907","3.09354","0.27870"
"3.10021","8.26575","90.50731","37.20000","0.00000","8.26575","3.10021","0.27930"
"3.10687","8.27703","90.63079","37.28000","0.00000","8.27703","3.10687","0.27990"
"3.11333","8.28939","90.76611","37.36000","0.00000","8.28939","3.11333","0.28048"
"3.12021","8.31217","91.01561","37.44000","0.00000","8.31217","3.12021","0.28110"
"3.12687","8.33479","91.26332","37.52000","0.00000","8.33479","3.12687","0.28170"
"3.13333","8.35212","91.45302","37.60000","0.00000","8.35212","3.13333","0.28228"
"3.13979","8.37373","91.68964","37.68000","0.00000","8.37373","3.13979","0.28286"
"3.14687","8.39124","91.88141","37.76000","0.00000","8.39124","3.14687","0.28350"
"3.15354","8.40699","92.05389","37.84000","0.00000","8.40699","3.15354","0.28410"
"3.16021","8.42842","92.28848","37.92000","0.00000","8.42842","3.16021","0.28470"
"3.16667","8.44063","92.42217","38.00000","0.00000","8.44063","3.16667","0.28529"
"3.17312","8.46146","92.65022","38.08000","0.00000","8.46146","3.17312","0.28587"
"3.17979","8.49198","92.98442","38.16000","0.00000","8.49198","3.17979","0.28647"
"3.18687","8.50380","93.11392","38.24000","0.00000","8.50380","3.18687","0.28711"
"3.19354","8.52527","93.34897","38.32000","0.00000","8.52527","3.19354","0.28771"
"3.20021","8.54175","93.52940","38.40000","0.00000","8.54175","3.20021","0.28831"
"3.20667","8.56287","93.76070","38.48000","0.00000","8.56287","3.20667","0.28889"
"3.21312","8.56715","93.80758","38.56000","0.00000","8.56715","3.21312","0.28947"
"3.22000","8.58749","94.03022","38.64000","0.00000","8.58749","3.22000","0.29009"
"3.22708","8.60678","94.24149","38.72000","0.00000","8.60678","3.22708","0.29073"
"3.23396","8.63318","94.53055","38.80000","0.00000","8.63318","3.23396","0.29135"
"3.24042","8.64684","94.68016","38.88000","0.00000","8.64684","3.24042","0.29193"
"3.24687","8.67460","94.98409","38.96000","0.00000","8.67460","3.24687","0.29251"
"3.25333","8.68294","95.07539","39.04000","0.00000","8.68294","3.25333","0.29309"
"3.26000","8.70088","95.27181","39.12000","0.00000","8.70088","3.26000","0.29369"
"3.26687","8.72026","95.48402","39.20000","0.00000","8.72026","3.26687","0.29431"
"3.27354","8.74476","95.75234","39.28000","0.00000","8.74476","3.27354","0.29491"
"3.28042","8.76639","95.98918","39.36000","0.00000","8.76639","3.28042","0.29553"
"3.28667","8.77134","96.04333","39.44000","0.00000","8.77134","3.28667","0.29610"
"3.29312","8.78743","96.21947","39.52000","0.00000","8.78743","3.29312","0.29668"
"3.30000","8.80164","96.37512","39.60000","0.00000","8.80164","3.30000","0.29730"
"3.30687","8.82863","96.67066","39.68000","0.00000","8.82863","3.30687","0.29792"
"3.31375","8.84722","96.87418","39.76000","0.00000","8.84722","3.31375","0.29854"
"3.32042","8.86414","97.05949","39.84000","0.00000","8.86414","3.32042","0.29914"
"3.32687","8.86592","97.07897","39.92000","0.00000","8.86592","3.32687","0.29972"
"3.33312","8.87711","97.20152","40.00000","0.00000","8.87711","3.33312","0.30028"
"3.33958","8.89349","97.38088","40.08000","0.00000","8.89349","3.33958","0.30086"
"3.34646","8.90390","97.49480","40.16000","0.00000","8.90390","3.34646","0.30148"
"3.35354","8.92941","97.77416","40.24000","0.00000","8.92941","3.35354","0.30212"
"3.36021","8.95141","98.01501","40.32000","0.00000","8.95141","3.36021","0.30272"
"3.36667","8.96365","98.14905","40.40000","0.00000","8.96365","3.36667","0.30330"
"3.37292","8.97403","98.26276","40.48000","0.00000","8.97403","3.37292","0.30387"
"3.37979","9.00306","98.58060","40.56000","0.00000","9.00306","3.37979","0.30449"
"3.38646","9.01650","98.72781","40.64000","0.00000","9.01650","3.38646","0.30509"
"3.39354","9.01367","98.69675","40.72000","0.00000","9.01367","3.39354","0.30572"
"3.40042","9.03038","98.87978","40.80000","0.00000","9.03038","3.40042","0.30634"
"3.40687","9.04053","98.99088","40.88000","0.00000","9.04053","3.40687","0.30693"
"3.41312","9.04313","99.01931","40.96000","0.00000","9.04313","3.41312","0.30749"
"3.41979","9.06322","99.23939","41.04000","0.00000","9.06322","3.41979","0.30809"
"3.42667","9.07613","99.38074","41.12000","0.00000","9.07613","3.42667","0.30871"
"3.43375","5.49851","60.20695","41.20000","0.00000","5.49851","3.43375","0.30935"
"3.44062","3.71753","40.70579","41.28000","0.00000","3.71753","3.44062","0.30997"
"3.44708","3.77729","41.36013","41.36000","0.00000","3.77729","3.44708","0.31055"
"3.45333","3.78457","41.43982","41.44000","0.00000","3.78457","3.45333","0.31111"
"3.46000","3.79938","41.60201","41.52000","0.00000","3.79938","3.46000","0.31171"
"3.46667","3.80225","41.63340","41.60000","0.00000","3.80225","3.46667","0.31231"
"3.47375","3.82528","41.88554","41.68000","0.00000","3.82528","3.47375","0.31295"
"3.48062","3.83966","42.04300","41.76000","0.00000","3.83966","3.48062","0.31357"
"3.48708","3.85839","42.24818","41.84000","0.00000","3.85839","3.48708","0.31415"
"3.49333","3.87490","42.42896","41.92000","0.00000","3.87490","3.49333","0.31471"
"3.49979","3.87783","42.46097","42.00000","0.00000","3.87783","3.49979","0.31530"
"3.50667","3.89525","42.65175","42.08000","0.00000","3.89525","3.50667","0.31592"
"3.51354","3.90170","42.72232","42.16000","0.00000","3.90170","3.51354","0.31654"
"3.52062","3.91981","42.92063","42.24000","0.00000","3.91981","3.52062","0.31717"
"3.52687","3.92772","43.00725","42.32000","0.00000","3.92772","3.52687","0.31774"
"3.53312","3.93717","43.11078","42.40000","0.00000","3.93717","3.53312","0.31830"
"3.53958","3.94530","43.19981","42.48000","0.00000","3.94530","3.53958","0.31888"
"3.54646","3.96030","43.36401","42.56000","0.00000","3.96030","3.54646","0.31950"
"3.55333","3.97458","43.52032","42.64000","0.00000","3.97458","3.55333","0.32012"
"3.56021","3.97879","43.56646","42.72000","0.00000","3.97879","3.56021","0.32074"
"3.56687","3.98666","43.65262","42.80000","0.00000","3.98666","3.56687","0.32134"
"3.57333","3.99818","43.77873","42.88000","0.00000","3.99818","3.57333","0.32192"
"3.57979","4.00943","43.90200","42.96000","0.00000","4.00943","3.57979","0.32250"
"3.58646","4.02177","44.03704","43.04000","0.00000","4.02177","3.58646","0.32310"
"3.59333","4.02921","44.11861","43.12000","0.00000","4.02921","3.59333","0.32372"
"3.60021","4.03031","44.13062","43.20000","0.00000","4.03031","3.60021","0.32434"
"3.60687","4.04269","44.26616","43.28000","0.00000","4.04269","3.60687","0.32494"
"3.61333","4.04254","44.26446","43.36000","0.00000","4.04254","3.61333","0.32553"
"3.61979","4.04531","44.29483","43.44000","0.00000","4.04531","3.61979","0.32611"
"3.62646","4.03045","44.13216","43.52000","0.00000","4.03045","3.62646","0.32671"
"3.63333","4.03704","44.20433","43.60000","0.00000","4.03704","3.63333","0.32733"
"3.64021","4.04180","44.25642","43.68000","0.00000","4.04180","3.64021","0.32795"
"3.64396","4.03526","44.18482","43.72200","0.00000","4.03526","3.64396","0.32828"