File: G1 -Incubated Stress relaxation-20210318/Specimen_RawData_1 (1).csv
Specimen properties : Specimen label,""
Specimen properties : Diameter,"0.37600",mm
Specimen properties : Length,"12.02000",mm
Test : Rate 1,"5.00000",mm/min
Test : Start of hold value,"0.05000",mm/mm
Test : Duration,"180.00000",s

Extension,Load,Tensile stress,Time,PIP count,Tenacity,Tensile extension,Tensile strain (Extension)
(mm),(N),(MPa),(s),,(N/tex),(mm),(mm/mm)
"0.00000","0.00980","0.08829","0.00000","0.00000","0.00980","0.00000","0.00000"
"0.03167","0.07825","0.70473","0.40000","0.00000","0.07825","0.03167","0.00263"
"0.06646","0.15702","1.41413","0.80000","0.00000","0.15702","0.06646","0.00553"
"0.10042","0.22407","2.01801","1.20000","0.00000","0.22407","0.10042","0.00835"
"0.13333","0.31184","2.80847","1.60000","0.00000","0.31184","0.13333","0.01109"
"0.16667","0.38689","3.48438","2.00000","0.00000","0.38689","0.16667","0.01387"
"0.20021","0.49135","4.42514","2.40000","0.00000","0.49135","0.20021","0.01666"
"0.23354","0.57139","5.14592","2.80000","0.00000","0.57139","0.23354","0.01943"
"0.26708","0.65580","5.90617","3.20000","0.00000","0.65580","0.26708","0.02222"
"0.30021","0.73362","6.60700","3.60000","0.00000","0.73362","0.30021","0.02498"
"0.33312","0.79859","7.19215","4.00000","0.00000","0.79859","0.33312","0.02771"
"0.36687","0.89030","8.01813","4.40000","0.00000","0.89030","0.36687","0.03052"
"0.40021","0.98812","8.89907","4.80000","0.00000","0.98812","0.40021","0.03330"
"0.43396","1.05657","9.51553","5.20000","0.00000","1.05657","0.43396","0.03610"
"0.46708","1.13317","10.20535","5.60000","0.00000","1.13317","0.46708","0.03886"
"0.50000","0.99873","8.99463","6.00000","0.00000","0.99873","0.50000","0.04160"
"0.53312","1.15235","10.37816","6.40000","0.00000","1.15235","0.53312","0.04435"
"0.56687","1.26495","11.39221","6.80000","0.00000","1.26495","0.56687","0.04716"
"0.60042","1.36065","12.25409","7.20000","0.00000","1.36065","0.60042","0.04995"
"0.60333","1.32479","11.93111","7.40800","0.00000","1.32479","0.60333","0.05019"
"0.60333","1.25292","11.28383","7.80800","0.00000","1.25292","0.60333","0.05019"
"0.60271","1.21500","10.94240","8.20800","0.00000","1.21500","0.60271","0.05014"
"0.60208","1.18311","10.65515","8.60800","0.00000","1.18311","0.60208","0.05009"
"0.60125","1.15884","10.43655","9.00800","0.00000","1.15884","0.60125","0.05002"
"0.60083","1.13919","10.25960","9.40800","0.00000","1.13919","0.60083","0.04999"
"0.60083","1.13087","10.18469","9.80800","0.00000","1.13087","0.60083","0.04999"
"0.60083","1.11476","10.03955","10.20800","0.00000","1.11476","0.60083","0.04999"
"0.60083","1.10366","9.93961","10.60800","0.00000","1.10366","0.60083","0.04999"
"0.60083","1.09063","9.82230","11.00800","0.00000","1.09063","0.60083","0.04999"
"0.60083","1.08141","9.73926","11.40800","0.00000","1.08141","0.60083","0.04999"
"0.60083","1.08193","9.74396","11.80800","0.00000","1.08193","0.60083","0.04999"
"0.60083","1.07020","9.63827","12.20800","0.00000","1.07020","0.60083","0.04999"
"0.60083","1.05873","9.53493","12.60800","0.00000","1.05873","0.60083","0.04999"
"0.60083","1.06026","9.54879","13.00800","0.00000","1.06026","0.60083","0.04999"
"0.60083","1.04793","9.43773","13.40800","0.00000","1.04793","0.60083","0.04999"
"0.60083","1.04232","9.38719","13.80800","0.00000","1.04232","0.60083","0.04999"
"0.60083","1.04371","9.39967","14.20800","0.00000","1.04371","0.60083","0.04999"
"0.60083","1.03625","9.33252","14.60800","0.00000","1.03625","0.60083","0.04999"
"0.60083","1.03474","9.31896","15.00800","0.00000","1.03474","0.60083","0.04999"
"0.60083","1.02998","9.27603","15.40800","0.00000","1.02998","0.60083","0.04999"
"0.60083","1.02310","9.21407","15.80800","0.00000","1.02310","0.60083","0.04999"
"0.60083","1.02027","9.18856","16.20800","0.00000","1.02027","0.60083","0.04999"
"0.60062","1.01916","9.17864","16.60800","0.00000","1.01916","0.60062","0.04997"
"0.60062","1.00696","9.06872","17.00800","0.00000","1.00696","0.60062","0.04997"
"0.60062","1.00469","9.04826","17.40800","0.00000","1.00469","0.60062","0.04997"
"0.60062","1.00471","9.04845","17.80800","0.00000","1.00471","0.60062","0.04997"
"0.60062","1.00335","9.03626","18.20800","0.00000","1.00335","0.60062","0.04997"
"0.60062","0.99680","8.97726","18.60800","0.00000","0.99680","0.60062","0.04997"
"0.60062","0.99389","8.95103","19.00800","0.00000","0.99389","0.60062","0.04997"
"0.60062","0.99478","8.95901","19.40800","0.00000","0.99478","0.60062","0.04997"
"0.60062","0.99149","8.92938","19.80800","0.00000","0.99149","0.60062","0.04997"
"0.60062","0.99233","8.93699","20.20800","0.00000","0.99233","0.60062","0.04997"
"0.60062","0.98662","8.88551","20.60800","0.00000","0.98662","0.60062","0.04997"
"0.60062","0.98731","8.89174","21.00800","0.00000","0.98731","0.60062","0.04997"
"0.60062","0.98619","8.88165","21.40800","0.00000","0.98619","0.60062","0.04997"
"0.60062","0.98402","8.86218","21.80800","0.00000","0.98402","0.60062","0.04997"
"0.60062","0.97761","8.80444","22.20800","0.00000","0.97761","0.60062","0.04997"
"0.60062","0.97789","8.80695","22.60800","0.00000","0.97789","0.60062","0.04997"
"0.60062","0.97394","8.77132","23.00800","0.00000","0.97394","0.60062","0.04997"
"0.60062","0.97392","8.77119","23.40800","0.00000","0.97392","0.60062","0.04997"
"0.60062","0.97284","8.76143","23.80800","0.00000","0.97284","0.60062","0.04997"
"0.60062","0.96808","8.71861","24.20800","0.00000","0.96808","0.60062","0.04997"
"0.60062","0.97031","8.73864","24.60800","0.00000","0.97031","0.60062","0.04997"
"0.60062","0.96865","8.72368","25.00800","0.00000","0.96865","0.60062","0.04997"
"0.60062","0.97779","8.80600","25.40800","0.00000","0.97779","0.60062","0.04997"
"0.60062","0.96348","8.67711","25.80800","0.00000","0.96348","0.60062","0.04997"
"0.60062","0.96008","8.64656","26.20800","0.00000","0.96008","0.60062","0.04997"
"0.60062","0.96633","8.70285","26.60800","0.00000","0.96633","0.60062","0.04997"
"0.60062","0.96661","8.70536","27.00800","0.00000","0.96661","0.60062","0.04997"
"0.60062","0.95809","8.62858","27.40800","0.00000","0.95809","0.60062","0.04997"
"0.60062","0.96179","8.66192","27.80800","0.00000","0.96179","0.60062","0.04997"
"0.60062","0.96123","8.65688","28.20800","0.00000","0.96123","0.60062","0.04997"
"0.60062","0.95876","8.63469","28.60800","0.00000","0.95876","0.60062","0.04997"
"0.60062","0.95856","8.63282","29.00800","0.00000","0.95856","0.60062","0.04997"
"0.60062","0.96006","8.64635","29.40800","0.00000","0.96006","0.60062","0.04997"
"0.60062","0.95823","8.62989","29.80800","0.00000","0.95823","0.60062","0.04997"
"0.60062","0.94878","8.54479","30.20800","0.00000","0.94878","0.60062","0.04997"
"0.60062","0.95918","8.63841","30.60800","0.00000","0.95918","0.60062","0.04997"
"0.60062","0.95085","8.56345","31.00800","0.00000","0.95085","0.60062","0.04997"
"0.60062","0.95378","8.58980","31.40800","0.00000","0.95378","0.60062","0.04997"
"0.60062","0.95314","8.58398","31.80800","0.00000","0.95314","0.60062","0.04997"
"0.60062","0.95156","8.56981","32.20800","0.00000","0.95156","0.60062","0.04997"
"0.60062","0.95150","8.56927","32.60800","0.00000","0.95150","0.60062","0.04997"
"0.60062","0.94771","8.53510","33.00800","0.00000","0.94771","0.60062","0.04997"
"0.60062","0.95119","8.56649","33.40800","0.00000","0.95119","0.60062","0.04997"
"0.60062","0.94504","8.51104","33.80800","0.00000","0.94504","0.60062","0.04997"
"0.60062","0.94789","8.53676","34.20800","0.00000","0.94789","0.60062","0.04997"
"0.60062","0.94939","8.55025","34.60800","0.00000","0.94939","0.60062","0.04997"
"0.60062","0.95146","8.56891","35.00800","0.00000","0.95146","0.60062","0.04997"
"0.60062","0.95193","8.57310","35.40800","0.00000","0.95193","0.60062","0.04997"
"0.60062","0.93996","8.46532","35.80800","0.00000","0.93996","0.60062","0.04997"
"0.60062","0.94627","8.52217","36.20800","0.00000","0.94627","0.60062","0.04997"
"0.60062","0.94608","8.52046","36.60800","0.00000","0.94608","0.60062","0.04997"
"0.60062","0.94142","8.47848","37.00800","0.00000","0.94142","0.60062","0.04997"
"0.60062","0.94411","8.50266","37.40800","0.00000","0.94411","0.60062","0.04997"
"0.60062","0.94096","8.47431","37.80800","0.00000","0.94096","0.60062","0.04997"
"0.60062","0.94165","8.48054","38.20800","0.00000","0.94165","0.60062","0.04997"
"0.60062","0.94065","8.47158","38.60800","0.00000","0.94065","0.60062","0.04997"
"0.60062","0.93945","8.46075","39.00800","0.00000","0.93945","0.60062","0.04997"
"0.60062","0.93288","8.40159","39.40800","0.00000","0.93288","0.60062","0.04997"
"0.60062","0.93905","8.45714","39.80800","0.00000","0.93905","0.60062","0.04997"
"0.60062","0.94136","8.47790","40.20800","0.00000","0.94136","0.60062","0.04997"
"0.60062","0.94033","8.46869","40.60800","0.00000","0.94033","0.60062","0.04997"
"0.60062","0.94262","8.48925","41.00800","0.00000","0.94262","0.60062","0.04997"
"0.60062","0.93628","8.43219","41.40800","0.00000","0.93628","0.60062","0.04997"
"0.60062","0.94001","8.46578","41.80800","0.00000","0.94001","0.60062","0.04997"
"0.60062","0.93665","8.43549","42.20800","0.00000","0.93665","0.60062","0.04997"
"0.60062","0.93864","8.45348","42.60800","0.00000","0.93864","0.60062","0.04997"
"0.60062","0.93829","8.45031","43.00800","0.00000","0.93829","0.60062","0.04997"
"0.60062","0.93551","8.42524","43.40800","0.00000","0.93551","0.60062","0.04997"
"0.60062","0.93267","8.39966","43.80800","0.00000","0.93267","0.60062","0.04997"
"0.60062","0.93185","8.39232","44.20800","0.00000","0.93185","0.60062","0.04997"
"0.60062","0.93511","8.42167","44.60800","0.00000","0.93511","0.60062","0.04997"
"0.60062","0.93510","8.42157","45.00800","0.00000","0.93510","0.60062","0.04997"
"0.60062","0.94064","8.47145","45.40800","0.00000","0.94064","0.60062","0.04997"
"0.60062","0.93251","8.39827","45.80800","0.00000","0.93251","0.60062","0.04997"
"0.60062","0.93821","8.44958","46.20800","0.00000","0.93821","0.60062","0.04997"
"0.60062","0.93457","8.41682","46.60800","0.00000","0.93457","0.60062","0.04997"
"0.60062","0.93378","8.40968","47.00800","0.00000","0.93378","0.60062","0.04997"
"0.60062","0.93849","8.45205","47.40800","0.00000","0.93849","0.60062","0.04997"
"0.60062","0.93450","8.41613","47.80800","0.00000","0.93450","0.60062","0.04997"
"0.60062","0.93395","8.41119","48.20800","0.00000","0.93395","0.60062","0.04997"
"0.60062","0.93988","8.46463","48.60800","0.00000","0.93988","0.60062","0.04997"
"0.60062","0.92580","8.33780","49.00800","0.00000","0.92580","0.60062","0.04997"
"0.60062","0.93145","8.38864","49.40800","0.00000","0.93145","0.60062","0.04997"
"0.60062","0.93010","8.37654","49.80800","0.00000","0.93010","0.60062","0.04997"
"0.60062","0.93046","8.37973","50.20800","0.00000","0.93046","0.60062","0.04997"
"0.60062","0.92927","8.36903","50.60800","0.00000","0.92927","0.60062","0.04997"
"0.60062","0.92653","8.34439","51.00800","0.00000","0.92653","0.60062","0.04997"
"0.60062","0.93630","8.43235","51.40800","0.00000","0.93630","0.60062","0.04997"
"0.60062","0.93837","8.45103","51.80800","0.00000","0.93837","0.60062","0.04997"
"0.60062","0.93195","8.39323","52.20800","0.00000","0.93195","0.60062","0.04997"
"0.60062","0.93765","8.44451","52.60800","0.00000","0.93765","0.60062","0.04997"
"0.60062","0.93225","8.39587","53.00800","0.00000","0.93225","0.60062","0.04997"
"0.60062","0.93398","8.41150","53.40800","0.00000","0.93398","0.60062","0.04997"
"0.60062","0.93515","8.42202","53.80800","0.00000","0.93515","0.60062","0.04997"
"0.60062","0.92722","8.35059","54.20800","0.00000","0.92722","0.60062","0.04997"
"0.60062","0.92746","8.35276","54.60800","0.00000","0.92746","0.60062","0.04997"
"0.60062","0.93147","8.38889","55.00800","0.00000","0.93147","0.60062","0.04997"
"0.60062","0.93522","8.42263","55.40800","0.00000","0.93522","0.60062","0.04997"
"0.60062","0.93528","8.42317","55.80800","0.00000","0.93528","0.60062","0.04997"
"0.60062","0.93100","8.38465","56.20800","0.00000","0.93100","0.60062","0.04997"
"0.60062","0.93584","8.42822","56.60800","0.00000","0.93584","0.60062","0.04997"
"0.60062","0.93183","8.39212","57.00800","0.00000","0.93183","0.60062","0.04997"
"0.60062","0.92631","8.34244","57.40800","0.00000","0.92631","0.60062","0.04997"
"0.60062","0.93134","8.38766","57.80800","0.00000","0.93134","0.60062","0.04997"
"0.60062","0.93183","8.39212","58.20800","0.00000","0.93183","0.60062","0.04997"
"0.60062","0.93446","8.41577","58.60800","0.00000","0.93446","0.60062","0.04997"
"0.60062","0.92704","8.34897","59.00800","0.00000","0.92704","0.60062","0.04997"
"0.60062","0.92331","8.31534","59.40800","0.00000","0.92331","0.60062","0.04997"
"0.60062","0.93540","8.42430","59.80800","0.00000","0.93540","0.60062","0.04997"
"0.60062","0.92606","8.34016","60.20800","0.00000","0.92606","0.60062","0.04997"
"0.60062","0.93446","8.41579","60.60800","0.00000","0.93446","0.60062","0.04997"
"0.60062","0.93306","8.40322","61.00800","0.00000","0.93306","0.60062","0.04997"
"0.60062","0.92355","8.31751","61.40800","0.00000","0.92355","0.60062","0.04997"
"0.60062","0.93167","8.39070","61.80800","0.00000","0.93167","0.60062","0.04997"
"0.60062","0.92599","8.33953","62.20800","0.00000","0.92599","0.60062","0.04997"
"0.60062","0.92435","8.32471","62.60800","0.00000","0.92435","0.60062","0.04997"
"0.60062","0.92642","8.34342","63.00800","0.00000","0.92642","0.60062","0.04997"
"0.60062","0.93136","8.38791","63.40800","0.00000","0.93136","0.60062","0.04997"
"0.60062","0.92160","8.29993","63.80800","0.00000","0.92160","0.60062","0.04997"
"0.60062","0.92969","8.37282","64.20800","0.00000","0.92969","0.60062","0.04997"
"0.60062","0.92012","8.28661","64.60800","0.00000","0.92012","0.60062","0.04997"
"0.60062","0.92718","8.35022","65.00800","0.00000","0.92718","0.60062","0.04997"
"0.60062","0.92719","8.35035","65.40800","0.00000","0.92719","0.60062","0.04997"
"0.60062","0.92857","8.36274","65.80800","0.00000","0.92857","0.60062","0.04997"
"0.60062","0.92206","8.30411","66.20800","0.00000","0.92206","0.60062","0.04997"
"0.60062","0.92597","8.33930","66.60800","0.00000","0.92597","0.60062","0.04997"
"0.60062","0.92524","8.33273","67.00800","0.00000","0.92524","0.60062","0.04997"
"0.60062","0.92282","8.31093","67.40800","0.00000","0.92282","0.60062","0.04997"
"0.60062","0.92516","8.33208","67.80800","0.00000","0.92516","0.60062","0.04997"
"0.60062","0.93120","8.38647","68.20800","0.00000","0.93120","0.60062","0.04997"
"0.60062","0.92445","8.32565","68.60800","0.00000","0.92445","0.60062","0.04997"
"0.60062","0.92867","8.36364","69.00800","0.00000","0.92867","0.60062","0.04997"
"0.60062","0.92477","8.32853","69.40800","0.00000","0.92477","0.60062","0.04997"
"0.60062","0.92070","8.29187","69.80800","0.00000","0.92070","0.60062","0.04997"
"0.60062","0.92869","8.36379","70.20800","0.00000","0.92869","0.60062","0.04997"
"0.60062","0.92493","8.32994","70.60800","0.00000","0.92493","0.60062","0.04997"
"0.60062","0.92399","8.32147","71.00800","0.00000","0.92399","0.60062","0.04997"
"0.60062","0.92562","8.33621","71.40800","0.00000","0.92562","0.60062","0.04997"
"0.60062","0.92197","8.30330","71.80800","0.00000","0.92197","0.60062","0.04997"
"0.60062","0.91904","8.27691","72.20800","0.00000","0.91904","0.60062","0.04997"
"0.60062","0.92217","8.30507","72.60800","0.00000","0.92217","0.60062","0.04997"
"0.60062","0.92898","8.36641","73.00800","0.00000","0.92898","0.60062","0.04997"
"0.60062","0.92492","8.32987","73.40800","0.00000","0.92492","0.60062","0.04997"
"0.60062","0.92808","8.35834","73.80800","0.00000","0.92808","0.60062","0.04997"
"0.60062","0.92490","8.32969","74.20800","0.00000","0.92490","0.60062","0.04997"
"0.60062","0.92198","8.30344","74.60800","0.00000","0.92198","0.60062","0.04997"
"0.60062","0.92973","8.37319","75.00800","0.00000","0.92973","0.60062","0.04997"
"0.60062","0.93118","8.38629","75.40800","0.00000","0.93118","0.60062","0.04997"
"0.60062","0.92192","8.30286","75.80800","0.00000","0.92192","0.60062","0.04997"
"0.60062","0.92356","8.31761","76.20800","0.00000","0.92356","0.60062","0.04997"
"0.60062","0.91801","8.26762","76.60800","0.00000","0.91801","0.60062","0.04997"
"0.60062","0.92242","8.30737","77.00800","0.00000","0.92242","0.60062","0.04997"
"0.60062","0.92521","8.33245","77.40800","0.00000","0.92521","0.60062","0.04997"
"0.60062","0.92791","8.35680","77.80800","0.00000","0.92791","0.60062","0.04997"
"0.60062","0.91916","8.27797","78.20800","0.00000","0.91916","0.60062","0.04997"
"0.60062","0.92927","8.36907","78.60800","0.00000","0.92927","0.60062","0.04997"
"0.60062","0.92226","8.30594","79.00800","0.00000","0.92226","0.60062","0.04997"
"0.60062","0.92484","8.32919","79.40800","0.00000","0.92484","0.60062","0.04997"
"0.60062","0.92757","8.35376","79.80800","0.00000","0.92757","0.60062","0.04997"
"0.60062","0.92282","8.31099","80.20800","0.00000","0.92282","0.60062","0.04997"
"0.60062","0.92230","8.30632","80.60800","0.00000","0.92230","0.60062","0.04997"
"0.60062","0.91785","8.26622","81.00800","0.00000","0.91785","0.60062","0.04997"
"0.60062","0.93315","8.40396","81.40800","0.00000","0.93315","0.60062","0.04997"
"0.60062","0.92625","8.34186","81.80800","0.00000","0.92625","0.60062","0.04997"
"0.60062","0.92475","8.32838","82.20800","0.00000","0.92475","0.60062","0.04997"
"0.60062","0.92382","8.31993","82.60800","0.00000","0.92382","0.60062","0.04997"
"0.60062","0.91671","8.25591","83.00800","0.00000","0.91671","0.60062","0.04997"
"0.60062","0.92875","8.36438","83.40800","0.00000","0.92875","0.60062","0.04997"
"0.60062","0.92774","8.35525","83.80800","0.00000","0.92774","0.60062","0.04997"
"0.60062","0.92533","8.33357","84.20800","0.00000","0.92533","0.60062","0.04997"
"0.60062","0.92728","8.35111","84.60800","0.00000","0.92728","0.60062","0.04997"
"0.60062","0.92811","8.35863","85.00800","0.00000","0.92811","0.60062","0.04997"
"0.60062","0.91924","8.27869","85.40800","0.00000","0.91924","0.60062","0.04997"
"0.60062","0.92159","8.29988","85.80800","0.00000","0.92159","0.60062","0.04997"
"0.60062","0.92786","8.35635","86.20800","0.00000","0.92786","0.60062","0.04997"
"0.60062","0.92312","8.31363","86.60800","0.00000","0.92312","0.60062","0.04997"
"0.60062","0.92914","8.36791","87.00800","0.00000","0.92914","0.60062","0.04997"
"0.60062","0.92276","8.31041","87.40800","0.00000","0.92276","0.60062","0.04997"
"0.60062","0.92234","8.30662","87.80800","0.00000","0.92234","0.60062","0.04997"
"0.60062","0.91469","8.23776","88.20800","0.00000","0.91469","0.60062","0.04997"
"0.60062","0.92833","8.36056","88.60800","0.00000","0.92833","0.60062","0.04997"
"0.60062","0.92422","8.32357","89.00800","0.00000","0.92422","0.60062","0.04997"
"0.60062","0.92184","8.30211","89.40800","0.00000","0.92184","0.60062","0.04997"
"0.60062","0.92467","8.32765","89.80800","0.00000","0.92467","0.60062","0.04997"
"0.60062","0.93250","8.39811","90.20800","0.00000","0.93250","0.60062","0.04997"
"0.60062","0.92176","8.30144","90.60800","0.00000","0.92176","0.60062","0.04997"
"0.60062","0.92795","8.35721","91.00800","0.00000","0.92795","0.60062","0.04997"
"0.60062","0.92264","8.30933","91.40800","0.00000","0.92264","0.60062","0.04997"
"0.60062","0.91867","8.27361","91.80800","0.00000","0.91867","0.60062","0.04997"
"0.60062","0.92672","8.34605","92.20800","0.00000","0.92672","0.60062","0.04997"
"0.60062","0.92497","8.33035","92.60800","0.00000","0.92497","0.60062","0.04997"
"0.60062","0.92644","8.34355","93.00800","0.00000","0.92644","0.60062","0.04997"
"0.60062","0.92416","8.32302","93.40800","0.00000","0.92416","0.60062","0.04997"
"0.60062","0.92316","8.31404","93.80800","0.00000","0.92316","0.60062","0.04997"
"0.60062","0.92595","8.33919","94.20800","0.00000","0.92595","0.60062","0.04997"
"0.60062","0.92575","8.33739","94.60800","0.00000","0.92575","0.60062","0.04997"
"0.60062","0.92639","8.34310","95.00800","0.00000","0.92639","0.60062","0.04997"
"0.60062","0.92170","8.30088","95.40800","0.00000","0.92170","0.60062","0.04997"
"0.60062","0.92415","8.32295","95.80800","0.00000","0.92415","0.60062","0.04997"
"0.60062","0.93248","8.39798","96.20800","0.00000","0.93248","0.60062","0.04997"
"0.60062","0.92450","8.32605","96.60800","0.00000","0.92450","0.60062","0.04997"
"0.60062","0.92449","8.32596","97.00800","0.00000","0.92449","0.60062","0.04997"
"0.60062","0.93031","8.37838","97.40800","0.00000","0.93031","0.60062","0.04997"
"0.60062","0.92177","8.30149","97.80800","0.00000","0.92177","0.60062","0.04997"
"0.60062","0.92220","8.30540","98.20800","0.00000","0.92220","0.60062","0.04997"
"0.60062","0.93227","8.39606","98.60800","0.00000","0.93227","0.60062","0.04997"
"0.60062","0.92751","8.35320","99.00800","0.00000","0.92751","0.60062","0.04997"
"0.60062","0.92723","8.35072","99.40800","0.00000","0.92723","0.60062","0.04997"
"0.60062","0.92419","8.32330","99.80800","0.00000","0.92419","0.60062","0.04997"
"0.60062","0.92838","8.36106","100.20800","0.00000","0.92838","0.60062","0.04997"
"0.60062","0.92752","8.35327","100.60800","0.00000","0.92752","0.60062","0.04997"
"0.60062","0.92087","8.29339","101.00800","0.00000","0.92087","0.60062","0.04997"
"0.60062","0.92432","8.32443","101.40800","0.00000","0.92432","0.60062","0.04997"
"0.60062","0.92026","8.28794","101.80800","0.00000","0.92026","0.60062","0.04997"
"0.60062","0.92474","8.32827","102.20800","0.00000","0.92474","0.60062","0.04997"
"0.60062","0.92387","8.32046","102.60800","0.00000","0.92387","0.60062","0.04997"
"0.60062","0.92531","8.33340","103.00800","0.00000","0.92531","0.60062","0.04997"
"0.60062","0.93285","8.40130","103.40800","0.00000","0.93285","0.60062","0.04997"
"0.60062","0.92771","8.35499","103.80800","0.00000","0.92771","0.60062","0.04997"
"0.60062","0.93236","8.39686","104.20800","0.00000","0.93236","0.60062","0.04997"
"0.60062","0.92388","8.32048","104.60800","0.00000","0.92388","0.60062","0.04997"
"0.60062","0.92815","8.35901","105.00800","0.00000","0.92815","0.60062","0.04997"
"0.60062","0.92141","8.29823","105.40800","0.00000","0.92141","0.60062","0.04997"
"0.60062","0.92882","8.36504","105.80800","0.00000","0.92882","0.60062","0.04997"
"0.60062","0.92190","8.30267","106.20800","0.00000","0.92190","0.60062","0.04997"
"0.60062","0.92652","8.34432","106.60800","0.00000","0.92652","0.60062","0.04997"
"0.60062","0.92514","8.33183","107.00800","0.00000","0.92514","0.60062","0.04997"
"0.60062","0.92728","8.35113","107.40800","0.00000","0.92728","0.60062","0.04997"
"0.60062","0.92272","8.31008","107.80800","0.00000","0.92272","0.60062","0.04997"
"0.60062","0.92420","8.32335","108.20800","0.00000","0.92420","0.60062","0.04997"
"0.60062","0.92768","8.35473","108.60800","0.00000","0.92768","0.60062","0.04997"
"0.60062","0.92680","8.34682","109.00800","0.00000","0.92680","0.60062","0.04997"
"0.60062","0.92506","8.33110","109.40800","0.00000","0.92506","0.60062","0.04997"
"0.60062","0.92199","8.30348","109.80800","0.00000","0.92199","0.60062","0.04997"
"0.60062","0.92764","8.35438","110.20800","0.00000","0.92764","0.60062","0.04997"
"0.60062","0.92459","8.32689","110.60800","0.00000","0.92459","0.60062","0.04997"
"0.60062","0.93047","8.37988","111.00800","0.00000","0.93047","0.60062","0.04997"
"0.60062","0.92800","8.35763","111.40800","0.00000","0.92800","0.60062","0.04997"
"0.60062","0.92523","8.33266","111.80800","0.00000","0.92523","0.60062","0.04997"
"0.60062","0.92638","8.34301","112.20800","0.00000","0.92638","0.60062","0.04997"
"0.60062","0.92541","8.33431","112.60800","0.00000","0.92541","0.60062","0.04997"
"0.60062","0.92769","8.35486","113.00800","0.00000","0.92769","0.60062","0.04997"
"0.60062","0.92749","8.35306","113.40800","0.00000","0.92749","0.60062","0.04997"
"0.60062","0.92916","8.36803","113.80800","0.00000","0.92916","0.60062","0.04997"
"0.60062","0.92442","8.32534","114.20800","0.00000","0.92442","0.60062","0.04997"
"0.60062","0.92900","8.36664","114.60800","0.00000","0.92900","0.60062","0.04997"
"0.60062","0.92748","8.35294","115.00800","0.00000","0.92748","0.60062","0.04997"
"0.60062","0.92844","8.36159","115.40800","0.00000","0.92844","0.60062","0.04997"
"0.60062","0.92035","8.28869","115.80800","0.00000","0.92035","0.60062","0.04997"
"0.60062","0.92993","8.37500","116.20800","0.00000","0.92993","0.60062","0.04997"
"0.60062","0.92899","8.36656","116.60800","0.00000","0.92899","0.60062","0.04997"
"0.60062","0.93004","8.37595","117.00800","0.00000","0.93004","0.60062","0.04997"
"0.60062","0.92495","8.33013","117.40800","0.00000","0.92495","0.60062","0.04997"
"0.60062","0.92307","8.31323","117.80800","0.00000","0.92307","0.60062","0.04997"
"0.60062","0.92326","8.31495","118.20800","0.00000","0.92326","0.60062","0.04997"
"0.60062","0.91867","8.27360","118.60800","0.00000","0.91867","0.60062","0.04997"
"0.60062","0.92693","8.34802","119.00800","0.00000","0.92693","0.60062","0.04997"
"0.60062","0.92855","8.36255","119.40800","0.00000","0.92855","0.60062","0.04997"
"0.60062","0.92815","8.35900","119.80800","0.00000","0.92815","0.60062","0.04997"
"0.60062","0.92902","8.36684","120.20800","0.00000","0.92902","0.60062","0.04997"
"0.60062","0.92228","8.30609","120.60800","0.00000","0.92228","0.60062","0.04997"
"0.60062","0.92494","8.33007","121.00800","0.00000","0.92494","0.60062","0.04997"
"0.60062","0.92756","8.35368","121.40800","0.00000","0.92756","0.60062","0.04997"
"0.60062","0.92662","8.34522","121.80800","0.00000","0.92662","0.60062","0.04997"
"0.60062","0.92441","8.32525","122.20800","0.00000","0.92441","0.60062","0.04997"
"0.60062","0.93307","8.40327","122.60800","0.00000","0.93307","0.60062","0.04997"
"0.60062","0.92694","8.34805","123.00800","0.00000","0.92694","0.60062","0.04997"
"0.60062","0.93304","8.40296","123.40800","0.00000","0.93304","0.60062","0.04997"
"0.60062","0.92484","8.32917","123.80800","0.00000","0.92484","0.60062","0.04997"
"0.60062","0.92870","8.36395","124.20800","0.00000","0.92870","0.60062","0.04997"
"0.60062","0.92886","8.36532","124.60800","0.00000","0.92886","0.60062","0.04997"
"0.60062","0.93206","8.39417","125.00800","0.00000","0.93206","0.60062","0.04997"
"0.60062","0.92729","8.35122","125.40800","0.00000","0.92729","0.60062","0.04997"
"0.60062","0.92815","8.35900","125.80800","0.00000","0.92815","0.60062","0.04997"
"0.60062","0.92798","8.35748","126.20800","0.00000","0.92798","0.60062","0.04997"
"0.60062","0.93661","8.43515","126.60800","0.00000","0.93661","0.60062","0.04997"
"0.60062","0.93015","8.37698","127.00800","0.00000","0.93015","0.60062","0.04997"
"0.60062","0.92729","8.35124","127.40800","0.00000","0.92729","0.60062","0.04997"
"0.60062","0.93308","8.40335","127.80800","0.00000","0.93308","0.60062","0.04997"
"0.60062","0.93261","8.39915","128.20800","0.00000","0.93261","0.60062","0.04997"
"0.60062","0.92529","8.33320","128.60800","0.00000","0.92529","0.60062","0.04997"
"0.60062","0.92080","8.29278","129.00800","0.00000","0.92080","0.60062","0.04997"
"0.60062","0.93199","8.39353","129.40800","0.00000","0.93199","0.60062","0.04997"
"0.60062","0.93143","8.38848","129.80800","0.00000","0.93143","0.60062","0.04997"
"0.60062","0.93341","8.40635","130.20800","0.00000","0.93341","0.60062","0.04997"
"0.60062","0.93234","8.39673","130.60800","0.00000","0.93234","0.60062","0.04997"
"0.60062","0.93300","8.40268","131.00800","0.00000","0.93300","0.60062","0.04997"
"0.60062","0.93748","8.44297","131.40800","0.00000","0.93748","0.60062","0.04997"
"0.60062","0.93456","8.41667","131.80800","0.00000","0.93456","0.60062","0.04997"
"0.60062","0.92526","8.33296","132.20800","0.00000","0.92526","0.60062","0.04997"
"0.60062","0.92842","8.36144","132.60800","0.00000","0.92842","0.60062","0.04997"
"0.60062","0.93539","8.42421","133.00800","0.00000","0.93539","0.60062","0.04997"
"0.60062","0.93326","8.40494","133.40800","0.00000","0.93326","0.60062","0.04997"
"0.60062","0.93021","8.37756","133.80800","0.00000","0.93021","0.60062","0.04997"
"0.60062","0.92771","8.35498","134.20800","0.00000","0.92771","0.60062","0.04997"
"0.60062","0.92747","8.35287","134.60800","0.00000","0.92747","0.60062","0.04997"
"0.60062","0.93185","8.39227","135.00800","0.00000","0.93185","0.60062","0.04997"
"0.60062","0.93401","8.41171","135.40800","0.00000","0.93401","0.60062","0.04997"
"0.60062","0.93324","8.40484","135.80800","0.00000","0.93324","0.60062","0.04997"
"0.60062","0.93884","8.45524","136.20800","0.00000","0.93884","0.60062","0.04997"
"0.60062","0.93567","8.42668","136.60800","0.00000","0.93567","0.60062","0.04997"
"0.60062","0.92653","8.34441","137.00800","0.00000","0.92653","0.60062","0.04997"
"0.60062","0.93143","8.38853","137.40800","0.00000","0.93143","0.60062","0.04997"
"0.60062","0.93553","8.42540","137.80800","0.00000","0.93553","0.60062","0.04997"
"0.60062","0.92546","8.33473","138.20800","0.00000","0.92546","0.60062","0.04997"
"0.60062","0.93234","8.39670","138.60800","0.00000","0.93234","0.60062","0.04997"
"0.60062","0.93321","8.40449","139.00800","0.00000","0.93321","0.60062","0.04997"
"0.60062","0.94282","8.49106","139.40800","0.00000","0.94282","0.60062","0.04997"
"0.60062","0.93279","8.40074","139.80800","0.00000","0.93279","0.60062","0.04997"
"0.60062","0.93137","8.38794","140.20800","0.00000","0.93137","0.60062","0.04997"
"0.60062","0.93256","8.39870","140.60800","0.00000","0.93256","0.60062","0.04997"
"0.60062","0.93170","8.39092","141.00800","0.00000","0.93170","0.60062","0.04997"
"0.60062","0.92467","8.32765","141.40800","0.00000","0.92467","0.60062","0.04997"
"0.60062","0.92828","8.36011","141.80800","0.00000","0.92828","0.60062","0.04997"
"0.60062","0.93136","8.38785","142.20800","0.00000","0.93136","0.60062","0.04997"
"0.60062","0.93099","8.38458","142.60800","0.00000","0.93099","0.60062","0.04997"
"0.60062","0.93149","8.38900","143.00800","0.00000","0.93149","0.60062","0.04997"
"0.60062","0.93311","8.40360","143.40800","0.00000","0.93311","0.60062","0.04997"
"0.60062","0.93482","8.41901","143.80800","0.00000","0.93482","0.60062","0.04997"
"0.60062","0.93339","8.40618","144.20800","0.00000","0.93339","0.60062","0.04997"
"0.60062","0.93034","8.37872","144.60800","0.00000","0.93034","0.60062","0.04997"
"0.60062","0.93368","8.40874","145.00800","0.00000","0.93368","0.60062","0.04997"
"0.60062","0.93447","8.41587","145.40800","0.00000","0.93447","0.60062","0.04997"
"0.60062","0.93158","8.38984","145.80800","0.00000","0.93158","0.60062","0.04997"
"0.60062","0.93082","8.38303","146.20800","0.00000","0.93082","0.60062","0.04997"
"0.60062","0.92824","8.35975","146.60800","0.00000","0.92824","0.60062","0.04997"
"0.60062","0.93506","8.42116","147.00800","0.00000","0.93506","0.60062","0.04997"
"0.60062","0.94023","8.46779","147.40800","0.00000","0.94023","0.60062","0.04997"
"0.60062","0.92739","8.35213","147.80800","0.00000","0.92739","0.60062","0.04997"
"0.60062","0.92240","8.30715","148.20800","0.00000","0.92240","0.60062","0.04997"
"0.60062","0.92773","8.35515","148.60800","0.00000","0.92773","0.60062","0.04997"
"0.60062","0.93312","8.40377","149.00800","0.00000","0.93312","0.60062","0.04997"
"0.60062","0.93350","8.40713","149.40800","0.00000","0.93350","0.60062","0.04997"
"0.60062","0.93984","8.46424","149.80800","0.00000","0.93984","0.60062","0.04997"
"0.60062","0.92474","8.32823","150.20800","0.00000","0.92474","0.60062","0.04997"
"0.60062","0.93384","8.41018","150.60800","0.00000","0.93384","0.60062","0.04997"
"0.60062","0.94247","8.48796","151.00800","0.00000","0.94247","0.60062","0.04997"
"0.60062","0.93626","8.43199","151.40800","0.00000","0.93626","0.60062","0.04997"
"0.60062","0.93413","8.41282","151.80800","0.00000","0.93413","0.60062","0.04997"
"0.60062","0.93542","8.42447","152.20800","0.00000","0.93542","0.60062","0.04997"
"0.60062","0.93744","8.44260","152.60800","0.00000","0.93744","0.60062","0.04997"
"0.60062","0.93428","8.41416","153.00800","0.00000","0.93428","0.60062","0.04997"
"0.60062","0.93715","8.44005","153.40800","0.00000","0.93715","0.60062","0.04997"
"0.60062","0.93244","8.39760","153.80800","0.00000","0.93244","0.60062","0.04997"
"0.60062","0.92776","8.35548","154.20800","0.00000","0.92776","0.60062","0.04997"
"0.60062","0.93389","8.41066","154.60800","0.00000","0.93389","0.60062","0.04997"
"0.60062","0.93650","8.43413","155.00800","0.00000","0.93650","0.60062","0.04997"
"0.60062","0.93180","8.39184","155.40800","0.00000","0.93180","0.60062","0.04997"
"0.60062","0.93492","8.41996","155.80800","0.00000","0.93492","0.60062","0.04997"
"0.60062","0.93533","8.42366","156.20800","0.00000","0.93533","0.60062","0.04997"
"0.60062","0.93159","8.38991","156.60800","0.00000","0.93159","0.60062","0.04997"
"0.60062","0.93606","8.43022","157.00800","0.00000","0.93606","0.60062","0.04997"
"0.60062","0.93636","8.43294","157.40800","0.00000","0.93636","0.60062","0.04997"
"0.60062","0.93933","8.45970","157.80800","0.00000","0.93933","0.60062","0.04997"
"0.60062","0.92725","8.35083","158.20800","0.00000","0.92725","0.60062","0.04997"
"0.60062","0.93917","8.45825","158.60800","0.00000","0.93917","0.60062","0.04997"
"0.60062","0.94228","8.48623","159.00800","0.00000","0.94228","0.60062","0.04997"
"0.60062","0.93120","8.38647","159.40800","0.00000","0.93120","0.60062","0.04997"
"0.60062","0.93580","8.42785","159.80800","0.00000","0.93580","0.60062","0.04997"
"0.60062","0.94007","8.46629","160.20800","0.00000","0.94007","0.60062","0.04997"
"0.60062","0.93931","8.45944","160.60800","0.00000","0.93931","0.60062","0.04997"
"0.60062","0.93842","8.45143","161.00800","0.00000","0.93842","0.60062","0.04997"
"0.60062","0.93687","8.43747","161.40800","0.00000","0.93687","0.60062","0.04997"
"0.60062","0.93471","8.41803","161.80800","0.00000","0.93471","0.60062","0.04997"
"0.60062","0.93674","8.43635","162.20800","0.00000","0.93674","0.60062","0.04997"
"0.60062","0.93341","8.40636","162.60800","0.00000","0.93341","0.60062","0.04997"
"0.60062","0.93860","8.45309","163.00800","0.00000","0.93860","0.60062","0.04997"
"0.60062","0.93861","8.45320","163.40800","0.00000","0.93861","0.60062","0.04997"
"0.60062","0.94046","8.46980","163.80800","0.00000","0.94046","0.60062","0.04997"
"0.60062","0.94457","8.50684","164.20800","0.00000","0.94457","0.60062","0.04997"
"0.60062","0.94239","8.48718","164.60800","0.00000","0.94239","0.60062","0.04997"
"0.60062","0.93801","8.44774","165.00800","0.00000","0.93801","0.60062","0.04997"
"0.60062","0.94090","8.47382","165.40800","0.00000","0.94090","0.60062","0.04997"
"0.60062","0.93867","8.45373","165.80800","0.00000","0.93867","0.60062","0.04997"
"0.60062","0.93699","8.43858","166.20800","0.00000","0.93699","0.60062","0.04997"
"0.60062","0.92838","8.36106","166.60800","0.00000","0.92838","0.60062","0.04997"
"0.60062","0.93832","8.45052","167.00800","0.00000","0.93832","0.60062","0.04997"
"0.60062","0.93221","8.39553","167.40800","0.00000","0.93221","0.60062","0.04997"
"0.60062","0.93335","8.40581","167.80800","0.00000","0.93335","0.60062","0.04997"
"0.60062","0.93959","8.46200","168.20800","0.00000","0.93959","0.60062","0.04997"
"0.60062","0.93301","8.40271","168.60800","0.00000","0.93301","0.60062","0.04997"
"0.60062","0.93637","8.43299","169.00800","0.00000","0.93637","0.60062","0.04997"
"0.60062","0.94211","8.48468","169.40800","0.00000","0.94211","0.60062","0.04997"
"0.60062","0.94012","8.46673","169.80800","0.00000","0.94012","0.60062","0.04997"
"0.60062","0.93309","8.40342","170.20800","0.00000","0.93309","0.60062","0.04997"
"0.60062","0.93908","8.45739","170.60800","0.00000","0.93908","0.60062","0.04997"
"0.60062","0.93262","8.39926","171.00800","0.00000","0.93262","0.60062","0.04997"
"0.60062","0.93879","8.45477","171.40800","0.00000","0.93879","0.60062","0.04997"
"0.60062","0.94535","8.51388","171.80800","0.00000","0.94535","0.60062","0.04997"
"0.60062","0.94091","8.47388","172.20800","0.00000","0.94091","0.60062","0.04997"
"0.60062","0.94671","8.52616","172.60800","0.00000","0.94671","0.60062","0.04997"
"0.60062","0.93719","8.44037","173.00800","0.00000","0.93719","0.60062","0.04997"
"0.60062","0.93598","8.42949","173.40800","0.00000","0.93598","0.60062","0.04997"
"0.60062","0.93388","8.41055","173.80800","0.00000","0.93388","0.60062","0.04997"
"0.60062","0.93512","8.42173","174.20800","0.00000","0.93512","0.60062","0.04997"
"0.60062","0.93897","8.45646","174.60800","0.00000","0.93897","0.60062","0.04997"
"0.60062","0.93793","8.44705","175.00800","0.00000","0.93793","0.60062","0.04997"
"0.60062","0.94114","8.47599","175.40800","0.00000","0.94114","0.60062","0.04997"
"0.60062","0.93733","8.44161","175.80800","0.00000","0.93733","0.60062","0.04997"
"0.60062","0.93853","8.45243","176.20800","0.00000","0.93853","0.60062","0.04997"
"0.60062","0.94045","8.46974","176.60800","0.00000","0.94045","0.60062","0.04997"
"0.60062","0.94223","8.48575","177.00800","0.00000","0.94223","0.60062","0.04997"
"0.60062","0.94312","8.49382","177.40800","0.00000","0.94312","0.60062","0.04997"
"0.60062","0.94369","8.49895","177.80800","0.00000","0.94369","0.60062","0.04997"
"0.60062","0.93840","8.45123","178.20800","0.00000","0.93840","0.60062","0.04997"
"0.60062","0.94074","8.47233","178.60800","0.00000","0.94074","0.60062","0.04997"
"0.60062","0.93901","8.45676","179.00800","0.00000","0.93901","0.60062","0.04997"
"0.60062","0.93853","8.45242","179.40800","0.00000","0.93853","0.60062","0.04997"
"0.60062","0.93819","8.44940","179.80800","0.00000","0.93819","0.60062","0.04997"
"0.60062","0.94100","8.47466","180.20800","0.00000","0.94100","0.60062","0.04997"
"0.60062","0.94016","8.46716","180.60800","0.00000","0.94016","0.60062","0.04997"
"0.60062","0.93895","8.45622","181.00800","0.00000","0.93895","0.60062","0.04997"
"0.60062","0.93933","8.45962","181.40800","0.00000","0.93933","0.60062","0.04997"
"0.60062","0.93392","8.41097","181.80800","0.00000","0.93392","0.60062","0.04997"
"0.60062","0.93229","8.39622","182.20800","0.00000","0.93229","0.60062","0.04997"
"0.60062","0.93918","8.45828","182.60800","0.00000","0.93918","0.60062","0.04997"
"0.60062","0.93801","8.44775","183.00800","0.00000","0.93801","0.60062","0.04997"
"0.60062","0.93920","8.45848","183.40800","0.00000","0.93920","0.60062","0.04997"
"0.60062","0.94591","8.51890","183.80800","0.00000","0.94591","0.60062","0.04997"
"0.60062","0.94611","8.52070","184.20800","0.00000","0.94611","0.60062","0.04997"
"0.60062","0.93238","8.39704","184.60800","0.00000","0.93238","0.60062","0.04997"
"0.60062","0.94023","8.46777","185.00800","0.00000","0.94023","0.60062","0.04997"
"0.60062","0.94173","8.48130","185.40800","0.00000","0.94173","0.60062","0.04997"
"0.60062","0.94089","8.47367","185.80800","0.00000","0.94089","0.60062","0.04997"
"0.60062","0.94176","8.48155","186.20800","0.00000","0.94176","0.60062","0.04997"
"0.60062","0.93631","8.43243","186.60800","0.00000","0.93631","0.60062","0.04997"
"0.60062","0.93901","8.45680","187.00800","0.00000","0.93901","0.60062","0.04997"
"0.60062","0.93634","8.43270","187.20800","0.00000","0.93634","0.60062","0.04997"