File: G1 -Incubated Stress relaxation-20210318/Specimen_RawData_2 (1).csv
Specimen properties : Specimen label,""
Specimen properties : Diameter,"0.33600",mm
Specimen properties : Length,"16.10000",mm
Test : Rate 1,"5.00000",mm/min
Test : Start of hold value,"0.05000",mm/mm
Test : Duration,"180.00000",s

Extension,Load,Tensile stress,Time,PIP count,Tenacity,Tensile extension,Tensile strain (Extension)
(mm),(N),(MPa),(s),,(N/tex),(mm),(mm/mm)
"0.00000","0.00484","0.05462","0.00000","0.00000","0.00484","0.00000","0.00000"
"0.03208","0.03057","0.34481","0.40000","0.00000","0.03057","0.03208","0.00199"
"0.06687","0.06634","0.74819","0.80000","0.00000","0.06634","0.06687","0.00415"
"0.10000","0.08198","0.92455","1.20000","0.00000","0.08198","0.10000","0.00621"
"0.13333","0.11449","1.29124","1.60000","0.00000","0.11449","0.13333","0.00828"
"0.16708","0.15202","1.71449","2.00000","0.00000","0.15202","0.16708","0.01038"
"0.20021","0.18596","2.09722","2.40000","0.00000","0.18596","0.20021","0.01244"
"0.23396","0.24927","2.81125","2.80000","0.00000","0.24927","0.23396","0.01453"
"0.26667","0.29430","3.31906","3.20000","0.00000","0.29430","0.26667","0.01656"
"0.30000","0.36293","4.09307","3.60000","0.00000","0.36293","0.30000","0.01863"
"0.33333","0.41531","4.68384","4.00000","0.00000","0.41531","0.33333","0.02070"
"0.36729","0.48163","5.43181","4.40000","0.00000","0.48163","0.36729","0.02281"
"0.40042","0.53730","6.05963","4.80000","0.00000","0.53730","0.40042","0.02487"
"0.43354","0.59495","6.70986","5.20000","0.00000","0.59495","0.43354","0.02693"
"0.46667","0.64674","7.29387","5.60000","0.00000","0.64674","0.46667","0.02899"
"0.50000","0.70181","7.91503","6.00000","0.00000","0.70181","0.50000","0.03106"
"0.53354","0.76185","8.59209","6.40000","0.00000","0.76185","0.53354","0.03314"
"0.56687","0.81149","9.15196","6.80000","0.00000","0.81149","0.56687","0.03521"
"0.60021","0.86413","9.74569","7.20000","0.00000","0.86413","0.60021","0.03728"
"0.63354","0.91659","10.33734","7.60000","0.00000","0.91659","0.63354","0.03935"
"0.66687","0.98145","11.06882","8.00000","0.00000","0.98145","0.66687","0.04142"
"0.70021","1.03865","11.71386","8.40000","0.00000","1.03865","0.70021","0.04349"
"0.73354","1.10405","12.45143","8.80000","0.00000","1.10405","0.73354","0.04556"
"0.76667","1.16255","13.11126","9.20000","0.00000","1.16255","0.76667","0.04762"
"0.80021","1.23192","13.89363","9.60000","0.00000","1.23192","0.80021","0.04970"
"0.80771","1.19060","13.42756","9.86200","0.00000","1.19060","0.80771","0.05017"
"0.80771","1.11542","12.57965","10.26200","0.00000","1.11542","0.80771","0.05017"
"0.80708","1.07273","12.09826","10.66200","0.00000","1.07273","0.80708","0.05013"
"0.80667","1.04359","11.76962","11.06200","0.00000","1.04359","0.80667","0.05010"
"0.80604","1.02587","11.56975","11.46200","0.00000","1.02587","0.80604","0.05006"
"0.80562","1.01015","11.39243","11.86200","0.00000","1.01015","0.80562","0.05004"
"0.80542","0.99154","11.18261","12.26200","0.00000","0.99154","0.80542","0.05003"
"0.80542","0.98428","11.10075","12.66200","0.00000","0.98428","0.80542","0.05003"
"0.80542","0.98174","11.07204","13.06200","0.00000","0.98174","0.80542","0.05003"
"0.80542","0.96475","10.88041","13.46200","0.00000","0.96475","0.80542","0.05003"
"0.80542","0.96041","10.83151","13.86200","0.00000","0.96041","0.80542","0.05003"
"0.80542","0.94898","10.70254","14.26200","0.00000","0.94898","0.80542","0.05003"
"0.80542","0.94674","10.67732","14.66200","0.00000","0.94674","0.80542","0.05003"
"0.80542","0.93752","10.57339","15.06200","0.00000","0.93752","0.80542","0.05003"
"0.80542","0.93195","10.51058","15.46200","0.00000","0.93195","0.80542","0.05003"
"0.80542","0.93066","10.49599","15.86200","0.00000","0.93066","0.80542","0.05003"
"0.80542","0.92265","10.40565","16.26200","0.00000","0.92265","0.80542","0.05003"
"0.80542","0.92189","10.39706","16.66200","0.00000","0.92189","0.80542","0.05003"
"0.80542","0.91738","10.34622","17.06200","0.00000","0.91738","0.80542","0.05003"
"0.80542","0.92063","10.38288","17.46200","0.00000","0.92063","0.80542","0.05003"
"0.80542","0.91248","10.29097","17.86200","0.00000","0.91248","0.80542","0.05003"
"0.80542","0.91962","10.37144","18.26200","0.00000","0.91962","0.80542","0.05003"
"0.80542","0.91098","10.27404","18.66200","0.00000","0.91098","0.80542","0.05003"
"0.80542","0.91356","10.30308","19.06200","0.00000","0.91356","0.80542","0.05003"
"0.80542","0.90552","10.21245","19.46200","0.00000","0.90552","0.80542","0.05003"
"0.80542","0.90009","10.15121","19.86200","0.00000","0.90009","0.80542","0.05003"
"0.80542","0.90075","10.15868","20.26200","0.00000","0.90075","0.80542","0.05003"
"0.80542","0.90018","10.15223","20.66200","0.00000","0.90018","0.80542","0.05003"
"0.80542","0.89805","10.12819","21.06200","0.00000","0.89805","0.80542","0.05003"
"0.80542","0.90475","10.20381","21.46200","0.00000","0.90475","0.80542","0.05003"
"0.80542","0.90615","10.21952","21.86200","0.00000","0.90615","0.80542","0.05003"
"0.80542","0.90031","10.15366","22.26200","0.00000","0.90031","0.80542","0.05003"
"0.80542","0.89379","10.08010","22.66200","0.00000","0.89379","0.80542","0.05003"
"0.80542","0.89865","10.13496","23.06200","0.00000","0.89865","0.80542","0.05003"
"0.80542","0.88951","10.03190","23.46200","0.00000","0.88951","0.80542","0.05003"
"0.80542","0.89914","10.14050","23.86200","0.00000","0.89914","0.80542","0.05003"
"0.80542","0.89383","10.08057","24.26200","0.00000","0.89383","0.80542","0.05003"
"0.80542","0.89133","10.05246","24.66200","0.00000","0.89133","0.80542","0.05003"
"0.80521","0.89583","10.10314","25.06200","0.00000","0.89583","0.80521","0.05001"
"0.80521","0.88807","10.01559","25.46200","0.00000","0.88807","0.80521","0.05001"
"0.80521","0.89253","10.06597","25.86200","0.00000","0.89253","0.80521","0.05001"
"0.80521","0.89100","10.04867","26.26200","0.00000","0.89100","0.80521","0.05001"
"0.80521","0.89446","10.08770","26.66200","0.00000","0.89446","0.80521","0.05001"
"0.80521","0.88859","10.02145","27.06200","0.00000","0.88859","0.80521","0.05001"
"0.80521","0.89374","10.07959","27.46200","0.00000","0.89374","0.80521","0.05001"
"0.80521","0.89270","10.06784","27.86200","0.00000","0.89270","0.80521","0.05001"
"0.80521","0.89386","10.08098","28.26200","0.00000","0.89386","0.80521","0.05001"
"0.80521","0.90053","10.15617","28.66200","0.00000","0.90053","0.80521","0.05001"
"0.80521","0.88841","10.01945","29.06200","0.00000","0.88841","0.80521","0.05001"
"0.80521","0.89511","10.09506","29.46200","0.00000","0.89511","0.80521","0.05001"
"0.80521","0.89059","10.04411","29.86200","0.00000","0.89059","0.80521","0.05001"
"0.80521","0.89524","10.09656","30.26200","0.00000","0.89524","0.80521","0.05001"
"0.80521","0.89133","10.05245","30.66200","0.00000","0.89133","0.80521","0.05001"
"0.80521","0.90216","10.17456","31.06200","0.00000","0.90216","0.80521","0.05001"
"0.80521","0.89384","10.08077","31.46200","0.00000","0.89384","0.80521","0.05001"
"0.80521","0.89612","10.10646","31.86200","0.00000","0.89612","0.80521","0.05001"
"0.80521","0.89693","10.11559","32.26200","0.00000","0.89693","0.80521","0.05001"
"0.80521","0.89571","10.10177","32.66200","0.00000","0.89571","0.80521","0.05001"
"0.80521","0.89364","10.07842","33.06200","0.00000","0.89364","0.80521","0.05001"
"0.80521","0.90259","10.17940","33.46200","0.00000","0.90259","0.80521","0.05001"
"0.80521","0.89765","10.12368","33.86200","0.00000","0.89765","0.80521","0.05001"
"0.80521","0.90118","10.16348","34.26200","0.00000","0.90118","0.80521","0.05001"
"0.80521","0.89913","10.14032","34.66200","0.00000","0.89913","0.80521","0.05001"
"0.80521","0.90024","10.15285","35.06200","0.00000","0.90024","0.80521","0.05001"
"0.80521","0.89911","10.14018","35.46200","0.00000","0.89911","0.80521","0.05001"
"0.80521","0.90512","10.20789","35.86200","0.00000","0.90512","0.80521","0.05001"
"0.80521","0.90242","10.17745","36.26200","0.00000","0.90242","0.80521","0.05001"
"0.80521","0.90117","10.16333","36.66200","0.00000","0.90117","0.80521","0.05001"
"0.80521","0.89915","10.14063","37.06200","0.00000","0.89915","0.80521","0.05001"
"0.80521","0.90496","10.20615","37.46200","0.00000","0.90496","0.80521","0.05001"
"0.80521","0.90007","10.15093","37.86200","0.00000","0.90007","0.80521","0.05001"
"0.80521","0.90393","10.19450","38.26200","0.00000","0.90393","0.80521","0.05001"
"0.80521","0.90919","10.25385","38.66200","0.00000","0.90919","0.80521","0.05001"
"0.80521","0.90605","10.21840","39.06200","0.00000","0.90605","0.80521","0.05001"
"0.80521","0.90966","10.25911","39.46200","0.00000","0.90966","0.80521","0.05001"
"0.80521","0.90874","10.24881","39.86200","0.00000","0.90874","0.80521","0.05001"
"0.80521","0.90691","10.22817","40.26200","0.00000","0.90691","0.80521","0.05001"
"0.80521","0.90506","10.20722","40.66200","0.00000","0.90506","0.80521","0.05001"
"0.80521","0.90983","10.26108","41.06200","0.00000","0.90983","0.80521","0.05001"
"0.80521","0.91491","10.31833","41.46200","0.00000","0.91491","0.80521","0.05001"
"0.80521","0.91523","10.32198","41.86200","0.00000","0.91523","0.80521","0.05001"
"0.80521","0.91324","10.29951","42.26200","0.00000","0.91324","0.80521","0.05001"
"0.80521","0.91912","10.36582","42.66200","0.00000","0.91912","0.80521","0.05001"
"0.80521","0.91973","10.37276","43.06200","0.00000","0.91973","0.80521","0.05001"
"0.80521","0.92405","10.42139","43.46200","0.00000","0.92405","0.80521","0.05001"
"0.80521","0.91753","10.34787","43.86200","0.00000","0.91753","0.80521","0.05001"
"0.80521","0.91897","10.36413","44.26200","0.00000","0.91897","0.80521","0.05001"
"0.80521","0.90924","10.25436","44.66200","0.00000","0.90924","0.80521","0.05001"
"0.80521","0.91294","10.29609","45.06200","0.00000","0.91294","0.80521","0.05001"
"0.80521","0.92651","10.44920","45.46200","0.00000","0.92651","0.80521","0.05001"
"0.80521","0.91801","10.35327","45.86200","0.00000","0.91801","0.80521","0.05001"
"0.80521","0.92360","10.41632","46.26200","0.00000","0.92360","0.80521","0.05001"
"0.80521","0.92168","10.39474","46.66200","0.00000","0.92168","0.80521","0.05001"
"0.80521","0.92342","10.41434","47.06200","0.00000","0.92342","0.80521","0.05001"
"0.80521","0.91816","10.35497","47.46200","0.00000","0.91816","0.80521","0.05001"
"0.80521","0.92475","10.42935","47.86200","0.00000","0.92475","0.80521","0.05001"
"0.80521","0.92525","10.43495","48.26200","0.00000","0.92525","0.80521","0.05001"
"0.80521","0.91924","10.36718","48.66200","0.00000","0.91924","0.80521","0.05001"
"0.80521","0.92440","10.42541","49.06200","0.00000","0.92440","0.80521","0.05001"
"0.80521","0.92548","10.43759","49.46200","0.00000","0.92548","0.80521","0.05001"
"0.80521","0.93002","10.48880","49.86200","0.00000","0.93002","0.80521","0.05001"
"0.80521","0.92527","10.43516","50.26200","0.00000","0.92527","0.80521","0.05001"
"0.80521","0.92164","10.39427","50.66200","0.00000","0.92164","0.80521","0.05001"
"0.80521","0.92947","10.48260","51.06200","0.00000","0.92947","0.80521","0.05001"
"0.80521","0.92700","10.45465","51.46200","0.00000","0.92700","0.80521","0.05001"
"0.80521","0.93103","10.50017","51.86200","0.00000","0.93103","0.80521","0.05001"
"0.80521","0.93277","10.51979","52.26200","0.00000","0.93277","0.80521","0.05001"
"0.80521","0.92525","10.43496","52.66200","0.00000","0.92525","0.80521","0.05001"
"0.80521","0.92932","10.48091","53.06200","0.00000","0.92932","0.80521","0.05001"
"0.80521","0.93111","10.50101","53.46200","0.00000","0.93111","0.80521","0.05001"
"0.80521","0.94109","10.61360","53.86200","0.00000","0.94109","0.80521","0.05001"
"0.80521","0.93186","10.50947","54.26200","0.00000","0.93186","0.80521","0.05001"
"0.80521","0.94084","10.61073","54.66200","0.00000","0.94084","0.80521","0.05001"
"0.80521","0.93279","10.51996","55.06200","0.00000","0.93279","0.80521","0.05001"
"0.80521","0.93203","10.51138","55.46200","0.00000","0.93203","0.80521","0.05001"
"0.80521","0.93321","10.52470","55.86200","0.00000","0.93321","0.80521","0.05001"
"0.80521","0.93861","10.58560","56.26200","0.00000","0.93861","0.80521","0.05001"
"0.80521","0.93309","10.52336","56.66200","0.00000","0.93309","0.80521","0.05001"
"0.80521","0.93747","10.57272","57.06200","0.00000","0.93747","0.80521","0.05001"
"0.80521","0.94212","10.62526","57.46200","0.00000","0.94212","0.80521","0.05001"
"0.80521","0.93568","10.55253","57.86200","0.00000","0.93568","0.80521","0.05001"
"0.80521","0.93703","10.56782","58.26200","0.00000","0.93703","0.80521","0.05001"
"0.80521","0.93867","10.58635","58.66200","0.00000","0.93867","0.80521","0.05001"
"0.80521","0.94407","10.64719","59.06200","0.00000","0.94407","0.80521","0.05001"
"0.80521","0.94485","10.65600","59.46200","0.00000","0.94485","0.80521","0.05001"
"0.80521","0.94934","10.70668","59.86200","0.00000","0.94934","0.80521","0.05001"
"0.80521","0.93840","10.58322","60.26200","0.00000","0.93840","0.80521","0.05001"
"0.80521","0.95514","10.77205","60.66200","0.00000","0.95514","0.80521","0.05001"
"0.80521","0.94784","10.68978","61.06200","0.00000","0.94784","0.80521","0.05001"
"0.80521","0.94603","10.66929","61.46200","0.00000","0.94603","0.80521","0.05001"
"0.80521","0.95571","10.77845","61.86200","0.00000","0.95571","0.80521","0.05001"
"0.80521","0.95028","10.71726","62.26200","0.00000","0.95028","0.80521","0.05001"
"0.80521","0.95845","10.80934","62.66200","0.00000","0.95845","0.80521","0.05001"
"0.80521","0.95580","10.77951","63.06200","0.00000","0.95580","0.80521","0.05001"
"0.80521","0.96215","10.85111","63.46200","0.00000","0.96215","0.80521","0.05001"
"0.80521","0.96448","10.87735","63.86200","0.00000","0.96448","0.80521","0.05001"
"0.80521","0.95247","10.74192","64.26200","0.00000","0.95247","0.80521","0.05001"
"0.80521","0.94928","10.70596","64.66200","0.00000","0.94928","0.80521","0.05001"
"0.80521","0.95983","10.82492","65.06200","0.00000","0.95983","0.80521","0.05001"
"0.80521","0.96077","10.83557","65.46200","0.00000","0.96077","0.80521","0.05001"
"0.80521","0.95771","10.80099","65.86200","0.00000","0.95771","0.80521","0.05001"
"0.80521","0.96133","10.84191","66.26200","0.00000","0.96133","0.80521","0.05001"
"0.80521","0.96066","10.83427","66.66200","0.00000","0.96066","0.80521","0.05001"
"0.80521","0.95983","10.82493","67.06200","0.00000","0.95983","0.80521","0.05001"
"0.80521","0.96420","10.87425","67.46200","0.00000","0.96420","0.80521","0.05001"
"0.80521","0.96557","10.88969","67.86200","0.00000","0.96557","0.80521","0.05001"
"0.80521","0.96884","10.92652","68.26200","0.00000","0.96884","0.80521","0.05001"
"0.80521","0.97413","10.98619","68.66200","0.00000","0.97413","0.80521","0.05001"
"0.80521","0.96999","10.93949","69.06200","0.00000","0.96999","0.80521","0.05001"
"0.80521","0.96937","10.93256","69.46200","0.00000","0.96937","0.80521","0.05001"
"0.80521","0.96915","10.93005","69.86200","0.00000","0.96915","0.80521","0.05001"
"0.80521","0.96639","10.89899","70.26200","0.00000","0.96639","0.80521","0.05001"
"0.80521","0.97443","10.98961","70.66200","0.00000","0.97443","0.80521","0.05001"
"0.80521","0.97381","10.98256","71.06200","0.00000","0.97381","0.80521","0.05001"
"0.80521","0.96999","10.93951","71.46200","0.00000","0.96999","0.80521","0.05001"
"0.80521","0.98302","11.08654","71.86200","0.00000","0.98302","0.80521","0.05001"
"0.80521","0.98346","11.09150","72.26200","0.00000","0.98346","0.80521","0.05001"
"0.80521","0.97494","10.99541","72.66200","0.00000","0.97494","0.80521","0.05001"
"0.80521","0.97390","10.98368","73.06200","0.00000","0.97390","0.80521","0.05001"
"0.80521","0.97734","11.02247","73.46200","0.00000","0.97734","0.80521","0.05001"
"0.80521","0.97851","11.03557","73.86200","0.00000","0.97851","0.80521","0.05001"
"0.80521","0.98106","11.06433","74.26200","0.00000","0.98106","0.80521","0.05001"
"0.80521","0.99014","11.16681","74.66200","0.00000","0.99014","0.80521","0.05001"
"0.80521","0.98468","11.10522","75.06200","0.00000","0.98468","0.80521","0.05001"
"0.80521","0.98223","11.07763","75.46200","0.00000","0.98223","0.80521","0.05001"
"0.80521","0.98529","11.11212","75.86200","0.00000","0.98529","0.80521","0.05001"
"0.80521","0.98965","11.16124","76.26200","0.00000","0.98965","0.80521","0.05001"
"0.80521","0.98895","11.15332","76.66200","0.00000","0.98895","0.80521","0.05001"
"0.80521","0.99230","11.19113","77.06200","0.00000","0.99230","0.80521","0.05001"
"0.80521","0.98423","11.10015","77.46200","0.00000","0.98423","0.80521","0.05001"
"0.80521","0.99006","11.16585","77.86200","0.00000","0.99006","0.80521","0.05001"
"0.80521","0.98604","11.12059","78.26200","0.00000","0.98604","0.80521","0.05001"
"0.80521","0.99521","11.22397","78.66200","0.00000","0.99521","0.80521","0.05001"
"0.80521","0.99458","11.21681","79.06200","0.00000","0.99458","0.80521","0.05001"
"0.80521","0.99529","11.22482","79.46200","0.00000","0.99529","0.80521","0.05001"
"0.80521","0.99404","11.21079","79.86200","0.00000","0.99404","0.80521","0.05001"
"0.80521","0.99889","11.26542","80.26200","0.00000","0.99889","0.80521","0.05001"
"0.80521","0.99426","11.21325","80.66200","0.00000","0.99426","0.80521","0.05001"
"0.80521","1.00083","11.28736","81.06200","0.00000","1.00083","0.80521","0.05001"
"0.80521","0.99801","11.25559","81.46200","0.00000","0.99801","0.80521","0.05001"
"0.80521","0.99633","11.23664","81.86200","0.00000","0.99633","0.80521","0.05001"
"0.80521","0.99645","11.23790","82.26200","0.00000","0.99645","0.80521","0.05001"
"0.80521","1.00311","11.31305","82.66200","0.00000","1.00311","0.80521","0.05001"
"0.80521","1.00157","11.29570","83.06200","0.00000","1.00157","0.80521","0.05001"
"0.80521","1.00357","11.31828","83.46200","0.00000","1.00357","0.80521","0.05001"
"0.80521","0.99937","11.27093","83.86200","0.00000","0.99937","0.80521","0.05001"
"0.80521","1.00522","11.33685","84.26200","0.00000","1.00522","0.80521","0.05001"
"0.80521","1.00609","11.34671","84.66200","0.00000","1.00609","0.80521","0.05001"
"0.80521","1.00804","11.36866","85.06200","0.00000","1.00804","0.80521","0.05001"
"0.80521","1.01337","11.42876","85.46200","0.00000","1.01337","0.80521","0.05001"
"0.80521","1.00396","11.32264","85.86200","0.00000","1.00396","0.80521","0.05001"
"0.80521","1.00712","11.35826","86.26200","0.00000","1.00712","0.80521","0.05001"
"0.80521","1.00411","11.32436","86.66200","0.00000","1.00411","0.80521","0.05001"
"0.80521","1.01611","11.45971","87.06200","0.00000","1.01611","0.80521","0.05001"
"0.80521","1.01044","11.39574","87.46200","0.00000","1.01044","0.80521","0.05001"
"0.80521","1.00692","11.35603","87.86200","0.00000","1.00692","0.80521","0.05001"
"0.80521","1.01747","11.47502","88.26200","0.00000","1.01747","0.80521","0.05001"
"0.80521","1.02201","11.52624","88.66200","0.00000","1.02201","0.80521","0.05001"
"0.80521","1.01269","11.42113","89.06200","0.00000","1.01269","0.80521","0.05001"
"0.80521","1.01732","11.47332","89.46200","0.00000","1.01732","0.80521","0.05001"
"0.80521","1.01586","11.45687","89.86200","0.00000","1.01586","0.80521","0.05001"
"0.80521","1.02497","11.55961","90.26200","0.00000","1.02497","0.80521","0.05001"
"0.80521","1.01584","11.45662","90.66200","0.00000","1.01584","0.80521","0.05001"
"0.80521","1.02005","11.50409","91.06200","0.00000","1.02005","0.80521","0.05001"
"0.80521","1.03067","11.62384","91.46200","0.00000","1.03067","0.80521","0.05001"
"0.80521","1.02738","11.58673","91.86200","0.00000","1.02738","0.80521","0.05001"
"0.80521","1.02371","11.54538","92.26200","0.00000","1.02371","0.80521","0.05001"
"0.80521","1.02561","11.56683","92.66200","0.00000","1.02561","0.80521","0.05001"
"0.80521","1.02665","11.57856","93.06200","0.00000","1.02665","0.80521","0.05001"
"0.80521","1.03256","11.64521","93.46200","0.00000","1.03256","0.80521","0.05001"
"0.80521","1.02586","11.56964","93.86200","0.00000","1.02586","0.80521","0.05001"
"0.80521","1.02479","11.55754","94.26200","0.00000","1.02479","0.80521","0.05001"
"0.80521","1.02720","11.58477","94.66200","0.00000","1.02720","0.80521","0.05001"
"0.80521","1.03089","11.62641","95.06200","0.00000","1.03089","0.80521","0.05001"
"0.80521","1.02994","11.61565","95.46200","0.00000","1.02994","0.80521","0.05001"
"0.80521","1.02809","11.59473","95.86200","0.00000","1.02809","0.80521","0.05001"
"0.80521","1.03096","11.62714","96.26200","0.00000","1.03096","0.80521","0.05001"
"0.80521","1.03633","11.68773","96.66200","0.00000","1.03633","0.80521","0.05001"
"0.80521","1.04014","11.73063","97.06200","0.00000","1.04014","0.80521","0.05001"
"0.80521","1.03292","11.64926","97.46200","0.00000","1.03292","0.80521","0.05001"
"0.80521","1.03905","11.71836","97.86200","0.00000","1.03905","0.80521","0.05001"
"0.80521","1.03599","11.68391","98.26200","0.00000","1.03599","0.80521","0.05001"
"0.80521","1.03657","11.69041","98.66200","0.00000","1.03657","0.80521","0.05001"
"0.80521","1.03178","11.63636","99.06200","0.00000","1.03178","0.80521","0.05001"
"0.80521","1.03509","11.67378","99.46200","0.00000","1.03509","0.80521","0.05001"
"0.80521","1.04364","11.77017","99.86200","0.00000","1.04364","0.80521","0.05001"
"0.80521","1.04495","11.78491","100.26200","0.00000","1.04495","0.80521","0.05001"
"0.80521","1.04446","11.77943","100.66200","0.00000","1.04446","0.80521","0.05001"
"0.80521","1.03824","11.70924","101.06200","0.00000","1.03824","0.80521","0.05001"
"0.80521","1.04819","11.82153","101.46200","0.00000","1.04819","0.80521","0.05001"
"0.80521","1.04317","11.76483","101.86200","0.00000","1.04317","0.80521","0.05001"
"0.80521","1.04497","11.78519","102.26200","0.00000","1.04497","0.80521","0.05001"
"0.80521","1.04990","11.84073","102.66200","0.00000","1.04990","0.80521","0.05001"
"0.80521","1.04129","11.74364","103.06200","0.00000","1.04129","0.80521","0.05001"
"0.80521","1.04285","11.76129","103.46200","0.00000","1.04285","0.80521","0.05001"
"0.80521","1.04687","11.80663","103.86200","0.00000","1.04687","0.80521","0.05001"
"0.80521","1.04489","11.78426","104.26200","0.00000","1.04489","0.80521","0.05001"
"0.80521","1.05395","11.88647","104.66200","0.00000","1.05395","0.80521","0.05001"
"0.80521","1.05560","11.90508","105.06200","0.00000","1.05560","0.80521","0.05001"
"0.80521","1.05210","11.86552","105.46200","0.00000","1.05210","0.80521","0.05001"
"0.80521","1.05677","11.91827","105.86200","0.00000","1.05677","0.80521","0.05001"
"0.80521","1.05555","11.90446","106.26200","0.00000","1.05555","0.80521","0.05001"
"0.80521","1.05279","11.87335","106.66200","0.00000","1.05279","0.80521","0.05001"
"0.80521","1.05428","11.89018","107.06200","0.00000","1.05428","0.80521","0.05001"
"0.80521","1.05787","11.93070","107.46200","0.00000","1.05787","0.80521","0.05001"
"0.80521","1.05111","11.85435","107.86200","0.00000","1.05111","0.80521","0.05001"
"0.80521","1.05890","11.94228","108.26200","0.00000","1.05890","0.80521","0.05001"
"0.80521","1.06106","11.96664","108.66200","0.00000","1.06106","0.80521","0.05001"
"0.80521","1.06272","11.98537","109.06200","0.00000","1.06272","0.80521","0.05001"
"0.80521","1.06085","11.96425","109.46200","0.00000","1.06085","0.80521","0.05001"
"0.80521","1.05395","11.88646","109.86200","0.00000","1.05395","0.80521","0.05001"
"0.80521","1.05912","11.94479","110.26200","0.00000","1.05912","0.80521","0.05001"
"0.80521","1.06571","12.01903","110.66200","0.00000","1.06571","0.80521","0.05001"
"0.80521","1.05840","11.93660","111.06200","0.00000","1.05840","0.80521","0.05001"
"0.80521","1.06077","11.96341","111.46200","0.00000","1.06077","0.80521","0.05001"
"0.80521","1.05388","11.88570","111.86200","0.00000","1.05388","0.80521","0.05001"
"0.80521","1.06269","11.98505","112.26200","0.00000","1.06269","0.80521","0.05001"
"0.80521","1.06205","11.97774","112.66200","0.00000","1.06205","0.80521","0.05001"
"0.80521","1.06639","12.02669","113.06200","0.00000","1.06639","0.80521","0.05001"
"0.80521","1.06786","12.04333","113.46200","0.00000","1.06786","0.80521","0.05001"
"0.80521","1.06904","12.05665","113.86200","0.00000","1.06904","0.80521","0.05001"
"0.80521","1.07119","12.08089","114.26200","0.00000","1.07119","0.80521","0.05001"
"0.80521","1.06872","12.05303","114.66200","0.00000","1.06872","0.80521","0.05001"
"0.80521","1.06811","12.04611","115.06200","0.00000","1.06811","0.80521","0.05001"
"0.80521","1.06506","12.01177","115.46200","0.00000","1.06506","0.80521","0.05001"
"0.80521","1.06832","12.04854","115.86200","0.00000","1.06832","0.80521","0.05001"
"0.80521","1.06366","11.99590","116.26200","0.00000","1.06366","0.80521","0.05001"
"0.80521","1.07162","12.08572","116.66200","0.00000","1.07162","0.80521","0.05001"
"0.80521","1.07026","12.07035","117.06200","0.00000","1.07026","0.80521","0.05001"
"0.80521","1.07005","12.06800","117.46200","0.00000","1.07005","0.80521","0.05001"
"0.80521","1.06802","12.04517","117.86200","0.00000","1.06802","0.80521","0.05001"
"0.80521","1.07401","12.11261","118.26200","0.00000","1.07401","0.80521","0.05001"
"0.80521","1.07078","12.07626","118.66200","0.00000","1.07078","0.80521","0.05001"
"0.80521","1.07020","12.06972","119.06200","0.00000","1.07020","0.80521","0.05001"
"0.80521","1.07737","12.15053","119.46200","0.00000","1.07737","0.80521","0.05001"
"0.80521","1.07548","12.12920","119.86200","0.00000","1.07548","0.80521","0.05001"
"0.80521","1.07799","12.15757","120.26200","0.00000","1.07799","0.80521","0.05001"
"0.80521","1.07800","12.15762","120.66200","0.00000","1.07800","0.80521","0.05001"
"0.80521","1.07676","12.14369","121.06200","0.00000","1.07676","0.80521","0.05001"
"0.80521","1.07595","12.13449","121.46200","0.00000","1.07595","0.80521","0.05001"
"0.80521","1.08055","12.18642","121.86200","0.00000","1.08055","0.80521","0.05001"
"0.80521","1.07980","12.17800","122.26200","0.00000","1.07980","0.80521","0.05001"
"0.80521","1.07473","12.12082","122.66200","0.00000","1.07473","0.80521","0.05001"
"0.80521","1.09191","12.31450","123.06200","0.00000","1.09191","0.80521","0.05001"
"0.80521","1.08656","12.25426","123.46200","0.00000","1.08656","0.80521","0.05001"
"0.80521","1.08903","12.28208","123.86200","0.00000","1.08903","0.80521","0.05001"
"0.80521","1.08904","12.28221","124.26200","0.00000","1.08904","0.80521","0.05001"
"0.80521","1.08732","12.26274","124.66200","0.00000","1.08732","0.80521","0.05001"
"0.80521","1.08727","12.26225","125.06200","0.00000","1.08727","0.80521","0.05001"
"0.80521","1.08567","12.24417","125.46200","0.00000","1.08567","0.80521","0.05001"
"0.80521","1.09137","12.30841","125.86200","0.00000","1.09137","0.80521","0.05001"
"0.80521","1.09111","12.30553","126.26200","0.00000","1.09111","0.80521","0.05001"
"0.80521","1.08709","12.26018","126.66200","0.00000","1.08709","0.80521","0.05001"
"0.80521","1.08691","12.25821","127.06200","0.00000","1.08691","0.80521","0.05001"
"0.80521","1.08671","12.25593","127.46200","0.00000","1.08671","0.80521","0.05001"
"0.80521","1.09629","12.36395","127.86200","0.00000","1.09629","0.80521","0.05001"
"0.80521","1.09043","12.29788","128.26200","0.00000","1.09043","0.80521","0.05001"
"0.80521","1.09322","12.32932","128.66200","0.00000","1.09322","0.80521","0.05001"
"0.80521","1.09841","12.38780","129.06200","0.00000","1.09841","0.80521","0.05001"
"0.80521","1.09407","12.33888","129.46200","0.00000","1.09407","0.80521","0.05001"
"0.80521","1.09346","12.33204","129.86200","0.00000","1.09346","0.80521","0.05001"
"0.80521","1.09785","12.38151","130.26200","0.00000","1.09785","0.80521","0.05001"
"0.80521","1.09829","12.38651","130.66200","0.00000","1.09829","0.80521","0.05001"
"0.80521","1.09734","12.37579","131.06200","0.00000","1.09734","0.80521","0.05001"
"0.80521","1.09807","12.38405","131.46200","0.00000","1.09807","0.80521","0.05001"
"0.80521","1.10656","12.47981","131.86200","0.00000","1.10656","0.80521","0.05001"
"0.80521","1.09870","12.39117","132.26200","0.00000","1.09870","0.80521","0.05001"
"0.80521","1.10265","12.43564","132.66200","0.00000","1.10265","0.80521","0.05001"
"0.80521","1.09922","12.39704","133.06200","0.00000","1.09922","0.80521","0.05001"
"0.80521","1.09997","12.40545","133.46200","0.00000","1.09997","0.80521","0.05001"
"0.80521","1.09617","12.36265","133.86200","0.00000","1.09617","0.80521","0.05001"
"0.80521","1.10213","12.42984","134.26200","0.00000","1.10213","0.80521","0.05001"
"0.80521","1.10350","12.44523","134.66200","0.00000","1.10350","0.80521","0.05001"
"0.80521","1.10044","12.41074","135.06200","0.00000","1.10044","0.80521","0.05001"
"0.80521","1.10803","12.49640","135.46200","0.00000","1.10803","0.80521","0.05001"
"0.80521","1.10922","12.50975","135.86200","0.00000","1.10922","0.80521","0.05001"
"0.80521","1.10212","12.42966","136.26200","0.00000","1.10212","0.80521","0.05001"
"0.80521","1.10138","12.42139","136.66200","0.00000","1.10138","0.80521","0.05001"
"0.80521","1.10516","12.46401","137.06200","0.00000","1.10516","0.80521","0.05001"
"0.80521","1.10775","12.49324","137.46200","0.00000","1.10775","0.80521","0.05001"
"0.80521","1.10678","12.48226","137.86200","0.00000","1.10678","0.80521","0.05001"
"0.80521","1.10946","12.51243","138.26200","0.00000","1.10946","0.80521","0.05001"
"0.80521","1.10762","12.49173","138.66200","0.00000","1.10762","0.80521","0.05001"
"0.80521","1.10607","12.47423","139.06200","0.00000","1.10607","0.80521","0.05001"
"0.80521","1.10773","12.49297","139.46200","0.00000","1.10773","0.80521","0.05001"
"0.80521","1.10634","12.47731","139.86200","0.00000","1.10634","0.80521","0.05001"
"0.80521","1.11335","12.55630","140.26200","0.00000","1.11335","0.80521","0.05001"
"0.80521","1.11425","12.56654","140.66200","0.00000","1.11425","0.80521","0.05001"
"0.80521","1.10467","12.45845","141.06200","0.00000","1.10467","0.80521","0.05001"
"0.80521","1.11220","12.54333","141.46200","0.00000","1.11220","0.80521","0.05001"
"0.80521","1.11391","12.56270","141.86200","0.00000","1.11391","0.80521","0.05001"
"0.80521","1.10748","12.49009","142.26200","0.00000","1.10748","0.80521","0.05001"
"0.80521","1.11488","12.57360","142.66200","0.00000","1.11488","0.80521","0.05001"
"0.80521","1.11712","12.59890","143.06200","0.00000","1.11712","0.80521","0.05001"
"0.80521","1.10923","12.50990","143.46200","0.00000","1.10923","0.80521","0.05001"
"0.80521","1.11719","12.59968","143.86200","0.00000","1.11719","0.80521","0.05001"
"0.80521","1.11939","12.62447","144.26200","0.00000","1.11939","0.80521","0.05001"
"0.80521","1.12048","12.63677","144.66200","0.00000","1.12048","0.80521","0.05001"
"0.80521","1.11681","12.59541","145.06200","0.00000","1.11681","0.80521","0.05001"
"0.80521","1.11051","12.52429","145.46200","0.00000","1.11051","0.80521","0.05001"
"0.80521","1.11459","12.57034","145.86200","0.00000","1.11459","0.80521","0.05001"
"0.80521","1.11700","12.59746","146.26200","0.00000","1.11700","0.80521","0.05001"
"0.80521","1.11495","12.57439","146.66200","0.00000","1.11495","0.80521","0.05001"
"0.80521","1.11626","12.58918","147.06200","0.00000","1.11626","0.80521","0.05001"
"0.80521","1.11180","12.53886","147.46200","0.00000","1.11180","0.80521","0.05001"
"0.80521","1.11915","12.62171","147.86200","0.00000","1.11915","0.80521","0.05001"
"0.80521","1.11259","12.54783","148.26200","0.00000","1.11259","0.80521","0.05001"
"0.80521","1.11866","12.61625","148.66200","0.00000","1.11866","0.80521","0.05001"
"0.80521","1.11915","12.62178","149.06200","0.00000","1.11915","0.80521","0.05001"
"0.80521","1.11542","12.57969","149.46200","0.00000","1.11542","0.80521","0.05001"
"0.80521","1.11925","12.62287","149.86200","0.00000","1.11925","0.80521","0.05001"
"0.80521","1.12093","12.64178","150.26200","0.00000","1.12093","0.80521","0.05001"
"0.80521","1.11750","12.60314","150.66200","0.00000","1.11750","0.80521","0.05001"
"0.80521","1.11584","12.58448","151.06200","0.00000","1.11584","0.80521","0.05001"
"0.80521","1.11997","12.63106","151.46200","0.00000","1.11997","0.80521","0.05001"
"0.80521","1.11569","12.58271","151.86200","0.00000","1.11569","0.80521","0.05001"
"0.80521","1.11907","12.62083","152.26200","0.00000","1.11907","0.80521","0.05001"
"0.80521","1.12680","12.70799","152.66200","0.00000","1.12680","0.80521","0.05001"
"0.80521","1.12628","12.70212","153.06200","0.00000","1.12628","0.80521","0.05001"
"0.80521","1.12125","12.64544","153.46200","0.00000","1.12125","0.80521","0.05001"
"0.80521","1.12231","12.65745","153.86200","0.00000","1.12231","0.80521","0.05001"
"0.80521","1.12607","12.69981","154.26200","0.00000","1.12607","0.80521","0.05001"
"0.80521","1.12291","12.66411","154.66200","0.00000","1.12291","0.80521","0.05001"
"0.80521","1.12687","12.70887","155.06200","0.00000","1.12687","0.80521","0.05001"
"0.80521","1.12214","12.65549","155.46200","0.00000","1.12214","0.80521","0.05001"
"0.80521","1.12724","12.71300","155.86200","0.00000","1.12724","0.80521","0.05001"
"0.80521","1.13092","12.75445","156.26200","0.00000","1.13092","0.80521","0.05001"
"0.80521","1.13009","12.74513","156.66200","0.00000","1.13009","0.80521","0.05001"
"0.80521","1.13179","12.76433","157.06200","0.00000","1.13179","0.80521","0.05001"
"0.80521","1.12798","12.72131","157.46200","0.00000","1.12798","0.80521","0.05001"
"0.80521","1.12397","12.67612","157.86200","0.00000","1.12397","0.80521","0.05001"
"0.80521","1.13367","12.78551","158.26200","0.00000","1.13367","0.80521","0.05001"
"0.80521","1.13084","12.75363","158.66200","0.00000","1.13084","0.80521","0.05001"
"0.80521","1.13550","12.80614","159.06200","0.00000","1.13550","0.80521","0.05001"
"0.80521","1.13131","12.75894","159.46200","0.00000","1.13131","0.80521","0.05001"
"0.80521","1.14009","12.85795","159.86200","0.00000","1.14009","0.80521","0.05001"
"0.80521","1.12669","12.70675","160.26200","0.00000","1.12669","0.80521","0.05001"
"0.80521","1.13976","12.85423","160.66200","0.00000","1.13976","0.80521","0.05001"
"0.80521","1.13508","12.80141","161.06200","0.00000","1.13508","0.80521","0.05001"
"0.80521","1.13380","12.78700","161.46200","0.00000","1.13380","0.80521","0.05001"
"0.80521","1.13957","12.85204","161.86200","0.00000","1.13957","0.80521","0.05001"
"0.80521","1.13937","12.84985","162.26200","0.00000","1.13937","0.80521","0.05001"
"0.80521","1.13232","12.77030","162.66200","0.00000","1.13232","0.80521","0.05001"
"0.80521","1.14110","12.86932","163.06200","0.00000","1.14110","0.80521","0.05001"
"0.80521","1.13695","12.82249","163.46200","0.00000","1.13695","0.80521","0.05001"
"0.80521","1.14172","12.87630","163.86200","0.00000","1.14172","0.80521","0.05001"
"0.80521","1.13333","12.78169","164.26200","0.00000","1.13333","0.80521","0.05001"
"0.80521","1.14037","12.86109","164.66200","0.00000","1.14037","0.80521","0.05001"
"0.80521","1.13832","12.83794","165.06200","0.00000","1.13832","0.80521","0.05001"
"0.80521","1.13503","12.80089","165.46200","0.00000","1.13503","0.80521","0.05001"
"0.80521","1.14058","12.86345","165.86200","0.00000","1.14058","0.80521","0.05001"
"0.80521","1.13539","12.80489","166.26200","0.00000","1.13539","0.80521","0.05001"
"0.80521","1.13721","12.82538","166.66200","0.00000","1.13721","0.80521","0.05001"
"0.80521","1.13316","12.77972","167.06200","0.00000","1.13316","0.80521","0.05001"
"0.80521","1.14240","12.88400","167.46200","0.00000","1.14240","0.80521","0.05001"
"0.80521","1.13720","12.82537","167.86200","0.00000","1.13720","0.80521","0.05001"
"0.80521","1.13975","12.85406","168.26200","0.00000","1.13975","0.80521","0.05001"
"0.80521","1.13356","12.78431","168.66200","0.00000","1.13356","0.80521","0.05001"
"0.80521","1.12887","12.73142","169.06200","0.00000","1.12887","0.80521","0.05001"
"0.80521","1.14256","12.88573","169.46200","0.00000","1.14256","0.80521","0.05001"
"0.80521","1.13738","12.82734","169.86200","0.00000","1.13738","0.80521","0.05001"
"0.80521","1.14491","12.91232","170.26200","0.00000","1.14491","0.80521","0.05001"
"0.80521","1.14032","12.86052","170.66200","0.00000","1.14032","0.80521","0.05001"
"0.80521","1.14043","12.86178","171.06200","0.00000","1.14043","0.80521","0.05001"
"0.80521","1.13743","12.82789","171.46200","0.00000","1.13743","0.80521","0.05001"
"0.80521","1.14189","12.87820","171.86200","0.00000","1.14189","0.80521","0.05001"
"0.80521","1.14596","12.92408","172.26200","0.00000","1.14596","0.80521","0.05001"
"0.80521","1.14592","12.92362","172.66200","0.00000","1.14592","0.80521","0.05001"
"0.80521","1.14529","12.91661","173.06200","0.00000","1.14529","0.80521","0.05001"
"0.80521","1.14686","12.93430","173.46200","0.00000","1.14686","0.80521","0.05001"
"0.80521","1.14564","12.92053","173.86200","0.00000","1.14564","0.80521","0.05001"
"0.80521","1.14068","12.86456","174.26200","0.00000","1.14068","0.80521","0.05001"
"0.80521","1.14411","12.90327","174.66200","0.00000","1.14411","0.80521","0.05001"
"0.80521","1.14539","12.91770","175.06200","0.00000","1.14539","0.80521","0.05001"
"0.80521","1.15160","12.98773","175.46200","0.00000","1.15160","0.80521","0.05001"
"0.80521","1.14875","12.95563","175.86200","0.00000","1.14875","0.80521","0.05001"
"0.80521","1.15198","12.99197","176.26200","0.00000","1.15198","0.80521","0.05001"
"0.80521","1.14118","12.87019","176.66200","0.00000","1.14118","0.80521","0.05001"
"0.80521","1.15135","12.98493","177.06200","0.00000","1.15135","0.80521","0.05001"
"0.80521","1.15587","13.03584","177.46200","0.00000","1.15587","0.80521","0.05001"
"0.80521","1.14895","12.95781","177.86200","0.00000","1.14895","0.80521","0.05001"
"0.80521","1.14626","12.92755","178.26200","0.00000","1.14626","0.80521","0.05001"
"0.80521","1.15246","12.99747","178.66200","0.00000","1.15246","0.80521","0.05001"
"0.80521","1.14477","12.91071","179.06200","0.00000","1.14477","0.80521","0.05001"
"0.80521","1.14734","12.93966","179.46200","0.00000","1.14734","0.80521","0.05001"
"0.80521","1.15264","12.99944","179.86200","0.00000","1.15264","0.80521","0.05001"
"0.80521","1.15328","13.00667","180.26200","0.00000","1.15328","0.80521","0.05001"
"0.80521","1.15646","13.04249","180.66200","0.00000","1.15646","0.80521","0.05001"
"0.80521","1.15425","13.01767","181.06200","0.00000","1.15425","0.80521","0.05001"
"0.80521","1.15069","12.97752","181.46200","0.00000","1.15069","0.80521","0.05001"
"0.80521","1.16010","13.08361","181.86200","0.00000","1.16010","0.80521","0.05001"
"0.80521","1.15381","13.01269","182.26200","0.00000","1.15381","0.80521","0.05001"
"0.80521","1.15556","13.03235","182.66200","0.00000","1.15556","0.80521","0.05001"
"0.80521","1.15835","13.06380","183.06200","0.00000","1.15835","0.80521","0.05001"
"0.80521","1.15050","12.97529","183.46200","0.00000","1.15050","0.80521","0.05001"
"0.80521","1.15224","12.99495","183.86200","0.00000","1.15224","0.80521","0.05001"
"0.80521","1.15746","13.05377","184.26200","0.00000","1.15746","0.80521","0.05001"
"0.80521","1.16240","13.10958","184.66200","0.00000","1.16240","0.80521","0.05001"
"0.80521","1.15430","13.01814","185.06200","0.00000","1.15430","0.80521","0.05001"
"0.80521","1.16305","13.11682","185.46200","0.00000","1.16305","0.80521","0.05001"
"0.80521","1.15548","13.03149","185.86200","0.00000","1.15548","0.80521","0.05001"
"0.80521","1.15873","13.06809","186.26200","0.00000","1.15873","0.80521","0.05001"
"0.80521","1.15143","12.98577","186.66200","0.00000","1.15143","0.80521","0.05001"
"0.80521","1.15858","13.06651","187.06200","0.00000","1.15858","0.80521","0.05001"
"0.80521","1.15939","13.07558","187.46200","0.00000","1.15939","0.80521","0.05001"
"0.80521","1.15853","13.06584","187.86200","0.00000","1.15853","0.80521","0.05001"
"0.80521","1.15103","12.98131","188.26200","0.00000","1.15103","0.80521","0.05001"
"0.80521","1.15511","13.02728","188.66200","0.00000","1.15511","0.80521","0.05001"
"0.80521","1.15694","13.04797","189.06200","0.00000","1.15694","0.80521","0.05001"
"0.80521","1.16149","13.09931","189.46200","0.00000","1.16149","0.80521","0.05001"
"0.80521","1.16172","13.10191","189.66200","0.00000","1.16172","0.80521","0.05001"