File: G2- Fresh test to failure-20210318/Specimen_RawData_5.csv
Specimen properties : Specimen label,"sample-5"
Specimen properties : Length,"25.77000",mm
Specimen properties : Diameter,"0.27600",mm
Test : Rate 1,"5.00000",mm/min

Extension,Load,Tensile stress,Time,PIP count,Tenacity,Tensile extension,Tensile strain (Extension)
(mm),(N),(MPa),(s),,(N/tex),(mm),(mm/mm)
"0.00000","0.00799","0.13349","0.00000","0.00000","0.00799","0.00000","0.00000"
"0.00000","0.00048","0.00803","0.02000","0.00000","0.00048","0.00000","0.00000"
"0.00000","0.00076","0.01272","0.04000","0.00000","0.00076","0.00000","0.00000"
"0.00062","0.00467","0.07810","0.06000","0.00000","0.00467","0.00062","0.00002"
"0.00083","0.00790","0.13203","0.08000","0.00000","0.00790","0.00083","0.00003"
"0.00125","0.00638","0.10659","0.10000","0.00000","0.00638","0.00125","0.00005"
"0.00187","0.00504","0.08432","0.12000","0.00000","0.00504","0.00187","0.00007"
"0.00271","0.00967","0.16168","0.14000","0.00000","0.00967","0.00271","0.00011"
"0.00375","0.01300","0.21730","0.16000","0.00000","0.01300","0.00375","0.00015"
"0.00500","0.01559","0.26058","0.18000","0.00000","0.01559","0.00500","0.00019"
"0.00667","0.01775","0.29661","0.20000","0.00000","0.01775","0.00667","0.00026"
"0.00854","0.02358","0.39417","0.22000","0.00000","0.02358","0.00854","0.00033"
"0.01062","0.03175","0.53071","0.24000","0.00000","0.03175","0.01062","0.00041"
"0.01292","0.04401","0.73566","0.26000","0.00000","0.04401","0.01292","0.00050"
"0.01521","0.05286","0.88355","0.28000","0.00000","0.05286","0.01521","0.00059"
"0.01750","0.06033","1.00844","0.30000","0.00000","0.06033","0.01750","0.00068"
"0.01979","0.06378","1.06605","0.32000","0.00000","0.06378","0.01979","0.00077"
"0.02208","0.06768","1.13115","0.34000","0.00000","0.06768","0.02208","0.00086"
"0.02417","0.06892","1.15196","0.36000","0.00000","0.06892","0.02417","0.00094"
"0.02646","0.07510","1.25530","0.38000","0.00000","0.07510","0.02646","0.00103"
"0.02875","0.08132","1.35915","0.40000","0.00000","0.08132","0.02875","0.00112"
"0.03104","0.09058","1.51405","0.42000","0.00000","0.09058","0.03104","0.00120"
"0.03312","0.09733","1.62690","0.44000","0.00000","0.09733","0.03312","0.00129"
"0.03521","0.10185","1.70234","0.46000","0.00000","0.10185","0.03521","0.00137"
"0.03750","0.11560","1.93227","0.48000","0.00000","0.11560","0.03750","0.00146"
"0.03958","0.12347","2.06377","0.50000","0.00000","0.12347","0.03958","0.00154"
"0.04167","0.12960","2.16624","0.52000","0.00000","0.12960","0.04167","0.00162"
"0.04354","0.13081","2.18639","0.54000","0.00000","0.13081","0.04354","0.00169"
"0.04542","0.13418","2.24271","0.56000","0.00000","0.13418","0.04542","0.00176"
"0.04729","0.14622","2.44391","0.58000","0.00000","0.14622","0.04729","0.00184"
"0.04917","0.15848","2.64893","0.60000","0.00000","0.15848","0.04917","0.00191"
"0.05083","0.15857","2.65038","0.62000","0.00000","0.15857","0.05083","0.00197"
"0.05250","0.15893","2.65643","0.64000","0.00000","0.15893","0.05250","0.00204"
"0.05417","0.16170","2.70270","0.66000","0.00000","0.16170","0.05417","0.00210"
"0.05583","0.16869","2.81949","0.68000","0.00000","0.16869","0.05583","0.00217"
"0.05750","0.17679","2.95493","0.70000","0.00000","0.17679","0.05750","0.00223"
"0.05937","0.18063","3.01907","0.72000","0.00000","0.18063","0.05937","0.00230"
"0.06104","0.18364","3.06943","0.74000","0.00000","0.18364","0.06104","0.00237"
"0.06271","0.18602","3.10920","0.76000","0.00000","0.18602","0.06271","0.00243"
"0.06437","0.19303","3.22646","0.78000","0.00000","0.19303","0.06437","0.00250"
"0.06604","0.20395","3.40899","0.80000","0.00000","0.20395","0.06604","0.00256"
"0.06771","0.20327","3.39757","0.82000","0.00000","0.20327","0.06771","0.00263"
"0.06937","0.20553","3.43532","0.84000","0.00000","0.20553","0.06937","0.00269"
"0.07125","0.20725","3.46406","0.86000","0.00000","0.20725","0.07125","0.00276"
"0.07292","0.21301","3.56035","0.88000","0.00000","0.21301","0.07292","0.00283"
"0.07458","0.22513","3.76297","0.90000","0.00000","0.22513","0.07458","0.00289"
"0.07646","0.22732","3.79953","0.92000","0.00000","0.22732","0.07646","0.00297"
"0.07833","0.23139","3.86748","0.94000","0.00000","0.23139","0.07833","0.00304"
"0.08021","0.23792","3.97672","0.96000","0.00000","0.23792","0.08021","0.00311"
"0.08208","0.24087","4.02598","0.98000","0.00000","0.24087","0.08208","0.00319"
"0.08375","0.24574","4.10748","1.00000","0.00000","0.24574","0.08375","0.00325"
"0.08542","0.24893","4.16065","1.02000","0.00000","0.24893","0.08542","0.00331"
"0.08708","0.25822","4.31600","1.04000","0.00000","0.25822","0.08708","0.00338"
"0.08896","0.27032","4.51833","1.06000","0.00000","0.27032","0.08896","0.00345"
"0.09042","0.27198","4.54603","1.08000","0.00000","0.27198","0.09042","0.00351"
"0.09208","0.27188","4.54439","1.10000","0.00000","0.27188","0.09208","0.00357"
"0.09354","0.27563","4.60702","1.12000","0.00000","0.27563","0.09354","0.00363"
"0.09521","0.27790","4.64501","1.14000","0.00000","0.27790","0.09521","0.00369"
"0.09667","0.27599","4.61304","1.16000","0.00000","0.27599","0.09667","0.00375"
"0.09833","0.28415","4.74935","1.18000","0.00000","0.28415","0.09833","0.00382"
"0.10000","0.29241","4.88755","1.20000","0.00000","0.29241","0.10000","0.00388"
"0.10146","0.29263","4.89113","1.22000","0.00000","0.29263","0.10146","0.00394"
"0.10333","0.29503","4.93131","1.24000","0.00000","0.29503","0.10333","0.00401"
"0.10500","0.30270","5.05946","1.26000","0.00000","0.30270","0.10500","0.00407"
"0.10667","0.30812","5.14998","1.28000","0.00000","0.30812","0.10667","0.00414"
"0.10833","0.31403","5.24884","1.30000","0.00000","0.31403","0.10833","0.00420"
"0.11000","0.31933","5.33749","1.32000","0.00000","0.31933","0.11000","0.00427"
"0.11167","0.32345","5.40623","1.34000","0.00000","0.32345","0.11167","0.00433"
"0.11333","0.32372","5.41088","1.36000","0.00000","0.32372","0.11333","0.00440"
"0.11500","0.32587","5.44680","1.38000","0.00000","0.32587","0.11500","0.00446"
"0.11687","0.33255","5.55833","1.40000","0.00000","0.33255","0.11687","0.00454"
"0.11854","0.33989","5.68106","1.42000","0.00000","0.33989","0.11854","0.00460"
"0.12021","0.34574","5.77882","1.44000","0.00000","0.34574","0.12021","0.00466"
"0.12208","0.34787","5.81454","1.46000","0.00000","0.34787","0.12208","0.00474"
"0.12375","0.35171","5.87870","1.48000","0.00000","0.35171","0.12375","0.00480"
"0.12542","0.35638","5.95676","1.50000","0.00000","0.35638","0.12542","0.00487"
"0.12708","0.36075","6.02967","1.52000","0.00000","0.36075","0.12708","0.00493"
"0.12875","0.35862","5.99421","1.54000","0.00000","0.35862","0.12875","0.00500"
"0.13042","0.36424","6.08805","1.56000","0.00000","0.36424","0.13042","0.00506"
"0.13208","0.36943","6.17478","1.58000","0.00000","0.36943","0.13208","0.00513"
"0.13354","0.37330","6.23956","1.60000","0.00000","0.37330","0.13354","0.00518"
"0.13500","0.37750","6.30971","1.62000","0.00000","0.37750","0.13500","0.00524"
"0.13667","0.38669","6.46326","1.64000","0.00000","0.38669","0.13667","0.00530"
"0.13833","0.39054","6.52768","1.66000","0.00000","0.39054","0.13833","0.00537"
"0.14000","0.38684","6.46583","1.68000","0.00000","0.38684","0.14000","0.00543"
"0.14146","0.39013","6.52079","1.70000","0.00000","0.39013","0.14146","0.00549"
"0.14312","0.39040","6.52530","1.72000","0.00000","0.39040","0.14312","0.00555"
"0.14479","0.39611","6.62079","1.74000","0.00000","0.39611","0.14479","0.00562"
"0.14646","0.40160","6.71253","1.76000","0.00000","0.40160","0.14646","0.00568"
"0.14812","0.39979","6.68225","1.78000","0.00000","0.39979","0.14812","0.00575"
"0.14979","0.40154","6.71154","1.80000","0.00000","0.40154","0.14979","0.00581"
"0.15146","0.40569","6.78086","1.82000","0.00000","0.40569","0.15146","0.00588"
"0.15312","0.41517","6.93941","1.84000","0.00000","0.41517","0.15312","0.00594"
"0.15479","0.42576","7.11634","1.86000","0.00000","0.42576","0.15479","0.00601"
"0.15667","0.43115","7.20645","1.88000","0.00000","0.43115","0.15667","0.00608"
"0.15833","0.42265","7.06441","1.90000","0.00000","0.42265","0.15833","0.00614"
"0.16021","0.42485","7.10106","1.92000","0.00000","0.42485","0.16021","0.00622"
"0.16187","0.43166","7.21496","1.94000","0.00000","0.43166","0.16187","0.00628"
"0.16354","0.43246","7.22830","1.96000","0.00000","0.43246","0.16354","0.00635"
"0.16521","0.43536","7.27673","1.98000","0.00000","0.43536","0.16521","0.00641"
"0.16687","0.43424","7.25813","2.00000","0.00000","0.43424","0.16687","0.00648"
"0.16854","0.43495","7.27002","2.02000","0.00000","0.43495","0.16854","0.00654"
"0.17021","0.36202","6.05100","2.04000","0.00000","0.36202","0.17021","0.00660"
"0.17187","0.20534","3.43213","2.06000","0.00000","0.20534","0.17187","0.00667"
"0.17354","0.12407","2.07384","2.08000","0.00000","0.12407","0.17354","0.00673"
"0.17500","0.11133","1.86075","2.10000","0.00000","0.11133","0.17500","0.00679"
"0.17667","0.11824","1.97626","2.12000","0.00000","0.11824","0.17667","0.00686"
"0.17833","0.12920","2.15944","2.14000","0.00000","0.12920","0.17833","0.00692"
"0.18000","0.12553","2.09821","2.16000","0.00000","0.12553","0.18000","0.00698"
"0.18167","0.12687","2.12058","2.18000","0.00000","0.12687","0.18167","0.00705"
"0.18333","0.12177","2.03531","2.20000","0.00000","0.12177","0.18333","0.00711"
"0.18500","0.12355","2.06506","2.22000","0.00000","0.12355","0.18500","0.00718"
"0.18667","0.12809","2.14100","2.24000","0.00000","0.12809","0.18667","0.00724"
"0.18833","0.13125","2.19379","2.26000","0.00000","0.13125","0.18833","0.00731"
"0.19000","0.13290","2.22128","2.28000","0.00000","0.13290","0.19000","0.00737"
"0.19167","0.12812","2.14147","2.30000","0.00000","0.12812","0.19167","0.00744"
"0.19333","0.12727","2.12726","2.32000","0.00000","0.12727","0.19333","0.00750"
"0.19500","0.13064","2.18358","2.34000","0.00000","0.13064","0.19500","0.00757"
"0.19667","0.12741","2.12966","2.36000","0.00000","0.12741","0.19667","0.00763"
"0.19854","0.12953","2.16498","2.38000","0.00000","0.12953","0.19854","0.00770"
"0.20021","0.14213","2.37557","2.40000","0.00000","0.14213","0.20021","0.00777"
"0.20208","0.14869","2.48523","2.42000","0.00000","0.14869","0.20208","0.00784"
"0.20375","0.15257","2.55006","2.44000","0.00000","0.15257","0.20375","0.00791"
"0.20562","0.14982","2.50413","2.46000","0.00000","0.14982","0.20562","0.00798"
"0.20729","0.15013","2.50939","2.48000","0.00000","0.15013","0.20729","0.00804"
"0.20896","0.15136","2.52994","2.50000","0.00000","0.15136","0.20896","0.00811"
"0.21062","0.14807","2.47498","2.52000","0.00000","0.14807","0.21062","0.00817"
"0.21229","0.14842","2.48076","2.54000","0.00000","0.14842","0.21229","0.00824"
"0.21375","0.15190","2.53900","2.56000","0.00000","0.15190","0.21375","0.00829"
"0.21542","0.15358","2.56698","2.58000","0.00000","0.15358","0.21542","0.00836"
"0.21708","0.15652","2.61612","2.60000","0.00000","0.15652","0.21708","0.00842"
"0.21875","0.15848","2.64883","2.62000","0.00000","0.15848","0.21875","0.00849"
"0.22042","0.15942","2.66468","2.64000","0.00000","0.15942","0.22042","0.00855"
"0.22208","0.16375","2.73702","2.66000","0.00000","0.16375","0.22208","0.00862"
"0.22375","0.16110","2.69274","2.68000","0.00000","0.16110","0.22375","0.00868"
"0.22542","0.16658","2.78430","2.70000","0.00000","0.16658","0.22542","0.00875"
"0.22708","0.16877","2.82092","2.72000","0.00000","0.16877","0.22708","0.00881"
"0.22875","0.17509","2.92649","2.74000","0.00000","0.17509","0.22875","0.00888"
"0.23021","0.18046","3.01621","2.76000","0.00000","0.18046","0.23021","0.00893"
"0.23187","0.18167","3.03648","2.78000","0.00000","0.18167","0.23187","0.00900"
"0.23354","0.18010","3.01023","2.80000","0.00000","0.18010","0.23354","0.00906"
"0.23542","0.18196","3.04132","2.82000","0.00000","0.18196","0.23542","0.00914"
"0.23708","0.18676","3.12151","2.84000","0.00000","0.18676","0.23708","0.00920"
"0.23875","0.18532","3.09755","2.86000","0.00000","0.18532","0.23875","0.00926"
"0.24042","0.18824","3.14629","2.88000","0.00000","0.18824","0.24042","0.00933"
"0.24208","0.19332","3.23121","2.90000","0.00000","0.19332","0.24208","0.00939"
"0.24375","0.19735","3.29859","2.92000","0.00000","0.19735","0.24375","0.00946"
"0.24542","0.19757","3.30231","2.94000","0.00000","0.19757","0.24542","0.00952"
"0.24708","0.19748","3.30071","2.96000","0.00000","0.19748","0.24708","0.00959"
"0.24896","0.19944","3.33348","2.98000","0.00000","0.19944","0.24896","0.00966"
"0.25062","0.20108","3.36093","3.00000","0.00000","0.20108","0.25062","0.00973"
"0.25208","0.20206","3.37738","3.02000","0.00000","0.20206","0.25208","0.00978"
"0.25375","0.20162","3.36997","3.04000","0.00000","0.20162","0.25375","0.00985"
"0.25521","0.20679","3.45636","3.06000","0.00000","0.20679","0.25521","0.00990"
"0.25687","0.20969","3.50485","3.08000","0.00000","0.20969","0.25687","0.00997"
"0.25854","0.21620","3.61360","3.10000","0.00000","0.21620","0.25854","0.01003"
"0.26021","0.21589","3.60846","3.12000","0.00000","0.21589","0.26021","0.01010"
"0.26187","0.21310","3.56182","3.14000","0.00000","0.21310","0.26187","0.01016"
"0.26354","0.20824","3.48068","3.16000","0.00000","0.20824","0.26354","0.01023"
"0.26500","0.21365","3.57099","3.18000","0.00000","0.21365","0.26500","0.01028"
"0.26667","0.22011","3.67907","3.20000","0.00000","0.22011","0.26667","0.01035"
"0.26833","0.22537","3.76699","3.22000","0.00000","0.22537","0.26833","0.01041"
"0.27000","0.22859","3.82070","3.24000","0.00000","0.22859","0.27000","0.01048"
"0.27167","0.22672","3.78943","3.26000","0.00000","0.22672","0.27167","0.01054"
"0.27333","0.22978","3.84066","3.28000","0.00000","0.22978","0.27333","0.01061"
"0.27500","0.23685","3.95881","3.30000","0.00000","0.23685","0.27500","0.01067"
"0.27667","0.23901","3.99496","3.32000","0.00000","0.23901","0.27667","0.01074"
"0.27854","0.24153","4.03707","3.34000","0.00000","0.24153","0.27854","0.01081"
"0.28021","0.24420","4.08166","3.36000","0.00000","0.24420","0.28021","0.01087"
"0.28187","0.23614","3.94699","3.38000","0.00000","0.23614","0.28187","0.01094"
"0.28354","0.11626","1.94326","3.40000","0.00000","0.11626","0.28354","0.01100"
"0.28521","0.02961","0.49495","3.42000","0.00000","0.02961","0.28521","0.01107"
"0.28708","0.00028","0.00471","3.44000","0.00000","0.00028","0.28708","0.01114"
"0.28875","0.00223","0.03730","3.46000","0.00000","0.00223","0.28875","0.01120"
"0.29062","0.01603","0.26788","3.48000","0.00000","0.01603","0.29062","0.01128"
"0.29208","0.02115","0.35349","3.50000","0.00000","0.02115","0.29208","0.01133"
"0.29396","0.01578","0.26370","3.52000","0.00000","0.01578","0.29396","0.01141"
"0.29542","0.01363","0.22781","3.54000","0.00000","0.01363","0.29542","0.01146"
"0.29708","0.01891","0.31605","3.56000","0.00000","0.01891","0.29708","0.01153"
"0.29875","0.01788","0.29878","3.58000","0.00000","0.01788","0.29875","0.01159"
"0.30042","0.01963","0.32812","3.60000","0.00000","0.01963","0.30042","0.01166"
"0.30208","0.02218","0.37077","3.62000","0.00000","0.02218","0.30208","0.01172"
"0.30375","0.01826","0.30519","3.64000","0.00000","0.01826","0.30375","0.01179"
"0.30542","0.01977","0.33044","3.66000","0.00000","0.01977","0.30542","0.01185"
"0.30687","0.02372","0.39643","3.68000","0.00000","0.02372","0.30687","0.01191"
"0.30854","0.02507","0.41898","3.70000","0.00000","0.02507","0.30854","0.01197"
"0.31021","0.02407","0.40226","3.72000","0.00000","0.02407","0.31021","0.01204"
"0.31187","0.02473","0.41338","3.74000","0.00000","0.02473","0.31187","0.01210"
"0.31354","0.02723","0.45513","3.76000","0.00000","0.02723","0.31354","0.01217"
"0.31521","0.02091","0.34945","3.78000","0.00000","0.02091","0.31521","0.01223"
"0.31687","0.02741","0.45815","3.80000","0.00000","0.02741","0.31687","0.01230"
"0.31854","0.02925","0.48886","3.82000","0.00000","0.02925","0.31854","0.01236"
"0.32021","0.02004","0.33493","3.84000","0.00000","0.02004","0.32021","0.01243"
"0.32187","-0.03362","-0.56189","3.86000","0.00000","-0.03362","0.32187","0.01249"
"0.32354","-0.06309","-1.05448","3.88000","0.00000","-0.06309","0.32354","0.01255"
"0.32521","-0.06528","-1.09115","3.90000","0.00000","-0.06528","0.32521","0.01262"
"0.32687","-0.06750","-1.12816","3.92000","0.00000","-0.06750","0.32687","0.01268"
"0.32854","-0.06854","-1.14554","3.94000","0.00000","-0.06854","0.32854","0.01275"
"0.33021","-0.06954","-1.16240","3.96000","0.00000","-0.06954","0.33021","0.01281"
"0.33187","-0.06763","-1.13043","3.98000","0.00000","-0.06763","0.33187","0.01288"
"0.33354","-0.07197","-1.20294","4.00000","0.00000","-0.07197","0.33354","0.01294"
"0.33521","-0.07152","-1.19542","4.02000","0.00000","-0.07152","0.33521","0.01301"
"0.33687","-0.06776","-1.13257","4.04000","0.00000","-0.06776","0.33687","0.01307"
"0.33833","-0.06254","-1.04533","4.06000","0.00000","-0.06254","0.33833","0.01313"
"0.34000","-0.06247","-1.04411","4.08000","0.00000","-0.06247","0.34000","0.01319"
"0.34167","-0.06426","-1.07413","4.10000","0.00000","-0.06426","0.34167","0.01326"
"0.34333","-0.06341","-1.05989","4.12000","0.00000","-0.06341","0.34333","0.01332"
"0.34500","-0.06360","-1.06312","4.14000","0.00000","-0.06360","0.34500","0.01339"
"0.34667","-0.05919","-0.98929","4.16000","0.00000","-0.05919","0.34667","0.01345"
"0.34833","-0.05569","-0.93088","4.18000","0.00000","-0.05569","0.34833","0.01352"
"0.35000","-0.05061","-0.84588","4.20000","0.00000","-0.05061","0.35000","0.01358"
"0.35167","-0.04833","-0.80779","4.22000","0.00000","-0.04833","0.35167","0.01365"
"0.35333","-0.04999","-0.83554","4.24000","0.00000","-0.04999","0.35333","0.01371"
"0.35500","-0.05077","-0.84861","4.26000","0.00000","-0.05077","0.35500","0.01378"
"0.35687","-0.04690","-0.78388","4.28000","0.00000","-0.04690","0.35687","0.01385"
"0.35854","-0.04197","-0.70149","4.30000","0.00000","-0.04197","0.35854","0.01391"
"0.36000","-0.04674","-0.78125","4.32000","0.00000","-0.04674","0.36000","0.01397"
"0.36167","-0.04690","-0.78383","4.34000","0.00000","-0.04690","0.36167","0.01403"
"0.36333","-0.04755","-0.79469","4.36000","0.00000","-0.04755","0.36333","0.01410"
"0.36500","-0.04208","-0.70336","4.38000","0.00000","-0.04208","0.36500","0.01416"
"0.36667","-0.04127","-0.68975","4.40000","0.00000","-0.04127","0.36667","0.01423"
"0.36833","-0.04269","-0.71361","4.42000","0.00000","-0.04269","0.36833","0.01429"
"0.37000","-0.03904","-0.65261","4.44000","0.00000","-0.03904","0.37000","0.01436"
"0.37167","-0.03467","-0.57946","4.46000","0.00000","-0.03467","0.37167","0.01442"
"0.37333","-0.03059","-0.51129","4.48000","0.00000","-0.03059","0.37333","0.01449"
"0.37500","-0.03363","-0.56215","4.50000","0.00000","-0.03363","0.37500","0.01455"
"0.37687","-0.03075","-0.51398","4.52000","0.00000","-0.03075","0.37687","0.01462"
"0.37854","-0.02761","-0.46140","4.54000","0.00000","-0.02761","0.37854","0.01469"
"0.38021","-0.03131","-0.52334","4.56000","0.00000","-0.03131","0.38021","0.01475"
"0.38187","-0.02492","-0.41658","4.58000","0.00000","-0.02492","0.38187","0.01482"
"0.38354","-0.01537","-0.25687","4.60000","0.00000","-0.01537","0.38354","0.01488"
"0.38521","-0.01728","-0.28887","4.62000","0.00000","-0.01728","0.38521","0.01495"
"0.38687","-0.01773","-0.29627","4.64000","0.00000","-0.01773","0.38687","0.01501"
"0.38854","-0.01713","-0.28629","4.66000","0.00000","-0.01713","0.38854","0.01508"
"0.39021","-0.01531","-0.25589","4.68000","0.00000","-0.01531","0.39021","0.01514"
"0.39187","-0.01353","-0.22615","4.70000","0.00000","-0.01353","0.39187","0.01521"
"0.39354","-0.00696","-0.11630","4.72000","0.00000","-0.00696","0.39354","0.01527"
"0.39521","-0.00891","-0.14894","4.74000","0.00000","-0.00891","0.39521","0.01534"
"0.39687","-0.00689","-0.11511","4.76000","0.00000","-0.00689","0.39687","0.01540"
"0.39854","-0.00652","-0.10900","4.78000","0.00000","-0.00652","0.39854","0.01547"
"0.40021","-0.00703","-0.11748","4.80000","0.00000","-0.00703","0.40021","0.01553"
"0.40187","0.00098","0.01644","4.82000","0.00000","0.00098","0.40187","0.01559"
"0.40354","0.00264","0.04414","4.84000","0.00000","0.00264","0.40354","0.01566"
"0.40521","0.00372","0.06222","4.86000","0.00000","0.00372","0.40521","0.01572"
"0.40687","-0.00336","-0.05615","4.88000","0.00000","-0.00336","0.40687","0.01579"
"0.40854","-0.00513","-0.08568","4.90000","0.00000","-0.00513","0.40854","0.01585"
"0.41021","-0.00604","-0.10092","4.92000","0.00000","-0.00604","0.41021","0.01592"
"0.41187","0.00319","0.05330","4.94000","0.00000","0.00319","0.41187","0.01598"
"0.41354","0.00503","0.08403","4.96000","0.00000","0.00503","0.41354","0.01605"
"0.41542","-0.00078","-0.01301","4.98000","0.00000","-0.00078","0.41542","0.01612"
"0.41708","0.00000","0.00006","5.00000","0.00000","0.00000","0.41708","0.01618"
"0.41896","0.01197","0.20001","5.02000","0.00000","0.01197","0.41896","0.01626"
"0.42062","0.01158","0.19356","5.04000","0.00000","0.01158","0.42062","0.01632"
"0.42229","0.01422","0.23776","5.06000","0.00000","0.01422","0.42229","0.01639"
"0.42375","0.01533","0.25619","5.08000","0.00000","0.01533","0.42375","0.01644"
"0.42562","0.01807","0.30207","5.10000","0.00000","0.01807","0.42562","0.01652"
"0.42708","0.02076","0.34705","5.12000","0.00000","0.02076","0.42708","0.01657"
"0.42896","0.01333","0.22288","5.14000","0.00000","0.01333","0.42896","0.01665"
"0.43042","0.01774","0.29650","5.16000","0.00000","0.01774","0.43042","0.01670"
"0.43208","0.02190","0.36611","5.18000","0.00000","0.02190","0.43208","0.01677"
"0.43396","0.02470","0.41284","5.20000","0.00000","0.02470","0.43396","0.01684"
"0.43562","0.02351","0.39290","5.22000","0.00000","0.02351","0.43562","0.01690"
"0.43708","0.02351","0.39301","5.24000","0.00000","0.02351","0.43708","0.01696"
"0.43875","0.02488","0.41588","5.26000","0.00000","0.02488","0.43875","0.01703"
"0.44042","0.03178","0.53115","5.28000","0.00000","0.03178","0.44042","0.01709"
"0.44208","0.02799","0.46777","5.30000","0.00000","0.02799","0.44208","0.01715"
"0.44375","0.03056","0.51085","5.32000","0.00000","0.03056","0.44375","0.01722"
"0.44542","0.03393","0.56715","5.34000","0.00000","0.03393","0.44542","0.01728"
"0.44708","0.03346","0.55923","5.36000","0.00000","0.03346","0.44708","0.01735"
"0.44854","0.02820","0.47132","5.38000","0.00000","0.02820","0.44854","0.01741"
"0.45021","0.03102","0.51844","5.40000","0.00000","0.03102","0.45021","0.01747"
"0.45167","0.03593","0.60048","5.42000","0.00000","0.03593","0.45167","0.01753"
"0.45354","0.03972","0.66391","5.44000","0.00000","0.03972","0.45354","0.01760"
"0.45521","0.04012","0.67061","5.46000","0.00000","0.04012","0.45521","0.01766"
"0.45687","0.03792","0.63389","5.48000","0.00000","0.03792","0.45687","0.01773"
"0.45875","0.04430","0.74053","5.50000","0.00000","0.04430","0.45875","0.01780"
"0.46042","0.04207","0.70324","5.52000","0.00000","0.04207","0.46042","0.01787"
"0.46208","0.04371","0.73060","5.54000","0.00000","0.04371","0.46208","0.01793"
"0.46375","0.04628","0.77359","5.56000","0.00000","0.04628","0.46375","0.01800"
"0.46542","0.04820","0.80565","5.58000","0.00000","0.04820","0.46542","0.01806"
"0.46708","0.04742","0.79262","5.60000","0.00000","0.04742","0.46708","0.01813"
"0.46875","0.05183","0.86637","5.62000","0.00000","0.05183","0.46875","0.01819"
"0.47042","0.05717","0.95556","5.64000","0.00000","0.05717","0.47042","0.01825"
"0.47208","0.06017","1.00563","5.66000","0.00000","0.06017","0.47208","0.01832"
"0.47375","0.05784","0.96677","5.68000","0.00000","0.05784","0.47375","0.01838"
"0.47542","0.05448","0.91065","5.70000","0.00000","0.05448","0.47542","0.01845"
"0.47729","0.05810","0.97113","5.72000","0.00000","0.05810","0.47729","0.01852"
"0.47875","0.05400","0.90264","5.74000","0.00000","0.05400","0.47875","0.01858"
"0.48042","0.05733","0.95818","5.76000","0.00000","0.05733","0.48042","0.01864"
"0.48208","0.05876","0.98219","5.78000","0.00000","0.05876","0.48208","0.01871"
"0.48375","0.05650","0.94431","5.80000","0.00000","0.05650","0.48375","0.01877"
"0.48542","0.05776","0.96535","5.82000","0.00000","0.05776","0.48542","0.01884"
"0.48708","0.05952","0.99491","5.84000","0.00000","0.05952","0.48708","0.01890"
"0.48854","0.06020","1.00625","5.86000","0.00000","0.06020","0.48854","0.01896"
"0.49021","0.05795","0.96861","5.88000","0.00000","0.05795","0.49021","0.01902"
"0.49167","0.06366","1.06399","5.90000","0.00000","0.06366","0.49167","0.01908"
"0.49333","0.06977","1.16615","5.92000","0.00000","0.06977","0.49333","0.01914"
"0.49521","0.07481","1.25047","5.94000","0.00000","0.07481","0.49521","0.01922"
"0.49687","0.07541","1.26038","5.96000","0.00000","0.07541","0.49687","0.01928"
"0.49854","0.07477","1.24967","5.98000","0.00000","0.07477","0.49854","0.01935"
"0.50042","0.07969","1.33204","6.00000","0.00000","0.07969","0.50042","0.01942"
"0.50208","0.08429","1.40894","6.02000","0.00000","0.08429","0.50208","0.01948"
"0.50375","0.08308","1.38865","6.04000","0.00000","0.08308","0.50375","0.01955"
"0.50542","0.07922","1.32407","6.06000","0.00000","0.07922","0.50542","0.01961"
"0.50708","0.07893","1.31920","6.08000","0.00000","0.07893","0.50708","0.01968"
"0.50875","0.07505","1.25437","6.10000","0.00000","0.07505","0.50875","0.01974"
"0.51021","0.08372","1.39940","6.12000","0.00000","0.08372","0.51021","0.01980"
"0.51187","0.08825","1.47504","6.14000","0.00000","0.08825","0.51187","0.01986"
"0.51375","0.08342","1.39424","6.16000","0.00000","0.08342","0.51375","0.01994"
"0.51542","0.07824","1.30769","6.18000","0.00000","0.07824","0.51542","0.02000"
"0.51708","0.08049","1.34537","6.20000","0.00000","0.08049","0.51708","0.02007"
"0.51875","0.08565","1.43159","6.22000","0.00000","0.08565","0.51875","0.02013"
"0.52042","0.08660","1.44745","6.24000","0.00000","0.08660","0.52042","0.02019"
"0.52208","0.08504","1.42134","6.26000","0.00000","0.08504","0.52208","0.02026"
"0.52375","0.08337","1.39350","6.28000","0.00000","0.08337","0.52375","0.02032"
"0.52542","0.08497","1.42021","6.30000","0.00000","0.08497","0.52542","0.02039"
"0.52708","0.08723","1.45794","6.32000","0.00000","0.08723","0.52708","0.02045"
"0.52854","0.09004","1.50493","6.34000","0.00000","0.09004","0.52854","0.02051"
"0.53021","0.09260","1.54778","6.36000","0.00000","0.09260","0.53021","0.02057"
"0.53167","0.09210","1.53940","6.38000","0.00000","0.09210","0.53167","0.02063"
"0.53333","0.09570","1.59950","6.40000","0.00000","0.09570","0.53333","0.02070"
"0.53500","0.10123","1.69192","6.42000","0.00000","0.10123","0.53500","0.02076"
"0.53667","0.10379","1.73481","6.44000","0.00000","0.10379","0.53667","0.02083"
"0.53833","0.09918","1.65772","6.46000","0.00000","0.09918","0.53833","0.02089"
"0.54021","0.08861","1.48099","6.48000","0.00000","0.08861","0.54021","0.02096"
"0.54187","0.09311","1.55622","6.50000","0.00000","0.09311","0.54187","0.02103"
"0.54354","0.10074","1.68375","6.52000","0.00000","0.10074","0.54354","0.02109"
"0.54542","0.09650","1.61301","6.54000","0.00000","0.09650","0.54542","0.02116"
"0.54708","0.09569","1.59949","6.56000","0.00000","0.09569","0.54708","0.02123"
"0.54875","0.10152","1.69690","6.58000","0.00000","0.10152","0.54875","0.02129"
"0.55042","0.10535","1.76093","6.60000","0.00000","0.10535","0.55042","0.02136"
"0.55187","0.10683","1.78564","6.62000","0.00000","0.10683","0.55187","0.02142"
"0.55354","0.10871","1.81700","6.64000","0.00000","0.10871","0.55354","0.02148"
"0.55542","0.10624","1.77570","6.66000","0.00000","0.10624","0.55542","0.02155"
"0.55687","0.10163","1.69872","6.68000","0.00000","0.10163","0.55687","0.02161"
"0.55854","0.10487","1.75281","6.70000","0.00000","0.10487","0.55854","0.02167"
"0.56021","0.11121","1.85880","6.72000","0.00000","0.11121","0.56021","0.02174"
"0.56187","0.11127","1.85978","6.74000","0.00000","0.11127","0.56187","0.02180"
"0.56354","0.10930","1.82682","6.76000","0.00000","0.10930","0.56354","0.02187"
"0.56521","0.11274","1.88446","6.78000","0.00000","0.11274","0.56521","0.02193"
"0.56687","0.11210","1.87368","6.80000","0.00000","0.11210","0.56687","0.02200"
"0.56833","0.11179","1.86852","6.82000","0.00000","0.11179","0.56833","0.02205"
"0.57000","0.11054","1.84765","6.84000","0.00000","0.11054","0.57000","0.02212"
"0.57146","0.10756","1.79780","6.86000","0.00000","0.10756","0.57146","0.02218"
"0.57312","0.11155","1.86444","6.88000","0.00000","0.11155","0.57312","0.02224"
"0.57479","0.11124","1.85929","6.90000","0.00000","0.11124","0.57479","0.02230"
"0.57667","0.10969","1.83347","6.92000","0.00000","0.10969","0.57667","0.02238"
"0.57833","0.10299","1.72142","6.94000","0.00000","0.10299","0.57833","0.02244"
"0.58000","0.10670","1.78344","6.96000","0.00000","0.10670","0.58000","0.02251"
"0.58167","0.11056","1.84796","6.98000","0.00000","0.11056","0.58167","0.02257"
"0.58354","0.11440","1.91221","7.00000","0.00000","0.11440","0.58354","0.02264"
"0.58521","0.11472","1.91744","7.02000","0.00000","0.11472","0.58521","0.02271"
"0.58708","0.11046","1.84631","7.04000","0.00000","0.11046","0.58708","0.02278"
"0.58875","0.10878","1.81825","7.06000","0.00000","0.10878","0.58875","0.02285"
"0.59021","0.11635","1.94470","7.08000","0.00000","0.11635","0.59021","0.02290"
"0.59208","0.12126","2.02679","7.10000","0.00000","0.12126","0.59208","0.02298"
"0.59375","0.12054","2.01484","7.12000","0.00000","0.12054","0.59375","0.02304"
"0.59542","0.11799","1.97219","7.14000","0.00000","0.11799","0.59542","0.02311"
"0.59708","0.11405","1.90633","7.16000","0.00000","0.11405","0.59708","0.02317"
"0.59854","0.11925","1.99311","7.18000","0.00000","0.11925","0.59854","0.02323"
"0.60021","0.12150","2.03081","7.20000","0.00000","0.12150","0.60021","0.02329"
"0.60187","0.11913","1.99117","7.22000","0.00000","0.11913","0.60187","0.02336"
"0.60354","0.11518","1.92518","7.24000","0.00000","0.11518","0.60354","0.02342"
"0.60521","0.12307","2.05704","7.26000","0.00000","0.12307","0.60521","0.02348"
"0.60687","0.12211","2.04104","7.28000","0.00000","0.12211","0.60687","0.02355"
"0.60833","0.12216","2.04187","7.30000","0.00000","0.12216","0.60833","0.02361"
"0.61000","0.11696","1.95499","7.32000","0.00000","0.11696","0.61000","0.02367"
"0.61167","0.11885","1.98655","7.34000","0.00000","0.11885","0.61167","0.02374"
"0.61333","0.11974","2.00135","7.36000","0.00000","0.11974","0.61333","0.02380"
"0.61500","0.12818","2.14249","7.38000","0.00000","0.12818","0.61500","0.02386"
"0.61667","0.12308","2.05724","7.40000","0.00000","0.12308","0.61667","0.02393"
"0.61854","0.12250","2.04752","7.42000","0.00000","0.12250","0.61854","0.02400"
"0.62021","0.12419","2.07576","7.44000","0.00000","0.12419","0.62021","0.02407"
"0.62208","0.12515","2.09187","7.46000","0.00000","0.12515","0.62208","0.02414"
"0.62375","0.11995","2.00497","7.48000","0.00000","0.11995","0.62375","0.02420"
"0.62542","0.11740","1.96233","7.50000","0.00000","0.11740","0.62542","0.02427"
"0.62729","0.11946","1.99677","7.52000","0.00000","0.11946","0.62729","0.02434"
"0.62896","0.12459","2.08244","7.54000","0.00000","0.12459","0.62896","0.02441"
"0.63062","0.12267","2.05033","7.56000","0.00000","0.12267","0.63062","0.02447"
"0.63229","0.12098","2.02209","7.58000","0.00000","0.12098","0.63229","0.02454"
"0.63396","0.11817","1.97520","7.60000","0.00000","0.11817","0.63396","0.02460"
"0.63562","0.11643","1.94609","7.62000","0.00000","0.11643","0.63562","0.02467"
"0.63729","0.11990","2.00401","7.64000","0.00000","0.11990","0.63729","0.02473"
"0.63896","0.12028","2.01046","7.66000","0.00000","0.12028","0.63896","0.02479"
"0.64062","0.11714","1.95787","7.68000","0.00000","0.11714","0.64062","0.02486"
"0.64208","0.11758","1.96535","7.70000","0.00000","0.11758","0.64208","0.02492"
"0.64375","0.12183","2.03630","7.72000","0.00000","0.12183","0.64375","0.02498"
"0.64521","0.12328","2.06052","7.74000","0.00000","0.12328","0.64521","0.02504"
"0.64687","0.12339","2.06235","7.76000","0.00000","0.12339","0.64687","0.02510"
"0.64833","0.12067","2.01688","7.78000","0.00000","0.12067","0.64833","0.02516"
"0.65000","0.12315","2.05832","7.80000","0.00000","0.12315","0.65000","0.02522"
"0.65167","0.11819","1.97551","7.82000","0.00000","0.11819","0.65167","0.02529"
"0.65333","0.11241","1.87883","7.84000","0.00000","0.11241","0.65333","0.02535"
"0.65500","0.10821","1.80871","7.86000","0.00000","0.10821","0.65500","0.02542"
"0.65667","0.10964","1.83260","7.88000","0.00000","0.10964","0.65667","0.02548"
"0.65833","0.11339","1.89524","7.90000","0.00000","0.11339","0.65833","0.02555"
"0.66000","0.10980","1.83527","7.92000","0.00000","0.10980","0.66000","0.02561"
"0.66187","0.10200","1.70492","7.94000","0.00000","0.10200","0.66187","0.02568"
"0.66354","0.10040","1.67810","7.96000","0.00000","0.10040","0.66354","0.02575"
"0.66521","0.10994","1.83763","7.98000","0.00000","0.10994","0.66521","0.02581"
"0.66708","0.10602","1.77210","8.00000","0.00000","0.10602","0.66708","0.02589"
"0.66875","0.10275","1.71748","8.02000","0.00000","0.10275","0.66875","0.02595"
"0.67042","0.10873","1.81731","8.04000","0.00000","0.10873","0.67042","0.02602"
"0.67229","0.10647","1.77963","8.06000","0.00000","0.10647","0.67229","0.02609"
"0.67396","0.09808","1.63929","8.08000","0.00000","0.09808","0.67396","0.02615"
"0.67562","0.09709","1.62273","8.10000","0.00000","0.09709","0.67562","0.02622"
"0.67729","0.09817","1.64083","8.12000","0.00000","0.09817","0.67729","0.02628"
"0.67896","0.09933","1.66027","8.14000","0.00000","0.09933","0.67896","0.02635"
"0.68042","0.09797","1.63759","8.16000","0.00000","0.09797","0.68042","0.02640"
"0.68208","0.08887","1.48550","8.18000","0.00000","0.08887","0.68208","0.02647"
"0.68375","0.08825","1.47504","8.20000","0.00000","0.08825","0.68375","0.02653"
"0.68542","0.09186","1.53543","8.22000","0.00000","0.09186","0.68542","0.02660"
"0.68687","0.09277","1.55065","8.24000","0.00000","0.09277","0.68687","0.02665"
"0.68833","0.09372","1.56651","8.26000","0.00000","0.09372","0.68833","0.02671"
"0.69000","0.08568","1.43212","8.28000","0.00000","0.08568","0.69000","0.02678"
"0.69167","0.08500","1.42067","8.30000","0.00000","0.08500","0.69167","0.02684"
"0.69333","0.07998","1.33686","8.32000","0.00000","0.07998","0.69333","0.02690"
"0.69500","0.08264","1.38125","8.34000","0.00000","0.08264","0.69500","0.02697"
"0.69667","0.08070","1.34881","8.36000","0.00000","0.08070","0.69667","0.02703"
"0.69833","0.07183","1.20059","8.38000","0.00000","0.07183","0.69833","0.02710"
"0.70000","0.07000","1.16993","8.40000","0.00000","0.07000","0.70000","0.02716"
"0.70187","0.07008","1.17141","8.42000","0.00000","0.07008","0.70187","0.02724"
"0.70354","0.07679","1.28358","8.44000","0.00000","0.07679","0.70354","0.02730"
"0.70521","0.07657","1.27979","8.46000","0.00000","0.07657","0.70521","0.02737"
"0.70708","0.07520","1.25695","8.48000","0.00000","0.07520","0.70708","0.02744"
"0.70875","0.06931","1.15853","8.50000","0.00000","0.06931","0.70875","0.02750"
"0.71042","0.06262","1.04664","8.52000","0.00000","0.06262","0.71042","0.02757"
"0.71208","0.06521","1.08997","8.54000","0.00000","0.06521","0.71208","0.02763"
"0.71396","0.06086","1.01731","8.56000","0.00000","0.06086","0.71396","0.02771"
"0.71562","0.05887","0.98395","8.58000","0.00000","0.05887","0.71562","0.02777"
"0.71729","0.06307","1.05417","8.60000","0.00000","0.06307","0.71729","0.02783"
"0.71896","0.06335","1.05879","8.62000","0.00000","0.06335","0.71896","0.02790"
"0.72042","0.05854","0.97841","8.64000","0.00000","0.05854","0.72042","0.02796"
"0.72208","0.05521","0.92275","8.66000","0.00000","0.05521","0.72208","0.02802"
"0.72354","0.04858","0.81194","8.68000","0.00000","0.04858","0.72354","0.02808"
"0.72521","0.04108","0.68658","8.70000","0.00000","0.04108","0.72521","0.02814"
"0.72687","0.04141","0.69215","8.72000","0.00000","0.04141","0.72687","0.02821"
"0.72833","0.04387","0.73320","8.74000","0.00000","0.04387","0.72833","0.02826"
"0.73000","0.04359","0.72851","8.76000","0.00000","0.04359","0.73000","0.02833"
"0.73167","0.03914","0.65416","8.78000","0.00000","0.03914","0.73167","0.02839"
"0.73333","0.03271","0.54678","8.80000","0.00000","0.03271","0.73333","0.02846"
"0.73479","0.02845","0.47548","8.82000","0.00000","0.02845","0.73479","0.02851"
"0.73646","0.02980","0.49812","8.84000","0.00000","0.02980","0.73646","0.02858"
"0.73812","0.02518","0.42090","8.86000","0.00000","0.02518","0.73812","0.02864"
"0.73979","0.02020","0.33763","8.88000","0.00000","0.02020","0.73979","0.02871"
"0.74167","0.01851","0.30932","8.90000","0.00000","0.01851","0.74167","0.02878"
"0.74333","0.02399","0.40090","8.92000","0.00000","0.02399","0.74333","0.02884"
"0.74500","0.02138","0.35742","8.94000","0.00000","0.02138","0.74500","0.02891"
"0.74667","0.01221","0.20402","8.96000","0.00000","0.01221","0.74667","0.02897"
"0.74833","0.00745","0.12457","8.98000","0.00000","0.00745","0.74833","0.02904"
"0.75021","0.00204","0.03405","9.00000","0.00000","0.00204","0.75021","0.02911"
"0.75187","0.00205","0.03421","9.02000","0.00000","0.00205","0.75187","0.02918"
"0.75375","0.00061","0.01012","9.04000","0.00000","0.00061","0.75375","0.02925"
"0.75542","-0.00384","-0.06423","9.06000","0.00000","-0.00384","0.75542","0.02931"
"0.75708","-0.00604","-0.10098","9.08000","0.00000","-0.00604","0.75708","0.02938"
"0.75875","-0.00859","-0.14360","9.10000","0.00000","-0.00859","0.75875","0.02944"
"0.76042","-0.01119","-0.18701","9.12000","0.00000","-0.01119","0.76042","0.02951"
"0.76187","-0.01955","-0.32685","9.14000","0.00000","-0.01955","0.76187","0.02956"
"0.76354","-0.02082","-0.34801","9.16000","0.00000","-0.02082","0.76354","0.02963"
"0.76521","-0.02750","-0.45959","9.18000","0.00000","-0.02750","0.76521","0.02969"
"0.76667","-0.02514","-0.42018","9.20000","0.00000","-0.02514","0.76667","0.02975"
"0.76812","-0.03536","-0.59109","9.22000","0.00000","-0.03536","0.76812","0.02981"
"0.76979","-0.04182","-0.69903","9.24000","0.00000","-0.04182","0.76979","0.02987"
"0.77146","-0.05557","-0.92887","9.26000","0.00000","-0.05557","0.77146","0.02994"
"0.77312","-0.06917","-1.15619","9.28000","0.00000","-0.06917","0.77312","0.03000"
"0.77479","-0.07048","-1.17803","9.30000","0.00000","-0.07048","0.77479","0.03007"
"0.77646","-0.08102","-1.35425","9.32000","0.00000","-0.08102","0.77646","0.03013"
"0.77833","-0.09264","-1.54838","9.34000","0.00000","-0.09264","0.77833","0.03020"
"0.77979","-0.10204","-1.70549","9.36000","0.00000","-0.10204","0.77979","0.03026"
"0.78167","-0.10273","-1.71711","9.38000","0.00000","-0.10273","0.78167","0.03033"
"0.78333","-0.10514","-1.75739","9.40000","0.00000","-0.10514","0.78333","0.03040"
"0.78500","-0.11982","-2.00272","9.42000","0.00000","-0.11982","0.78500","0.03046"
"0.78667","-0.12457","-2.08204","9.44000","0.00000","-0.12457","0.78667","0.03053"
"0.78833","-0.13024","-2.17687","9.46000","0.00000","-0.13024","0.78833","0.03059"
"0.79021","-0.13784","-2.30395","9.48000","0.00000","-0.13784","0.79021","0.03066"
"0.79187","-0.15002","-2.50751","9.50000","0.00000","-0.15002","0.79187","0.03073"
"0.79375","-0.15825","-2.64511","9.52000","0.00000","-0.15825","0.79375","0.03080"
"0.79542","-0.15927","-2.66208","9.54000","0.00000","-0.15927","0.79542","0.03087"
"0.79729","-0.16116","-2.69364","9.56000","0.00000","-0.16116","0.79729","0.03094"
"0.79875","-0.16432","-2.74657","9.58000","0.00000","-0.16432","0.79875","0.03100"
"0.80042","-0.17114","-2.86044","9.60000","0.00000","-0.17114","0.80042","0.03106"
"0.80208","-0.17670","-2.95346","9.62000","0.00000","-0.17670","0.80208","0.03112"
"0.80375","-0.18213","-3.04417","9.64000","0.00000","-0.18213","0.80375","0.03119"
"0.80521","-0.18845","-3.14989","9.66000","0.00000","-0.18845","0.80521","0.03125"
"0.80687","-0.19354","-3.23485","9.68000","0.00000","-0.19354","0.80687","0.03131"
"0.80833","-0.19844","-3.31680","9.70000","0.00000","-0.19844","0.80833","0.03137"
"0.81000","-0.20209","-3.37789","9.72000","0.00000","-0.20209","0.81000","0.03143"
"0.81167","-0.19930","-3.33119","9.74000","0.00000","-0.19930","0.81167","0.03150"
"0.81333","-0.20433","-3.41534","9.76000","0.00000","-0.20433","0.81333","0.03156"
"0.81500","-0.20879","-3.48987","9.78000","0.00000","-0.20879","0.81500","0.03163"
"0.81667","-0.21771","-3.63884","9.80000","0.00000","-0.21771","0.81667","0.03169"
"0.81833","-0.21928","-3.66518","9.82000","0.00000","-0.21928","0.81833","0.03176"
"0.82000","-0.22884","-3.82494","9.84000","0.00000","-0.22884","0.82000","0.03182"
"0.82167","-0.23568","-3.93923","9.86000","0.00000","-0.23568","0.82167","0.03188"
"0.82354","-0.23683","-3.95854","9.88000","0.00000","-0.23683","0.82354","0.03196"
"0.82521","-0.23708","-3.96265","9.90000","0.00000","-0.23708","0.82521","0.03202"
"0.82687","-0.23775","-3.97384","9.92000","0.00000","-0.23775","0.82687","0.03209"
"0.82875","-0.24305","-4.06245","9.94000","0.00000","-0.24305","0.82875","0.03216"
"0.83042","-0.24694","-4.12753","9.96000","0.00000","-0.24694","0.83042","0.03222"
"0.83229","-0.24921","-4.16542","9.98000","0.00000","-0.24921","0.83229","0.03230"
"0.83396","-0.25031","-4.18380","10.00000","0.00000","-0.25031","0.83396","0.03236"
"0.83583","-0.24551","-4.10355","10.02000","0.00000","-0.24551","0.83583","0.03243"
"0.83750","-0.24915","-4.16439","10.04000","0.00000","-0.24915","0.83750","0.03250"
"0.83917","-0.25427","-4.24993","10.06000","0.00000","-0.25427","0.83917","0.03256"
"0.84083","-0.25885","-4.32650","10.08000","0.00000","-0.25885","0.84083","0.03263"
"0.84229","-0.26266","-4.39019","10.10000","0.00000","-0.26266","0.84229","0.03268"
"0.84396","-0.25858","-4.32195","10.12000","0.00000","-0.25858","0.84396","0.03275"
"0.84542","-0.26289","-4.39401","10.14000","0.00000","-0.26289","0.84542","0.03281"
"0.84708","-0.26930","-4.50124","10.16000","0.00000","-0.26930","0.84708","0.03287"
"0.84854","-0.26229","-4.38411","10.18000","0.00000","-0.26229","0.84854","0.03293"
"0.85021","-0.26865","-4.49033","10.20000","0.00000","-0.26865","0.85021","0.03299"
"0.85167","-0.27117","-4.53252","10.22000","0.00000","-0.27117","0.85167","0.03305"
"0.85333","-0.26859","-4.48925","10.24000","0.00000","-0.26859","0.85333","0.03311"
"0.85500","-0.26948","-4.50423","10.26000","0.00000","-0.26948","0.85500","0.03318"
"0.85667","-0.26768","-4.47416","10.28000","0.00000","-0.26768","0.85667","0.03324"
"0.85833","-0.27017","-4.51578","10.30000","0.00000","-0.27017","0.85833","0.03331"
"0.86000","-0.27099","-4.52940","10.32000","0.00000","-0.27099","0.86000","0.03337"
"0.86167","-0.26974","-4.50851","10.34000","0.00000","-0.26974","0.86167","0.03344"
"0.86333","-0.26870","-4.49123","10.36000","0.00000","-0.26870","0.86333","0.03350"
"0.86500","-0.27270","-4.55805","10.38000","0.00000","-0.27270","0.86500","0.03357"
"0.86667","-0.27590","-4.61149","10.40000","0.00000","-0.27590","0.86667","0.03363"
"0.86854","-0.27504","-4.59712","10.42000","0.00000","-0.27504","0.86854","0.03370"
"0.87021","-0.27228","-4.55104","10.44000","0.00000","-0.27228","0.87021","0.03377"
"0.87208","-0.27414","-4.58217","10.46000","0.00000","-0.27414","0.87208","0.03384"
"0.87375","-0.27670","-4.62482","10.48000","0.00000","-0.27670","0.87375","0.03391"
"0.87562","-0.27715","-4.63242","10.50000","0.00000","-0.27715","0.87562","0.03398"
"0.87729","-0.27396","-4.57901","10.52000","0.00000","-0.27396","0.87729","0.03404"
"0.87896","-0.27382","-4.57675","10.54000","0.00000","-0.27382","0.87896","0.03411"
"0.88042","-0.27549","-4.60468","10.56000","0.00000","-0.27549","0.88042","0.03416"
"0.88208","-0.27559","-4.60625","10.58000","0.00000","-0.27559","0.88208","0.03423"
"0.88375","-0.28018","-4.68305","10.60000","0.00000","-0.28018","0.88375","0.03429"
"0.88542","-0.28477","-4.75974","10.62000","0.00000","-0.28477","0.88542","0.03436"
"0.88687","-0.27763","-4.64044","10.64000","0.00000","-0.27763","0.88687","0.03442"
"0.88854","-0.27876","-4.65938","10.66000","0.00000","-0.27876","0.88854","0.03448"
"0.89000","-0.28466","-4.75798","10.68000","0.00000","-0.28466","0.89000","0.03454"
"0.89167","-0.28391","-4.74548","10.70000","0.00000","-0.28391","0.89167","0.03460"
"0.89333","-0.27656","-4.62255","10.72000","0.00000","-0.27656","0.89333","0.03467"
"0.89479","-0.28057","-4.68960","10.74000","0.00000","-0.28057","0.89479","0.03472"
"0.89646","-0.28091","-4.69522","10.76000","0.00000","-0.28091","0.89646","0.03479"
"0.89812","-0.27957","-4.67294","10.78000","0.00000","-0.27957","0.89812","0.03485"
"0.90000","-0.28112","-4.69880","10.80000","0.00000","-0.28112","0.90000","0.03492"
"0.90167","-0.28343","-4.73741","10.82000","0.00000","-0.28343","0.90167","0.03499"
"0.90333","-0.28571","-4.77545","10.84000","0.00000","-0.28571","0.90333","0.03505"
"0.90500","-0.28334","-4.73589","10.86000","0.00000","-0.28334","0.90500","0.03512"
"0.90687","-0.28420","-4.75022","10.88000","0.00000","-0.28420","0.90687","0.03519"
"0.90854","-0.28658","-4.79001","10.90000","0.00000","-0.28658","0.90854","0.03526"
"0.91042","-0.28908","-4.83182","10.92000","0.00000","-0.28908","0.91042","0.03533"
"0.91208","-0.29086","-4.86150","10.94000","0.00000","-0.29086","0.91208","0.03539"
"0.91396","-0.28776","-4.80977","10.96000","0.00000","-0.28776","0.91396","0.03547"
"0.91562","-0.29056","-4.85661","10.98000","0.00000","-0.29056","0.91562","0.03553"
"0.91750","-0.29029","-4.85199","11.00000","0.00000","-0.29029","0.91750","0.03560"
"0.91896","-0.28223","-4.71739","11.02000","0.00000","-0.28223","0.91896","0.03566"
"0.92062","-0.28764","-4.80778","11.04000","0.00000","-0.28764","0.92062","0.03572"
"0.92229","-0.29538","-4.93714","11.06000","0.00000","-0.29538","0.92229","0.03579"
"0.92375","-0.29827","-4.98536","11.08000","0.00000","-0.29827","0.92375","0.03585"
"0.92542","-0.29225","-4.88474","11.10000","0.00000","-0.29225","0.92542","0.03591"
"0.92687","-0.29348","-4.90530","11.12000","0.00000","-0.29348","0.92687","0.03597"
"0.92854","-0.29648","-4.95543","11.14000","0.00000","-0.29648","0.92854","0.03603"
"0.93000","-0.29499","-4.93059","11.16000","0.00000","-0.29499","0.93000","0.03609"
"0.93167","-0.29981","-5.01123","11.18000","0.00000","-0.29981","0.93167","0.03615"
"0.93333","-0.29491","-4.92927","11.20000","0.00000","-0.29491","0.93333","0.03622"
"0.93479","-0.29881","-4.99445","11.22000","0.00000","-0.29881","0.93479","0.03627"
"0.93646","-0.29747","-4.97201","11.24000","0.00000","-0.29747","0.93646","0.03634"
"0.93812","-0.29327","-4.90179","11.26000","0.00000","-0.29327","0.93812","0.03640"
"0.93979","-0.29503","-4.93131","11.28000","0.00000","-0.29503","0.93979","0.03647"
"0.94167","-0.29254","-4.88961","11.30000","0.00000","-0.29254","0.94167","0.03654"
"0.94333","-0.29489","-4.92884","11.32000","0.00000","-0.29489","0.94333","0.03661"
"0.94500","-0.29558","-4.94042","11.34000","0.00000","-0.29558","0.94500","0.03667"
"0.94667","-0.29789","-4.97915","11.36000","0.00000","-0.29789","0.94667","0.03674"
"0.94833","-0.29516","-4.93343","11.38000","0.00000","-0.29516","0.94833","0.03680"
"0.95000","-0.29228","-4.88534","11.40000","0.00000","-0.29228","0.95000","0.03686"
"0.95187","-0.29571","-4.94271","11.42000","0.00000","-0.29571","0.95187","0.03694"
"0.95354","-0.29950","-5.00592","11.44000","0.00000","-0.29950","0.95354","0.03700"
"0.95542","-0.30016","-5.01706","11.46000","0.00000","-0.30016","0.95542","0.03707"
"0.95708","-0.30613","-5.11679","11.48000","0.00000","-0.30613","0.95708","0.03714"
"0.95875","-0.30138","-5.03738","11.50000","0.00000","-0.30138","0.95875","0.03720"
"0.96042","-0.29614","-4.94981","11.52000","0.00000","-0.29614","0.96042","0.03727"
"0.96208","-0.29386","-4.91169","11.54000","0.00000","-0.29386","0.96208","0.03733"
"0.96375","-0.29611","-4.94926","11.56000","0.00000","-0.29611","0.96375","0.03740"
"0.96542","-0.29702","-4.96453","11.58000","0.00000","-0.29702","0.96542","0.03746"
"0.96687","-0.29793","-4.97969","11.60000","0.00000","-0.29793","0.96687","0.03752"
"0.96854","-0.30518","-5.10095","11.62000","0.00000","-0.30518","0.96854","0.03758"
"0.97000","-0.30240","-5.05440","11.64000","0.00000","-0.30240","0.97000","0.03764"
"0.97167","-0.30252","-5.05649","11.66000","0.00000","-0.30252","0.97167","0.03771"
"0.97333","-0.30519","-5.10110","11.68000","0.00000","-0.30519","0.97333","0.03777"
"0.97500","-0.30661","-5.12480","11.70000","0.00000","-0.30661","0.97500","0.03783"
"0.97646","-0.30423","-5.08501","11.72000","0.00000","-0.30423","0.97646","0.03789"
"0.97812","-0.30592","-5.11330","11.74000","0.00000","-0.30592","0.97812","0.03796"
"0.97979","-0.31020","-5.18477","11.76000","0.00000","-0.31020","0.97979","0.03802"
"0.98167","-0.30892","-5.16334","11.78000","0.00000","-0.30892","0.98167","0.03809"
"0.98333","-0.31216","-5.21759","11.80000","0.00000","-0.31216","0.98333","0.03816"
"0.98500","-0.31319","-5.23476","11.82000","0.00000","-0.31319","0.98500","0.03822"
"0.98583","-0.31232","-5.22032","11.83200","0.00000","-0.31232","0.98583","0.03826"