File: G2- Fresh test to failure-20210318/Specimen_RawData_4.csv
Specimen properties : Specimen label,"Sample-4"
Specimen properties : Length,"24.48000",mm
Specimen properties : Diameter,"0.35300",mm
Test : Rate 1,"5.00000",mm/min

Extension,Load,Tensile stress,Time,PIP count,Tenacity,Tensile extension,Tensile strain (Extension)
(mm),(N),(MPa),(s),,(N/tex),(mm),(mm/mm)
"0.00000","0.00820","0.08381","0.00000","0.00000","0.00820","0.00000","0.00000"
"0.00042","0.00282","0.02878","0.06000","0.00000","0.00282","0.00042","0.00002"
"0.00229","0.00987","0.10089","0.12000","0.00000","0.00987","0.00229","0.00009"
"0.00583","0.02716","0.27750","0.18000","0.00000","0.02716","0.00583","0.00024"
"0.01167","0.05655","0.57783","0.24000","0.00000","0.05655","0.01167","0.00048"
"0.01833","0.09694","0.99047","0.30000","0.00000","0.09694","0.01833","0.00075"
"0.02500","0.13239","1.35271","0.36000","0.00000","0.13239","0.02500","0.00102"
"0.03104","0.17093","1.74657","0.42000","0.00000","0.17093","0.03104","0.00127"
"0.03708","0.19773","2.02035","0.48000","0.00000","0.19773","0.03708","0.00151"
"0.04312","0.22724","2.32192","0.54000","0.00000","0.22724","0.04312","0.00176"
"0.04875","0.26018","2.65852","0.60000","0.00000","0.26018","0.04875","0.00199"
"0.05437","0.28588","2.92110","0.66000","0.00000","0.28588","0.05437","0.00222"
"0.05958","0.31393","3.20773","0.72000","0.00000","0.31393","0.05958","0.00243"
"0.06458","0.32937","3.36551","0.78000","0.00000","0.32937","0.06458","0.00264"
"0.06958","0.36140","3.69275","0.84000","0.00000","0.36140","0.06958","0.00284"
"0.07458","0.37664","3.84846","0.90000","0.00000","0.37664","0.07458","0.00305"
"0.07979","0.39740","4.06057","0.96000","0.00000","0.39740","0.07979","0.00326"
"0.08479","0.41550","4.24556","1.02000","0.00000","0.41550","0.08479","0.00346"
"0.08979","0.44853","4.58299","1.08000","0.00000","0.44853","0.08979","0.00367"
"0.09500","0.46603","4.76188","1.14000","0.00000","0.46603","0.09500","0.00388"
"0.10000","0.48865","4.99295","1.20000","0.00000","0.48865","0.10000","0.00408"
"0.10500","0.50287","5.13825","1.26000","0.00000","0.50287","0.10500","0.00429"
"0.10979","0.52348","5.34880","1.32000","0.00000","0.52348","0.10979","0.00448"
"0.11458","0.54833","5.60282","1.38000","0.00000","0.54833","0.11458","0.00468"
"0.11979","0.57184","5.84295","1.44000","0.00000","0.57184","0.11979","0.00489"
"0.12500","0.58437","5.97101","1.50000","0.00000","0.58437","0.12500","0.00511"
"0.12979","0.60961","6.22896","1.56000","0.00000","0.60961","0.12979","0.00530"
"0.13479","0.62496","6.38572","1.62000","0.00000","0.62496","0.13479","0.00551"
"0.13979","0.63983","6.53775","1.68000","0.00000","0.63983","0.13979","0.00571"
"0.14479","0.66964","6.84234","1.74000","0.00000","0.66964","0.14479","0.00591"
"0.14979","0.68247","6.97335","1.80000","0.00000","0.68247","0.14979","0.00612"
"0.15479","0.70293","7.18243","1.86000","0.00000","0.70293","0.15479","0.00632"
"0.16000","0.72456","7.40352","1.92000","0.00000","0.72456","0.16000","0.00654"
"0.16500","0.74178","7.57943","1.98000","0.00000","0.74178","0.16500","0.00674"
"0.17021","0.75712","7.73618","2.04000","0.00000","0.75712","0.17021","0.00695"
"0.17521","0.77562","7.92515","2.10000","0.00000","0.77562","0.17521","0.00716"
"0.18021","0.78929","8.06487","2.16000","0.00000","0.78929","0.18021","0.00736"
"0.18521","0.80884","8.26460","2.22000","0.00000","0.80884","0.18521","0.00757"
"0.19021","0.81995","8.37816","2.28000","0.00000","0.81995","0.19021","0.00777"
"0.19521","0.83813","8.56392","2.34000","0.00000","0.83813","0.19521","0.00797"
"0.20021","0.86313","8.81937","2.40000","0.00000","0.86313","0.20021","0.00818"
"0.20521","0.87674","8.95838","2.46000","0.00000","0.87674","0.20521","0.00838"
"0.21021","0.89433","9.13815","2.52000","0.00000","0.89433","0.21021","0.00859"
"0.21500","0.90087","9.20501","2.58000","0.00000","0.90087","0.21500","0.00878"
"0.22000","0.92339","9.43505","2.64000","0.00000","0.92339","0.22000","0.00899"
"0.22521","0.94339","9.63946","2.70000","0.00000","0.94339","0.22521","0.00920"
"0.23021","0.95212","9.72868","2.76000","0.00000","0.95212","0.23021","0.00940"
"0.23521","0.97256","9.93750","2.82000","0.00000","0.97256","0.23521","0.00961"
"0.24021","0.98069","10.02055","2.88000","0.00000","0.98069","0.24021","0.00981"
"0.24521","0.99736","10.19088","2.94000","0.00000","0.99736","0.24521","0.01002"
"0.25021","1.01492","10.37030","3.00000","0.00000","1.01492","0.25021","0.01022"
"0.25521","1.03343","10.55947","3.06000","0.00000","1.03343","0.25521","0.01043"
"0.26000","1.04043","10.63100","3.12000","0.00000","1.04043","0.26000","0.01062"
"0.26521","1.04848","10.71328","3.18000","0.00000","1.04848","0.26521","0.01083"
"0.27000","1.06808","10.91355","3.24000","0.00000","1.06808","0.27000","0.01103"
"0.27479","1.08403","11.07651","3.30000","0.00000","1.08403","0.27479","0.01123"
"0.28000","1.09631","11.20200","3.36000","0.00000","1.09631","0.28000","0.01144"
"0.28500","1.11681","11.41138","3.42000","0.00000","1.11681","0.28500","0.01164"
"0.28979","1.12290","11.47366","3.48000","0.00000","1.12290","0.28979","0.01184"
"0.29479","1.13372","11.58426","3.54000","0.00000","1.13372","0.29479","0.01204"
"0.29958","1.14489","11.69832","3.60000","0.00000","1.14489","0.29958","0.01224"
"0.30479","1.15632","11.81512","3.66000","0.00000","1.15632","0.30479","0.01245"
"0.31000","1.17846","12.04136","3.72000","0.00000","1.17846","0.31000","0.01266"
"0.31500","1.18625","12.12095","3.78000","0.00000","1.18625","0.31500","0.01287"
"0.32000","1.20727","12.33572","3.84000","0.00000","1.20727","0.32000","0.01307"
"0.32500","1.21463","12.41093","3.90000","0.00000","1.21463","0.32500","0.01328"
"0.33000","1.23347","12.60345","3.96000","0.00000","1.23347","0.33000","0.01348"
"0.33479","1.23861","12.65596","4.02000","0.00000","1.23861","0.33479","0.01368"
"0.33958","1.24759","12.74767","4.08000","0.00000","1.24759","0.33958","0.01387"
"0.34479","1.26594","12.93524","4.14000","0.00000","1.26594","0.34479","0.01408"
"0.35000","1.27428","13.02048","4.20000","0.00000","1.27428","0.35000","0.01430"
"0.35521","1.29399","13.22181","4.26000","0.00000","1.29399","0.35521","0.01451"
"0.36021","1.29798","13.26256","4.32000","0.00000","1.29798","0.36021","0.01471"
"0.36521","1.32301","13.51837","4.38000","0.00000","1.32301","0.36521","0.01492"
"0.37021","1.32814","13.57079","4.44000","0.00000","1.32814","0.37021","0.01512"
"0.37479","1.33314","13.62186","4.50000","0.00000","1.33314","0.37479","0.01531"
"0.37979","1.35022","13.79635","4.56000","0.00000","1.35022","0.37979","0.01551"
"0.38500","1.36078","13.90433","4.62000","0.00000","1.36078","0.38500","0.01573"
"0.39021","1.37043","14.00288","4.68000","0.00000","1.37043","0.39021","0.01594"
"0.39521","1.38425","14.14409","4.74000","0.00000","1.38425","0.39521","0.01614"
"0.40042","1.39063","14.20934","4.80000","0.00000","1.39063","0.40042","0.01636"
"0.40542","1.40711","14.37768","4.86000","0.00000","1.40711","0.40542","0.01656"
"0.41021","1.41222","14.42990","4.92000","0.00000","1.41222","0.41021","0.01676"
"0.41479","1.43085","14.62030","4.98000","0.00000","1.43085","0.41479","0.01694"
"0.41979","1.43960","14.70965","5.04000","0.00000","1.43960","0.41979","0.01715"
"0.42479","1.44092","14.72318","5.10000","0.00000","1.44092","0.42479","0.01735"
"0.43000","1.46072","14.92547","5.16000","0.00000","1.46072","0.43000","0.01757"
"0.43500","1.46836","15.00356","5.22000","0.00000","1.46836","0.43500","0.01777"
"0.44021","1.47103","15.03084","5.28000","0.00000","1.47103","0.44021","0.01798"
"0.44500","1.48115","15.13425","5.34000","0.00000","1.48115","0.44500","0.01818"
"0.45000","1.49682","15.29433","5.40000","0.00000","1.49682","0.45000","0.01838"
"0.45479","1.50245","15.35182","5.46000","0.00000","1.50245","0.45479","0.01858"
"0.45979","1.50518","15.37976","5.52000","0.00000","1.50518","0.45979","0.01878"
"0.46479","1.51747","15.50531","5.58000","0.00000","1.51747","0.46479","0.01899"
"0.47000","1.53026","15.63604","5.64000","0.00000","1.53026","0.47000","0.01920"
"0.47521","1.54252","15.76124","5.70000","0.00000","1.54252","0.47521","0.01941"
"0.48042","1.55136","15.85163","5.76000","0.00000","1.55136","0.48042","0.01962"
"0.48521","1.56287","15.96917","5.82000","0.00000","1.56287","0.48521","0.01982"
"0.49021","1.56208","15.96111","5.88000","0.00000","1.56208","0.49021","0.02002"
"0.49479","1.57748","16.11852","5.94000","0.00000","1.57748","0.49479","0.02021"
"0.49958","1.58243","16.16911","6.00000","0.00000","1.58243","0.49958","0.02041"
"0.50479","1.59143","16.26104","6.06000","0.00000","1.59143","0.50479","0.02062"
"0.50979","1.59733","16.32134","6.12000","0.00000","1.59733","0.50979","0.02082"
"0.51500","1.61140","16.46509","6.18000","0.00000","1.61140","0.51500","0.02104"
"0.52021","1.61358","16.48740","6.24000","0.00000","1.61358","0.52021","0.02125"
"0.52521","1.62788","16.63344","6.30000","0.00000","1.62788","0.52521","0.02145"
"0.53000","1.63921","16.74921","6.36000","0.00000","1.63921","0.53000","0.02165"
"0.53479","1.64513","16.80978","6.42000","0.00000","1.64513","0.53479","0.02185"
"0.53958","1.65152","16.87502","6.48000","0.00000","1.65152","0.53958","0.02204"
"0.54458","1.66049","16.96670","6.54000","0.00000","1.66049","0.54458","0.02225"
"0.54958","1.66692","17.03243","6.60000","0.00000","1.66692","0.54958","0.02245"
"0.55479","1.67764","17.14187","6.66000","0.00000","1.67764","0.55479","0.02266"
"0.56021","1.68420","17.20890","6.72000","0.00000","1.68420","0.56021","0.02288"
"0.56521","1.70054","17.37593","6.78000","0.00000","1.70054","0.56521","0.02309"
"0.57000","1.69681","17.33775","6.84000","0.00000","1.69681","0.57000","0.02328"
"0.57479","1.71470","17.52063","6.90000","0.00000","1.71470","0.57479","0.02348"
"0.57979","1.72628","17.63892","6.96000","0.00000","1.72628","0.57979","0.02368"
"0.58479","1.73265","17.70403","7.02000","0.00000","1.73265","0.58479","0.02389"
"0.58979","1.73636","17.74191","7.08000","0.00000","1.73636","0.58979","0.02409"
"0.59500","1.74996","17.88092","7.14000","0.00000","1.74996","0.59500","0.02431"
"0.60062","1.75744","17.95736","7.20000","0.00000","1.75744","0.60062","0.02454"
"0.60542","1.77503","18.13703","7.26000","0.00000","1.77503","0.60542","0.02473"
"0.61042","1.77618","18.14876","7.32000","0.00000","1.77618","0.61042","0.02494"
"0.61500","1.78762","18.26573","7.38000","0.00000","1.78762","0.61500","0.02512"
"0.61979","1.79367","18.32746","7.44000","0.00000","1.79367","0.61979","0.02532"
"0.62479","1.80045","18.39676","7.50000","0.00000","1.80045","0.62479","0.02552"
"0.63000","1.81192","18.51399","7.56000","0.00000","1.81192","0.63000","0.02574"
"0.63500","1.82438","18.64126","7.62000","0.00000","1.82438","0.63500","0.02594"
"0.64042","1.83226","18.72178","7.68000","0.00000","1.83226","0.64042","0.02616"
"0.64562","1.84003","18.80122","7.74000","0.00000","1.84003","0.64562","0.02637"
"0.65042","1.84684","18.87075","7.80000","0.00000","1.84684","0.65042","0.02657"
"0.65500","1.85459","18.94997","7.86000","0.00000","1.85459","0.65500","0.02676"
"0.65979","1.86296","19.03546","7.92000","0.00000","1.86296","0.65979","0.02695"
"0.66458","1.87593","19.16799","7.98000","0.00000","1.87593","0.66458","0.02715"
"0.66979","1.87571","19.16574","8.04000","0.00000","1.87571","0.66979","0.02736"
"0.67479","1.88156","19.22551","8.10000","0.00000","1.88156","0.67479","0.02757"
"0.68042","1.89645","19.37765","8.16000","0.00000","1.89645","0.68042","0.02779"
"0.68542","1.89263","19.33868","8.22000","0.00000","1.89263","0.68542","0.02800"
"0.69021","1.91014","19.51759","8.28000","0.00000","1.91014","0.69021","0.02819"
"0.69479","1.89778","19.39124","8.34000","0.00000","1.89778","0.69479","0.02838"
"0.69958","1.91212","19.53784","8.40000","0.00000","1.91212","0.69958","0.02858"
"0.70458","1.92047","19.62314","8.46000","0.00000","1.92047","0.70458","0.02878"
"0.70958","1.92245","19.64341","8.52000","0.00000","1.92245","0.70958","0.02899"
"0.71479","1.93086","19.72926","8.58000","0.00000","1.93086","0.71479","0.02920"
"0.72000","1.94443","19.86798","8.64000","0.00000","1.94443","0.72000","0.02941"
"0.72521","1.95562","19.98224","8.70000","0.00000","1.95562","0.72521","0.02962"
"0.73000","1.95618","19.98799","8.76000","0.00000","1.95618","0.73000","0.02982"
"0.73479","1.96375","20.06537","8.82000","0.00000","1.96375","0.73479","0.03002"
"0.73979","1.97205","20.15016","8.88000","0.00000","1.97205","0.73979","0.03022"
"0.74458","1.98040","20.23552","8.94000","0.00000","1.98040","0.74458","0.03042"
"0.74958","1.99083","20.34210","9.00000","0.00000","1.99083","0.74958","0.03062"
"0.75479","2.00837","20.52132","9.06000","0.00000","2.00837","0.75479","0.03083"
"0.76000","2.01648","20.60417","9.12000","0.00000","2.01648","0.76000","0.03105"
"0.76500","2.02850","20.72697","9.18000","0.00000","2.02850","0.76500","0.03125"
"0.77021","2.03605","20.80415","9.24000","0.00000","2.03605","0.77021","0.03146"
"0.77500","2.04595","20.90526","9.30000","0.00000","2.04595","0.77500","0.03166"
"0.77979","2.05734","21.02161","9.36000","0.00000","2.05734","0.77979","0.03185"
"0.78479","2.06851","21.13582","9.42000","0.00000","2.06851","0.78479","0.03206"
"0.78979","2.07785","21.23120","9.48000","0.00000","2.07785","0.78979","0.03226"
"0.79479","2.08295","21.28335","9.54000","0.00000","2.08295","0.79479","0.03247"
"0.80021","2.09465","21.40291","9.60000","0.00000","2.09465","0.80021","0.03269"
"0.80542","2.09869","21.44414","9.66000","0.00000","2.09869","0.80542","0.03290"
"0.81042","2.10536","21.51236","9.72000","0.00000","2.10536","0.81042","0.03311"
"0.81521","2.11649","21.62600","9.78000","0.00000","2.11649","0.81521","0.03330"
"0.82000","2.12574","21.72053","9.84000","0.00000","2.12574","0.82000","0.03350"
"0.82500","2.14537","21.92115","9.90000","0.00000","2.14537","0.82500","0.03370"
"0.83000","2.15360","22.00526","9.96000","0.00000","2.15360","0.83000","0.03391"
"0.83500","2.16720","22.14417","10.02000","0.00000","2.16720","0.83500","0.03411"
"0.84021","2.16369","22.10828","10.08000","0.00000","2.16369","0.84021","0.03432"
"0.84521","2.18398","22.31565","10.14000","0.00000","2.18398","0.84521","0.03453"
"0.85021","2.19165","22.39404","10.20000","0.00000","2.19165","0.85021","0.03473"
"0.85500","2.19761","22.45493","10.26000","0.00000","2.19761","0.85500","0.03493"
"0.86000","2.21434","22.62590","10.32000","0.00000","2.21434","0.86000","0.03513"
"0.86500","2.21817","22.66495","10.38000","0.00000","2.21817","0.86500","0.03533"
"0.86979","2.23737","22.86113","10.44000","0.00000","2.23737","0.86979","0.03553"
"0.87500","2.23708","22.85820","10.50000","0.00000","2.23708","0.87500","0.03574"
"0.88000","2.24832","22.97310","10.56000","0.00000","2.24832","0.88000","0.03595"
"0.88521","2.26020","23.09449","10.62000","0.00000","2.26020","0.88521","0.03616"
"0.89042","2.26713","23.16524","10.68000","0.00000","2.26713","0.89042","0.03637"
"0.89521","2.28010","23.29779","10.74000","0.00000","2.28010","0.89521","0.03657"
"0.90000","2.28460","23.34374","10.80000","0.00000","2.28460","0.90000","0.03676"
"0.90500","2.30125","23.51386","10.86000","0.00000","2.30125","0.90500","0.03697"
"0.90979","2.30387","23.54064","10.92000","0.00000","2.30387","0.90979","0.03716"
"0.91500","2.31205","23.62425","10.98000","0.00000","2.31205","0.91500","0.03738"
"0.92000","2.33083","23.81612","11.04000","0.00000","2.33083","0.92000","0.03758"
"0.92500","2.33916","23.90130","11.10000","0.00000","2.33916","0.92500","0.03779"
"0.93000","2.35077","24.01992","11.16000","0.00000","2.35077","0.93000","0.03799"
"0.93500","2.35295","24.04213","11.22000","0.00000","2.35295","0.93500","0.03819"
"0.94000","2.36121","24.12654","11.28000","0.00000","2.36121","0.94000","0.03840"
"0.94479","2.36819","24.19789","11.34000","0.00000","2.36819","0.94479","0.03859"
"0.94958","2.38457","24.36525","11.40000","0.00000","2.38457","0.94958","0.03879"
"0.95479","2.39556","24.47755","11.46000","0.00000","2.39556","0.95479","0.03900"
"0.95979","2.39853","24.50788","11.52000","0.00000","2.39853","0.95979","0.03921"
"0.96479","2.40204","24.54375","11.58000","0.00000","2.40204","0.96479","0.03941"
"0.96979","2.42406","24.76880","11.64000","0.00000","2.42406","0.96979","0.03962"
"0.97479","2.43044","24.83389","11.70000","0.00000","2.43044","0.97479","0.03982"
"0.97979","2.44195","24.95154","11.76000","0.00000","2.44195","0.97979","0.04002"
"0.98479","2.44102","24.94207","11.82000","0.00000","2.44102","0.98479","0.04023"
"0.98979","2.44899","25.02353","11.88000","0.00000","2.44899","0.98979","0.04043"
"0.99479","2.46145","25.15076","11.94000","0.00000","2.46145","0.99479","0.04064"
"1.00000","2.47984","25.33875","12.00000","0.00000","2.47984","1.00000","0.04085"
"1.00500","2.49079","25.45058","12.06000","0.00000","2.49079","1.00500","0.04105"
"1.01021","2.49621","25.50593","12.12000","0.00000","2.49621","1.01021","0.04127"
"1.01521","2.50736","25.61993","12.18000","0.00000","2.50736","1.01521","0.04147"
"1.02042","2.51080","25.65502","12.24000","0.00000","2.51080","1.02042","0.04168"
"1.02542","2.53306","25.88248","12.30000","0.00000","2.53306","1.02542","0.04189"
"1.03021","2.53445","25.89675","12.36000","0.00000","2.53445","1.03021","0.04208"
"1.03542","2.53963","25.94966","12.42000","0.00000","2.53963","1.03542","0.04230"
"1.04021","2.55290","26.08526","12.48000","0.00000","2.55290","1.04021","0.04249"
"1.04521","2.56504","26.20930","12.54000","0.00000","2.56504","1.04521","0.04270"
"1.04979","2.57617","26.32298","12.60000","0.00000","2.57617","1.04979","0.04288"
"1.05479","2.58127","26.37514","12.66000","0.00000","2.58127","1.05479","0.04309"
"1.06000","2.58469","26.41008","12.72000","0.00000","2.58469","1.06000","0.04330"
"1.06500","2.60129","26.57970","12.78000","0.00000","2.60129","1.06500","0.04350"
"1.07000","2.61301","26.69939","12.84000","0.00000","2.61301","1.07000","0.04371"
"1.07521","2.62490","26.82088","12.90000","0.00000","2.62490","1.07521","0.04392"
"1.08021","2.63646","26.93902","12.96000","0.00000","2.63646","1.08021","0.04413"
"1.08521","2.64125","26.98798","13.02000","0.00000","2.64125","1.08521","0.04433"
"1.09000","2.64196","26.99520","13.08000","0.00000","2.64196","1.09000","0.04453"
"1.09500","2.65202","27.09803","13.14000","0.00000","2.65202","1.09500","0.04473"
"1.10021","2.67366","27.31909","13.20000","0.00000","2.67366","1.10021","0.04494"
"1.10521","2.68077","27.39182","13.26000","0.00000","2.68077","1.10521","0.04515"
"1.11000","2.69138","27.50017","13.32000","0.00000","2.69138","1.11000","0.04534"
"1.11500","2.69529","27.54009","13.38000","0.00000","2.69529","1.11500","0.04555"
"1.12000","2.70313","27.62030","13.44000","0.00000","2.70313","1.12000","0.04575"
"1.12500","2.71353","27.72651","13.50000","0.00000","2.71353","1.12500","0.04596"
"1.12979","2.72812","27.87557","13.56000","0.00000","2.72812","1.12979","0.04615"
"1.13458","2.73525","27.94841","13.62000","0.00000","2.73525","1.13458","0.04635"
"1.14000","2.73115","27.90654","13.68000","0.00000","2.73115","1.14000","0.04657"
"1.14500","2.75446","28.14475","13.74000","0.00000","2.75446","1.14500","0.04677"
"1.15000","2.75167","28.11626","13.80000","0.00000","2.75167","1.15000","0.04698"
"1.15500","2.76562","28.25880","13.86000","0.00000","2.76562","1.15500","0.04718"
"1.16000","2.77672","28.37217","13.92000","0.00000","2.77672","1.16000","0.04739"
"1.16479","2.78983","28.50617","13.98000","0.00000","2.78983","1.16479","0.04758"
"1.16958","2.78569","28.46386","14.04000","0.00000","2.78569","1.16958","0.04778"
"1.17458","2.80838","28.69567","14.10000","0.00000","2.80838","1.17458","0.04798"
"1.17979","2.81131","28.72558","14.16000","0.00000","2.81131","1.17979","0.04819"
"1.18521","2.82067","28.82129","14.22000","0.00000","2.82067","1.18521","0.04842"
"1.19021","2.83312","28.94843","14.28000","0.00000","2.83312","1.19021","0.04862"
"1.19521","2.84005","29.01926","14.34000","0.00000","2.84005","1.19521","0.04882"
"1.20021","2.85388","29.16058","14.40000","0.00000","2.85388","1.20021","0.04903"
"1.20500","2.85374","29.15922","14.46000","0.00000","2.85374","1.20500","0.04922"
"1.20979","2.86602","29.28468","14.52000","0.00000","2.86602","1.20979","0.04942"
"1.21479","2.87462","29.37250","14.58000","0.00000","2.87462","1.21479","0.04962"
"1.22021","2.88595","29.48828","14.64000","0.00000","2.88595","1.22021","0.04985"
"1.22542","2.88978","29.52740","14.70000","0.00000","2.88978","1.22542","0.05006"
"1.23042","2.90394","29.67207","14.76000","0.00000","2.90394","1.23042","0.05026"
"1.23521","2.91295","29.76414","14.82000","0.00000","2.91295","1.23521","0.05046"
"1.24021","2.91094","29.74362","14.88000","0.00000","2.91094","1.24021","0.05066"
"1.24500","2.92727","29.91047","14.94000","0.00000","2.92727","1.24500","0.05086"
"1.24958","2.93684","30.00831","15.00000","0.00000","2.93684","1.24958","0.05105"
"1.25479","2.94533","30.09506","15.06000","0.00000","2.94533","1.25479","0.05126"
"1.26000","2.95333","30.17677","15.12000","0.00000","2.95333","1.26000","0.05147"
"1.26521","2.96056","30.25067","15.18000","0.00000","2.96056","1.26521","0.05168"
"1.27021","2.96809","30.32755","15.24000","0.00000","2.96809","1.27021","0.05189"
"1.27521","2.98216","30.47136","15.30000","0.00000","2.98216","1.27521","0.05209"
"1.28021","2.98541","30.50453","15.36000","0.00000","2.98541","1.28021","0.05230"
"1.28500","2.99628","30.61561","15.42000","0.00000","2.99628","1.28500","0.05249"
"1.28979","2.99986","30.65215","15.48000","0.00000","2.99986","1.28979","0.05269"
"1.29479","3.00819","30.73737","15.54000","0.00000","3.00819","1.29479","0.05289"
"1.30000","3.02782","30.93786","15.60000","0.00000","3.02782","1.30000","0.05310"
"1.30500","3.02911","30.95113","15.66000","0.00000","3.02911","1.30500","0.05331"
"1.31021","3.03568","31.01821","15.72000","0.00000","3.03568","1.31021","0.05352"
"1.31542","3.05034","31.16801","15.78000","0.00000","3.05034","1.31542","0.05373"
"1.32021","3.05179","31.18280","15.84000","0.00000","3.05179","1.32021","0.05393"
"1.32479","3.06826","31.35107","15.90000","0.00000","3.06826","1.32479","0.05412"
"1.32958","3.06255","31.29280","15.96000","0.00000","3.06255","1.32958","0.05431"
"1.33458","3.08040","31.47516","16.02000","0.00000","3.08040","1.33458","0.05452"
"1.33979","3.09105","31.58393","16.08000","0.00000","3.09105","1.33979","0.05473"
"1.34500","3.10397","31.71596","16.14000","0.00000","3.10397","1.34500","0.05494"
"1.35000","3.10918","31.76920","16.20000","0.00000","3.10918","1.35000","0.05515"
"1.35521","3.11937","31.87336","16.26000","0.00000","3.11937","1.35521","0.05536"
"1.36021","3.13216","32.00401","16.32000","0.00000","3.13216","1.36021","0.05556"
"1.36500","3.12680","31.94925","16.38000","0.00000","3.12680","1.36500","0.05576"
"1.36958","3.14181","32.10266","16.44000","0.00000","3.14181","1.36958","0.05595"
"1.37458","3.14871","32.17309","16.50000","0.00000","3.14871","1.37458","0.05615"
"1.37958","3.16850","32.37537","16.56000","0.00000","3.16850","1.37958","0.05636"
"1.38479","3.17088","32.39970","16.62000","0.00000","3.17088","1.38479","0.05657"
"1.39000","3.18406","32.53436","16.68000","0.00000","3.18406","1.39000","0.05678"
"1.39521","3.18497","32.54366","16.74000","0.00000","3.18497","1.39521","0.05699"
"1.40000","3.19482","32.64425","16.80000","0.00000","3.19482","1.40000","0.05719"
"1.40500","3.20070","32.70435","16.86000","0.00000","3.20070","1.40500","0.05739"
"1.40979","3.21863","32.88760","16.92000","0.00000","3.21863","1.40979","0.05759"
"1.41458","3.22256","32.92768","16.98000","0.00000","3.22256","1.41458","0.05779"
"1.41979","3.22348","32.93711","17.04000","0.00000","3.22348","1.41979","0.05800"
"1.42500","3.24210","33.12743","17.10000","0.00000","3.24210","1.42500","0.05821"
"1.43021","3.25444","33.25344","17.16000","0.00000","3.25444","1.43021","0.05842"
"1.43562","3.25564","33.26577","17.22000","0.00000","3.25564","1.43562","0.05864"
"1.44042","3.26756","33.38748","17.28000","0.00000","3.26756","1.44042","0.05884"
"1.44521","3.27611","33.47493","17.34000","0.00000","3.27611","1.44521","0.05904"
"1.44979","3.28171","33.53207","17.40000","0.00000","3.28171","1.44979","0.05922"
"1.45479","3.28229","33.53805","17.46000","0.00000","3.28229","1.45479","0.05943"
"1.45979","3.29350","33.65260","17.52000","0.00000","3.29350","1.45979","0.05963"
"1.46479","3.30390","33.75886","17.58000","0.00000","3.30390","1.46479","0.05984"
"1.47021","3.31466","33.86882","17.64000","0.00000","3.31466","1.47021","0.06006"
"1.47542","3.32244","33.94831","17.70000","0.00000","3.32244","1.47542","0.06027"
"1.48042","3.32754","34.00039","17.76000","0.00000","3.32754","1.48042","0.06047"
"1.48521","3.33597","34.08652","17.82000","0.00000","3.33597","1.48521","0.06067"
"1.48979","3.34623","34.19137","17.88000","0.00000","3.34623","1.48979","0.06086"
"1.49458","3.34709","34.20013","17.94000","0.00000","3.34709","1.49458","0.06105"
"1.49958","3.35613","34.29256","18.00000","0.00000","3.35613","1.49958","0.06126"
"1.50479","3.36872","34.42113","18.06000","0.00000","3.36872","1.50479","0.06147"
"1.51000","3.38058","34.54232","18.12000","0.00000","3.38058","1.51000","0.06168"
"1.51542","3.38049","34.54148","18.18000","0.00000","3.38049","1.51542","0.06190"
"1.52042","3.39079","34.64672","18.24000","0.00000","3.39079","1.52042","0.06211"
"1.52521","3.40023","34.74318","18.30000","0.00000","3.40023","1.52521","0.06230"
"1.52979","3.39972","34.73788","18.36000","0.00000","3.39972","1.52979","0.06249"
"1.53479","3.40775","34.81993","18.42000","0.00000","3.40775","1.53479","0.06270"
"1.53979","3.41055","34.84860","18.48000","0.00000","3.41055","1.53979","0.06290"
"1.54479","3.42846","35.03156","18.54000","0.00000","3.42846","1.54479","0.06310"
"1.54979","3.43338","35.08183","18.60000","0.00000","3.43338","1.54979","0.06331"
"1.55521","3.44649","35.21585","18.66000","0.00000","3.44649","1.55521","0.06353"
"1.56021","3.44437","35.19413","18.72000","0.00000","3.44437","1.56021","0.06373"
"1.56500","3.46464","35.40123","18.78000","0.00000","3.46464","1.56500","0.06393"
"1.56979","3.46826","35.43827","18.84000","0.00000","3.46826","1.56979","0.06413"
"1.57458","3.46885","35.44432","18.90000","0.00000","3.46885","1.57458","0.06432"
"1.57958","3.47277","35.48431","18.96000","0.00000","3.47277","1.57958","0.06453"
"1.58458","3.49104","35.67099","19.02000","0.00000","3.49104","1.58458","0.06473"
"1.58979","3.49781","35.74016","19.08000","0.00000","3.49781","1.58979","0.06494"
"1.59500","3.50626","35.82657","19.14000","0.00000","3.50626","1.59500","0.06516"
"1.60021","3.51628","35.92894","19.20000","0.00000","3.51628","1.60021","0.06537"
"1.60500","3.52856","36.05441","19.26000","0.00000","3.52856","1.60500","0.06556"
"1.60979","3.52987","36.06775","19.32000","0.00000","3.52987","1.60979","0.06576"
"1.61479","3.53232","36.09283","19.38000","0.00000","3.53232","1.61479","0.06596"
"1.61979","3.54157","36.18734","19.44000","0.00000","3.54157","1.61979","0.06617"
"1.62458","3.56136","36.38960","19.50000","0.00000","3.56136","1.62458","0.06636"
"1.62979","3.56199","36.39598","19.56000","0.00000","3.56199","1.62979","0.06658"
"1.63521","3.58103","36.59050","19.62000","0.00000","3.58103","1.63521","0.06680"
"1.64042","3.57924","36.57222","19.68000","0.00000","3.57924","1.64042","0.06701"
"1.64542","3.59200","36.70263","19.74000","0.00000","3.59200","1.64542","0.06721"
"1.65021","3.59642","36.74778","19.80000","0.00000","3.59642","1.65021","0.06741"
"1.65521","3.60426","36.82792","19.86000","0.00000","3.60426","1.65521","0.06761"
"1.66000","3.61455","36.93298","19.92000","0.00000","3.61455","1.66000","0.06781"
"1.66500","3.61539","36.94159","19.98000","0.00000","3.61539","1.66500","0.06801"
"1.67000","3.62255","37.01482","20.04000","0.00000","3.62255","1.67000","0.06822"
"1.67521","3.63951","37.18809","20.10000","0.00000","3.63951","1.67521","0.06843"
"1.68042","3.64937","37.28880","20.16000","0.00000","3.64937","1.68042","0.06864"
"1.68521","3.64752","37.26993","20.22000","0.00000","3.64752","1.68521","0.06884"
"1.69000","3.66276","37.42563","20.28000","0.00000","3.66276","1.69000","0.06904"
"1.69479","3.67685","37.56962","20.34000","0.00000","3.67685","1.69479","0.06923"
"1.69979","3.67210","37.52111","20.40000","0.00000","3.67210","1.69979","0.06944"
"1.70458","3.68428","37.64550","20.46000","0.00000","3.68428","1.70458","0.06963"
"1.70979","3.69584","37.76365","20.52000","0.00000","3.69584","1.70979","0.06984"
"1.71500","3.70178","37.82432","20.58000","0.00000","3.70178","1.71500","0.07006"
"1.72021","3.71162","37.92483","20.64000","0.00000","3.71162","1.72021","0.07027"
"1.72521","3.71576","37.96719","20.70000","0.00000","3.71576","1.72521","0.07047"
"1.73021","3.73354","38.14882","20.76000","0.00000","3.73354","1.73021","0.07068"
"1.73521","3.73232","38.13638","20.82000","0.00000","3.73232","1.73521","0.07088"
"1.74000","3.74085","38.22355","20.88000","0.00000","3.74085","1.74000","0.07108"
"1.74479","3.74700","38.28643","20.94000","0.00000","3.74700","1.74479","0.07127"
"1.75000","3.75306","38.34834","21.00000","0.00000","3.75306","1.75000","0.07149"
"1.75500","3.76444","38.46455","21.06000","0.00000","3.76444","1.75500","0.07169"
"1.76000","3.76955","38.51677","21.12000","0.00000","3.76955","1.76000","0.07190"
"1.76500","3.77520","38.57456","21.18000","0.00000","3.77520","1.76500","0.07210"
"1.77000","3.78281","38.65231","21.24000","0.00000","3.78281","1.77000","0.07230"
"1.77500","3.79303","38.75673","21.30000","0.00000","3.79303","1.77500","0.07251"
"1.77979","3.79079","38.73383","21.36000","0.00000","3.79079","1.77979","0.07270"
"1.78458","3.79926","38.82042","21.42000","0.00000","3.79926","1.78458","0.07290"
"1.78979","3.81574","38.98881","21.48000","0.00000","3.81574","1.78979","0.07311"
"1.79479","3.81710","39.00269","21.54000","0.00000","3.81710","1.79479","0.07332"
"1.79979","3.82352","39.06825","21.60000","0.00000","3.82352","1.79979","0.07352"
"1.80479","3.82892","39.12341","21.66000","0.00000","3.82892","1.80479","0.07373"
"1.80979","3.84588","39.29675","21.72000","0.00000","3.84588","1.80979","0.07393"
"1.81500","3.84186","39.25563","21.78000","0.00000","3.84186","1.81500","0.07414"
"1.82000","3.85108","39.34983","21.84000","0.00000","3.85108","1.82000","0.07435"
"1.82479","3.86252","39.46671","21.90000","0.00000","3.86252","1.82479","0.07454"
"1.83000","3.86692","39.51169","21.96000","0.00000","3.86692","1.83000","0.07475"
"1.83500","3.87469","39.59107","22.02000","0.00000","3.87469","1.83500","0.07496"
"1.84000","3.88249","39.67085","22.08000","0.00000","3.88249","1.84000","0.07516"
"1.84521","3.88807","39.72787","22.14000","0.00000","3.88807","1.84521","0.07538"
"1.85042","3.88496","39.69609","22.20000","0.00000","3.88496","1.85042","0.07559"
"1.85542","3.89227","39.77076","22.26000","0.00000","3.89227","1.85542","0.07579"
"1.86021","3.90026","39.85234","22.32000","0.00000","3.90026","1.86021","0.07599"
"1.86521","3.91227","39.97509","22.38000","0.00000","3.91227","1.86521","0.07619"
"1.87021","3.91255","39.97797","22.44000","0.00000","3.91255","1.87021","0.07640"
"1.87521","3.92325","40.08727","22.50000","0.00000","3.92325","1.87521","0.07660"
"1.88000","3.92516","40.10676","22.56000","0.00000","3.92516","1.88000","0.07680"
"1.88500","3.92613","40.11676","22.62000","0.00000","3.92613","1.88500","0.07700"
"1.89021","3.93524","40.20980","22.68000","0.00000","3.93524","1.89021","0.07721"
"1.89521","3.94568","40.31649","22.74000","0.00000","3.94568","1.89521","0.07742"
"1.90021","3.95201","40.38111","22.80000","0.00000","3.95201","1.90021","0.07762"
"1.90500","3.94988","40.35939","22.86000","0.00000","3.94988","1.90500","0.07782"
"1.91021","3.96433","40.50706","22.92000","0.00000","3.96433","1.91021","0.07803"
"1.91500","3.96843","40.54892","22.98000","0.00000","3.96843","1.91500","0.07823"
"1.92000","3.96935","40.55835","23.04000","0.00000","3.96935","1.92000","0.07843"
"1.92479","3.98066","40.67392","23.10000","0.00000","3.98066","1.92479","0.07863"
"1.93000","3.98130","40.68049","23.16000","0.00000","3.98130","1.93000","0.07884"
"1.93521","3.99205","40.79024","23.22000","0.00000","3.99205","1.93521","0.07905"
"1.94021","4.00090","40.88071","23.28000","0.00000","4.00090","1.94021","0.07926"
"1.94500","4.00546","40.92728","23.34000","0.00000","4.00546","1.94500","0.07945"
"1.95021","4.01260","41.00027","23.40000","0.00000","4.01260","1.95021","0.07967"
"1.95500","4.01846","41.06016","23.46000","0.00000","4.01846","1.95500","0.07986"
"1.96000","4.02187","41.09503","23.52000","0.00000","4.02187","1.96000","0.08007"
"1.96479","4.03247","41.20329","23.58000","0.00000","4.03247","1.96479","0.08026"
"1.96979","4.03116","41.18993","23.64000","0.00000","4.03116","1.96979","0.08047"
"1.97500","4.04151","41.29563","23.70000","0.00000","4.04151","1.97500","0.08068"
"1.98000","4.05092","41.39179","23.76000","0.00000","4.05092","1.98000","0.08088"
"1.98500","4.05483","41.43177","23.82000","0.00000","4.05483","1.98500","0.08109"
"1.99021","4.06390","41.52443","23.88000","0.00000","4.06390","1.99021","0.08130"
"1.99500","4.06170","41.50193","23.94000","0.00000","4.06170","1.99500","0.08150"
"1.99979","4.06966","41.58334","24.00000","0.00000","4.06966","1.99979","0.08169"
"2.00458","4.08329","41.72256","24.06000","0.00000","4.08329","2.00458","0.08189"
"2.00979","4.08532","41.74333","24.12000","0.00000","4.08532","2.00979","0.08210"
"2.01479","4.08912","41.78213","24.18000","0.00000","4.08912","2.01479","0.08230"
"2.02021","4.09785","41.87135","24.24000","0.00000","4.09785","2.02021","0.08252"
"2.02521","4.10315","41.92548","24.30000","0.00000","4.10315","2.02521","0.08273"
"2.03021","4.10939","41.98926","24.36000","0.00000","4.10939","2.03021","0.08293"
"2.03500","4.11194","42.01534","24.42000","0.00000","4.11194","2.03500","0.08313"
"2.03979","4.11505","42.04704","24.48000","0.00000","4.11505","2.03979","0.08332"
"2.04479","4.12490","42.14772","24.54000","0.00000","4.12490","2.04479","0.08353"
"2.04979","4.12704","42.16955","24.60000","0.00000","4.12704","2.04979","0.08373"
"2.05521","4.13378","42.23851","24.66000","0.00000","4.13378","2.05521","0.08395"
"2.06042","4.14741","42.37774","24.72000","0.00000","4.14741","2.06042","0.08417"
"2.06542","4.15541","42.45946","24.78000","0.00000","4.15541","2.06542","0.08437"
"2.07042","4.15357","42.44062","24.84000","0.00000","4.15357","2.07042","0.08458"
"2.07521","4.15384","42.44342","24.90000","0.00000","4.15384","2.07521","0.08477"
"2.07979","4.16152","42.52190","24.96000","0.00000","4.16152","2.07979","0.08496"
"2.08479","4.16022","42.50864","25.02000","0.00000","4.16022","2.08479","0.08516"
"2.08979","4.16983","42.60682","25.08000","0.00000","4.16983","2.08979","0.08537"
"2.09500","4.17332","42.64249","25.14000","0.00000","4.17332","2.09500","0.08558"
"2.10021","4.17951","42.70575","25.20000","0.00000","4.17951","2.10021","0.08579"
"2.10542","4.19017","42.81463","25.26000","0.00000","4.19017","2.10542","0.08601"
"2.11021","4.18318","42.74326","25.32000","0.00000","4.18318","2.11021","0.08620"
"2.11521","4.18842","42.79680","25.38000","0.00000","4.18842","2.11521","0.08641"
"2.11979","4.19261","42.83955","25.44000","0.00000","4.19261","2.11979","0.08659"
"2.12458","4.19461","42.86004","25.50000","0.00000","4.19461","2.12458","0.08679"
"2.12979","4.19630","42.87732","25.56000","0.00000","4.19630","2.12979","0.08700"
"2.13479","4.19767","42.89132","25.62000","0.00000","4.19767","2.13479","0.08721"
"2.14000","4.19994","42.91448","25.68000","0.00000","4.19994","2.14000","0.08742"
"2.14521","4.20446","42.96068","25.74000","0.00000","4.20446","2.14521","0.08763"
"2.15042","4.20284","42.94406","25.80000","0.00000","4.20284","2.15042","0.08784"
"2.15521","4.20822","42.99905","25.86000","0.00000","4.20822","2.15521","0.08804"
"2.15979","4.21010","43.01825","25.92000","0.00000","4.21010","2.15979","0.08823"
"2.16458","4.20457","42.96179","25.98000","0.00000","4.20457","2.16458","0.08842"
"2.16958","4.20349","42.95071","26.04000","0.00000","4.20349","2.16958","0.08863"
"2.17458","4.20047","42.91993","26.10000","0.00000","4.20047","2.17458","0.08883"
"2.17979","4.20645","42.98096","26.16000","0.00000","4.20645","2.17979","0.08904"
"2.18500","4.19670","42.88135","26.22000","0.00000","4.19670","2.18500","0.08926"
"2.19000","4.19900","42.90483","26.28000","0.00000","4.19900","2.19000","0.08946"
"2.19500","4.19210","42.83434","26.34000","0.00000","4.19210","2.19500","0.08967"
"2.19958","4.19078","42.82084","26.40000","0.00000","4.19078","2.19958","0.08985"
"2.20458","4.19826","42.89727","26.46000","0.00000","4.19826","2.20458","0.09006"
"2.20958","4.19231","42.83650","26.52000","0.00000","4.19231","2.20958","0.09026"
"2.21479","4.19477","42.86166","26.58000","0.00000","4.19477","2.21479","0.09047"
"2.21979","4.19317","42.84526","26.64000","0.00000","4.19317","2.21979","0.09068"
"2.22500","4.19222","42.83558","26.70000","0.00000","4.19222","2.22500","0.09089"
"2.23021","4.19327","42.84632","26.76000","0.00000","4.19327","2.23021","0.09110"
"2.23521","4.18856","42.79824","26.82000","0.00000","4.18856","2.23521","0.09131"
"2.24000","4.19104","42.82350","26.88000","0.00000","4.19104","2.24000","0.09150"
"2.24479","4.19404","42.85419","26.94000","0.00000","4.19404","2.24479","0.09170"
"2.24979","4.18071","42.71796","27.00000","0.00000","4.18071","2.24979","0.09190"
"2.25479","4.17915","42.70208","27.06000","0.00000","4.17915","2.25479","0.09211"
"2.26000","4.17153","42.62421","27.12000","0.00000","4.17153","2.26000","0.09232"
"2.26542","4.17353","42.64460","27.18000","0.00000","4.17353","2.26542","0.09254"
"2.27062","4.16204","42.52718","27.24000","0.00000","4.16204","2.27062","0.09275"
"2.27542","4.15947","42.50092","27.30000","0.00000","4.15947","2.27542","0.09295"
"2.28021","4.12752","42.17448","27.36000","0.00000","4.12752","2.28021","0.09315"
"2.28479","4.11529","42.04949","27.42000","0.00000","4.11529","2.28479","0.09333"
"2.28979","4.08960","41.78706","27.48000","0.00000","4.08960","2.28979","0.09354"
"2.29479","4.07767","41.66510","27.54000","0.00000","4.07767","2.29479","0.09374"
"2.29979","4.05665","41.45038","27.60000","0.00000","4.05665","2.29979","0.09395"
"2.30521","4.02317","41.10823","27.66000","0.00000","4.02317","2.30521","0.09417"
"2.31021","4.00277","40.89980","27.72000","0.00000","4.00277","2.31021","0.09437"
"2.31521","3.96766","40.54110","27.78000","0.00000","3.96766","2.31521","0.09458"
"2.32000","3.91557","40.00887","27.84000","0.00000","3.91557","2.32000","0.09477"
"2.32479","3.86178","39.45922","27.90000","0.00000","3.86178","2.32479","0.09497"
"2.32958","3.80749","38.90443","27.96000","0.00000","3.80749","2.32958","0.09516"
"2.33479","3.75936","38.41270","28.02000","0.00000","3.75936","2.33479","0.09538"
"2.33979","3.70475","37.85469","28.08000","0.00000","3.70475","2.33979","0.09558"
"2.34521","3.63879","37.18076","28.14000","0.00000","3.63879","2.34521","0.09580"
"2.35042","3.55568","36.33152","28.20000","0.00000","3.55568","2.35042","0.09601"
"2.35542","3.45991","35.35295","28.26000","0.00000","3.45991","2.35542","0.09622"
"2.36000","3.34670","34.19618","28.32000","0.00000","3.34670","2.36000","0.09641"
"2.36479","3.16220","32.31097","28.38000","0.00000","3.16220","2.36479","0.09660"
"2.36979","2.26951","23.18954","28.44000","0.00000","2.26951","2.36979","0.09681"
"2.37479","0.25358","2.59103","28.50000","0.00000","0.25358","2.37479","0.09701"
"2.37979","0.11006","1.12460","28.56000","0.00000","0.11006","2.37979","0.09721"
"2.38500","0.03519","0.35961","28.62000","0.00000","0.03519","2.38500","0.09743"
"2.39000","-0.02689","-0.27472","28.68000","0.00000","-0.02689","2.39000","0.09763"
"2.39521","-0.06610","-0.67545","28.74000","0.00000","-0.06610","2.39521","0.09784"
"2.40000","-0.09723","-0.99349","28.80000","0.00000","-0.09723","2.40000","0.09804"
"2.40479","-0.11294","-1.15399","28.86000","0.00000","-0.11294","2.40479","0.09823"
"2.40958","-0.12995","-1.32778","28.92000","0.00000","-0.12995","2.40958","0.09843"
"2.41458","-0.14306","-1.46177","28.98000","0.00000","-0.14306","2.41458","0.09863"
"2.41958","-0.17168","-1.75422","29.04000","0.00000","-0.17168","2.41958","0.09884"
"2.42479","-0.18197","-1.85930","29.10000","0.00000","-0.18197","2.42479","0.09905"
"2.42979","-0.18738","-1.91464","29.16000","0.00000","-0.18738","2.42979","0.09926"
"2.43500","-0.20828","-2.12818","29.22000","0.00000","-0.20828","2.43500","0.09947"
"2.44000","-0.20828","-2.12817","29.28000","0.00000","-0.20828","2.44000","0.09967"
"2.44479","-0.23371","-2.38801","29.34000","0.00000","-0.23371","2.44479","0.09987"
"2.44979","-0.23668","-2.41841","29.40000","0.00000","-0.23668","2.44979","0.10007"
"2.45479","-0.24864","-2.54059","29.46000","0.00000","-0.24864","2.45479","0.10028"
"2.45979","-0.25862","-2.64250","29.52000","0.00000","-0.25862","2.45979","0.10048"
"2.46500","-0.25959","-2.65248","29.58000","0.00000","-0.25959","2.46500","0.10069"
"2.47042","-0.26669","-2.72505","29.64000","0.00000","-0.26669","2.47042","0.10092"
"2.47542","-0.29292","-2.99307","29.70000","0.00000","-0.29292","2.47542","0.10112"
"2.48042","-0.28230","-2.88448","29.76000","0.00000","-0.28230","2.48042","0.10132"
"2.48521","-0.30443","-3.11063","29.82000","0.00000","-0.30443","2.48521","0.10152"
"2.49000","-0.30647","-3.13142","29.88000","0.00000","-0.30647","2.49000","0.10172"
"2.49500","-0.31400","-3.20839","29.94000","0.00000","-0.31400","2.49500","0.10192"
"2.50000","-0.32865","-3.35810","30.00000","0.00000","-0.32865","2.50000","0.10212"
"2.50500","-0.32569","-3.32781","30.06000","0.00000","-0.32569","2.50500","0.10233"
"2.51021","-0.32912","-3.36290","30.12000","0.00000","-0.32912","2.51021","0.10254"
"2.51521","-0.33887","-3.46252","30.18000","0.00000","-0.33887","2.51521","0.10275"
"2.52021","-0.35490","-3.62636","30.24000","0.00000","-0.35490","2.52021","0.10295"
"2.52500","-0.36159","-3.69468","30.30000","0.00000","-0.36159","2.52500","0.10315"
"2.53000","-0.35852","-3.66330","30.36000","0.00000","-0.35852","2.53000","0.10335"
"2.53479","-0.36581","-3.73781","30.42000","0.00000","-0.36581","2.53479","0.10355"
"2.53979","-0.37769","-3.85915","30.48000","0.00000","-0.37769","2.53979","0.10375"
"2.54500","-0.38060","-3.88892","30.54000","0.00000","-0.38060","2.54500","0.10396"
"2.55000","-0.38805","-3.96500","30.60000","0.00000","-0.38805","2.55000","0.10417"
"2.55521","-0.38995","-3.98444","30.66000","0.00000","-0.38995","2.55521","0.10438"
"2.56021","-0.40025","-4.08970","30.72000","0.00000","-0.40025","2.56021","0.10458"
"2.56500","-0.40699","-4.15855","30.78000","0.00000","-0.40699","2.56500","0.10478"
"2.57000","-0.40948","-4.18398","30.84000","0.00000","-0.40948","2.57000","0.10498"
"2.57479","-0.41608","-4.25141","30.90000","0.00000","-0.41608","2.57479","0.10518"
"2.57979","-0.41957","-4.28710","30.96000","0.00000","-0.41957","2.57979","0.10538"
"2.58500","-0.42988","-4.39243","31.02000","0.00000","-0.42988","2.58500","0.10560"
"2.59000","-0.43208","-4.41493","31.08000","0.00000","-0.43208","2.59000","0.10580"
"2.59500","-0.42955","-4.38904","31.14000","0.00000","-0.42955","2.59500","0.10600"
"2.60000","-0.43610","-4.45606","31.20000","0.00000","-0.43610","2.60000","0.10621"
"2.60521","-0.43674","-4.46251","31.26000","0.00000","-0.43674","2.60521","0.10642"
"2.61000","-0.44981","-4.59606","31.32000","0.00000","-0.44981","2.61000","0.10662"
"2.61479","-0.44824","-4.58007","31.38000","0.00000","-0.44824","2.61479","0.10681"
"2.61979","-0.43844","-4.47996","31.44000","0.00000","-0.43844","2.61979","0.10702"
"2.62479","-0.45423","-4.64132","31.50000","0.00000","-0.45423","2.62479","0.10722"
"2.62979","-0.45730","-4.67264","31.56000","0.00000","-0.45730","2.62979","0.10743"
"2.63458","-0.46269","-4.72776","31.62000","0.00000","-0.46269","2.63458","0.10762"
"2.63979","-0.46485","-4.74974","31.68000","0.00000","-0.46485","2.63979","0.10783"
"2.64500","-0.46607","-4.76221","31.74000","0.00000","-0.46607","2.64500","0.10805"
"2.65000","-0.46545","-4.75594","31.80000","0.00000","-0.46545","2.65000","0.10825"
"2.65479","-0.47328","-4.83593","31.86000","0.00000","-0.47328","2.65479","0.10845"
"2.65979","-0.47502","-4.85369","31.92000","0.00000","-0.47502","2.65979","0.10865"
"2.66500","-0.47065","-4.80904","31.98000","0.00000","-0.47065","2.66500","0.10886"
"2.67000","-0.47199","-4.82275","32.04000","0.00000","-0.47199","2.67000","0.10907"
"2.67500","-0.47197","-4.82258","32.10000","0.00000","-0.47197","2.67500","0.10927"
"2.68000","-0.47996","-4.90420","32.16000","0.00000","-0.47996","2.68000","0.10948"
"2.68521","-0.47653","-4.86910","32.22000","0.00000","-0.47653","2.68521","0.10969"
"2.69021","-0.48058","-4.91047","32.28000","0.00000","-0.48058","2.69021","0.10989"
"2.69521","-0.48417","-4.94724","32.34000","0.00000","-0.48417","2.69521","0.11010"
"2.70042","-0.48522","-4.95788","32.40000","0.00000","-0.48522","2.70042","0.11031"
"2.70521","-0.48264","-4.93156","32.46000","0.00000","-0.48264","2.70521","0.11051"
"2.71021","-0.48062","-4.91090","32.52000","0.00000","-0.48062","2.71021","0.11071"
"2.71500","-0.49238","-5.03105","32.58000","0.00000","-0.49238","2.71500","0.11091"
"2.72000","-0.48827","-4.98909","32.64000","0.00000","-0.48827","2.72000","0.11111"
"2.72354","-0.48573","-4.96318","32.68200","0.00000","-0.48573","2.72354","0.11126"