File: G2 -Fresh stress relaxation-20210318/Specimen_RawData_1.csv
Specimen properties : Specimen label,"sample1"
Specimen properties : Diameter,"0.39900",mm
Specimen properties : Length,"14.33000",mm
Test : Rate 1,"5.00000",mm/min
Test : Start of hold value,"0.05000",mm/mm
Test : Delta,"180.00000",s

Extension,Load,Tensile stress,Time,PIP count,Tenacity,Tensile extension,Tensile strain (Extension)
(mm),(N),(MPa),(s),,(N/tex),(mm),(mm/mm)
"0.00000","0.01146","0.09162","0.00000","0.00000","0.01146","0.00000","0.00000"
"0.03167","0.14477","1.15779","0.40000","0.00000","0.14477","0.03167","0.00221"
"0.06667","0.28216","2.25662","0.80000","0.00000","0.28216","0.06667","0.00465"
"0.10042","0.40648","3.25090","1.20000","0.00000","0.40648","0.10042","0.00701"
"0.13375","0.53827","4.30492","1.60000","0.00000","0.53827","0.13375","0.00933"
"0.16708","0.67153","5.37071","2.00000","0.00000","0.67153","0.16708","0.01166"
"0.20042","0.80782","6.46070","2.40000","0.00000","0.80782","0.20042","0.01399"
"0.23333","0.94070","7.52340","2.80000","0.00000","0.94070","0.23333","0.01628"
"0.26687","1.07275","8.57949","3.20000","0.00000","1.07275","0.26687","0.01862"
"0.30021","1.20886","9.66806","3.60000","0.00000","1.20886","0.30021","0.02095"
"0.33396","1.34340","10.74408","4.00000","0.00000","1.34340","0.33396","0.02330"
"0.36729","1.46940","11.75181","4.40000","0.00000","1.46940","0.36729","0.02563"
"0.40021","1.59742","12.77565","4.80000","0.00000","1.59742","0.40021","0.02793"
"0.43333","1.71225","13.69407","5.20000","0.00000","1.71225","0.43333","0.03024"
"0.46729","1.84778","14.77800","5.60000","0.00000","1.84778","0.46729","0.03261"
"0.50062","1.95665","15.64868","6.00000","0.00000","1.95665","0.50062","0.03494"
"0.53396","2.07061","16.56011","6.40000","0.00000","2.07061","0.53396","0.03726"
"0.56708","2.18658","17.48758","6.80000","0.00000","2.18658","0.56708","0.03957"
"0.60021","2.28912","18.30767","7.20000","0.00000","2.28912","0.60021","0.04188"
"0.63354","2.40683","19.24905","7.60000","0.00000","2.40683","0.63354","0.04421"
"0.66708","2.51076","20.08024","8.00000","0.00000","2.51076","0.66708","0.04655"
"0.70062","2.62190","20.96916","8.40000","0.00000","2.62190","0.70062","0.04889"
"0.71896","2.65150","21.20589","8.69600","0.00000","2.65150","0.71896","0.05017"
"0.71896","2.51141","20.08545","9.09600","0.00000","2.51141","0.71896","0.05017"
"0.71812","2.44068","19.51976","9.49600","0.00000","2.44068","0.71812","0.05011"
"0.71812","2.37753","19.01472","9.89600","0.00000","2.37753","0.71812","0.05011"
"0.71750","2.32595","18.60222","10.29600","0.00000","2.32595","0.71750","0.05007"
"0.71687","2.28070","18.24034","10.69600","0.00000","2.28070","0.71687","0.05003"
"0.71667","2.25270","18.01636","11.09600","0.00000","2.25270","0.71667","0.05001"
"0.71667","2.21806","17.73936","11.49600","0.00000","2.21806","0.71667","0.05001"
"0.71667","2.20036","17.59778","11.89600","0.00000","2.20036","0.71667","0.05001"
"0.71667","2.17357","17.38355","12.29600","0.00000","2.17357","0.71667","0.05001"
"0.71667","2.15423","17.22885","12.69600","0.00000","2.15423","0.71667","0.05001"
"0.71667","2.13729","17.09335","13.09600","0.00000","2.13729","0.71667","0.05001"
"0.71667","2.12463","16.99216","13.49600","0.00000","2.12463","0.71667","0.05001"
"0.71667","2.10192","16.81046","13.89600","0.00000","2.10192","0.71667","0.05001"
"0.71667","2.08320","16.66080","14.29600","0.00000","2.08320","0.71667","0.05001"
"0.71667","2.07238","16.57426","14.69600","0.00000","2.07238","0.71667","0.05001"
"0.71667","2.06907","16.54775","15.09600","0.00000","2.06907","0.71667","0.05001"
"0.71667","2.04836","16.38213","15.49600","0.00000","2.04836","0.71667","0.05001"
"0.71667","2.04289","16.33840","15.89600","0.00000","2.04289","0.71667","0.05001"
"0.71667","2.02402","16.18746","16.29600","0.00000","2.02402","0.71667","0.05001"
"0.71667","2.01843","16.14273","16.69600","0.00000","2.01843","0.71667","0.05001"
"0.71667","2.00876","16.06540","17.09600","0.00000","2.00876","0.71667","0.05001"
"0.71667","1.99490","15.95459","17.49600","0.00000","1.99490","0.71667","0.05001"
"0.71667","1.98866","15.90467","17.89600","0.00000","1.98866","0.71667","0.05001"
"0.71667","1.98139","15.84657","18.29600","0.00000","1.98139","0.71667","0.05001"
"0.71667","1.96782","15.73797","18.69600","0.00000","1.96782","0.71667","0.05001"
"0.71667","1.95631","15.64596","19.09600","0.00000","1.95631","0.71667","0.05001"
"0.71667","1.95173","15.60930","19.49600","0.00000","1.95173","0.71667","0.05001"
"0.71667","1.94883","15.58611","19.89600","0.00000","1.94883","0.71667","0.05001"
"0.71667","1.93371","15.46523","20.29600","0.00000","1.93371","0.71667","0.05001"
"0.71667","1.92260","15.37638","20.69600","0.00000","1.92260","0.71667","0.05001"
"0.71667","1.91344","15.30306","21.09600","0.00000","1.91344","0.71667","0.05001"
"0.71667","1.91284","15.29829","21.49600","0.00000","1.91284","0.71667","0.05001"
"0.71667","1.90846","15.26328","21.89600","0.00000","1.90846","0.71667","0.05001"
"0.71667","1.90509","15.23634","22.29600","0.00000","1.90509","0.71667","0.05001"
"0.71667","1.89214","15.13272","22.69600","0.00000","1.89214","0.71667","0.05001"
"0.71667","1.89321","15.14129","23.09600","0.00000","1.89321","0.71667","0.05001"
"0.71667","1.88135","15.04646","23.49600","0.00000","1.88135","0.71667","0.05001"
"0.71667","1.87856","15.02417","23.89600","0.00000","1.87856","0.71667","0.05001"
"0.71667","1.87405","14.98810","24.29600","0.00000","1.87405","0.71667","0.05001"
"0.71667","1.87231","14.97417","24.69600","0.00000","1.87231","0.71667","0.05001"
"0.71667","1.86496","14.91535","25.09600","0.00000","1.86496","0.71667","0.05001"
"0.71667","1.84950","14.79173","25.49600","0.00000","1.84950","0.71667","0.05001"
"0.71667","1.85684","14.85044","25.89600","0.00000","1.85684","0.71667","0.05001"
"0.71667","1.85042","14.79907","26.29600","0.00000","1.85042","0.71667","0.05001"
"0.71667","1.84800","14.77975","26.69600","0.00000","1.84800","0.71667","0.05001"
"0.71667","1.84505","14.75610","27.09600","0.00000","1.84505","0.71667","0.05001"
"0.71667","1.82995","14.63536","27.49600","0.00000","1.82995","0.71667","0.05001"
"0.71667","1.83104","14.64411","27.89600","0.00000","1.83104","0.71667","0.05001"
"0.71646","1.82549","14.59972","28.29600","0.00000","1.82549","0.71646","0.05000"
"0.71646","1.82060","14.56055","28.69600","0.00000","1.82060","0.71646","0.05000"
"0.71646","1.81541","14.51908","29.09600","0.00000","1.81541","0.71646","0.05000"
"0.71646","1.80756","14.45627","29.49600","0.00000","1.80756","0.71646","0.05000"
"0.71646","1.80552","14.44001","29.89600","0.00000","1.80552","0.71646","0.05000"
"0.71646","1.80124","14.40579","30.29600","0.00000","1.80124","0.71646","0.05000"
"0.71646","1.79702","14.37200","30.69600","0.00000","1.79702","0.71646","0.05000"
"0.71646","1.79502","14.35598","31.09600","0.00000","1.79502","0.71646","0.05000"
"0.71646","1.78752","14.29604","31.49600","0.00000","1.78752","0.71646","0.05000"
"0.71646","1.78525","14.27791","31.89600","0.00000","1.78525","0.71646","0.05000"
"0.71646","1.77467","14.19323","32.29600","0.00000","1.77467","0.71646","0.05000"
"0.71646","1.77376","14.18595","32.69600","0.00000","1.77376","0.71646","0.05000"
"0.71646","1.77424","14.18979","33.09600","0.00000","1.77424","0.71646","0.05000"
"0.71646","1.77186","14.17082","33.49600","0.00000","1.77186","0.71646","0.05000"
"0.71646","1.76796","14.13962","33.89600","0.00000","1.76796","0.71646","0.05000"
"0.71646","1.75821","14.06164","34.29600","0.00000","1.75821","0.71646","0.05000"
"0.71646","1.75495","14.03550","34.69600","0.00000","1.75495","0.71646","0.05000"
"0.71646","1.75446","14.03160","35.09600","0.00000","1.75446","0.71646","0.05000"
"0.71646","1.75115","14.00514","35.49600","0.00000","1.75115","0.71646","0.05000"
"0.71646","1.74829","13.98227","35.89600","0.00000","1.74829","0.71646","0.05000"
"0.71646","1.74251","13.93606","36.29600","0.00000","1.74251","0.71646","0.05000"
"0.71646","1.74332","13.94255","36.69600","0.00000","1.74332","0.71646","0.05000"
"0.71646","1.74020","13.91760","37.09600","0.00000","1.74020","0.71646","0.05000"
"0.71646","1.73783","13.89866","37.49600","0.00000","1.73783","0.71646","0.05000"
"0.71646","1.73317","13.86134","37.89600","0.00000","1.73317","0.71646","0.05000"
"0.71646","1.73258","13.85660","38.29600","0.00000","1.73258","0.71646","0.05000"
"0.71646","1.72768","13.81742","38.69600","0.00000","1.72768","0.71646","0.05000"
"0.71646","1.72648","13.80781","39.09600","0.00000","1.72648","0.71646","0.05000"
"0.71646","1.71702","13.73216","39.49600","0.00000","1.71702","0.71646","0.05000"
"0.71646","1.71451","13.71210","39.89600","0.00000","1.71451","0.71646","0.05000"
"0.71646","1.72363","13.78507","40.29600","0.00000","1.72363","0.71646","0.05000"
"0.71646","1.71529","13.71832","40.69600","0.00000","1.71529","0.71646","0.05000"
"0.71646","1.70566","13.64135","41.09600","0.00000","1.70566","0.71646","0.05000"
"0.71646","1.70742","13.65542","41.49600","0.00000","1.70742","0.71646","0.05000"
"0.71646","1.70664","13.64919","41.89600","0.00000","1.70664","0.71646","0.05000"
"0.71646","1.70345","13.62367","42.29600","0.00000","1.70345","0.71646","0.05000"
"0.71646","1.70038","13.59912","42.69600","0.00000","1.70038","0.71646","0.05000"
"0.71646","1.70537","13.63898","43.09600","0.00000","1.70537","0.71646","0.05000"
"0.71646","1.69407","13.54861","43.49600","0.00000","1.69407","0.71646","0.05000"
"0.71646","1.69839","13.58323","43.89600","0.00000","1.69839","0.71646","0.05000"
"0.71646","1.69342","13.54347","44.29600","0.00000","1.69342","0.71646","0.05000"
"0.71646","1.68475","13.47407","44.69600","0.00000","1.68475","0.71646","0.05000"
"0.71646","1.68716","13.49338","45.09600","0.00000","1.68716","0.71646","0.05000"
"0.71646","1.68965","13.51327","45.49600","0.00000","1.68965","0.71646","0.05000"
"0.71646","1.68013","13.43717","45.89600","0.00000","1.68013","0.71646","0.05000"
"0.71646","1.67497","13.39590","46.29600","0.00000","1.67497","0.71646","0.05000"
"0.71646","1.67408","13.38877","46.69600","0.00000","1.67408","0.71646","0.05000"
"0.71646","1.67500","13.39609","47.09600","0.00000","1.67500","0.71646","0.05000"
"0.71646","1.67408","13.38879","47.49600","0.00000","1.67408","0.71646","0.05000"
"0.71646","1.66155","13.28855","47.89600","0.00000","1.66155","0.71646","0.05000"
"0.71646","1.67155","13.36850","48.29600","0.00000","1.67155","0.71646","0.05000"
"0.71646","1.67159","13.36889","48.69600","0.00000","1.67159","0.71646","0.05000"
"0.71646","1.66191","13.29142","49.09600","0.00000","1.66191","0.71646","0.05000"
"0.71646","1.66545","13.31976","49.49600","0.00000","1.66545","0.71646","0.05000"
"0.71646","1.66180","13.29053","49.89600","0.00000","1.66180","0.71646","0.05000"
"0.71646","1.65674","13.25009","50.29600","0.00000","1.65674","0.71646","0.05000"
"0.71646","1.65614","13.24530","50.69600","0.00000","1.65614","0.71646","0.05000"
"0.71646","1.65192","13.21151","51.09600","0.00000","1.65192","0.71646","0.05000"
"0.71646","1.64353","13.14447","51.49600","0.00000","1.64353","0.71646","0.05000"
"0.71646","1.63717","13.09357","51.89600","0.00000","1.63717","0.71646","0.05000"
"0.71646","1.63988","13.11522","52.29600","0.00000","1.63988","0.71646","0.05000"
"0.71646","1.64012","13.11717","52.69600","0.00000","1.64012","0.71646","0.05000"
"0.71646","1.63862","13.10519","53.09600","0.00000","1.63862","0.71646","0.05000"
"0.71646","1.64086","13.12309","53.49600","0.00000","1.64086","0.71646","0.05000"
"0.71646","1.62387","12.98720","53.89600","0.00000","1.62387","0.71646","0.05000"
"0.71646","1.63841","13.10349","54.29600","0.00000","1.63841","0.71646","0.05000"
"0.71646","1.62964","13.03337","54.69600","0.00000","1.62964","0.71646","0.05000"
"0.71646","1.62284","12.97898","55.09600","0.00000","1.62284","0.71646","0.05000"
"0.71646","1.62902","13.02837","55.49600","0.00000","1.62902","0.71646","0.05000"
"0.71646","1.62168","12.96973","55.89600","0.00000","1.62168","0.71646","0.05000"
"0.71646","1.62202","12.97238","56.29600","0.00000","1.62202","0.71646","0.05000"
"0.71646","1.61758","12.93687","56.69600","0.00000","1.61758","0.71646","0.05000"
"0.71646","1.61196","12.89191","57.09600","0.00000","1.61196","0.71646","0.05000"
"0.71646","1.61110","12.88507","57.49600","0.00000","1.61110","0.71646","0.05000"
"0.71646","1.60533","12.83889","57.89600","0.00000","1.60533","0.71646","0.05000"
"0.71646","1.60561","12.84116","58.29600","0.00000","1.60561","0.71646","0.05000"
"0.71646","1.60910","12.86909","58.69600","0.00000","1.60910","0.71646","0.05000"
"0.71646","1.60584","12.84297","59.09600","0.00000","1.60584","0.71646","0.05000"
"0.71646","1.60858","12.86490","59.49600","0.00000","1.60858","0.71646","0.05000"
"0.71646","1.60726","12.85440","59.89600","0.00000","1.60726","0.71646","0.05000"
"0.71646","1.60844","12.86379","60.29600","0.00000","1.60844","0.71646","0.05000"
"0.71646","1.60308","12.82091","60.69600","0.00000","1.60308","0.71646","0.05000"
"0.71646","1.59812","12.78123","61.09600","0.00000","1.59812","0.71646","0.05000"
"0.71646","1.59351","12.74440","61.49600","0.00000","1.59351","0.71646","0.05000"
"0.71646","1.59822","12.78203","61.89600","0.00000","1.59822","0.71646","0.05000"
"0.71646","1.59805","12.78067","62.29600","0.00000","1.59805","0.71646","0.05000"
"0.71646","1.59452","12.75250","62.69600","0.00000","1.59452","0.71646","0.05000"
"0.71646","1.59212","12.73330","63.09600","0.00000","1.59212","0.71646","0.05000"
"0.71646","1.59542","12.75970","63.49600","0.00000","1.59542","0.71646","0.05000"
"0.71646","1.59609","12.76505","63.89600","0.00000","1.59609","0.71646","0.05000"
"0.71646","1.59696","12.77197","64.29600","0.00000","1.59696","0.71646","0.05000"
"0.71646","1.59461","12.75319","64.69600","0.00000","1.59461","0.71646","0.05000"
"0.71646","1.59396","12.74797","65.09600","0.00000","1.59396","0.71646","0.05000"
"0.71646","1.58701","12.69241","65.49600","0.00000","1.58701","0.71646","0.05000"
"0.71646","1.58626","12.68638","65.89600","0.00000","1.58626","0.71646","0.05000"
"0.71646","1.58232","12.65487","66.29600","0.00000","1.58232","0.71646","0.05000"
"0.71646","1.58409","12.66905","66.69600","0.00000","1.58409","0.71646","0.05000"
"0.71646","1.58633","12.68699","67.09600","0.00000","1.58633","0.71646","0.05000"
"0.71646","1.58295","12.65993","67.49600","0.00000","1.58295","0.71646","0.05000"
"0.71646","1.58646","12.68797","67.89600","0.00000","1.58646","0.71646","0.05000"
"0.71646","1.58156","12.64885","68.29600","0.00000","1.58156","0.71646","0.05000"
"0.71646","1.58266","12.65761","68.69600","0.00000","1.58266","0.71646","0.05000"
"0.71646","1.58221","12.65401","69.09600","0.00000","1.58221","0.71646","0.05000"
"0.71646","1.58212","12.65329","69.49600","0.00000","1.58212","0.71646","0.05000"
"0.71646","1.57356","12.58481","69.89600","0.00000","1.57356","0.71646","0.05000"
"0.71646","1.58127","12.64650","70.29600","0.00000","1.58127","0.71646","0.05000"
"0.71646","1.57397","12.58812","70.69600","0.00000","1.57397","0.71646","0.05000"
"0.71646","1.57072","12.56215","71.09600","0.00000","1.57072","0.71646","0.05000"
"0.71646","1.57063","12.56142","71.49600","0.00000","1.57063","0.71646","0.05000"
"0.71646","1.56371","12.50604","71.89600","0.00000","1.56371","0.71646","0.05000"
"0.71646","1.56200","12.49242","72.29600","0.00000","1.56200","0.71646","0.05000"
"0.71646","1.55800","12.46037","72.69600","0.00000","1.55800","0.71646","0.05000"
"0.71646","1.56426","12.51047","73.09600","0.00000","1.56426","0.71646","0.05000"
"0.71646","1.55661","12.44930","73.49600","0.00000","1.55661","0.71646","0.05000"
"0.71646","1.55639","12.44749","73.89600","0.00000","1.55639","0.71646","0.05000"
"0.71646","1.55494","12.43592","74.29600","0.00000","1.55494","0.71646","0.05000"
"0.71646","1.55245","12.41604","74.69600","0.00000","1.55245","0.71646","0.05000"
"0.71646","1.55718","12.45387","75.09600","0.00000","1.55718","0.71646","0.05000"
"0.71646","1.55622","12.44616","75.49600","0.00000","1.55622","0.71646","0.05000"
"0.71646","1.55324","12.42232","75.89600","0.00000","1.55324","0.71646","0.05000"
"0.71646","1.55215","12.41364","76.29600","0.00000","1.55215","0.71646","0.05000"
"0.71646","1.54916","12.38973","76.69600","0.00000","1.54916","0.71646","0.05000"
"0.71646","1.53553","12.28068","77.09600","0.00000","1.53553","0.71646","0.05000"
"0.71646","1.53623","12.28632","77.49600","0.00000","1.53623","0.71646","0.05000"
"0.71646","1.53947","12.31220","77.89600","0.00000","1.53947","0.71646","0.05000"
"0.71646","1.53255","12.25688","78.29600","0.00000","1.53255","0.71646","0.05000"
"0.71646","1.54444","12.35197","78.69600","0.00000","1.54444","0.71646","0.05000"
"0.71646","1.54076","12.32253","79.09600","0.00000","1.54076","0.71646","0.05000"
"0.71646","1.54357","12.34499","79.49600","0.00000","1.54357","0.71646","0.05000"
"0.71646","1.54018","12.31791","79.89600","0.00000","1.54018","0.71646","0.05000"
"0.71646","1.53864","12.30559","80.29600","0.00000","1.53864","0.71646","0.05000"
"0.71646","1.54171","12.33014","80.69600","0.00000","1.54171","0.71646","0.05000"
"0.71646","1.54485","12.35521","81.09600","0.00000","1.54485","0.71646","0.05000"
"0.71646","1.53287","12.25937","81.49600","0.00000","1.53287","0.71646","0.05000"
"0.71646","1.53849","12.30434","81.89600","0.00000","1.53849","0.71646","0.05000"
"0.71646","1.52950","12.23244","82.29600","0.00000","1.52950","0.71646","0.05000"
"0.71646","1.53818","12.30185","82.69600","0.00000","1.53818","0.71646","0.05000"
"0.71646","1.53901","12.30849","83.09600","0.00000","1.53901","0.71646","0.05000"
"0.71646","1.53277","12.25859","83.49600","0.00000","1.53277","0.71646","0.05000"
"0.71646","1.53090","12.24368","83.89600","0.00000","1.53090","0.71646","0.05000"
"0.71646","1.53164","12.24955","84.29600","0.00000","1.53164","0.71646","0.05000"
"0.71646","1.53581","12.28295","84.69600","0.00000","1.53581","0.71646","0.05000"
"0.71646","1.53092","12.24382","85.09600","0.00000","1.53092","0.71646","0.05000"
"0.71646","1.53718","12.29387","85.49600","0.00000","1.53718","0.71646","0.05000"
"0.71646","1.52797","12.22025","85.89600","0.00000","1.52797","0.71646","0.05000"
"0.71646","1.52992","12.23585","86.29600","0.00000","1.52992","0.71646","0.05000"
"0.71646","1.52374","12.18636","86.69600","0.00000","1.52374","0.71646","0.05000"
"0.71646","1.52758","12.21710","87.09600","0.00000","1.52758","0.71646","0.05000"
"0.71646","1.53297","12.26023","87.49600","0.00000","1.53297","0.71646","0.05000"
"0.71646","1.52380","12.18690","87.89600","0.00000","1.52380","0.71646","0.05000"
"0.71646","1.52920","12.23008","88.29600","0.00000","1.52920","0.71646","0.05000"
"0.71646","1.53390","12.26766","88.69600","0.00000","1.53390","0.71646","0.05000"
"0.71646","1.52443","12.19192","89.09600","0.00000","1.52443","0.71646","0.05000"
"0.71646","1.52443","12.19193","89.49600","0.00000","1.52443","0.71646","0.05000"
"0.71646","1.52139","12.16761","89.89600","0.00000","1.52139","0.71646","0.05000"
"0.71646","1.51350","12.10448","90.29600","0.00000","1.51350","0.71646","0.05000"
"0.71646","1.50547","12.04024","90.69600","0.00000","1.50547","0.71646","0.05000"
"0.71646","1.52000","12.15647","91.09600","0.00000","1.52000","0.71646","0.05000"
"0.71646","1.51529","12.11884","91.49600","0.00000","1.51529","0.71646","0.05000"
"0.71646","1.51883","12.14713","91.89600","0.00000","1.51883","0.71646","0.05000"
"0.71646","1.51837","12.14341","92.29600","0.00000","1.51837","0.71646","0.05000"
"0.71646","1.52727","12.21461","92.69600","0.00000","1.52727","0.71646","0.05000"
"0.71646","1.52713","12.21347","93.09600","0.00000","1.52713","0.71646","0.05000"
"0.71646","1.51422","12.11028","93.49600","0.00000","1.51422","0.71646","0.05000"
"0.71646","1.51819","12.14198","93.89600","0.00000","1.51819","0.71646","0.05000"
"0.71646","1.51807","12.14102","94.29600","0.00000","1.51807","0.71646","0.05000"
"0.71646","1.51211","12.09335","94.69600","0.00000","1.51211","0.71646","0.05000"
"0.71646","1.50850","12.06448","95.09600","0.00000","1.50850","0.71646","0.05000"
"0.71646","1.50072","12.00225","95.49600","0.00000","1.50072","0.71646","0.05000"
"0.71646","1.50351","12.02457","95.89600","0.00000","1.50351","0.71646","0.05000"
"0.71646","1.50097","12.00427","96.29600","0.00000","1.50097","0.71646","0.05000"
"0.71646","1.49905","11.98893","96.69600","0.00000","1.49905","0.71646","0.05000"
"0.71646","1.49989","11.99568","97.09600","0.00000","1.49989","0.71646","0.05000"
"0.71646","1.49989","11.99562","97.49600","0.00000","1.49989","0.71646","0.05000"
"0.71646","1.49438","11.95160","97.89600","0.00000","1.49438","0.71646","0.05000"
"0.71646","1.50103","12.00480","98.29600","0.00000","1.50103","0.71646","0.05000"
"0.71646","1.48731","11.89502","98.69600","0.00000","1.48731","0.71646","0.05000"
"0.71646","1.49248","11.93640","99.09600","0.00000","1.49248","0.71646","0.05000"
"0.71646","1.48934","11.91125","99.49600","0.00000","1.48934","0.71646","0.05000"
"0.71646","1.49845","11.98415","99.89600","0.00000","1.49845","0.71646","0.05000"
"0.71646","1.48627","11.88675","100.29600","0.00000","1.48627","0.71646","0.05000"
"0.71646","1.48917","11.90989","100.69600","0.00000","1.48917","0.71646","0.05000"
"0.71646","1.49355","11.94490","101.09600","0.00000","1.49355","0.71646","0.05000"
"0.71646","1.48807","11.90111","101.49600","0.00000","1.48807","0.71646","0.05000"
"0.71646","1.48923","11.91043","101.89600","0.00000","1.48923","0.71646","0.05000"
"0.71646","1.48357","11.86514","102.29600","0.00000","1.48357","0.71646","0.05000"
"0.71646","1.49212","11.93351","102.69600","0.00000","1.49212","0.71646","0.05000"
"0.71646","1.48990","11.91578","103.09600","0.00000","1.48990","0.71646","0.05000"
"0.71646","1.48329","11.86290","103.49600","0.00000","1.48329","0.71646","0.05000"
"0.71646","1.47894","11.82808","103.89600","0.00000","1.47894","0.71646","0.05000"
"0.71646","1.48251","11.85663","104.29600","0.00000","1.48251","0.71646","0.05000"
"0.71646","1.48735","11.89533","104.69600","0.00000","1.48735","0.71646","0.05000"
"0.71646","1.49125","11.92658","105.09600","0.00000","1.49125","0.71646","0.05000"
"0.71646","1.48078","11.84282","105.49600","0.00000","1.48078","0.71646","0.05000"
"0.71646","1.47754","11.81690","105.89600","0.00000","1.47754","0.71646","0.05000"
"0.71646","1.47486","11.79543","106.29600","0.00000","1.47486","0.71646","0.05000"
"0.71646","1.47049","11.76048","106.69600","0.00000","1.47049","0.71646","0.05000"
"0.71646","1.47673","11.81044","107.09600","0.00000","1.47673","0.71646","0.05000"
"0.71646","1.47127","11.76677","107.49600","0.00000","1.47127","0.71646","0.05000"
"0.71646","1.47586","11.80350","107.89600","0.00000","1.47586","0.71646","0.05000"
"0.71646","1.47208","11.77326","108.29600","0.00000","1.47208","0.71646","0.05000"
"0.71646","1.46760","11.73744","108.69600","0.00000","1.46760","0.71646","0.05000"
"0.71646","1.47400","11.78856","109.09600","0.00000","1.47400","0.71646","0.05000"
"0.71646","1.47709","11.81329","109.49600","0.00000","1.47709","0.71646","0.05000"
"0.71646","1.46666","11.72985","109.89600","0.00000","1.46666","0.71646","0.05000"
"0.71646","1.46528","11.71885","110.29600","0.00000","1.46528","0.71646","0.05000"
"0.71646","1.46559","11.72133","110.69600","0.00000","1.46559","0.71646","0.05000"
"0.71646","1.46934","11.75131","111.09600","0.00000","1.46934","0.71646","0.05000"
"0.71646","1.45806","11.66113","111.49600","0.00000","1.45806","0.71646","0.05000"
"0.71646","1.46703","11.73281","111.89600","0.00000","1.46703","0.71646","0.05000"
"0.71646","1.46083","11.68330","112.29600","0.00000","1.46083","0.71646","0.05000"
"0.71646","1.46944","11.75213","112.69600","0.00000","1.46944","0.71646","0.05000"
"0.71646","1.46584","11.72334","113.09600","0.00000","1.46584","0.71646","0.05000"
"0.71646","1.46139","11.68771","113.49600","0.00000","1.46139","0.71646","0.05000"
"0.71646","1.46844","11.74416","113.89600","0.00000","1.46844","0.71646","0.05000"
"0.71646","1.46597","11.72437","114.29600","0.00000","1.46597","0.71646","0.05000"
"0.71646","1.46240","11.69580","114.69600","0.00000","1.46240","0.71646","0.05000"
"0.71646","1.46371","11.70633","115.09600","0.00000","1.46371","0.71646","0.05000"
"0.71646","1.46159","11.68934","115.49600","0.00000","1.46159","0.71646","0.05000"
"0.71646","1.46199","11.69254","115.89600","0.00000","1.46199","0.71646","0.05000"
"0.71646","1.46559","11.72133","116.29600","0.00000","1.46559","0.71646","0.05000"
"0.71646","1.45812","11.66159","116.69600","0.00000","1.45812","0.71646","0.05000"
"0.71646","1.45665","11.64983","117.09600","0.00000","1.45665","0.71646","0.05000"
"0.71646","1.45360","11.62543","117.49600","0.00000","1.45360","0.71646","0.05000"
"0.71646","1.45909","11.66933","117.89600","0.00000","1.45909","0.71646","0.05000"
"0.71646","1.46063","11.68169","118.29600","0.00000","1.46063","0.71646","0.05000"
"0.71646","1.46189","11.69170","118.69600","0.00000","1.46189","0.71646","0.05000"
"0.71646","1.45897","11.66842","119.09600","0.00000","1.45897","0.71646","0.05000"
"0.71646","1.45954","11.67292","119.49600","0.00000","1.45954","0.71646","0.05000"
"0.71646","1.45497","11.63637","119.89600","0.00000","1.45497","0.71646","0.05000"
"0.71646","1.46130","11.68700","120.29600","0.00000","1.46130","0.71646","0.05000"
"0.71646","1.45543","11.64008","120.69600","0.00000","1.45543","0.71646","0.05000"
"0.71646","1.45763","11.65768","121.09600","0.00000","1.45763","0.71646","0.05000"
"0.71646","1.44791","11.57991","121.49600","0.00000","1.44791","0.71646","0.05000"
"0.71646","1.44877","11.58682","121.89600","0.00000","1.44877","0.71646","0.05000"
"0.71646","1.44798","11.58047","122.29600","0.00000","1.44798","0.71646","0.05000"
"0.71646","1.44690","11.57189","122.69600","0.00000","1.44690","0.71646","0.05000"
"0.71646","1.44455","11.55302","123.09600","0.00000","1.44455","0.71646","0.05000"
"0.71646","1.43849","11.50460","123.49600","0.00000","1.43849","0.71646","0.05000"
"0.71646","1.44872","11.58638","123.89600","0.00000","1.44872","0.71646","0.05000"
"0.71646","1.44396","11.54837","124.29600","0.00000","1.44396","0.71646","0.05000"
"0.71646","1.44539","11.55980","124.69600","0.00000","1.44539","0.71646","0.05000"
"0.71646","1.45068","11.60210","125.09600","0.00000","1.45068","0.71646","0.05000"
"0.71646","1.44955","11.59308","125.49600","0.00000","1.44955","0.71646","0.05000"
"0.71646","1.44106","11.52513","125.89600","0.00000","1.44106","0.71646","0.05000"
"0.71646","1.44493","11.55612","126.29600","0.00000","1.44493","0.71646","0.05000"
"0.71646","1.44975","11.59466","126.69600","0.00000","1.44975","0.71646","0.05000"
"0.71646","1.44942","11.59198","127.09600","0.00000","1.44942","0.71646","0.05000"
"0.71646","1.44434","11.55137","127.49600","0.00000","1.44434","0.71646","0.05000"
"0.71646","1.44326","11.54271","127.89600","0.00000","1.44326","0.71646","0.05000"
"0.71646","1.44759","11.57738","128.29600","0.00000","1.44759","0.71646","0.05000"
"0.71646","1.45238","11.61566","128.69600","0.00000","1.45238","0.71646","0.05000"
"0.71646","1.44578","11.56290","129.09600","0.00000","1.44578","0.71646","0.05000"
"0.71646","1.44763","11.57769","129.49600","0.00000","1.44763","0.71646","0.05000"
"0.71646","1.45200","11.61267","129.89600","0.00000","1.45200","0.71646","0.05000"
"0.71646","1.44038","11.51974","130.29600","0.00000","1.44038","0.71646","0.05000"
"0.71646","1.45448","11.63250","130.69600","0.00000","1.45448","0.71646","0.05000"
"0.71646","1.44458","11.55333","131.09600","0.00000","1.44458","0.71646","0.05000"
"0.71646","1.44817","11.58197","131.49600","0.00000","1.44817","0.71646","0.05000"
"0.71646","1.44175","11.53065","131.89600","0.00000","1.44175","0.71646","0.05000"
"0.71646","1.43774","11.49859","132.29600","0.00000","1.43774","0.71646","0.05000"
"0.71646","1.43918","11.51014","132.69600","0.00000","1.43918","0.71646","0.05000"
"0.71646","1.43301","11.46074","133.09600","0.00000","1.43301","0.71646","0.05000"
"0.71646","1.42975","11.43470","133.49600","0.00000","1.42975","0.71646","0.05000"
"0.71646","1.43697","11.49241","133.89600","0.00000","1.43697","0.71646","0.05000"
"0.71646","1.43435","11.47145","134.29600","0.00000","1.43435","0.71646","0.05000"
"0.71646","1.43394","11.46818","134.69600","0.00000","1.43394","0.71646","0.05000"
"0.71646","1.43650","11.48868","135.09600","0.00000","1.43650","0.71646","0.05000"
"0.71646","1.43894","11.50817","135.49600","0.00000","1.43894","0.71646","0.05000"
"0.71646","1.42647","11.40843","135.89600","0.00000","1.42647","0.71646","0.05000"
"0.71646","1.43052","11.44083","136.29600","0.00000","1.43052","0.71646","0.05000"
"0.71646","1.43046","11.44036","136.69600","0.00000","1.43046","0.71646","0.05000"
"0.71646","1.43186","11.45156","137.09600","0.00000","1.43186","0.71646","0.05000"
"0.71646","1.43021","11.43835","137.49600","0.00000","1.43021","0.71646","0.05000"
"0.71646","1.42899","11.42861","137.89600","0.00000","1.42899","0.71646","0.05000"
"0.71646","1.42651","11.40881","138.29600","0.00000","1.42651","0.71646","0.05000"
"0.71646","1.43772","11.49842","138.69600","0.00000","1.43772","0.71646","0.05000"
"0.71646","1.42897","11.42842","139.09600","0.00000","1.42897","0.71646","0.05000"
"0.71646","1.43482","11.47521","139.49600","0.00000","1.43482","0.71646","0.05000"
"0.71646","1.42444","11.39222","139.89600","0.00000","1.42444","0.71646","0.05000"
"0.71646","1.43022","11.43846","140.29600","0.00000","1.43022","0.71646","0.05000"
"0.71646","1.43078","11.44293","140.69600","0.00000","1.43078","0.71646","0.05000"
"0.71646","1.42767","11.41808","141.09600","0.00000","1.42767","0.71646","0.05000"
"0.71646","1.42885","11.42753","141.49600","0.00000","1.42885","0.71646","0.05000"
"0.71646","1.42410","11.38950","141.89600","0.00000","1.42410","0.71646","0.05000"
"0.71646","1.42483","11.39538","142.29600","0.00000","1.42483","0.71646","0.05000"
"0.71646","1.42027","11.35889","142.69600","0.00000","1.42027","0.71646","0.05000"
"0.71646","1.42115","11.36593","143.09600","0.00000","1.42115","0.71646","0.05000"
"0.71646","1.41536","11.31961","143.49600","0.00000","1.41536","0.71646","0.05000"
"0.71646","1.41517","11.31812","143.89600","0.00000","1.41517","0.71646","0.05000"
"0.71646","1.41570","11.32234","144.29600","0.00000","1.41570","0.71646","0.05000"
"0.71646","1.42009","11.35746","144.69600","0.00000","1.42009","0.71646","0.05000"
"0.71646","1.41898","11.34852","145.09600","0.00000","1.41898","0.71646","0.05000"
"0.71646","1.41036","11.27961","145.49600","0.00000","1.41036","0.71646","0.05000"
"0.71646","1.40719","11.25429","145.89600","0.00000","1.40719","0.71646","0.05000"
"0.71646","1.40244","11.21627","146.29600","0.00000","1.40244","0.71646","0.05000"
"0.71646","1.40707","11.25333","146.69600","0.00000","1.40707","0.71646","0.05000"
"0.71646","1.39849","11.18467","147.09600","0.00000","1.39849","0.71646","0.05000"
"0.71646","1.40525","11.23876","147.49600","0.00000","1.40525","0.71646","0.05000"
"0.71646","1.40162","11.20970","147.89600","0.00000","1.40162","0.71646","0.05000"
"0.71646","1.40637","11.24774","148.29600","0.00000","1.40637","0.71646","0.05000"
"0.71646","1.40374","11.22665","148.69600","0.00000","1.40374","0.71646","0.05000"
"0.71646","1.40390","11.22792","149.09600","0.00000","1.40390","0.71646","0.05000"
"0.71646","1.39728","11.17498","149.49600","0.00000","1.39728","0.71646","0.05000"
"0.71646","1.40108","11.20538","149.89600","0.00000","1.40108","0.71646","0.05000"
"0.71646","1.41043","11.28021","150.29600","0.00000","1.41043","0.71646","0.05000"
"0.71646","1.40753","11.25702","150.69600","0.00000","1.40753","0.71646","0.05000"
"0.71646","1.39836","11.18365","151.09600","0.00000","1.39836","0.71646","0.05000"
"0.71646","1.39960","11.19356","151.49600","0.00000","1.39960","0.71646","0.05000"
"0.71646","1.40118","11.20620","151.89600","0.00000","1.40118","0.71646","0.05000"
"0.71646","1.40309","11.22151","152.29600","0.00000","1.40309","0.71646","0.05000"
"0.71646","1.40677","11.25087","152.69600","0.00000","1.40677","0.71646","0.05000"
"0.71646","1.39837","11.18372","153.09600","0.00000","1.39837","0.71646","0.05000"
"0.71646","1.41517","11.31805","153.49600","0.00000","1.41517","0.71646","0.05000"
"0.71646","1.40558","11.24137","153.89600","0.00000","1.40558","0.71646","0.05000"
"0.71646","1.40557","11.24131","154.29600","0.00000","1.40557","0.71646","0.05000"
"0.71646","1.40967","11.27408","154.69600","0.00000","1.40967","0.71646","0.05000"
"0.71646","1.41170","11.29035","155.09600","0.00000","1.41170","0.71646","0.05000"
"0.71646","1.40599","11.24465","155.49600","0.00000","1.40599","0.71646","0.05000"
"0.71646","1.40612","11.24568","155.89600","0.00000","1.40612","0.71646","0.05000"
"0.71646","1.40238","11.21582","156.29600","0.00000","1.40238","0.71646","0.05000"
"0.71646","1.39945","11.19236","156.69600","0.00000","1.39945","0.71646","0.05000"
"0.71646","1.39588","11.16385","157.09600","0.00000","1.39588","0.71646","0.05000"
"0.71646","1.40117","11.20613","157.49600","0.00000","1.40117","0.71646","0.05000"
"0.71646","1.41447","11.31251","157.89600","0.00000","1.41447","0.71646","0.05000"
"0.71646","1.39887","11.18774","158.29600","0.00000","1.39887","0.71646","0.05000"
"0.71646","1.40464","11.23384","158.69600","0.00000","1.40464","0.71646","0.05000"
"0.71646","1.40412","11.22971","159.09600","0.00000","1.40412","0.71646","0.05000"
"0.71646","1.40328","11.22301","159.49600","0.00000","1.40328","0.71646","0.05000"
"0.71646","1.39843","11.18420","159.89600","0.00000","1.39843","0.71646","0.05000"
"0.71646","1.40176","11.21083","160.29600","0.00000","1.40176","0.71646","0.05000"
"0.71646","1.40087","11.20373","160.69600","0.00000","1.40087","0.71646","0.05000"
"0.71646","1.40458","11.23342","161.09600","0.00000","1.40458","0.71646","0.05000"
"0.71646","1.39865","11.18595","161.49600","0.00000","1.39865","0.71646","0.05000"
"0.71646","1.39971","11.19442","161.89600","0.00000","1.39971","0.71646","0.05000"
"0.71646","1.40283","11.21942","162.29600","0.00000","1.40283","0.71646","0.05000"
"0.71646","1.40126","11.20684","162.69600","0.00000","1.40126","0.71646","0.05000"
"0.71646","1.40334","11.22351","163.09600","0.00000","1.40334","0.71646","0.05000"
"0.71646","1.40060","11.20154","163.49600","0.00000","1.40060","0.71646","0.05000"
"0.71646","1.39789","11.17989","163.89600","0.00000","1.39789","0.71646","0.05000"
"0.71646","1.39950","11.19275","164.29600","0.00000","1.39950","0.71646","0.05000"
"0.71646","1.40361","11.22567","164.69600","0.00000","1.40361","0.71646","0.05000"
"0.71646","1.39903","11.18904","165.09600","0.00000","1.39903","0.71646","0.05000"
"0.71646","1.41009","11.27744","165.49600","0.00000","1.41009","0.71646","0.05000"
"0.71646","1.40758","11.25735","165.89600","0.00000","1.40758","0.71646","0.05000"
"0.71646","1.39978","11.19499","166.29600","0.00000","1.39978","0.71646","0.05000"
"0.71646","1.40008","11.19743","166.69600","0.00000","1.40008","0.71646","0.05000"
"0.71646","1.39243","11.13624","167.09600","0.00000","1.39243","0.71646","0.05000"
"0.71646","1.39663","11.16983","167.49600","0.00000","1.39663","0.71646","0.05000"
"0.71646","1.40446","11.23243","167.89600","0.00000","1.40446","0.71646","0.05000"
"0.71646","1.40360","11.22558","168.29600","0.00000","1.40360","0.71646","0.05000"
"0.71646","1.40294","11.22024","168.69600","0.00000","1.40294","0.71646","0.05000"
"0.71646","1.40199","11.21265","169.09600","0.00000","1.40199","0.71646","0.05000"
"0.71646","1.40214","11.21388","169.49600","0.00000","1.40214","0.71646","0.05000"
"0.71646","1.39839","11.18390","169.89600","0.00000","1.39839","0.71646","0.05000"
"0.71646","1.40942","11.27210","170.29600","0.00000","1.40942","0.71646","0.05000"
"0.71646","1.40497","11.23647","170.69600","0.00000","1.40497","0.71646","0.05000"
"0.71646","1.39777","11.17889","171.09600","0.00000","1.39777","0.71646","0.05000"
"0.71646","1.40153","11.20901","171.49600","0.00000","1.40153","0.71646","0.05000"
"0.71646","1.40448","11.23259","171.89600","0.00000","1.40448","0.71646","0.05000"
"0.71646","1.40066","11.20207","172.29600","0.00000","1.40066","0.71646","0.05000"
"0.71646","1.39252","11.13697","172.69600","0.00000","1.39252","0.71646","0.05000"
"0.71646","1.39665","11.16994","173.09600","0.00000","1.39665","0.71646","0.05000"
"0.71646","1.39591","11.16404","173.49600","0.00000","1.39591","0.71646","0.05000"
"0.71646","1.40116","11.20603","173.89600","0.00000","1.40116","0.71646","0.05000"
"0.71646","1.39652","11.16897","174.29600","0.00000","1.39652","0.71646","0.05000"
"0.71646","1.39669","11.17030","174.69600","0.00000","1.39669","0.71646","0.05000"
"0.71646","1.39726","11.17486","175.09600","0.00000","1.39726","0.71646","0.05000"
"0.71646","1.38585","11.08361","175.49600","0.00000","1.38585","0.71646","0.05000"
"0.71646","1.38951","11.11283","175.89600","0.00000","1.38951","0.71646","0.05000"
"0.71646","1.39431","11.15123","176.29600","0.00000","1.39431","0.71646","0.05000"
"0.71646","1.39520","11.15836","176.69600","0.00000","1.39520","0.71646","0.05000"
"0.71646","1.39536","11.15965","177.09600","0.00000","1.39536","0.71646","0.05000"
"0.71646","1.38932","11.11131","177.49600","0.00000","1.38932","0.71646","0.05000"
"0.71646","1.38950","11.11275","177.89600","0.00000","1.38950","0.71646","0.05000"
"0.71646","1.39133","11.12743","178.29600","0.00000","1.39133","0.71646","0.05000"
"0.71646","1.39198","11.13261","178.69600","0.00000","1.39198","0.71646","0.05000"
"0.71646","1.39044","11.12029","179.09600","0.00000","1.39044","0.71646","0.05000"
"0.71646","1.39151","11.12885","179.49600","0.00000","1.39151","0.71646","0.05000"
"0.71646","1.39838","11.18384","179.89600","0.00000","1.39838","0.71646","0.05000"
"0.71646","1.39345","11.14436","180.29600","0.00000","1.39345","0.71646","0.05000"
"0.71646","1.38881","11.10723","180.69600","0.00000","1.38881","0.71646","0.05000"
"0.71646","1.38618","11.08622","181.09600","0.00000","1.38618","0.71646","0.05000"
"0.71646","1.37955","11.03324","181.49600","0.00000","1.37955","0.71646","0.05000"
"0.71646","1.38766","11.09807","181.89600","0.00000","1.38766","0.71646","0.05000"
"0.71646","1.38318","11.06222","182.29600","0.00000","1.38318","0.71646","0.05000"
"0.71646","1.37454","10.99315","182.69600","0.00000","1.37454","0.71646","0.05000"
"0.71646","1.37059","10.96158","183.09600","0.00000","1.37059","0.71646","0.05000"
"0.71646","1.37566","11.00208","183.49600","0.00000","1.37566","0.71646","0.05000"
"0.71646","1.37918","11.03024","183.89600","0.00000","1.37918","0.71646","0.05000"
"0.71646","1.37742","11.01617","184.29600","0.00000","1.37742","0.71646","0.05000"
"0.71646","1.38080","11.04321","184.69600","0.00000","1.38080","0.71646","0.05000"
"0.71646","1.38131","11.04731","185.09600","0.00000","1.38131","0.71646","0.05000"
"0.71646","1.38022","11.03856","185.49600","0.00000","1.38022","0.71646","0.05000"
"0.71646","1.37223","10.97463","185.89600","0.00000","1.37223","0.71646","0.05000"
"0.71646","1.37884","11.02753","186.29600","0.00000","1.37884","0.71646","0.05000"
"0.71646","1.37576","11.00290","186.69600","0.00000","1.37576","0.71646","0.05000"
"0.71646","1.37945","11.03243","187.09600","0.00000","1.37945","0.71646","0.05000"
"0.71646","1.37288","10.97985","187.49600","0.00000","1.37288","0.71646","0.05000"
"0.71646","1.37037","10.95982","187.89600","0.00000","1.37037","0.71646","0.05000"
"0.71646","1.37923","11.03065","188.29600","0.00000","1.37923","0.71646","0.05000"
"0.71646","1.37036","10.95969","188.59600","0.00000","1.37036","0.71646","0.05000"