File: G2 -Fresh stress relaxation-20210318/Specimen_RawData_2.csv
Specimen properties : Specimen label,"sample2"
Specimen properties : Diameter,"0.34300",mm
Specimen properties : Length,"13.08000",mm
Test : Rate 1,"5.00000",mm/min
Test : Start of hold value,"0.05000",mm/mm
Test : Delta,"180.00000",s

Extension,Load,Tensile stress,Time,PIP count,Tenacity,Tensile extension,Tensile strain (Extension)
(mm),(N),(MPa),(s),,(N/tex),(mm),(mm/mm)
"0.00000","-0.00244","-0.02636","0.00000","0.00000","-0.00244","0.00000","0.00000"
"0.03187","0.01202","0.13006","0.40000","0.00000","0.01202","0.03187","0.00244"
"0.06667","0.01233","0.13341","0.80000","0.00000","0.01233","0.06667","0.00510"
"0.10000","0.04038","0.43696","1.20000","0.00000","0.04038","0.10000","0.00765"
"0.13333","0.06719","0.72712","1.60000","0.00000","0.06719","0.13333","0.01019"
"0.16646","0.10674","1.15513","2.00000","0.00000","0.10674","0.16646","0.01273"
"0.20021","0.15075","1.63151","2.40000","0.00000","0.15075","0.20021","0.01531"
"0.23375","0.21103","2.28388","2.80000","0.00000","0.21103","0.23375","0.01787"
"0.26708","0.27630","2.99018","3.20000","0.00000","0.27630","0.26708","0.02042"
"0.30021","0.34426","3.72575","3.60000","0.00000","0.34426","0.30021","0.02295"
"0.33333","0.41382","4.47851","4.00000","0.00000","0.41382","0.33333","0.02548"
"0.36667","0.49925","5.40307","4.40000","0.00000","0.49925","0.36667","0.02803"
"0.40042","0.60023","6.49588","4.80000","0.00000","0.60023","0.40042","0.03061"
"0.43375","0.70436","7.62288","5.20000","0.00000","0.70436","0.43375","0.03316"
"0.46708","0.81773","8.84982","5.60000","0.00000","0.81773","0.46708","0.03571"
"0.50000","0.92279","9.98675","6.00000","0.00000","0.92279","0.50000","0.03823"
"0.53354","1.04420","11.30075","6.40000","0.00000","1.04420","0.53354","0.04079"
"0.56687","1.15845","12.53721","6.80000","0.00000","1.15845","0.56687","0.04334"
"0.60021","1.27653","13.81503","7.20000","0.00000","1.27653","0.60021","0.04589"
"0.63354","1.39098","15.05367","7.60000","0.00000","1.39098","0.63354","0.04844"
"0.65437","1.46669","15.87309","7.85200","0.00000","1.46669","0.65437","0.05003"
"0.65667","1.38830","15.02472","8.25200","0.00000","1.38830","0.65667","0.05020"
"0.65667","1.33172","14.41240","8.65200","0.00000","1.33172","0.65667","0.05020"
"0.65604","1.29521","14.01717","9.05200","0.00000","1.29521","0.65604","0.05016"
"0.65542","1.25552","13.58771","9.45200","0.00000","1.25552","0.65542","0.05011"
"0.65479","1.23737","13.39128","9.85200","0.00000","1.23737","0.65479","0.05006"
"0.65458","1.21390","13.13731","10.25200","0.00000","1.21390","0.65458","0.05004"
"0.65437","1.20816","13.07512","10.65200","0.00000","1.20816","0.65437","0.05003"
"0.65437","1.18232","12.79550","11.05200","0.00000","1.18232","0.65437","0.05003"
"0.65437","1.17397","12.70515","11.45200","0.00000","1.17397","0.65437","0.05003"
"0.65437","1.16128","12.56776","11.85200","0.00000","1.16128","0.65437","0.05003"
"0.65437","1.15820","12.53450","12.25200","0.00000","1.15820","0.65437","0.05003"
"0.65437","1.14376","12.37822","12.65200","0.00000","1.14376","0.65437","0.05003"
"0.65437","1.13855","12.32181","13.05200","0.00000","1.13855","0.65437","0.05003"
"0.65437","1.13431","12.27586","13.45200","0.00000","1.13431","0.65437","0.05003"
"0.65437","1.12108","12.13278","13.85200","0.00000","1.12108","0.65437","0.05003"
"0.65437","1.11202","12.03465","14.25200","0.00000","1.11202","0.65437","0.05003"
"0.65437","1.10852","11.99677","14.65200","0.00000","1.10852","0.65437","0.05003"
"0.65437","1.10300","11.93705","15.05200","0.00000","1.10300","0.65437","0.05003"
"0.65437","1.09575","11.85855","15.45200","0.00000","1.09575","0.65437","0.05003"
"0.65437","1.09284","11.82715","15.85200","0.00000","1.09284","0.65437","0.05003"
"0.65437","1.09120","11.80934","16.25200","0.00000","1.09120","0.65437","0.05003"
"0.65437","1.08401","11.73156","16.65200","0.00000","1.08401","0.65437","0.05003"
"0.65437","1.08291","11.71968","17.05200","0.00000","1.08291","0.65437","0.05003"
"0.65437","1.07143","11.59537","17.45200","0.00000","1.07143","0.65437","0.05003"
"0.65437","1.07451","11.62876","17.85200","0.00000","1.07451","0.65437","0.05003"
"0.65437","1.06603","11.53695","18.25200","0.00000","1.06603","0.65437","0.05003"
"0.65437","1.06524","11.52837","18.65200","0.00000","1.06524","0.65437","0.05003"
"0.65437","1.06261","11.49995","19.05200","0.00000","1.06261","0.65437","0.05003"
"0.65437","1.05065","11.37052","19.45200","0.00000","1.05065","0.65437","0.05003"
"0.65437","1.05683","11.43737","19.85200","0.00000","1.05683","0.65437","0.05003"
"0.65437","1.04907","11.35343","20.25200","0.00000","1.04907","0.65437","0.05003"
"0.65437","1.04141","11.27050","20.65200","0.00000","1.04141","0.65437","0.05003"
"0.65437","1.04363","11.29449","21.05200","0.00000","1.04363","0.65437","0.05003"
"0.65437","1.03429","11.19341","21.45200","0.00000","1.03429","0.65437","0.05003"
"0.65437","1.03491","11.20014","21.85200","0.00000","1.03491","0.65437","0.05003"
"0.65437","1.03754","11.22864","22.25200","0.00000","1.03754","0.65437","0.05003"
"0.65437","1.03197","11.16833","22.65200","0.00000","1.03197","0.65437","0.05003"
"0.65437","1.03090","11.15673","23.05200","0.00000","1.03090","0.65437","0.05003"
"0.65437","1.02857","11.13159","23.45200","0.00000","1.02857","0.65437","0.05003"
"0.65437","1.03054","11.15288","23.85200","0.00000","1.03054","0.65437","0.05003"
"0.65437","1.02408","11.08293","24.25200","0.00000","1.02408","0.65437","0.05003"
"0.65437","1.02054","11.04467","24.65200","0.00000","1.02054","0.65437","0.05003"
"0.65437","1.01742","11.01088","25.05200","0.00000","1.01742","0.65437","0.05003"
"0.65437","1.01009","10.93152","25.45200","0.00000","1.01009","0.65437","0.05003"
"0.65437","1.01616","10.99720","25.85200","0.00000","1.01616","0.65437","0.05003"
"0.65437","1.01658","11.00177","26.25200","0.00000","1.01658","0.65437","0.05003"
"0.65437","1.01312","10.96440","26.65200","0.00000","1.01312","0.65437","0.05003"
"0.65437","1.01654","11.00131","27.05200","0.00000","1.01654","0.65437","0.05003"
"0.65437","1.00489","10.87530","27.45200","0.00000","1.00489","0.65437","0.05003"
"0.65437","1.00530","10.87974","27.85200","0.00000","1.00530","0.65437","0.05003"
"0.65437","0.99538","10.77238","28.25200","0.00000","0.99538","0.65437","0.05003"
"0.65437","0.99780","10.79851","28.65200","0.00000","0.99780","0.65437","0.05003"
"0.65437","0.99720","10.79207","29.05200","0.00000","0.99720","0.65437","0.05003"
"0.65437","0.99811","10.80188","29.45200","0.00000","0.99811","0.65437","0.05003"
"0.65437","0.99272","10.74357","29.85200","0.00000","0.99272","0.65437","0.05003"
"0.65437","0.99060","10.72059","30.25200","0.00000","0.99060","0.65437","0.05003"
"0.65437","0.98909","10.70424","30.65200","0.00000","0.98909","0.65437","0.05003"
"0.65417","0.99382","10.75548","31.05200","0.00000","0.99382","0.65417","0.05001"
"0.65417","0.98867","10.69973","31.45200","0.00000","0.98867","0.65417","0.05001"
"0.65417","0.98665","10.67790","31.85200","0.00000","0.98665","0.65417","0.05001"
"0.65417","0.98313","10.63975","32.25200","0.00000","0.98313","0.65417","0.05001"
"0.65417","0.98785","10.69091","32.65200","0.00000","0.98785","0.65417","0.05001"
"0.65417","0.97803","10.58454","33.05200","0.00000","0.97803","0.65417","0.05001"
"0.65417","0.97443","10.54566","33.45200","0.00000","0.97443","0.65417","0.05001"
"0.65417","0.97384","10.53921","33.85200","0.00000","0.97384","0.65417","0.05001"
"0.65417","0.97616","10.56434","34.25200","0.00000","0.97616","0.65417","0.05001"
"0.65417","0.96979","10.49541","34.65200","0.00000","0.96979","0.65417","0.05001"
"0.65417","0.97642","10.56712","35.05200","0.00000","0.97642","0.65417","0.05001"
"0.65417","0.96602","10.45463","35.45200","0.00000","0.96602","0.65417","0.05001"
"0.65417","0.97068","10.50502","35.85200","0.00000","0.97068","0.65417","0.05001"
"0.65417","0.96975","10.49502","36.25200","0.00000","0.96975","0.65417","0.05001"
"0.65417","0.97168","10.51585","36.65200","0.00000","0.97168","0.65417","0.05001"
"0.65417","0.96903","10.48715","37.05200","0.00000","0.96903","0.65417","0.05001"
"0.65417","0.96536","10.44744","37.45200","0.00000","0.96536","0.65417","0.05001"
"0.65417","0.97194","10.51866","37.85200","0.00000","0.97194","0.65417","0.05001"
"0.65417","0.96484","10.44190","38.25200","0.00000","0.96484","0.65417","0.05001"
"0.65417","0.96379","10.43048","38.65200","0.00000","0.96379","0.65417","0.05001"
"0.65417","0.96205","10.41168","39.05200","0.00000","0.96205","0.65417","0.05001"
"0.65417","0.95878","10.37623","39.45200","0.00000","0.95878","0.65417","0.05001"
"0.65417","0.96780","10.47386","39.85200","0.00000","0.96780","0.65417","0.05001"
"0.65417","0.95915","10.38026","40.25200","0.00000","0.95915","0.65417","0.05001"
"0.65417","0.95880","10.37643","40.65200","0.00000","0.95880","0.65417","0.05001"
"0.65417","0.95979","10.38723","41.05200","0.00000","0.95979","0.65417","0.05001"
"0.65417","0.96254","10.41692","41.45200","0.00000","0.96254","0.65417","0.05001"
"0.65417","0.95621","10.34849","41.85200","0.00000","0.95621","0.65417","0.05001"
"0.65417","0.95007","10.28203","42.25200","0.00000","0.95007","0.65417","0.05001"
"0.65417","0.95917","10.38045","42.65200","0.00000","0.95917","0.65417","0.05001"
"0.65417","0.95307","10.31442","43.05200","0.00000","0.95307","0.65417","0.05001"
"0.65417","0.94954","10.27630","43.45200","0.00000","0.94954","0.65417","0.05001"
"0.65417","0.94617","10.23983","43.85200","0.00000","0.94617","0.65417","0.05001"
"0.65417","0.95317","10.31559","44.25200","0.00000","0.95317","0.65417","0.05001"
"0.65417","0.94926","10.27323","44.65200","0.00000","0.94926","0.65417","0.05001"
"0.65417","0.95003","10.28157","45.05200","0.00000","0.95003","0.65417","0.05001"
"0.65417","0.94987","10.27980","45.45200","0.00000","0.94987","0.65417","0.05001"
"0.65417","0.93952","10.16780","45.85200","0.00000","0.93952","0.65417","0.05001"
"0.65417","0.94357","10.21164","46.25200","0.00000","0.94357","0.65417","0.05001"
"0.65417","0.94591","10.23696","46.65200","0.00000","0.94591","0.65417","0.05001"
"0.65417","0.94653","10.24369","47.05200","0.00000","0.94653","0.65417","0.05001"
"0.65417","0.95145","10.29694","47.45200","0.00000","0.95145","0.65417","0.05001"
"0.65417","0.93367","10.10452","47.85200","0.00000","0.93367","0.65417","0.05001"
"0.65417","0.94176","10.19205","48.25200","0.00000","0.94176","0.65417","0.05001"
"0.65417","0.94204","10.19512","48.65200","0.00000","0.94204","0.65417","0.05001"
"0.65417","0.94343","10.21016","49.05200","0.00000","0.94343","0.65417","0.05001"
"0.65417","0.93359","10.10369","49.45200","0.00000","0.93359","0.65417","0.05001"
"0.65417","0.94421","10.21861","49.85200","0.00000","0.94421","0.65417","0.05001"
"0.65417","0.93793","10.15064","50.25200","0.00000","0.93793","0.65417","0.05001"
"0.65417","0.93620","10.13185","50.65200","0.00000","0.93620","0.65417","0.05001"
"0.65417","0.93739","10.14481","51.05200","0.00000","0.93739","0.65417","0.05001"
"0.65417","0.93525","10.12166","51.45200","0.00000","0.93525","0.65417","0.05001"
"0.65417","0.93917","10.16403","51.85200","0.00000","0.93917","0.65417","0.05001"
"0.65417","0.93375","10.10543","52.25200","0.00000","0.93375","0.65417","0.05001"
"0.65417","0.92689","10.03114","52.65200","0.00000","0.92689","0.65417","0.05001"
"0.65417","0.93609","10.13067","53.05200","0.00000","0.93609","0.65417","0.05001"
"0.65417","0.92939","10.05821","53.45200","0.00000","0.92939","0.65417","0.05001"
"0.65417","0.93148","10.08083","53.85200","0.00000","0.93148","0.65417","0.05001"
"0.65417","0.92938","10.05814","54.25200","0.00000","0.92938","0.65417","0.05001"
"0.65417","0.92844","10.04791","54.65200","0.00000","0.92844","0.65417","0.05001"
"0.65417","0.93324","10.09984","55.05200","0.00000","0.93324","0.65417","0.05001"
"0.65417","0.92958","10.06024","55.45200","0.00000","0.92958","0.65417","0.05001"
"0.65417","0.93568","10.12629","55.85200","0.00000","0.93568","0.65417","0.05001"
"0.65417","0.93246","10.09142","56.25200","0.00000","0.93246","0.65417","0.05001"
"0.65417","0.92476","10.00811","56.65200","0.00000","0.92476","0.65417","0.05001"
"0.65417","0.93058","10.07108","57.05200","0.00000","0.93058","0.65417","0.05001"
"0.65417","0.92515","10.01233","57.45200","0.00000","0.92515","0.65417","0.05001"
"0.65417","0.92165","9.97447","57.85200","0.00000","0.92165","0.65417","0.05001"
"0.65417","0.92934","10.05762","58.25200","0.00000","0.92934","0.65417","0.05001"
"0.65417","0.92393","9.99915","58.65200","0.00000","0.92393","0.65417","0.05001"
"0.65417","0.91633","9.91684","59.05200","0.00000","0.91633","0.65417","0.05001"
"0.65417","0.92145","9.97223","59.45200","0.00000","0.92145","0.65417","0.05001"
"0.65417","0.91323","9.88335","59.85200","0.00000","0.91323","0.65417","0.05001"
"0.65417","0.92220","9.98043","60.25200","0.00000","0.92220","0.65417","0.05001"
"0.65417","0.91452","9.89725","60.65200","0.00000","0.91452","0.65417","0.05001"
"0.65417","0.92184","9.97651","61.05200","0.00000","0.92184","0.65417","0.05001"
"0.65417","0.91979","9.95433","61.45200","0.00000","0.91979","0.65417","0.05001"
"0.65417","0.91263","9.87681","61.85200","0.00000","0.91263","0.65417","0.05001"
"0.65417","0.91836","9.93881","62.25200","0.00000","0.91836","0.65417","0.05001"
"0.65417","0.92422","10.00219","62.65200","0.00000","0.92422","0.65417","0.05001"
"0.65417","0.92113","9.96879","63.05200","0.00000","0.92113","0.65417","0.05001"
"0.65417","0.91705","9.92466","63.45200","0.00000","0.91705","0.65417","0.05001"
"0.65417","0.92537","10.01472","63.85200","0.00000","0.92537","0.65417","0.05001"
"0.65417","0.92354","9.99492","64.25200","0.00000","0.92354","0.65417","0.05001"
"0.65417","0.92481","10.00867","64.65200","0.00000","0.92481","0.65417","0.05001"
"0.65417","0.91862","9.94161","65.05200","0.00000","0.91862","0.65417","0.05001"
"0.65417","0.92801","10.04321","65.45200","0.00000","0.92801","0.65417","0.05001"
"0.65417","0.91628","9.91632","65.85200","0.00000","0.91628","0.65417","0.05001"
"0.65417","0.91968","9.95308","66.25200","0.00000","0.91968","0.65417","0.05001"
"0.65417","0.91213","9.87140","66.65200","0.00000","0.91213","0.65417","0.05001"
"0.65417","0.91756","9.93020","67.05200","0.00000","0.91756","0.65417","0.05001"
"0.65417","0.90904","9.83797","67.45200","0.00000","0.90904","0.65417","0.05001"
"0.65417","0.90973","9.84542","67.85200","0.00000","0.90973","0.65417","0.05001"
"0.65417","0.91439","9.89586","68.25200","0.00000","0.91439","0.65417","0.05001"
"0.65417","0.90812","9.82799","68.65200","0.00000","0.90812","0.65417","0.05001"
"0.65417","0.90988","9.84701","69.05200","0.00000","0.90988","0.65417","0.05001"
"0.65417","0.91011","9.84951","69.45200","0.00000","0.91011","0.65417","0.05001"
"0.65417","0.91245","9.87489","69.85200","0.00000","0.91245","0.65417","0.05001"
"0.65417","0.90794","9.82602","70.25200","0.00000","0.90794","0.65417","0.05001"
"0.65417","0.91235","9.87382","70.65200","0.00000","0.91235","0.65417","0.05001"
"0.65417","0.91916","9.94744","71.05200","0.00000","0.91916","0.65417","0.05001"
"0.65417","0.90976","9.84579","71.45200","0.00000","0.90976","0.65417","0.05001"
"0.65417","0.91178","9.86761","71.85200","0.00000","0.91178","0.65417","0.05001"
"0.65417","0.91069","9.85584","72.25200","0.00000","0.91069","0.65417","0.05001"
"0.65417","0.91077","9.85671","72.65200","0.00000","0.91077","0.65417","0.05001"
"0.65417","0.90213","9.76320","73.05200","0.00000","0.90213","0.65417","0.05001"
"0.65417","0.90979","9.84610","73.45200","0.00000","0.90979","0.65417","0.05001"
"0.65417","0.90945","9.84244","73.85200","0.00000","0.90945","0.65417","0.05001"
"0.65417","0.90511","9.79542","74.25200","0.00000","0.90511","0.65417","0.05001"
"0.65417","0.90475","9.79156","74.65200","0.00000","0.90475","0.65417","0.05001"
"0.65417","0.90867","9.83399","75.05200","0.00000","0.90867","0.65417","0.05001"
"0.65417","0.89764","9.71454","75.45200","0.00000","0.89764","0.65417","0.05001"
"0.65417","0.90195","9.76124","75.85200","0.00000","0.90195","0.65417","0.05001"
"0.65417","0.89176","9.65092","76.25200","0.00000","0.89176","0.65417","0.05001"
"0.65417","0.89498","9.68579","76.65200","0.00000","0.89498","0.65417","0.05001"
"0.65417","0.89091","9.64172","77.05200","0.00000","0.89091","0.65417","0.05001"
"0.65417","0.89245","9.65839","77.45200","0.00000","0.89245","0.65417","0.05001"
"0.65417","0.89128","9.64577","77.85200","0.00000","0.89128","0.65417","0.05001"
"0.65417","0.89109","9.64371","78.25200","0.00000","0.89109","0.65417","0.05001"
"0.65417","0.88740","9.60378","78.65200","0.00000","0.88740","0.65417","0.05001"
"0.65417","0.88945","9.62591","79.05200","0.00000","0.88945","0.65417","0.05001"
"0.65417","0.89535","9.68977","79.45200","0.00000","0.89535","0.65417","0.05001"
"0.65417","0.89002","9.63210","79.85200","0.00000","0.89002","0.65417","0.05001"
"0.65417","0.89906","9.72993","80.25200","0.00000","0.89906","0.65417","0.05001"
"0.65417","0.89644","9.70160","80.65200","0.00000","0.89644","0.65417","0.05001"
"0.65417","0.89182","9.65164","81.05200","0.00000","0.89182","0.65417","0.05001"
"0.65417","0.89746","9.71260","81.45200","0.00000","0.89746","0.65417","0.05001"
"0.65417","0.89335","9.66817","81.85200","0.00000","0.89335","0.65417","0.05001"
"0.65417","0.90199","9.76161","82.25200","0.00000","0.90199","0.65417","0.05001"
"0.65417","0.89541","9.69039","82.65200","0.00000","0.89541","0.65417","0.05001"
"0.65417","0.90534","9.79786","83.05200","0.00000","0.90534","0.65417","0.05001"
"0.65417","0.89594","9.69620","83.45200","0.00000","0.89594","0.65417","0.05001"
"0.65417","0.90237","9.76577","83.85200","0.00000","0.90237","0.65417","0.05001"
"0.65417","0.90060","9.74660","84.25200","0.00000","0.90060","0.65417","0.05001"
"0.65417","0.89266","9.66068","84.65200","0.00000","0.89266","0.65417","0.05001"
"0.65417","0.89560","9.69253","85.05200","0.00000","0.89560","0.65417","0.05001"
"0.65417","0.89266","9.66072","85.45200","0.00000","0.89266","0.65417","0.05001"
"0.65417","0.90508","9.79512","85.85200","0.00000","0.90508","0.65417","0.05001"
"0.65417","0.89860","9.72501","86.25200","0.00000","0.89860","0.65417","0.05001"
"0.65417","0.89931","9.73269","86.65200","0.00000","0.89931","0.65417","0.05001"
"0.65417","0.90523","9.79670","87.05200","0.00000","0.90523","0.65417","0.05001"
"0.65417","0.89658","9.70308","87.45200","0.00000","0.89658","0.65417","0.05001"
"0.65417","0.89784","9.71677","87.85200","0.00000","0.89784","0.65417","0.05001"
"0.65417","0.89878","9.72693","88.25200","0.00000","0.89878","0.65417","0.05001"
"0.65417","0.89752","9.71331","88.65200","0.00000","0.89752","0.65417","0.05001"
"0.65417","0.89475","9.68327","89.05200","0.00000","0.89475","0.65417","0.05001"
"0.65417","0.89745","9.71254","89.45200","0.00000","0.89745","0.65417","0.05001"
"0.65417","0.89491","9.68501","89.85200","0.00000","0.89491","0.65417","0.05001"
"0.65417","0.88625","9.59129","90.25200","0.00000","0.88625","0.65417","0.05001"
"0.65417","0.89382","9.67321","90.65200","0.00000","0.89382","0.65417","0.05001"
"0.65417","0.89343","9.66906","91.05200","0.00000","0.89343","0.65417","0.05001"
"0.65417","0.89398","9.67501","91.45200","0.00000","0.89398","0.65417","0.05001"
"0.65417","0.88659","9.59494","91.85200","0.00000","0.88659","0.65417","0.05001"
"0.65417","0.88792","9.60937","92.25200","0.00000","0.88792","0.65417","0.05001"
"0.65417","0.89718","9.70960","92.65200","0.00000","0.89718","0.65417","0.05001"
"0.65417","0.89573","9.69393","93.05200","0.00000","0.89573","0.65417","0.05001"
"0.65417","0.89476","9.68338","93.45200","0.00000","0.89476","0.65417","0.05001"
"0.65417","0.89212","9.65479","93.85200","0.00000","0.89212","0.65417","0.05001"
"0.65417","0.88935","9.62490","94.25200","0.00000","0.88935","0.65417","0.05001"
"0.65417","0.89311","9.66552","94.65200","0.00000","0.89311","0.65417","0.05001"
"0.65417","0.89302","9.66459","95.05200","0.00000","0.89302","0.65417","0.05001"
"0.65417","0.89225","9.65628","95.45200","0.00000","0.89225","0.65417","0.05001"
"0.65417","0.89858","9.72478","95.85200","0.00000","0.89858","0.65417","0.05001"
"0.65417","0.88875","9.61840","96.25200","0.00000","0.88875","0.65417","0.05001"
"0.65417","0.89298","9.66413","96.65200","0.00000","0.89298","0.65417","0.05001"
"0.65417","0.88066","9.53080","97.05200","0.00000","0.88066","0.65417","0.05001"
"0.65417","0.89205","9.65404","97.45200","0.00000","0.89205","0.65417","0.05001"
"0.65417","0.87790","9.50090","97.85200","0.00000","0.87790","0.65417","0.05001"
"0.65417","0.88403","9.56731","98.25200","0.00000","0.88403","0.65417","0.05001"
"0.65417","0.88824","9.61287","98.65200","0.00000","0.88824","0.65417","0.05001"
"0.65417","0.88789","9.60904","99.05200","0.00000","0.88789","0.65417","0.05001"
"0.65417","0.88504","9.57819","99.45200","0.00000","0.88504","0.65417","0.05001"
"0.65417","0.88715","9.60102","99.85200","0.00000","0.88715","0.65417","0.05001"
"0.65417","0.88994","9.63122","100.25200","0.00000","0.88994","0.65417","0.05001"
"0.65417","0.88261","9.55190","100.65200","0.00000","0.88261","0.65417","0.05001"
"0.65417","0.88453","9.57272","101.05200","0.00000","0.88453","0.65417","0.05001"
"0.65417","0.88653","9.59434","101.45200","0.00000","0.88653","0.65417","0.05001"
"0.65417","0.88845","9.61517","101.85200","0.00000","0.88845","0.65417","0.05001"
"0.65417","0.88453","9.57274","102.25200","0.00000","0.88453","0.65417","0.05001"
"0.65417","0.88729","9.60256","102.65200","0.00000","0.88729","0.65417","0.05001"
"0.65417","0.89750","9.71301","103.05200","0.00000","0.89750","0.65417","0.05001"
"0.65417","0.89143","9.64740","103.45200","0.00000","0.89143","0.65417","0.05001"
"0.65417","0.88757","9.60555","103.85200","0.00000","0.88757","0.65417","0.05001"
"0.65417","0.89245","9.65845","104.25200","0.00000","0.89245","0.65417","0.05001"
"0.65417","0.89299","9.66425","104.65200","0.00000","0.89299","0.65417","0.05001"
"0.65417","0.89254","9.65942","105.05200","0.00000","0.89254","0.65417","0.05001"
"0.65417","0.88540","9.58207","105.45200","0.00000","0.88540","0.65417","0.05001"
"0.65417","0.89339","9.66857","105.85200","0.00000","0.89339","0.65417","0.05001"
"0.65417","0.88707","9.60022","106.25200","0.00000","0.88707","0.65417","0.05001"
"0.65417","0.89185","9.65195","106.65200","0.00000","0.89185","0.65417","0.05001"
"0.65417","0.88120","9.53664","107.05200","0.00000","0.88120","0.65417","0.05001"
"0.65417","0.89471","9.68287","107.45200","0.00000","0.89471","0.65417","0.05001"
"0.65417","0.88037","9.52764","107.85200","0.00000","0.88037","0.65417","0.05001"
"0.65417","0.88501","9.57786","108.25200","0.00000","0.88501","0.65417","0.05001"
"0.65417","0.88802","9.61045","108.65200","0.00000","0.88802","0.65417","0.05001"
"0.65417","0.88556","9.58381","109.05200","0.00000","0.88556","0.65417","0.05001"
"0.65417","0.89342","9.66894","109.45200","0.00000","0.89342","0.65417","0.05001"
"0.65417","0.89284","9.66266","109.85200","0.00000","0.89284","0.65417","0.05001"
"0.65417","0.88724","9.60203","110.25200","0.00000","0.88724","0.65417","0.05001"
"0.65417","0.89030","9.63512","110.65200","0.00000","0.89030","0.65417","0.05001"
"0.65417","0.88656","9.59467","111.05200","0.00000","0.88656","0.65417","0.05001"
"0.65417","0.88970","9.62866","111.45200","0.00000","0.88970","0.65417","0.05001"
"0.65417","0.89499","9.68595","111.85200","0.00000","0.89499","0.65417","0.05001"
"0.65417","0.89104","9.64317","112.25200","0.00000","0.89104","0.65417","0.05001"
"0.65417","0.88672","9.59637","112.65200","0.00000","0.88672","0.65417","0.05001"
"0.65417","0.89040","9.63622","113.05200","0.00000","0.89040","0.65417","0.05001"
"0.65417","0.89407","9.67598","113.45200","0.00000","0.89407","0.65417","0.05001"
"0.65417","0.89584","9.69509","113.85200","0.00000","0.89584","0.65417","0.05001"
"0.65417","0.88954","9.62687","114.25200","0.00000","0.88954","0.65417","0.05001"
"0.65417","0.88920","9.62321","114.65200","0.00000","0.88920","0.65417","0.05001"
"0.65417","0.89475","9.68333","115.05200","0.00000","0.89475","0.65417","0.05001"
"0.65417","0.88995","9.63135","115.45200","0.00000","0.88995","0.65417","0.05001"
"0.65417","0.88334","9.55987","115.85200","0.00000","0.88334","0.65417","0.05001"
"0.65417","0.88929","9.62417","116.25200","0.00000","0.88929","0.65417","0.05001"
"0.65417","0.89001","9.63204","116.65200","0.00000","0.89001","0.65417","0.05001"
"0.65417","0.89116","9.64446","117.05200","0.00000","0.89116","0.65417","0.05001"
"0.65417","0.88878","9.61874","117.45200","0.00000","0.88878","0.65417","0.05001"
"0.65417","0.88915","9.62271","117.85200","0.00000","0.88915","0.65417","0.05001"
"0.65417","0.88992","9.63099","118.25200","0.00000","0.88992","0.65417","0.05001"
"0.65417","0.88914","9.62254","118.65200","0.00000","0.88914","0.65417","0.05001"
"0.65417","0.89372","9.67219","119.05200","0.00000","0.89372","0.65417","0.05001"
"0.65417","0.89278","9.66195","119.45200","0.00000","0.89278","0.65417","0.05001"
"0.65417","0.89176","9.65097","119.85200","0.00000","0.89176","0.65417","0.05001"
"0.65417","0.88643","9.59324","120.25200","0.00000","0.88643","0.65417","0.05001"
"0.65417","0.89359","9.67078","120.65200","0.00000","0.89359","0.65417","0.05001"
"0.65417","0.89347","9.66941","121.05200","0.00000","0.89347","0.65417","0.05001"
"0.65417","0.89078","9.64034","121.45200","0.00000","0.89078","0.65417","0.05001"
"0.65417","0.88969","9.62859","121.85200","0.00000","0.88969","0.65417","0.05001"
"0.65417","0.89711","9.70884","122.25200","0.00000","0.89711","0.65417","0.05001"
"0.65417","0.88781","9.60819","122.65200","0.00000","0.88781","0.65417","0.05001"
"0.65417","0.89391","9.67425","123.05200","0.00000","0.89391","0.65417","0.05001"
"0.65417","0.89404","9.67560","123.45200","0.00000","0.89404","0.65417","0.05001"
"0.65417","0.89005","9.63240","123.85200","0.00000","0.89005","0.65417","0.05001"
"0.65417","0.89123","9.64516","124.25200","0.00000","0.89123","0.65417","0.05001"
"0.65417","0.89067","9.63910","124.65200","0.00000","0.89067","0.65417","0.05001"
"0.65417","0.89804","9.71893","125.05200","0.00000","0.89804","0.65417","0.05001"
"0.65417","0.89466","9.68228","125.45200","0.00000","0.89466","0.65417","0.05001"
"0.65417","0.89668","9.70417","125.85200","0.00000","0.89668","0.65417","0.05001"
"0.65417","0.89308","9.66522","126.25200","0.00000","0.89308","0.65417","0.05001"
"0.65417","0.88894","9.62044","126.65200","0.00000","0.88894","0.65417","0.05001"
"0.65417","0.90482","9.79230","127.05200","0.00000","0.90482","0.65417","0.05001"
"0.65417","0.89067","9.63910","127.45200","0.00000","0.89067","0.65417","0.05001"
"0.65417","0.88905","9.62158","127.85200","0.00000","0.88905","0.65417","0.05001"
"0.65417","0.89308","9.66518","128.25200","0.00000","0.89308","0.65417","0.05001"
"0.65417","0.89791","9.71745","128.65200","0.00000","0.89791","0.65417","0.05001"
"0.65417","0.89775","9.71579","129.05200","0.00000","0.89775","0.65417","0.05001"
"0.65417","0.90045","9.74505","129.45200","0.00000","0.90045","0.65417","0.05001"
"0.65417","0.90622","9.80745","129.85200","0.00000","0.90622","0.65417","0.05001"
"0.65417","0.90342","9.77715","130.25200","0.00000","0.90342","0.65417","0.05001"
"0.65417","0.90030","9.74336","130.65200","0.00000","0.90030","0.65417","0.05001"
"0.65417","0.89040","9.63618","131.05200","0.00000","0.89040","0.65417","0.05001"
"0.65417","0.88933","9.62460","131.45200","0.00000","0.88933","0.65417","0.05001"
"0.65417","0.89416","9.67696","131.85200","0.00000","0.89416","0.65417","0.05001"
"0.65417","0.90163","9.75772","132.25200","0.00000","0.90163","0.65417","0.05001"
"0.65417","0.89862","9.72522","132.65200","0.00000","0.89862","0.65417","0.05001"
"0.65417","0.90424","9.78603","133.05200","0.00000","0.90424","0.65417","0.05001"
"0.65417","0.90115","9.75254","133.45200","0.00000","0.90115","0.65417","0.05001"
"0.65417","0.89411","9.67636","133.85200","0.00000","0.89411","0.65417","0.05001"
"0.65417","0.89035","9.63573","134.25200","0.00000","0.89035","0.65417","0.05001"
"0.65417","0.90640","9.80943","134.65200","0.00000","0.90640","0.65417","0.05001"
"0.65417","0.89457","9.68141","135.05200","0.00000","0.89457","0.65417","0.05001"
"0.65417","0.90702","9.81606","135.45200","0.00000","0.90702","0.65417","0.05001"
"0.65417","0.89335","9.66816","135.85200","0.00000","0.89335","0.65417","0.05001"
"0.65417","0.89876","9.72672","136.25200","0.00000","0.89876","0.65417","0.05001"
"0.65417","0.90028","9.74319","136.65200","0.00000","0.90028","0.65417","0.05001"
"0.65417","0.88684","9.59773","137.05200","0.00000","0.88684","0.65417","0.05001"
"0.65417","0.88891","9.62011","137.45200","0.00000","0.88891","0.65417","0.05001"
"0.65417","0.89758","9.71388","137.85200","0.00000","0.89758","0.65417","0.05001"
"0.65417","0.88698","9.59922","138.25200","0.00000","0.88698","0.65417","0.05001"
"0.65417","0.89593","9.69609","138.65200","0.00000","0.89593","0.65417","0.05001"
"0.65417","0.89145","9.64754","139.05200","0.00000","0.89145","0.65417","0.05001"
"0.65417","0.89147","9.64783","139.45200","0.00000","0.89147","0.65417","0.05001"
"0.65417","0.89688","9.70635","139.85200","0.00000","0.89688","0.65417","0.05001"
"0.65417","0.89975","9.73738","140.25200","0.00000","0.89975","0.65417","0.05001"
"0.65417","0.90389","9.78223","140.65200","0.00000","0.90389","0.65417","0.05001"
"0.65417","0.89855","9.72446","141.05200","0.00000","0.89855","0.65417","0.05001"
"0.65417","0.90564","9.80115","141.45200","0.00000","0.90564","0.65417","0.05001"
"0.65417","0.89961","9.73591","141.85200","0.00000","0.89961","0.65417","0.05001"
"0.65417","0.90161","9.75756","142.25200","0.00000","0.90161","0.65417","0.05001"
"0.65417","0.89693","9.70687","142.65200","0.00000","0.89693","0.65417","0.05001"
"0.65417","0.89883","9.72746","143.05200","0.00000","0.89883","0.65417","0.05001"
"0.65417","0.90181","9.75975","143.45200","0.00000","0.90181","0.65417","0.05001"
"0.65417","0.90217","9.76362","143.85200","0.00000","0.90217","0.65417","0.05001"
"0.65417","0.89543","9.69064","144.25200","0.00000","0.89543","0.65417","0.05001"
"0.65417","0.89075","9.64000","144.65200","0.00000","0.89075","0.65417","0.05001"
"0.65417","0.90248","9.76693","145.05200","0.00000","0.90248","0.65417","0.05001"
"0.65417","0.90841","9.83117","145.45200","0.00000","0.90841","0.65417","0.05001"
"0.65417","0.89894","9.72861","145.85200","0.00000","0.89894","0.65417","0.05001"
"0.65417","0.90150","9.75637","146.25200","0.00000","0.90150","0.65417","0.05001"
"0.65417","0.89506","9.68669","146.65200","0.00000","0.89506","0.65417","0.05001"
"0.65417","0.90067","9.74733","147.05200","0.00000","0.90067","0.65417","0.05001"
"0.65417","0.90510","9.79530","147.45200","0.00000","0.90510","0.65417","0.05001"
"0.65417","0.90303","9.77289","147.85200","0.00000","0.90303","0.65417","0.05001"
"0.65417","0.90386","9.78195","148.25200","0.00000","0.90386","0.65417","0.05001"
"0.65417","0.90487","9.79287","148.65200","0.00000","0.90487","0.65417","0.05001"
"0.65417","0.90512","9.79557","149.05200","0.00000","0.90512","0.65417","0.05001"
"0.65417","0.90765","9.82293","149.45200","0.00000","0.90765","0.65417","0.05001"
"0.65417","0.90480","9.79208","149.85200","0.00000","0.90480","0.65417","0.05001"
"0.65417","0.90448","9.78860","150.25200","0.00000","0.90448","0.65417","0.05001"
"0.65417","0.90653","9.81084","150.65200","0.00000","0.90653","0.65417","0.05001"
"0.65417","0.90472","9.79123","151.05200","0.00000","0.90472","0.65417","0.05001"
"0.65417","0.90411","9.78456","151.45200","0.00000","0.90411","0.65417","0.05001"
"0.65417","0.90710","9.81691","151.85200","0.00000","0.90710","0.65417","0.05001"
"0.65417","0.90133","9.75452","152.25200","0.00000","0.90133","0.65417","0.05001"
"0.65417","0.90076","9.74832","152.65200","0.00000","0.90076","0.65417","0.05001"
"0.65417","0.90656","9.81108","153.05200","0.00000","0.90656","0.65417","0.05001"
"0.65417","0.90885","9.83595","153.45200","0.00000","0.90885","0.65417","0.05001"
"0.65417","0.90840","9.83105","153.85200","0.00000","0.90840","0.65417","0.05001"
"0.65417","0.90438","9.78748","154.25200","0.00000","0.90438","0.65417","0.05001"
"0.65417","0.90951","9.84305","154.65200","0.00000","0.90951","0.65417","0.05001"
"0.65417","0.90395","9.78288","155.05200","0.00000","0.90395","0.65417","0.05001"
"0.65417","0.89939","9.73347","155.45200","0.00000","0.89939","0.65417","0.05001"
"0.65417","0.90146","9.75593","155.85200","0.00000","0.90146","0.65417","0.05001"
"0.65417","0.90260","9.76825","156.25200","0.00000","0.90260","0.65417","0.05001"
"0.65417","0.90400","9.78344","156.65200","0.00000","0.90400","0.65417","0.05001"
"0.65417","0.90396","9.78299","157.05200","0.00000","0.90396","0.65417","0.05001"
"0.65417","0.90672","9.81279","157.45200","0.00000","0.90672","0.65417","0.05001"
"0.65417","0.90718","9.81780","157.85200","0.00000","0.90718","0.65417","0.05001"
"0.65417","0.90599","9.80494","158.25200","0.00000","0.90599","0.65417","0.05001"
"0.65417","0.90822","9.82905","158.65200","0.00000","0.90822","0.65417","0.05001"
"0.65417","0.90370","9.78016","159.05200","0.00000","0.90370","0.65417","0.05001"
"0.65417","0.90089","9.74978","159.45200","0.00000","0.90089","0.65417","0.05001"
"0.65417","0.91359","9.88723","159.85200","0.00000","0.91359","0.65417","0.05001"
"0.65417","0.90465","9.79041","160.25200","0.00000","0.90465","0.65417","0.05001"
"0.65417","0.91149","9.86443","160.65200","0.00000","0.91149","0.65417","0.05001"
"0.65417","0.91581","9.91127","161.05200","0.00000","0.91581","0.65417","0.05001"
"0.65417","0.90813","9.82806","161.45200","0.00000","0.90813","0.65417","0.05001"
"0.65417","0.90388","9.78213","161.85200","0.00000","0.90388","0.65417","0.05001"
"0.65417","0.90499","9.79414","162.25200","0.00000","0.90499","0.65417","0.05001"
"0.65417","0.90928","9.84055","162.65200","0.00000","0.90928","0.65417","0.05001"
"0.65417","0.91152","9.86483","163.05200","0.00000","0.91152","0.65417","0.05001"
"0.65417","0.91205","9.87056","163.45200","0.00000","0.91205","0.65417","0.05001"
"0.65417","0.91968","9.95313","163.85200","0.00000","0.91968","0.65417","0.05001"
"0.65417","0.91255","9.87593","164.25200","0.00000","0.91255","0.65417","0.05001"
"0.65417","0.90985","9.84668","164.65200","0.00000","0.90985","0.65417","0.05001"
"0.65417","0.90525","9.79691","165.05200","0.00000","0.90525","0.65417","0.05001"
"0.65417","0.91545","9.90730","165.45200","0.00000","0.91545","0.65417","0.05001"
"0.65417","0.90818","9.82862","165.85200","0.00000","0.90818","0.65417","0.05001"
"0.65417","0.91627","9.91617","166.25200","0.00000","0.91627","0.65417","0.05001"
"0.65417","0.91823","9.93743","166.65200","0.00000","0.91823","0.65417","0.05001"
"0.65417","0.91428","9.89462","167.05200","0.00000","0.91428","0.65417","0.05001"
"0.65417","0.90178","9.75937","167.45200","0.00000","0.90178","0.65417","0.05001"
"0.65417","0.91052","9.85398","167.85200","0.00000","0.91052","0.65417","0.05001"
"0.65417","0.90726","9.81867","168.25200","0.00000","0.90726","0.65417","0.05001"
"0.65417","0.90533","9.79781","168.65200","0.00000","0.90533","0.65417","0.05001"
"0.65417","0.90779","9.82441","169.05200","0.00000","0.90779","0.65417","0.05001"
"0.65417","0.90971","9.84521","169.45200","0.00000","0.90971","0.65417","0.05001"
"0.65417","0.90558","9.80053","169.85200","0.00000","0.90558","0.65417","0.05001"
"0.65417","0.91554","9.90830","170.25200","0.00000","0.91554","0.65417","0.05001"
"0.65417","0.91378","9.88925","170.65200","0.00000","0.91378","0.65417","0.05001"
"0.65417","0.91135","9.86291","171.05200","0.00000","0.91135","0.65417","0.05001"
"0.65417","0.91163","9.86599","171.45200","0.00000","0.91163","0.65417","0.05001"
"0.65417","0.90935","9.84131","171.85200","0.00000","0.90935","0.65417","0.05001"
"0.65417","0.90650","9.81050","172.25200","0.00000","0.90650","0.65417","0.05001"
"0.65417","0.90985","9.84673","172.65200","0.00000","0.90985","0.65417","0.05001"
"0.65417","0.90182","9.75979","173.05200","0.00000","0.90182","0.65417","0.05001"
"0.65417","0.90716","9.81765","173.45200","0.00000","0.90716","0.65417","0.05001"
"0.65417","0.91297","9.88044","173.85200","0.00000","0.91297","0.65417","0.05001"
"0.65417","0.90153","9.75664","174.25200","0.00000","0.90153","0.65417","0.05001"
"0.65417","0.90662","9.81175","174.65200","0.00000","0.90662","0.65417","0.05001"
"0.65417","0.91094","9.85848","175.05200","0.00000","0.91094","0.65417","0.05001"
"0.65417","0.90974","9.84552","175.45200","0.00000","0.90974","0.65417","0.05001"
"0.65417","0.91109","9.86015","175.85200","0.00000","0.91109","0.65417","0.05001"
"0.65417","0.91174","9.86720","176.25200","0.00000","0.91174","0.65417","0.05001"
"0.65417","0.90886","9.83604","176.65200","0.00000","0.90886","0.65417","0.05001"
"0.65417","0.91028","9.85142","177.05200","0.00000","0.91028","0.65417","0.05001"
"0.65417","0.90967","9.84476","177.45200","0.00000","0.90967","0.65417","0.05001"
"0.65417","0.91044","9.85313","177.85200","0.00000","0.91044","0.65417","0.05001"
"0.65417","0.90920","9.83968","178.25200","0.00000","0.90920","0.65417","0.05001"
"0.65417","0.91410","9.89267","178.65200","0.00000","0.91410","0.65417","0.05001"
"0.65417","0.91534","9.90611","179.05200","0.00000","0.91534","0.65417","0.05001"
"0.65417","0.91466","9.89880","179.45200","0.00000","0.91466","0.65417","0.05001"
"0.65417","0.91625","9.91603","179.85200","0.00000","0.91625","0.65417","0.05001"
"0.65417","0.90898","9.83730","180.25200","0.00000","0.90898","0.65417","0.05001"
"0.65417","0.90733","9.81942","180.65200","0.00000","0.90733","0.65417","0.05001"
"0.65417","0.91536","9.90636","181.05200","0.00000","0.91536","0.65417","0.05001"
"0.65417","0.91711","9.92534","181.45200","0.00000","0.91711","0.65417","0.05001"
"0.65417","0.92020","9.95877","181.85200","0.00000","0.92020","0.65417","0.05001"
"0.65417","0.91601","9.91335","182.25200","0.00000","0.91601","0.65417","0.05001"
"0.65417","0.91201","9.87015","182.65200","0.00000","0.91201","0.65417","0.05001"
"0.65417","0.91685","9.92252","183.05200","0.00000","0.91685","0.65417","0.05001"
"0.65417","0.92392","9.99904","183.45200","0.00000","0.92392","0.65417","0.05001"
"0.65417","0.91505","9.90299","183.85200","0.00000","0.91505","0.65417","0.05001"
"0.65417","0.92034","9.96023","184.25200","0.00000","0.92034","0.65417","0.05001"
"0.65417","0.91039","9.85254","184.65200","0.00000","0.91039","0.65417","0.05001"
"0.65417","0.91240","9.87431","185.05200","0.00000","0.91240","0.65417","0.05001"
"0.65417","0.92252","9.98389","185.45200","0.00000","0.92252","0.65417","0.05001"
"0.65417","0.91647","9.91832","185.85200","0.00000","0.91647","0.65417","0.05001"
"0.65417","0.91357","9.88699","186.25200","0.00000","0.91357","0.65417","0.05001"
"0.65417","0.91621","9.91560","186.65200","0.00000","0.91621","0.65417","0.05001"
"0.65417","0.92481","10.00866","187.05200","0.00000","0.92481","0.65417","0.05001"
"0.65417","0.92050","9.96203","187.45200","0.00000","0.92050","0.65417","0.05001"
"0.65417","0.91730","9.92733","187.85200","0.00000","0.91730","0.65417","0.05001"